Workbook

Sheet 表紙・条件
B1: 御 見 積 書
B3: 工事名称 | C3: （仮称）サンフレッチェ広島 三矢寮新築工事
B4: 工事場所 | C4: 広島県安芸高田市吉田町西浦字日南山835-27
B5: 見積範囲 | C5: 機械設備工事のうち 空調設備工事（空気調和設備・換気設備）
B6: 設計図書 | C6: ベース: 機械設備図 06（若本建築事務所 '26.1.31 図面No.機械1～36）／追加: 金額変更案検討図 08（No1～6のうち空調換気に係る No3・4 ロスナイ中止、No5・6 空調追加）
B7: 工期(参考) | C7: 2026年5月1日～2027年2月15日（詳細工程表 2026.8.18 共栄店舗）
B8: 見積作成日 | C8: 2026年10月5日
B10: ■ 前提条件
B11: 1. 機器 | C11: 空調・換気機器（室内機・室外機・リモコン・換気扇・全熱交換器・屋外機架台・ドレンアップ等 機器表記載の本体および付属品）は元請支給とし、本見積には機器費を含みません。据付労務・据付用副資材・配管・ダクト・保温・試運転調整のみ計上しています。
B12: 2. 工事区分 | C12: 機器の電源供給（電源配線・接地）は電気工事。機器付属の制御盤およびリモコン制御の配管・配線（工事区分表「機械」）は本工事。基礎・躯体貫通穴明け・スリーブ穴埋め・天井点検口は建築工事（工事区分表による）。
B13: 3. 数量 | C13: 数量は図面から拾い出した値です。PDF図面のベクトルデータから配管・ダクト線の平面延長を機械的に計測した値を「実測」、図面に表記のない立上り・立下り・機器接続部・配管経路未記載部（追AC）を経験則で推定した値を「推測」として明細の「根拠」欄に区分しています。台数は「図面カウント」としています。
B14: 4. 朱書き | C14: 図面08（金額変更案検討図）に基づく追加・変更項目は明細で赤字（区分「08」）で表示しています。ロスナイ中止はベース計上分の減額と代替機器の計上を併記しています。
B15: 5. 単価 | C15: 単価は本見積作成用の仮単価（材工共・税抜）です。「単価仮定」シートを参照のうえ、自社の複合単価・実勢価格に置き換えてご使用ください。
B16: 6. 除外 | C16: 電気工事（電源・接地・インバータ盤）、基礎・躯体工事、天井点検口、衛生・消火・ガス・浄化槽設備、自動制御設備（特記 ○）、共通仮設、産廃処分費（諸経費に含むものとする）。
B17: 7. 要確認事項 | C17: ①冷媒管 被覆銅管の仕様（特記仕様書は脱酸銅管/被覆銅管とも未選択、管種凡例は被覆銅管）。②ドレン管保温の要否（特記 保温表は空欄）。③厨房フード①～④の工事区分（機械図 フードリストに記載）。④追AC トリプル用分岐管の支給範囲。⑤ロスナイ中止後の OA 側ダクト・制気口の扱い（本見積では自然給気として図示どおり残置）。⑥吸気口 KS-8841PR3-SG の支給有無。

Sheet 見積内訳書
A1: 見 積 内 訳 書 （仮称）サンフレッチェ広島 三矢寮新築工事 空調設備工事（機器元請支給）
A3: 項目 | B3: 名称 | C3: 金額(円) | D3: 備考
A4: A | B4: 空調設備工事（ベース図面06） | C4: =明細!H58 -> 9891800
A5: A-1 | B5: 空調機器据付（機器元請支給） | C5: =明細!H28 -> 3723000
A6: A-2 | B6: 冷媒配管 | C6: =明細!H40 -> 4195400
A7: A-3 | B7: ドレン配管 | C7: =明細!H48 -> 1158400
A8: A-4 | B8: 付帯工事・試運転 | C8: =明細!H57 -> 815000
A9: B | B9: 換気設備工事（ベース図面06） | C9: =明細!H152 -> 9065000
A10: B-1 | B10: 換気機器据付（機器元請支給） | C10: =明細!H101 -> 2247000
A11: B-2 | B11: ダクト工事 | C11: =明細!H116 -> 2732500
A12: B-3 | B12: ダクト保温 | C12: =明細!H120 -> 570500
A13: B-4 | B13: 制気口・ボックス | C13: =明細!H141 -> 1369000
A14: B-5 | B14: フード類・その他 | C14: =明細!H151 -> 2146000
A15: C | B15: 金額変更案（図面08 朱書き） | C15: =明細!H198 -> 4784500 | D15: 図面08 金額変更案に基づく追加・減額（朱書き）
A16: C-1 | B16: No3・4 ロスナイ中止（減額・代替） | C16: =明細!H169 -> 406000
A17: C-2 | B17: No5・6 空調追加 | C17: =明細!H197 -> 4378500
B19: 直接工事費 計（A＋B＋C） | C19: =C4+C9+C15 -> 23741300
B20: うち ベース（A＋B） | C20: =C4+C9 -> 18956800
B21: うち 金額変更案（C） | C21: =C15 -> 4784500
B22: 法定福利費（労務費率50%×16.3% と仮定） | C22: =ROUND(C19*0.5*0.163,0) -> 1934916 | D22: 仮定値。自社の算定方法に置換のこと
B23: 諸経費（現場管理費・一般管理費 12% と仮定） | C23: =ROUND(C19*0.12,0) -> 2848956 | D23: 仮定値
B24: 見積金額（税抜） | C24: =C19+C22+C23 -> 28525172
B25: 消費税（10%） | C25: =ROUND(C24*0.1,0) -> 2852517
B26: 見積金額（税込） | C26: =C24+C25 -> 31377689

Sheet 明細
A1: 区分 | B1: 項目 | C1: 名称 | D1: 規格・仕様 | E1: 数量 | F1: 単位 | G1: 単価(円) | H1: 金額(円) | I1: 根拠 | J1: 備考
A2: A | C2: 空調設備工事（ベース図面06）
B3: A-1 | C3: 空調機器据付（機器元請支給）
A4: 06 | C4: AC-1 室内機 据付 | D4: 4方向天井カセット ツイン子機 PA-P280U7HDNB(10HP) 1F食堂・ﾐｰﾃｨﾝｸﾞ・ﾄﾚｰﾆﾝｸﾞ・ﾎｰﾙ | E4: 8 | F4: 台 | G4: 55000 | H4: =ROUND(E4*G4,0) -> 440000 | I4: 図面カウント | J4: 4系統×2台 空調平面図1F
A5: 06 | C5: AC-1 室外機 据付 | D5: 10HP 屋外機架台(支給)上 1F地上 | E5: 4 | F5: 台 | G5: 50000 | H5: =ROUND(E5*G5,0) -> 200000 | I5: 図面カウント | J5: 基礎は建築工事
A6: 06 | C6: AC-2 室内機 据付 | D6: 4方向天井カセット ツイン子機 PA-P224U7HDNB(8HP) コーチルーム | E6: 2 | F6: 台 | G6: 55000 | H6: =ROUND(E6*G6,0) -> 110000 | I6: 図面カウント
A7: 06 | C7: AC-2 室外機 据付 | D7: 8HP | E7: 1 | F7: 台 | G7: 50000 | H7: =ROUND(E7*G7,0) -> 50000 | I7: 図面カウント
A8: 06 | C8: AC-3 室内機 据付 | D8: 4方向天井カセット ツイン子機 (4HP) 脱衣室 | E8: 2 | F8: 台 | G8: 45000 | H8: =ROUND(E8*G8,0) -> 90000 | I8: 図面カウント
A9: 06 | C9: AC-3 室外機 据付 | D9: 4HP 物干場側 | E9: 1 | F9: 台 | G9: 35000 | H9: =ROUND(E9*G9,0) -> 35000 | I9: 図面カウント
A10: 06 | C10: AC-5 室内機 据付 | D10: 4方向天井カセット PA-P56U7HNB(2HP) ケア室・管理人室 | E10: 2 | F10: 台 | G10: 45000 | H10: =ROUND(E10*G10,0) -> 90000 | I10: 図面カウント
A11: 06 | C11: AC-5 室外機 据付 | D11: 2HP | E11: 2 | F11: 台 | G11: 35000 | H11: =ROUND(E11*G11,0) -> 70000 | I11: 図面カウント
A12: 06 | C12: AC-6 室内機 据付 | D12: 天吊形厨房用 PA-P140V7HNB(5HP) 厨房 | E12: 1 | F12: 台 | G12: 50000 | H12: =ROUND(E12*G12,0) -> 50000 | I12: 図面カウント
A13: 06 | C13: AC-6 室外機 据付 | D13: 5HP | E13: 1 | F13: 台 | G13: 35000 | H13: =ROUND(E13*G13,0) -> 35000 | I13: 図面カウント
A14: 06 | C14: AC-7 室内機 据付 | D14: 2方向天井カセット PA-P50L7HNB(1.8HP) 面談室 | E14: 1 | F14: 台 | G14: 45000 | H14: =ROUND(E14*G14,0) -> 45000 | I14: 図面カウント
A15: 06 | C15: AC-7 室外機 据付 | D15: 1.8HP | E15: 1 | F15: 台 | G15: 35000 | H15: =ROUND(E15*G15,0) -> 35000 | I15: 図面カウント
A16: 06 | C16: AC-8 室内機 据付 | D16: ビルトインダクト PA-P56FE7HNBC(2HP) 厨房 | E16: 1 | F16: 台 | G16: 50000 | H16: =ROUND(E16*G16,0) -> 50000 | I16: 図面カウント | J16: ダクト・制気口は A-4 に計上
A17: 06 | C17: AC-8 室外機 据付 | D17: 2HP | E17: 1 | F17: 台 | G17: 35000 | H17: =ROUND(E17*G17,0) -> 35000 | I17: 図面カウント
A18: 06 | C18: AC-9 室内機 据付 | D18: 天吊形厨房用 PA-P80V7HNB(3HP) 弁当室 | E18: 1 | F18: 台 | G18: 50000 | H18: =ROUND(E18*G18,0) -> 50000 | I18: 図面カウント
A19: 06 | C19: AC-9 室外機 据付 | D19: 3HP | E19: 1 | F19: 台 | G19: 35000 | H19: =ROUND(E19*G19,0) -> 35000 | I19: 図面カウント
A20: 06 | C20: AC-10 室内機 据付 | D20: 4方向天井カセット PA-P140U7HNB(5HP) 2F多目的スペース | E20: 1 | F20: 台 | G20: 45000 | H20: =ROUND(E20*G20,0) -> 45000 | I20: 図面カウント
A21: 06 | C21: AC-10 室外機 据付 | D21: 5HP 1F地上(中庭2西側) | E21: 1 | F21: 台 | G21: 35000 | H21: =ROUND(E21*G21,0) -> 35000 | I21: 図面カウント
A22: 06 | C22: RAC-1 据付 | D22: 壁掛ルームエアコン XCS-255DGX-W 内外機・ドレンアップ共 洗浄室・休憩室 | E22: 2 | F22: 組 | G22: 28000 | H22: =ROUND(E22*G22,0) -> 56000 | I22: 図面カウント | J22: 屋外機架台支給
A23: 06 | C23: RAC-2 据付 | D23: 壁掛ルームエアコン XCS-405DGX-W 内外機・ドレンアップ共 来客室・和室・洋室・DK | E23: 8 | F23: 組 | G23: 28000 | H23: =ROUND(E23*G23,0) -> 224000 | I23: 図面カウント | J23: 屋外機架台(2段)支給
A24: 06 | C24: RAC-3 据付 | D24: 壁掛ルームエアコン XCS-405DGX2-W 内外機 2F寮室・予備室・コーチ宿泊室 | E24: 66 | F24: 組 | G24: 25000 | H24: =ROUND(E24*G24,0) -> 1650000 | I24: 図面カウント | J24: 屋外機はバルコニー2段架台(支給)
A25: 06 | C25: RAC-4 据付 | D25: 壁掛ルームエアコン XCS-635DGX2-W 内外機 2F寮務スタッフ室 | E25: 1 | F25: 組 | G25: 28000 | H25: =ROUND(E25*G25,0) -> 28000 | I25: 図面カウント
A26: 06 | C26: CR-1 集中リモコン 取付 | D26: CZ-10ESM5・CZ-10ESW4 管理人室 | E26: 1 | F26: 台 | G26: 15000 | H26: =ROUND(E26*G26,0) -> 15000 | I26: 図面カウント | J26: 配線は A-4
A27: 06 | C27: 機器搬入・揚重・養生 | D27: PAC 32台・RAC 154台分 | E27: 1 | F27: 式 | G27: 250000 | H27: =ROUND(E27*G27,0) -> 250000 | I27: 推測
C28: A-1 空調機器据付（機器元請支給） 小計 | H28: =SUM(H4:H27) -> 3723000
B29: A-2 | C29: 冷媒配管
A30: 06 | C30: 冷媒配管 ① | D30: 被覆銅管 9.52/6.35 (RAC-1,2 1F 及び RAC-3 2F) | E30: 360 | F30: m | G30: 4500 | H30: =ROUND(E30*G30,0) -> 1620000 | I30: 実測+推測 | J30: 平面実測34.3m＋推測(RAC-3 66台×4m、来客室RAC-2 5台×4m、RAC-1補正8m、立上り10台×3m)
A31: 06 | C31: 冷媒配管 ② | D31: 被覆銅管 12.7/6.35 (AC-5,7,8 AC-3枝 RAC-4) | E31: 77 | F31: m | G31: 5200 | H31: =ROUND(E31*G31,0) -> 400400 | I31: 実測+推測 | J31: 平面実測56m＋推測(立上り4系統×4m、RAC-4 5m)
A32: 06 | C32: 冷媒配管 ③ | D32: 被覆銅管 15.88/9.52 (AC-1/2枝 AC-3主 AC-6,9,10) | E32: 96 | F32: m | G32: 6500 | H32: =ROUND(E32*G32,0) -> 624000 | I32: 実測+推測 | J32: 平面実測72.2m＋推測(立上り3系統×4m、AC-10 2F分3.5m＋立管8m)
A33: 06 | C33: 冷媒配管 ⑥ | D33: 被覆銅管 25.4/9.52 (AC-2主管) | E33: 9 | F33: m | G33: 9500 | H33: =ROUND(E33*G33,0) -> 85500 | I33: 実測+推測 | J33: 平面実測5m＋立上り4m
A34: 06 | C34: 冷媒配管 ⑦ | D34: 被覆銅管 25.4/12.7 (AC-1主管 4系統) | E34: 57 | F34: m | G34: 10500 | H34: =ROUND(E34*G34,0) -> 598500 | I34: 実測+推測 | J34: 平面実測41m＋立上り4系統×4m
A35: 06 | C35: 冷媒配管 化粧ケース | D35: 屋外・屋内露出部 (管種凡例: 露出管は化粧ケース仕上) | E35: 125 | F35: m | G35: 3000 | H35: =ROUND(E35*G35,0) -> 375000 | I35: 推測 | J35: PAC13+RAC1F10箇所×2.5m、RAC-3/4 67台×1.0m
A36: 06 | C36: 外壁貫通スリーブ材 | D36: VP100 冷媒・ドレン用 (穴明けは建築工事) | E36: 90 | F36: 箇所 | G36: 2500 | H36: =ROUND(E36*G36,0) -> 225000 | I36: 推測 | J36: RAC77＋PAC13
A37: 06 | C37: 区画貫通処理 | D37: 冷媒管 フィブロック(認定工法) | E37: 2 | F37: 箇所 | G37: 12000 | H37: =ROUND(E37*G37,0) -> 24000 | I37: 実測 | J37: 空調平面図1F ●区画貫通部 2箇所
A38: 06 | C38: 気密試験・真空引き・冷媒追加充填 作業 | D38: PAC 系統毎 | E38: 13 | F38: 系統 | G38: 15000 | H38: =ROUND(E38*G38,0) -> 195000 | I38: 図面カウント
A39: 06 | C39: 冷媒追加充填 (冷媒代) | D39: R32/R410A | E39: 8 | F39: kg | G39: 6000 | H39: =ROUND(E39*G39,0) -> 48000 | I39: 推測 | J39: 配管延長より約20g/m換算
C40: A-2 冷媒配管 小計 | H40: =SUM(H30:H39) -> 4195400
...

Sheet 数量拾い根拠
A1: 数量拾い根拠 ※計測方法: PDF図面(A3 1:300、厨房詳細 1:70)のベクトル線分を色・線幅で分離し延長を集計。「実測」=図面線分の平面延長、「推測」=図面に無い部分の推定
A3: 1. 冷媒配管（ベース06）系統別
A4: 系統 | B4: 口径記号 | C4: 平面実測(m) | D4: 推測加算(m) | E4: 合計(m) | H4: 推測内容
A5: RAC-2×3 和室・洋室・DK | B5: ① | C5: 28.1 | D5: 9 | E5: 37.1 | H5: 屋外機→屋内機 立上り 3台×3m
A6: AC-7 面談室 | B6: ② | C6: 13 | D6: 4 | E6: 17 | H6: 北西ゾーン実測60.3mを3系統に配分。立上り4m
A7: AC-5 管理人室 | B7: ② | C7: 18 | D7: 4 | E7: 22 | H7: 同上
A8: AC-1 ホール(ツイン) | B8: ⑦主/③枝 | C8: 29 | D8: 4 | E8: 33 | H8: 主管17m・枝管12m。立上り4m(⑦)
A9: AC-6/AC-8/AC-9/RAC-1×2 厨房ブロック | B9: ③/②/③/① | C9: 22.2 | D9: 20 | E9: 42.2 | H9: 重なり配管の未計測補正8m(RAC-1休憩室)・立上り4系統×3～4m
A10: AC-1 食堂・ミーティング(ツイン×2) | B10: ⑦主/③枝 | C10: 30.7 | D10: 8 | E10: 38.7 | H10: 各系統 主管8m・枝管7.5m。立上り各4m
A11: AC-10 多目的スペース(2F) | B11: ③ | C11: 10.2 | D11: 11.5 | E11: 21.7 | H11: 2F平面3.5m・立管(1F地上→2F天井)8m
A12: AC-2 コーチルーム(ツイン) | B12: ⑥主/③枝 | C12: 11.1 | D12: 4 | E12: 15.1 | H12: 主管5m・枝管6m。立上り4m
A13: AC-1 トレーニング(ツイン)＋AC-5 ケア室 | B13: ⑦/③ ・ ② | C13: 32 | D13: 8 | E13: 40 | H13: AC-1 主8m枝12m・AC-5 12m。立上り各4m
A14: AC-3 脱衣室(ツイン) | B14: ③主/②枝 | C14: 13.9 | D14: 4 | E14: 17.9 | H14: 主管7m・枝管7m。立上り4m
A15: RAC-2×5 来客室 | B15: ① | C15: 2.7 | D15: 18 | E15: 20.7 | H15: 屋外機が各室直近。1台4m×5台(実測分は微小)
A16: RAC-3×66 2F寮室等 | B16: ① | C16: 0 | D16: 264 | E16: 264 | H16: 図面に配管線なし。壁掛機→バルコニー屋外機 4m/台
A17: RAC-4 寮務スタッフ室 | B17: ② | C17: 0 | D17: 5 | E17: 5 | H17: 同上 5m
A18: 合計 | C18: 211 | D18: 363.5 | E18: 574.5 | H18: 口径別集計: ①360 ②77 ③96 ⑥9 ⑦57 (m・端数調整後)
A20: 2. ドレン配管（ベース06）
A21: 区分 | B21: 口径 | C21: 平面実測(m) | D21: 推測加算(m) | E21: 合計(m) | H21: 備考
A22: 1F 空調平面図 青線(D) | B22: VP20 | C22: 6.6 | D22: 30 | E22: 36.6 | H22: RAC-1/2 ドレンアップ吐出→屋外 10台×3m
A23: 1F 空調平面図 青線(D) | B23: VP25 | C23: 87.3 | D23: 0 | E23: 87.3 | H23: 口径ラベル未割当31.3mを25/40へ比例配分済
A24: 1F 空調平面図 青線(D) | B24: VP40 | C24: 50.2 | D24: 18 | E24: 68.2 | H24: 立下り・屋外放流部 12箇所×1.5m
A25: 2F 空調平面図 青線(D) AC-10 | B25: VP25 | C25: 6.1 | D25: 0 | E25: 6.1
A26: 合計 | C26: 150.2 | D26: 48 | E26: 198.2
A28: 3. 冷媒配管（図面08 追加 空調）
A29: 系統 | B29: 口径記号 | C29: 平面実測(m) | D29: 推測(m) | E29: 合計(m) | H29: 推定根拠
A30: 追AC1 PA-P140U7GTNB トリプル | B30: ③主/①枝 | C30: 0 | D30: 51 | E30: 51 | H30: 室外機:物干場側(AC-3隣) 室内機:ホール・洗濯室前廊下・階段ホール。主管12m＋立上り4m、枝管8+10+12＋余裕
A31: 追AC2 PA-P224L7HTNB トリプル | B31: ⑥主/③枝 | C31: 0 | D31: 57 | E31: 57 | H31: 室外機:南側(AC-1/5隣) 室内機:1F南廊下3箇所。主管8m＋立上り4m、枝管10+20+15
A32: 追AC3 PA-P224L7HTNB トリプル | B32: ⑥主/③枝 | C32: 0 | D32: 64 | E32: 64 | H32: 室外機:東側地上 室内機:2F北廊下3箇所。立管6m＋主管8m、枝管0+16+32(＋2)
A33: 追AC4 PA-P224L7HTNB トリプル | B33: ⑥主/③枝 | C33: 0 | D33: 51 | E33: 51 | H33: 室外機:東側地上(倉庫2東) 室内機:階段ホール2・南廊下1。立管6m＋主管25m、枝管5+8+6(＋1)
A34: 追AC5 PA-P224L7HTNB トリプル | B34: ⑥主/③枝 | C34: 0 | D34: 69 | E34: 69 | H34: 室外機:東側地上 室内機:2F南廊下3箇所。立管6m＋主管10m、枝管0+18+35
A35: 合計 | C35: 0 | D35: 292 | E35: 292 | H35: 口径別: ①35 ③184 ⑥73
A37: 4. ダクト（ベース06）
A38: 図面 | B38: 系統 | C38: 100φ(m) | D38: 150φ(m) | E38: 200φ(m) | F38: 250φ(m) | G38: 300φ(m) | H38: 備考
A39: 1F換気平面図(p22) 黒太線 | B39: EA | C39: 62.6 | D39: 122.4 | E39: 25.2 | F39: 0 | G39: 0 | H39: 150φに口径未判読16.6m含む（実測）
A40: 1F換気平面図(p22) 青線 | B40: OA | C40: 3.5 | D40: 50.4 | E40: 45.7 | F40: 0 | G40: 0 | H40: 150φに未判読9.1m含む（実測）
A41: 2F換気平面図(p23) 黒太線 | B41: EA | C41: 5.2 | D41: 28.2 | E41: 9.8 | F41: 0 | G41: 0 | H41: 実測
A42: 2F換気平面図(p23) 青線 | B42: OA | C42: 0 | D42: 0 | E42: 3.5 | F42: 0 | G42: 0 | H42: 実測
A43: 厨房廻り詳細図(p24) 1:70 | B43: EA | C43: 0 | D43: 0 | E43: 9 | F43: 6 | G43: 5 | H43: 推測（二重線表記のため目視換算）
A44: 厨房廻り詳細図(p24) 1:70 | B44: OA(FS-1/2・F-3給気) | C44: 0 | D44: 0 | E44: 7.5 | F44: 6 | G44: 3 | H44: 推測
...

Sheet 単価仮定
A1: 単価仮定一覧（材工共・税抜・仮単価） ※自社単価に置換してください
A3: 名称 | B3: 単価(円) | C3: 単位 | D3: 規格（代表）
A4: AC-1 室内機 据付 | B4: 55000 | C4: 台 | D4: 4方向天井カセット ツイン子機 PA-P280U7HDNB(10HP) 1F食堂・ﾐｰﾃｨﾝｸﾞ・ﾄﾚｰﾆﾝｸﾞ・ﾎｰﾙ
A5: AC-1 室外機 据付 | B5: 50000 | C5: 台 | D5: 10HP 屋外機架台(支給)上 1F地上
A6: AC-2 室内機 据付 | B6: 55000 | C6: 台 | D6: 4方向天井カセット ツイン子機 PA-P224U7HDNB(8HP) コーチルーム
A7: AC-2 室外機 据付 | B7: 50000 | C7: 台 | D7: 8HP
A8: AC-3 室内機 据付 | B8: 45000 | C8: 台 | D8: 4方向天井カセット ツイン子機 (4HP) 脱衣室
A9: AC-3 室外機 据付 | B9: 35000 | C9: 台 | D9: 4HP 物干場側
A10: AC-5 室内機 据付 | B10: 45000 | C10: 台 | D10: 4方向天井カセット PA-P56U7HNB(2HP) ケア室・管理人室
A11: AC-5 室外機 据付 | B11: 35000 | C11: 台 | D11: 2HP
A12: AC-6 室内機 据付 | B12: 50000 | C12: 台 | D12: 天吊形厨房用 PA-P140V7HNB(5HP) 厨房
A13: AC-6 室外機 据付 | B13: 35000 | C13: 台 | D13: 5HP
A14: AC-7 室内機 据付 | B14: 45000 | C14: 台 | D14: 2方向天井カセット PA-P50L7HNB(1.8HP) 面談室
A15: AC-7 室外機 据付 | B15: 35000 | C15: 台 | D15: 1.8HP
... A105: VHS 200×200 (開口率70%) | B105: 10000 | C105: 個 | D105: SUS/鋼製 指定色
A106: VHS 250×250 | B106: 12000 | C106: 個
A107: VHS 300×300 | B107: 14000 | C107: 個
A108: VHS 350×350 | B108: 16000 | C108: 個
A109: VHS 400×400 | B109: 18000 | C109: 個
A110: VHS 450×450 | B110: 20000 | C110: 個
A111: HS/VHS 550×550 | B111: 25000 | C111: 個
A112: VHS 650×650 | B112: 30000 | C112: 個
A113: HS 150×150 | B113: 7000 | C113: 個
A114: HS 200×200 | B114: 8000 | C114: 個
A115: BOX(内貼) 300×300×300H | B115: 14000 | C115: 個 | D115: GW25 内貼
A116: BOX(内貼) 350×350×300H | B116: 15000 | C116: 個
A117: BOX(内貼) 400×400×300H | B117: 17000 | C117: 個
A118: BOX(内貼) 450×450×350H | B118: 18000 | C118: 個
A119: BOX(内貼) 500×500×350H | B119: 20000 | C119: 個
A120: BOX(内貼) 550×550×400H | B120: 22000 | C120: 個
A121: BOX(内貼) 600×600×400H | B121: 25000 | C121: 個
A122: BOX(内貼) 700×700×450H | B122: 28000 | C122: 個
A123: BOX(内貼) 800×800×500H | B123: 35000 | C123: 個
A124: SUS製フード 取付 (支給品) | B124: 4000 | C124: 箇所 | D124: 指定色塗装 外壁貫通部
A125: ウェザーカバー 取付 (支給品) | B125: 5000 | C125: 箇所 | D125: 有圧扇用
A126: 厨房フード① 製作取付 | B126: 180000 | C126: 台 | D126: SUS製 900×850×800H 二重フード
A127: 厨房フード② 製作取付 | B127: 260000 | C127: 台 | D127: SUS製 1400×900×800H GF・二重フード
A128: 厨房フード③ 製作取付 | B128: 260000 | C128: 台 | D128: SUS製 1170×1170×800H GF
A129: 厨房フード④ 製作取付 | B129: 450000 | C129: 台 | D129: SUS製 3350×750×800H GF
A130: 衣類乾燥機排気用スリーブ | B130: 15000 | C130: 箇所 | D130: スリーブキャップ共
...
