Workbook
Name COEF: '表紙(工事)'!$N$4
Name OVERHEAD_RATE: '表紙(工事)'!$N$5
Name ROUND_UNIT: '表紙(工事)'!$N$6
Name WELFARE_RATE: '法定福利費内訳明細書'!$E$26
Name LABOR_DAY: '表紙(工事)'!$N$8
Name TARGET: '表紙(工事)'!$N$9

Sheet 表紙(工事)
A1: 御 見 積 書
J3: No. | M3: 【設定・内部用】（印刷範囲外）
J4: 46301 | M4: 提出係数（原価→定価ベース単価） | N4: 1.22
A5: 株式会社共栄店舗 | G5: 御中 | M5: 諸経費率（現場経費・運搬・雑材・工事諸経費） | N5: 0.22
M6: 出精値引き 丸め単位（目標額空欄時） | N6: 100000
A7: 金額 | B7: ="¥"&TEXT(K28,"#,##0")&"-" -> ¥21,400,000- | F7: （税別） | H7: 宮地機工株式会社 | M7: 法定福利費率（労務費比） | N7: =WELFARE_RATE -> 0.16375
M8: 労務原価日額（円/人工） | N8: 19000
A9: 上記の通り御見積申し上げます。 | H9: 代表取締役 濱本 義樹 | M9: 目標提出額（税別・空欄なら丸め）
A10: 何卒ご用命賜わりますようお願い申し上げます。 | M10: 参考：宮地機工 人工単価（定価ベース） | N10: 23225
H11: 〒722-0051 | M11: ※ 原価＝材料原価＋人工×N8。提出単価＝原価×N4（1.22で参考見積の人工単価23,225に一致）。目標提出額 N9 を入れると出精値引きで合わせる
A12: 工事名 | D12: （仮称）サンフレッチェ広島 三矢寮新築工事 | H12: 広島県尾道市東尾道9-9
D13: 空調工事（機械設備図06ベース＋金額変更案08 空調追加） | H13: TEL.0848-20-2121 | K13: FAX.0848-20-2126
A14: 施工場所 | D14: 広島県安芸高田市吉田町西浦字日南山835-27 | H14: 担当者 | J14: 濱本 義武
A15: 工事期限 | D15: 全体工期 2026年5月1日～2027年2月15日（空調工事は工程表による・別途お打ち合わせ）
A16: 御支払条件 | D16: 別途お打ち合わせ
A17: 有効期限 | D17: 発行後3ヶ月
A19: 項 目 | B19: 内 容 | G19: 数 量 | H19: 単位 | I19: 単 価 | K19: 金 額 | L19: 備 考 | M19: 内部集計（原価・粗利） | N19: 基準原価 | O19: 労務費(提出) | P19: 粗利 | Q19: 粗利率
B20: 【（仮称）サンフレッチェ広島 三矢寮新築工事 空調設備工事 空調工事】
B21: ［空調機器（空調機器表・追加分 PA-P140U7GTNB・PA-P224L7HTNB）は元請様手配、電気工事・建築工事・自動制御は含まず］
A22: ① | B22: 空調工事（機械設備図 06） | G22: 1 | H22: 式 | I22: =K22 -> 10624080 | K22: ='内訳書(1.空調工事)'!H58 -> 10624080 | L22: 内訳書 No.1 | M22: ①空調工事 | N22: ='内訳書(1.空調工事)'!O58 -> 8707010 | O22: ='内訳書(1.空調工事)'!P58 -> 6712464 | P22: =K22-N22 -> 1917070 | Q22: =IF(K22=0,"",P22/K22) -> 0.18044574
A23: ② | B23: 金額変更案 No5・6 空調追加（検討図 08） | G23: 1 | H23: 式 | I23: =K23 -> 5660790 | K23: ='内訳書(2.空調追加)'!H34 -> 5660790 | L23: 内訳書 No.2 | M23: ②空調追加 | N23: ='内訳書(2.空調追加)'!O34 -> 4639680 | O23: ='内訳書(2.空調追加)'!P34 -> 2910712 | P23: =K23-N23 -> 1021110 | Q23: =IF(K23=0,"",P23/K23) -> 0.18038295
A24: ③ | B24: 法定福利費（労務費に係る事業主負担分） | G24: 1 | H24: 式 | I24: =K24 -> 1575792 | K24: ='法定福利費内訳明細書'!F26 -> 1575792 | L24: 別紙明細書 | M24: ③法定福利費（原価＝提出値） | N24: =K24 -> 1575792
A25: ④ | B25: 諸経費（現場経費・資材運搬・工事諸経費） | G25: 1 | H25: 式 | I25: =K25 -> 3583000 | K25: =ROUND(SUM(K22:K23)*OVERHEAD_RATE,-3) -> 3583000 | L25: ="①〜②計の"&TEXT(OVERHEAD_RATE,"0%") -> ①〜②計の22% | M25: ④諸経費（原価計上なし） | N25: 0
B27: 出精値引き | K27: =IF(TARGET="",FLOOR(SUM(K22:K25),ROUND_UNIT)-SUM(K22:K25),TARGET-SUM(K22:K25)) -> -43662 | L27: 端数調整 | M27: 出精値引き（原価なし・粗利から控除） | N27: 0 | P27: =K27 -> -43662
B28: 合 計 | K28: =SUM(K22:K27) -> 21400000 | L28: （税別） | M28: 合計（原価合計／粗利／粗利率） | N28: =SUM(N22:N27) -> 14922482 | O28: =SUM(O22:O27) -> 9623176 | P28: =K28-N28 -> 6477518 | Q28: =IF(K28=0,"",P28/K28) -> 0.30268776
A30: ※ | B30: 本見積は機械設備図（図面No.06 若本建築事務所 '26.1.31）に基づき当社にて数量を拾い出して積算しております。金額変更案検討図（図面No.08）の No5・6 空調追加は内訳書 No.2（朱書き）に計上しています。換気工事は別途御見積書によります。実施数量との差異は別途精算とさせていただきます。
A31: ※ | B31: 空調機器・換気機器（室内機・室外機・リモコン・換気扇・全熱交換器・屋外機架台・ドレンアップ等 機器表記載の本体および付属品）は元請様手配のため含みません（据付・取付費のみ計上）。
A32: ※ | B32: 機器の電源供給・接地等の電気工事、基礎・躯体貫通穴明け・スリーブ穴埋め・天井点検口等の建築工事、衛生・消火・ガス・浄化槽設備、自動制御設備は含みません。 | M32: 粗利率別 参考提出額（税別・万円未満切上げ） | N32: 参考提出額 | O32: 必要提出係数
A33: ※ | B33: 機器・資材の揚重機（クレーン・レッカー等）、仮設設備、産業廃棄物の処分は元請様にてご手配・ご負担願います。 | M33: 0.1 | N33: =ROUNDUP($N$28/(1-M33),-4) -> 16590000 | O33: =IF(SUM($N$22:$N$23)=0,"",ROUND(($N$28/(1-M33)-$N$24-$K$25)/SUM($N$22:$N$23),3)) -> 0.856
A34: ※ | B34: 一式計上および想定数量の項目は別紙「御見積条件」記載の前提にて計上しており、実数量確定後に精算させていただきます。 | M34: 0.15 | N34: =ROUNDUP($N$28/(1-M34),-4) -> 17560000 | O34: =IF(SUM($N$22:$N$23)=0,"",ROUND(($N$28/(1-M34)-$N$24-$K$25)/SUM($N$22:$N$23),3)) -> 0.929
A35: ※ | B35: 本見積書に記載なき事項については別途とさせて頂きます。工事に係る電気・水道は無償支給願います。 | M35: 0.2 | N35: =ROUNDUP($N$28/(1-M35),-4) -> 18660000 | O35: =IF(SUM($N$22:$N$23)=0,"",ROUND(($N$28/(1-M35)-$N$24-$K$25)/SUM($N$22:$N$23),3)) -> 1.011
A36: ※ | B36: 本見積金額には消費税は含まれておりません。有効期限内でも銅管・鋼材等の市況が著しく変動した場合は再見積をさせていただくことがあります。 | M36: 0.25 | N36: =ROUNDUP($N$28/(1-M36),-4) -> 19900000 | O36: =IF(SUM($N$22:$N$23)=0,"",ROUND(($N$28/(1-M36)-$N$24-$K$25)/SUM($N$22:$N$23),3)) -> 1.104
A37: ※ | B37: 詳細条件は別紙「御見積条件」をご参照ください。 | M37: 0.3 | N37: =ROUNDUP($N$28/(1-M37),-4) -> 21320000 | O37: =IF(SUM($N$22:$N$23)=0,"",ROUND(($N$28/(1-M37)-$N$24-$K$25)/SUM($N$22:$N$23),3)) -> 1.211
M38: ※ 必要提出係数は諸経費を現状額に固定した場合の目安

Sheet 内訳書(1.空調工事)
A1: 内 訳 書 | J1: 原 価 内 訳 書（内部用・印刷範囲外）
A2: 工事名：（仮称）サンフレッチェ広島 三矢寮新築工事 空調設備工事 空調工事 | I2: 内訳書 No.1
A3: 名 称 | C3: 規格・寸法 | E3: 数 量 | F3: 単位 | G3: 単 価 | H3: 金 額 | I3: 備 考 | J3: 材料原価 | K3: 人工/単位 | L3: 労務原価 | M3: 基準原価単価 | N3: 提出係数 | O3: 基準原価 | P3: 労務費(提出) | Q3: 数量根拠 | R3: 粗利 | S3: 粗利率 | T3: 参考定価ベース | U3: 当社/参考 | V3: 単価出典・メモ（内部）
A4: １．空調工事（機械設備図 06）
A6: （1）空調機器据付（機器は元請様支給）
A7: AC-1 室内機 据付 | C7: 4方向天井カセット ツイン子機 PA-P280U7HDNB(10HP) 1F食堂・ﾐｰﾃｨﾝｸﾞ・ﾄﾚｰﾆﾝｸﾞ・ﾎｰﾙ | E7: 8 | F7: 台 | G7: =IF(M7="","",ROUND(M7*N7,-1)) -> 25620 | H7: =IF(G7="","",ROUND(E7*G7,0)) -> 204960 | I7: 本体は元請様支給 | J7: 2000 | K7: 1 | L7: =ROUND(K7*LABOR_DAY,0) -> 19000 | M7: =J7+L7 -> 21000 | N7: =COEF -> 1.22 | O7: =E7*M7 -> 168000 | P7: =ROUND(E7*L7*N7,0) -> 185440 | Q7: 図面カウント | R7: =IF(H7="","",H7-O7) -> 36960 | S7: =IF(OR(H7="",H7=0),"",R7/H7) -> 0.18032787 | T7: 27860 | U7: =IF(OR(T7="",T7=0),"",G7/T7) -> 0.91959799 | V7: 6330558 VRV 90クラス 27,860/台｜4系統×2台 空調平面図1F
A8: AC-1 室外機 据付 | C8: 10HP 屋外機架台(支給)上 1F地上 | E8: 4 | F8: 台 | G8: =IF(M8="","",ROUND(M8*N8,-1)) -> 30380 | H8: =IF(G8="","",ROUND(E8*G8,0)) -> 121520 | I8: 本体は元請様支給 | J8: 4000 | K8: 1.1 | L8: =ROUND(K8*LABOR_DAY,0) -> 20900 | M8: =J8+L8 -> 24900 | N8: =COEF -> 1.22 | O8: =E8*M8 -> 99600 | P8: =ROUND(E8*L8*N8,0) -> 101992 | Q8: 図面カウント | R8: =IF(H8="","",H8-O8) -> 21920 | S8: =IF(OR(H8="",H8=0),"",R8/H8) -> 0.18038183 | T8: 37860 | U8: =IF(OR(T8="",T8=0),"",G8/T8) -> 0.80243001 | V8: 8〜10HP 室外機（防振ゴム・架台固定共）｜基礎は建築工事
A9: AC-2 室内機 据付 | C9: 4方向天井カセット ツイン子機 PA-P224U7HDNB(8HP) コーチルーム | E9: 2 | F9: 台 | G9: =IF(M9="","",ROUND(M9*N9,-1)) -> 25620 | H9: =IF(G9="","",ROUND(E9*G9,0)) -> 51240 | I9: 本体は元請様支給 | J9: 2000 | K9: 1 | L9: =ROUND(K9*LABOR_DAY,0) -> 19000 | M9: =J9+L9 -> 21000 | N9: =COEF -> 1.22 | O9: =E9*M9 -> 42000 | P9: =ROUND(E9*L9*N9,0) -> 46360 | Q9: 図面カウント | R9: =IF(H9="","",H9-O9) -> 9240 | S9: =IF(OR(H9="",H9=0),"",R9/H9) -> 0.18032787 | T9: 27860 | U9: =IF(OR(T9="",T9=0),"",G9/T9) -> 0.91959799 | V9: 6330558 VRV 90クラス 27,860/台｜
A10: AC-2 室外機 据付 | C10: 8HP | E10: 1 | F10: 台 | G10: =IF(M10="","",ROUND(M10*N10,-1)) -> 30380 | H10: =IF(G10="","",ROUND(E10*G10,0)) -> 30380 | I10: 本体は元請様支給 | J10: 4000 | K10: 1.1 | L10: =ROUND(K10*LABOR_DAY,0) -> 20900 | M10: =J10+L10 -> 24900 | N10: =COEF -> 1.22 | O10: =E10*M10 -> 24900 | P10: =ROUND(E10*L10*N10,0) -> 25498 | Q10: 図面カウント | R10: =IF(H10="","",H10-O10) -> 5480 | S10: =IF(OR(H10="",H10=0),"",R10/H10) -> 0.18038183 | T10: 37860 | U10: =IF(OR(T10="",T10=0),"",G10/T10) -> 0.80243001 | V10: 8〜10HP 室外機（防振ゴム・架台固定共）｜
A11: AC-3 室内機 据付 | C11: 4方向天井カセット ツイン子機 (4HP) 脱衣室 | E11: 2 | F11: 台 | G11: =IF(M11="","",ROUND(M11*N11,-1)) -> 21660 | H11: =IF(G11="","",ROUND(E11*G11,0)) -> 43320 | I11: 本体は元請様支給 | J11: 1600 | K11: 0.85 | L11: =ROUND(K11*LABOR_DAY,0) -> 16150 | M11: =J11+L11 -> 17750 | N11: =COEF -> 1.22 | O11: =E11*M11 -> 35500 | P11: =ROUND(E11*L11*N11,0) -> 39406 | Q11: 図面カウント | R11: =IF(H11="","",H11-O11) -> 7820 | S11: =IF(OR(H11="",H11=0),"",R11/H11) -> 0.18051708 | T11: 21700 | U11: =IF(OR(T11="",T11=0),"",G11/T11) -> 0.99815668 | V11: 6330476-3 搬入据付 238,750/11台≒21,700/台、6330284-1 25,000/台｜
A12: AC-3 室外機 据付 | C12: 4HP 物干場側 | E12: 1 | F12: 台 | G12: =IF(M12="","",ROUND(M12*N12,-1)) -> 22200 | H12: =IF(G12="","",ROUND(E12*G12,0)) -> 22200 | I12: 本体は元請様支給 | J12: 3000 | K12: 0.8 | L12: =ROUND(K12*LABOR_DAY,0) -> 15200 | M12: =J12+L12 -> 18200 | N12: =COEF -> 1.22 | O12: =E12*M12 -> 18200 | P12: =ROUND(E12*L12*N12,0) -> 18544 | Q12: 図面カウント | R12: =IF(H12="","",H12-O12) -> 4000 | S12: =IF(OR(H12="",H12=0),"",R12/H12) -> 0.18018018 | T12: 29200 | U12: =IF(OR(T12="",T12=0),"",G12/T12) -> 0.76027397 | V12: 搬入据付＋基礎工事 5,800〜10,000/台（6330539/549/476-3）｜
A13: AC-5 室内機 据付 | C13: 4方向天井カセット PA-P56U7HNB(2HP) ケア室・管理人室 | E13: 2 | F13: 台 | G13: =IF(M13="","",ROUND(M13*N13,-1)) -> 21660 | H13: =IF(G13="","",ROUND(E13*G13,0)) -> 43320 | I13: 本体は元請様支給 | J13: 1600 | K13: 0.85 | L13: =ROUND(K13*LABOR_DAY,0) -> 16150 | M13: =J13+L13 -> 17750 | N13: =COEF -> 1.22 | O13: =E13*M13 -> 35500 | P13: =ROUND(E13*L13*N13,0) -> 39406 | Q13: 図面カウント | R13: =IF(H13="","",H13-O13) -> 7820 | S13: =IF(OR(H13="",H13=0),"",R13/H13) -> 0.18051708 | T13: 21700 | U13: =IF(OR(T13="",T13=0),"",G13/T13) -> 0.99815668 | V13: 6330476-3 搬入据付 238,750/11台≒21,700/台、6330284-1 25,000/台｜
A14: AC-5 室外機 据付 | C14: 2HP | E14: 2 | F14: 台 | G14: =IF(M14="","",ROUND(M14*N14,-1)) -> 22200 | H14: =IF(G14="","",ROUND(E14*G14,0)) -> 44400 | I14: 本体は元請様支給 | J14: 3000 | K14: 0.8 | L14: =ROUND(K14*LABOR_DAY,0) -> 15200 | M14: =J14+L14 -> 18200 | N14: =COEF -> 1.22 | O14: =E14*M14 -> 36400 | P14: =ROUND(E14*L14*N14,0) -> 37088 | Q14: 図面カウント | R14: =IF(H14="","",H14-O14) -> 8000 | S14: =IF(OR(H14="",H14=0),"",R14/H14) -> 0.18018018 | T14: 29200 | U14: =IF(OR(T14="",T14=0),"",G14/T14) -> 0.76027397 | V14: 搬入据付＋基礎工事 5,800〜10,000/台（6330539/549/476-3）｜
A15: AC-6 室内機 据付 | C15: 天吊形厨房用 PA-P140V7HNB(5HP) 厨房 | E15: 1 | F15: 台 | G15: =IF(M15="","",ROUND(M15*N15,-1)) -> 21660 | H15: =IF(G15="","",ROUND(E15*G15,0)) -> 21660 | I15: 本体は元請様支給 | J15: 1600 | K15: 0.85 | L15: =ROUND(K15*LABOR_DAY,0) -> 16150 | M15: =J15+L15 -> 17750 | N15: =COEF -> 1.22 | O15: =E15*M15 -> 17750 | P15: =ROUND(E15*L15*N15,0) -> 19703 | Q15: 図面カウント | R15: =IF(H15="","",H15-O15) -> 3910 | S15: =IF(OR(H15="",H15=0),"",R15/H15) -> 0.18051708 | T15: 21700 | U15: =IF(OR(T15="",T15=0),"",G15/T15) -> 0.99815668 | V15: 6330476-3 搬入据付 238,750/11台≒21,700/台、6330284-1 25,000/台｜
A16: AC-6 室外機 据付 | C16: 5HP | E16: 1 | F16: 台 | G16: =IF(M16="","",ROUND(M16*N16,-1)) -> 22200 | H16: =IF(G16="","",ROUND(E16*G16,0)) -> 22200 | I16: 本体は元請様支給 | J16: 3000 | K16: 0.8 | L16: =ROUND(K16*LABOR_DAY,0) -> 15200 | M16: =J16+L16 -> 18200 | N16: =COEF -> 1.22 | O16: =E16*M16 -> 18200 | P16: =ROUND(E16*L16*N16,0) -> 18544 | Q16: 図面カウント | R16: =IF(H16="","",H16-O16) -> 4000 | S16: =IF(OR(H16="",H16=0),"",R16/H16) -> 0.18018018 | T16: 29200 | U16: =IF(OR(T16="",T16=0),"",G16/T16) -> 0.76027397 | V16: 搬入据付＋基礎工事 5,800〜10,000/台（6330539/549/476-3）｜
A17: AC-7 室内機 据付 | C17: 2方向天井カセット PA-P50L7HNB(1.8HP) 面談室 | E17: 1 | F17: 台 | G17: =IF(M17="","",ROUND(M17*N17,-1)) -> 25620 | H17: =IF(G17="","",ROUND(E17*G17,0)) -> 25620 | I17: 本体は元請様支給 | J17: 2000 | K17: 1 | L17: =ROUND(K17*LABOR_DAY,0) -> 19000 | M17: =J17+L17 -> 21000 | N17: =COEF -> 1.22 | O17: =E17*M17 -> 21000 | P17: =ROUND(E17*L17*N17,0) -> 23180 | Q17: 図面カウント | R17: =IF(H17="","",H17-O17) -> 4620 | S17: =IF(OR(H17="",H17=0),"",R17/H17) -> 0.18032787 | T17: 27860 | U17: =IF(OR(T17="",T17=0),"",G17/T17) -> 0.91959799 | V17: 6330558 VRV 90クラス 27,860/台｜
A18: AC-7 室外機 据付 | C18: 1.8HP | E18: 1 | F18: 台 | G18: =IF(M18="","",ROUND(M18*N18,-1)) -> 30380 | H18: =IF(G18="","",ROUND(E18*G18,0)) -> 30380 | I18: 本体は元請様支給 | J18: 4000 | K18: 1.1 | L18: =ROUND(K18*LABOR_DAY,0) -> 20900 | M18: =J18+L18 -> 24900 | N18: =COEF -> 1.22 | O18: =E18*M18 -> 24900 | P18: =ROUND(E18*L18*N18,0) -> 25498 | Q18: 図面カウント | R18: =IF(H18="","",H18-O18) -> 5480 | S18: =IF(OR(H18="",H18=0),"",R18/H18) -> 0.18038183 | T18: 37860 | U18: =IF(OR(T18="",T18=0),"",G18/T18) -> 0.80243001 | V18: 8〜10HP 室外機（防振ゴム・架台固定共）｜
... A28: RAC-4 据付 | C28: 壁掛ルームエアコン XCS-635DGX2-W 内外機 2F寮務スタッフ室 | E28: 1 | F28: 組 | G28: =IF(M28="","",ROUND(M28*N28,-1)) -> 12510 | H28: =IF(G28="","",ROUND(E28*G28,0)) -> 12510 | I28: 本体は元請様支給 | J28: 750 | K28: 0.5 | L28: =ROUND(K28*LABOR_DAY,0) -> 9500 | M28: =J28+L28 -> 10250 | N28: =COEF -> 1.22 | O28: =E28*M28 -> 10250 | P28: =ROUND(E28*L28*N28,0) -> 11590 | Q28: 図面カウント | R28: =IF(H28="","",H28-O28) -> 2260 | S28: =IF(OR(H28="",H28=0),"",R28/H28) -> 0.18065548 | T28: 18300 | U28: =IF(OR(T28="",T28=0),"",G28/T28) -> 0.68360656 | V28: 6330539 RA 搬入据付 12,500/組＋基礎 5,833/組｜
A29: CR-1 集中リモコン 取付 | C29: CZ-10ESM5・CZ-10ESW4 管理人室 | E29: 1 | F29: 台 | G29: =IF(M29="","",ROUND(M29*N29,-1)) -> 18190 | H29: =IF(G29="","",ROUND(E29*G29,0)) -> 18190 | J29: 7500 | K29: 0.39 | L29: =ROUND(K29*LABOR_DAY,0) -> 7410 | M29: =J29+L29 -> 14910 | N29: =COEF -> 1.22 | O29: =E29*M29 -> 14910 | P29: =ROUND(E29*L29*N29,0) -> 9040 | Q29: 図面カウント | R29: =IF(H29="","",H29-O29) -> 3280 | S29: =IF(OR(H29="",H29=0),"",R29/H29) -> 0.18031886 | V29: 旧仮単価（按分）｜配線は A-4
A30: 機器搬入・揚重・養生 | C30: PAC 32台・RAC 154台分 | E30: 1 | F30: 式 | G30: =IF(M30="","",ROUND(M30*N30,-1)) -> 91500 | H30: =IF(G30="","",ROUND(E30*G30,0)) -> 91500 | I30: 想定数量（別紙条件書） | J30: 75000 | K30: 0 | L30: =ROUND(K30*LABOR_DAY,0) -> 0 | M30: =J30+L30 -> 75000 | N30: =COEF -> 1.22 | O30: =E30*M30 -> 75000 | P30: =ROUND(E30*L30*N30,0) -> 0 | Q30: 推測 | R30: =IF(H30="","",H30-O30) -> 16500 | S30: =IF(OR(H30="",H30=0),"",R30/H30) -> 0.18032787 | T30: 93750 | U30: =IF(OR(T30="",T30=0),"",G30/T30) -> 0.976 | V30: 揚重工事費（レッカー）93,750/式（6330558）｜
A31: （2）冷媒配管
A32: 冷媒配管 ① | C32: 被覆銅管 9.52/6.35 (RAC-1,2 1F 及び RAC-3 2F) | E32: 360 | F32: m | G32: =IF(M32="","",ROUND(M32*N32,-1)) -> 7320 | H32: =IF(G32="","",ROUND(E32*G32,0)) -> 2635200 | I32: 図面実測＋想定（別紙） | J32: 2200 | K32: 0.2 | L32: =ROUND(K32*LABOR_DAY,0) -> 3800 | M32: =J32+L32 -> 6000 | N32: =COEF -> 1.22 | O32: =E32*M32 -> 2160000 | P32: =ROUND(E32*L32*N32,0) -> 1668960 | Q32: 実測+推測 | R32: =IF(H32="","",H32-O32) -> 475200 | S32: =IF(OR(H32="",H32=0),"",R32/H32) -> 0.18032787 | T32: 7328 | U32: =IF(OR(T32="",T32=0),"",G32/T32) -> 0.9989083 | V32: 6330539 ペアコイル6.35+9.52 988/m・2分3分級は1,450/m想定、5 m/人工｜平面実測34.3m＋推測(RAC-3 66台×4m、来客室RAC-2 5台×4m、RAC-1補正8m、立上り10台×3m)
A33: 冷媒配管 ② | C33: 被覆銅管 12.7/6.35 (AC-5,7,8 AC-3枝 RAC-4) | E33: 77 | F33: m | G33: =IF(M33="","",ROUND(M33*N33,-1)) -> 8480 | H33: =IF(G33="","",ROUND(E33*G33,0)) -> 652960 | I33: 図面実測＋想定（別紙） | J33: 2960 | K33: 0.21 | L33: =ROUND(K33*LABOR_DAY,0) -> 3990 | M33: =J33+L33 -> 6950 | N33: =COEF -> 1.22 | O33: =E33*M33 -> 535150 | P33: =ROUND(E33*L33*N33,0) -> 374821 | Q33: 実測+推測 | R33: =IF(H33="","",H33-O33) -> 117810 | S33: =IF(OR(H33="",H33=0),"",R33/H33) -> 0.18042453 | T33: 8485 | U33: =IF(OR(T33="",T33=0),"",G33/T33) -> 0.99941072 | V33: 補間（9.52+15.88 4,025 と 6.35+9.52 の間）｜平面実測56m＋推測(立上り4系統×4m、RAC-4 5m)
A34: 冷媒配管 ③ | C34: 被覆銅管 15.88/9.52 (AC-1/2枝 AC-3主 AC-6,9,10) | E34: 96 | F34: m | G34: =IF(M34="","",ROUND(M34*N34,-1)) -> 12540 | H34: =IF(G34="","",ROUND(E34*G34,0)) -> 1203840 | I34: 図面実測＋想定（別紙） | J34: 6100 | K34: 0.22 | L34: =ROUND(K34*LABOR_DAY,0) -> 4180 | M34: =J34+L34 -> 10280 | N34: =COEF -> 1.22 | O34: =E34*M34 -> 986880 | P34: =ROUND(E34*L34*N34,0) -> 489562 | Q34: 実測+推測 | R34: =IF(H34="","",H34-O34) -> 216960 | S34: =IF(OR(H34="",H34=0),"",R34/H34) -> 0.18022329 | T34: 12556 | U34: =IF(OR(T34="",T34=0),"",G34/T34) -> 0.99872571 | V34: 6330476-3 / 6330344-1 9.52+15.88 4,025/m、4.6 m/人工｜平面実測72.2m＋推測(立上り3系統×4m、AC-10 2F分3.5m＋立管8m)
A35: 冷媒配管 ⑥ | C35: 被覆銅管 25.4/9.52 (AC-2主管) | E35: 9 | F35: m | G35: =IF(M35="","",ROUND(M35*N35,-1)) -> 16620 | H35: =IF(G35="","",ROUND(E35*G35,0)) -> 149580 | I35: 図面実測＋想定（別紙） | J35: 8300 | K35: 0.28 | L35: =ROUND(K35*LABOR_DAY,0) -> 5320 | M35: =J35+L35 -> 13620 | N35: =COEF -> 1.22 | O35: =E35*M35 -> 122580 | P35: =ROUND(E35*L35*N35,0) -> 58414 | Q35: 実測+推測 | R35: =IF(H35="","",H35-O35) -> 27000 | S35: =IF(OR(H35="",H35=0),"",R35/H35) -> 0.18050542 | T35: 16632 | U35: =IF(OR(T35="",T35=0),"",G35/T35) -> 0.9992785 | V35: 6330476-3 9.52+25.40 5,475/m、3.5 m/人工｜平面実測5m＋立上り4m
A36: 冷媒配管 ⑦ | C36: 被覆銅管 25.4/12.7 (AC-1主管 4系統) | E36: 57 | F36: m | G36: =IF(M36="","",ROUND(M36*N36,-1)) -> 17460 | H36: =IF(G36="","",ROUND(E36*G36,0)) -> 995220 | I36: 図面実測＋想定（別紙） | J36: 8610 | K36: 0.3 | L36: =ROUND(K36*LABOR_DAY,0) -> 5700 | M36: =J36+L36 -> 14310 | N36: =COEF -> 1.22 | O36: =E36*M36 -> 815670 | P36: =ROUND(E36*L36*N36,0) -> 396378 | Q36: 実測+推測 | R36: =IF(H36="","",H36-O36) -> 179550 | S36: =IF(OR(H36="",H36=0),"",R36/H36) -> 0.18041237 | T36: 17466 | U36: =IF(OR(T36="",T36=0),"",G36/T36) -> 0.99965648 | V36: 6330476-3 12.70+25.40 5,675/m、3.3 m/人工｜平面実測41m＋立上り4系統×4m
A37: 冷媒配管 化粧ケース | C37: 屋外・屋内露出部 (管種凡例: 露出管は化粧ケース仕上) | E37: 125 | F37: m | G37: =IF(M37="","",ROUND(M37*N37,-1)) -> 4150 | H37: =IF(G37="","",ROUND(E37*G37,0)) -> 518750 | I37: 想定数量（別紙条件書） | J37: 1500 | K37: 0.1 | L37: =ROUND(K37*LABOR_DAY,0) -> 1900 | M37: =J37+L37 -> 3400 | N37: =COEF -> 1.22 | O37: =E37*M37 -> 425000 | P37: =ROUND(E37*L37*N37,0) -> 289750 | Q37: 推測 | R37: =IF(H37="","",H37-O37) -> 93750 | S37: =IF(OR(H37="",H37=0),"",R37/H37) -> 0.18072289 | T37: 3516 | U37: =IF(OR(T37="",T37=0),"",G37/T37) -> 1.1803185 | V37: 配管保温工事費 1,194/m（6330476-3）＋化粧ケース材｜PAC13+RAC1F10箇所×2.5m、RAC-3/4 67台×1.0m
A38: 外壁貫通スリーブ材 | C38: VP100 冷媒・ドレン用 (穴明けは建築工事) | E38: 90 | F38: 箇所 | G38: =IF(M38="","",ROUND(M38*N38,-1)) -> 2490 | H38: =IF(G38="","",ROUND(E38*G38,0)) -> 224100 | I38: 想定数量（別紙条件書） | J38: 900 | K38: 0.06 | L38: =ROUND(K38*LABOR_DAY,0) -> 1140 | M38: =J38+L38 -> 2040 | N38: =COEF -> 1.22 | O38: =E38*M38 -> 183600 | P38: =ROUND(E38*L38*N38,0) -> 125172 | Q38: 推測 | R38: =IF(H38="","",H38-O38) -> 40500 | S38: =IF(OR(H38="",H38=0),"",R38/H38) -> 0.18072289 | V38: VP100 スリーブ材＋取付（参考実績なし）｜RAC77＋PAC13
A39: 区画貫通処理 | C39: 冷媒管 フィブロック(認定工法) | E39: 2 | F39: 箇所 | G39: =IF(M39="","",ROUND(M39*N39,-1)) -> 14760 | H39: =IF(G39="","",ROUND(E39*G39,0)) -> 29520 | I39: 図面実測数量 | J39: 4500 | K39: 0.4 | L39: =ROUND(K39*LABOR_DAY,0) -> 7600 | M39: =J39+L39 -> 12100 | N39: =COEF -> 1.22 | O39: =E39*M39 -> 24200 | P39: =ROUND(E39*L39*N39,0) -> 18544 | Q39: 実測 | R39: =IF(H39="","",H39-O39) -> 5320 | S39: =IF(OR(H39="",H39=0),"",R39/H39) -> 0.1802168 | V39: 6330248-2 防火区画貫通 88,000/式（箇所数不明）｜空調平面図1F ●区画貫通部 2箇所
A40: 気密試験・真空引き・冷媒追加充填 作業 | C40: PAC 系統毎 | E40: 13 | F40: 系統 | G40: =IF(M40="","",ROUND(M40*N40,-1)) -> 17570 | H40: =IF(G40="","",ROUND(E40*G40,0)) -> 228410 | J40: 3000 | K40: 0.6 | L40: =ROUND(K40*LABOR_DAY,0) -> 11400 | M40: =J40+L40 -> 14400 | N40: =COEF -> 1.22 | O40: =E40*M40 -> 187200 | P40: =ROUND(E40*L40*N40,0) -> 180804 | Q40: 図面カウント | R40: =IF(H40="","",H40-O40) -> 41210 | S40: =IF(OR(H40="",H40=0),"",R40/H40) -> 0.18042117 | T40: 20000 | U40: =IF(OR(T40="",T40=0),"",G40/T40) -> 0.8785 | V40: 気密テスト 15,000〜25,000/系統・真空引き 3,750〜5,640/系統（6330558/344-1/549）｜
A41: 冷媒追加充填 (冷媒代) | C41: R32/R410A | E41: 8 | F41: kg | G41: =IF(M41="","",ROUND(M41*N41,-1)) -> 4640 | H41: =IF(G41="","",ROUND(E41*G41,0)) -> 37120 | I41: 想定数量（別紙条件書） | J41: 3800 | K41: 0 | L41: =ROUND(K41*LABOR_DAY,0) -> 0 | M41: =J41+L41 -> 3800 | N41: =COEF -> 1.22 | O41: =E41*M41 -> 30400 | P41: =ROUND(E41*L41*N41,0) -> 0 | Q41: 推測 | R41: =IF(H41="","",H41-O41) -> 6720 | S41: =IF(OR(H41="",H41=0),"",R41/H41) -> 0.18103448 | V41: R32 冷媒代（参考に単価行なし）｜配管延長より約20g/m換算
A42: （3）ドレン配管
A43: ドレン管 VP20 | C43: 硬質塩化ビニル管 継手・支持共 | E43: 37 | F43: m | G43: =IF(M43="","",ROUND(M43*N43,-1)) -> 2780 | H43: =IF(G43="","",ROUND(E43*G43,0)) -> 102860 | I43: 図面実測＋想定（別紙） | J43: 380 | K43: 0.1 | L43: =ROUND(K43*LABOR_DAY,0) -> 1900 | M43: =J43+L43 -> 2280 | N43: =COEF -> 1.22 | O43: =E43*M43 -> 84360 | P43: =ROUND(E43*L43*N43,0) -> 85766 | Q43: 実測+推測 | R43: =IF(H43="","",H43-O43) -> 18500 | S43: =IF(OR(H43="",H43=0),"",R43/H43) -> 0.17985612 | T43: 2578 | U43: =IF(OR(T43="",T43=0),"",G43/T43) -> 1.0783553 | V43: 6330539 VP13 138/m、塩ビ工費 9.3〜12 m/人工｜平面実測7m＋推測(RAC-1/2 ドレンアップ吐出→屋外 10台×3m)
A44: ドレン管 VP25 | C44: 硬質塩化ビニル管 継手・支持共 | E44: 94 | F44: m | G44: =IF(M44="","",ROUND(M44*N44,-1)) -> 3130 | H44: =IF(G44="","",ROUND(E44*G44,0)) -> 294220 | I44: 図面実測＋想定（別紙） | J44: 475 | K44: 0.11 | L44: =ROUND(K44*LABOR_DAY,0) -> 2090 | M44: =J44+L44 -> 2565 | N44: =COEF -> 1.22 | O44: =E44*M44 -> 241110 | P44: =ROUND(E44*L44*N44,0) -> 239681 | Q44: 実測+推測 | R44: =IF(H44="","",H44-O44) -> 53110 | S44: =IF(OR(H44="",H44=0),"",R44/H44) -> 0.18051118 | T44: 3134 | U44: =IF(OR(T44="",T44=0),"",G44/T44) -> 0.99872368 | V44: 6330344-1/476-3/248-2 VP25 313/m、工費 2,497/m｜平面実測1F 87.3m・2F 6.1m(未判読分比例配分含む)
A45: ドレン管 VP40 | C45: 硬質塩化ビニル管 継手・支持共 | E45: 68 | F45: m | G45: =IF(M45="","",ROUND(M45*N45,-1)) -> 3940 | H45: =IF(G45="","",ROUND(E45*G45,0)) -> 267920 | I45: 図面実測＋想定（別紙） | J45: 760 | K45: 0.13 | L45: =ROUND(K45*LABOR_DAY,0) -> 2470 | M45: =J45+L45 -> 3230 | N45: =COEF -> 1.22 | O45: =E45*M45 -> 219640 | P45: =ROUND(E45*L45*N45,0) -> 204911 | Q45: 実測+推測 | R45: =IF(H45="","",H45-O45) -> 48280 | S45: =IF(OR(H45="",H45=0),"",R45/H45) -> 0.18020305 | V45: VP25 比例｜平面実測50.2m＋推測(立下り・屋外放流部12箇所×1.5m)
A46: ドレン管 保温 | C46: GW保温筒20 ALGC 天井内 (特記仕様書 保温表は空欄・標準仕様に準じ計上 要確認) | E46: 143 | F46: m | G46: =IF(M46="","",ROUND(M46*N46,-1)) -> 2490 | H46: =IF(G46="","",ROUND(E46*G46,0)) -> 356070 | I46: 想定数量（別紙条件書） | J46: 900 | K46: 0.06 | L46: =ROUND(K46*LABOR_DAY,0) -> 1140 | M46: =J46+L46 -> 2040 | N46: =COEF -> 1.22 | O46: =E46*M46 -> 291720 | P46: =ROUND(E46*L46*N46,0) -> 198884 | Q46: 推測 | R46: =IF(H46="","",H46-O46) -> 64350 | S46: =IF(OR(H46="",H46=0),"",R46/H46) -> 0.18072289 | V46: GW保温筒20 ALGC（参考実績なし）｜VP25・VP40 天井内相当分
A47: ドレン管 区画貫通処理 | C47: 耐火二層管／フィブロック | E47: 2 | F47: 箇所 | G47: =IF(M47="","",ROUND(M47*N47,-1)) -> 14760 | H47: =IF(G47="","",ROUND(E47*G47,0)) -> 29520 | I47: 想定数量（別紙条件書） | J47: 4500 | K47: 0.4 | L47: =ROUND(K47*LABOR_DAY,0) -> 7600 | M47: =J47+L47 -> 12100 | N47: =COEF -> 1.22 | O47: =E47*M47 -> 24200 | P47: =ROUND(E47*L47*N47,0) -> 18544 | Q47: 推測 | R47: =IF(H47="","",H47-O47) -> 5320 | S47: =IF(OR(H47="",H47=0),"",R47/H47) -> 0.1802168 | V47: 6330248-2 防火区画貫通 88,000/式（箇所数不明）｜冷媒管と同位置
A48: RAC-3/4 ドレンホース 延長・共巻 | C48: 勾配確保の上 冷媒管共巻 (図示注記) | E48: 67 | F48: 台 | G48: =IF(M48="","",ROUND(M48*N48,-1)) -> 1530 | H48: =IF(G48="","",ROUND(E48*G48,0)) -> 102510 | I48: 想定数量（別紙条件書） | J48: 300 | K48: 0.05 | L48: =ROUND(K48*LABOR_DAY,0) -> 950 | M48: =J48+L48 -> 1250 | N48: =COEF -> 1.22 | O48: =E48*M48 -> 83750 | P48: =ROUND(E48*L48*N48,0) -> 77653 | Q48: 推測 | R48: =IF(H48="","",H48-O48) -> 18760 | S48: =IF(OR(H48="",H48=0),"",R48/H48) -> 0.18300654 | V48: 推定｜
A49: （4）付帯工事・試運転調整
A50: リモコン線・内外連絡線 配線 | C50: PAC 系統毎 (ワイヤードリモコン線 0.75×2C、渡り線) 工事区分表: 機械 | E50: 13 | F50: 系統 | G50: =IF(M50="","",ROUND(M50*N50,-1)) -> 8470 | H50: =IF(G50="","",ROUND(E50*G50,0)) -> 110110 | J50: 2000 | K50: 0.26 | L50: =ROUND(K50*LABOR_DAY,0) -> 4940 | M50: =J50+L50 -> 6940 | N50: =COEF -> 1.22 | O50: =E50*M50 -> 90220 | P50: =ROUND(E50*L50*N50,0) -> 78348 | Q50: 図面カウント | R50: =IF(H50="","",H50-O50) -> 19890 | S50: =IF(OR(H50="",H50=0),"",R50/H50) -> 0.18063754 | T50: 8436 | U50: =IF(OR(T50="",T50=0),"",G50/T50) -> 1.0040303 | V50: VVF2.0-3C 203/m＋電線材料施工費 約500/m（12m/系統 8,436）→ 原価 6,900｜電源は電気工事
...

Sheet 内訳書(2.空調追加)
A1: 内 訳 書 | J1: 原 価 内 訳 書（内部用・印刷範囲外）
A2: 工事名：（仮称）サンフレッチェ広島 三矢寮新築工事 空調設備工事 空調工事 | I2: 内訳書 No.2
A3: 名 称 | C3: 規格・寸法 | E3: 数 量 | F3: 単位 | G3: 単 価 | H3: 金 額 | I3: 備 考 | J3: 材料原価 | K3: 人工/単位 | L3: 労務原価 | M3: 基準原価単価 | N3: 提出係数 | O3: 基準原価 | P3: 労務費(提出) | Q3: 数量根拠 | R3: 粗利 | S3: 粗利率 | T3: 参考定価ベース | U3: 当社/参考 | V3: 単価出典・メモ（内部）
A4: ２．金額変更案 No5・6 空調追加（検討図 08 朱書き）
A6: （2）No5・6 空調追加
A7: 追AC1 室内機 据付 | C7: 空冷HP 4方向天井カセット PA-P140U7GTNB(5HP 同時トリプル) 子機 1Fホール・廊下(洗濯室前)・階段ホール | E7: 3 | F7: 台 | G7: =IF(M7="","",ROUND(M7*N7,-1)) -> 21660 | H7: =IF(G7="","",ROUND(E7*G7,0)) -> 64980 | I7: 本体は元請様支給 | J7: 1600 | K7: 0.85 | L7: =ROUND(K7*LABOR_DAY,0) -> 16150 | M7: =J7+L7 -> 17750 | N7: =COEF -> 1.22 | O7: =E7*M7 -> 53250 | P7: =ROUND(E7*L7*N7,0) -> 59109 | Q7: 図面カウント | R7: =IF(H7="","",H7-O7) -> 11730 | S7: =IF(OR(H7="",H7=0),"",R7/H7) -> 0.18051708 | T7: 21700 | U7: =IF(OR(T7="",T7=0),"",G7/T7) -> 0.99815668 | V7: 6330476-3 搬入据付 238,750/11台≒21,700/台、6330284-1 25,000/台｜空調平面図1F 朱書き □3箇所
A8: 追AC1 室外機 据付 | C8: 5HP 1F物干場側(AC-3室外機隣) | E8: 1 | F8: 台 | G8: =IF(M8="","",ROUND(M8*N8,-1)) -> 22200 | H8: =IF(G8="","",ROUND(E8*G8,0)) -> 22200 | I8: 本体は元請様支給 | J8: 3000 | K8: 0.8 | L8: =ROUND(K8*LABOR_DAY,0) -> 15200 | M8: =J8+L8 -> 18200 | N8: =COEF -> 1.22 | O8: =E8*M8 -> 18200 | P8: =ROUND(E8*L8*N8,0) -> 18544 | Q8: 図面カウント | R8: =IF(H8="","",H8-O8) -> 4000 | S8: =IF(OR(H8="",H8=0),"",R8/H8) -> 0.18018018 | T8: 29200 | U8: =IF(OR(T8="",T8=0),"",G8/T8) -> 0.76027397 | V8: 搬入据付＋基礎工事 5,800〜10,000/台（6330539/549/476-3）｜
A9: 追AC2 室内機 据付 | C9: 空冷HP 2方向天井カセット PA-P224L7HTNB(8HP 同時トリプル) 子機 1F南廊下 3箇所 | E9: 3 | F9: 台 | G9: =IF(M9="","",ROUND(M9*N9,-1)) -> 25620 | H9: =IF(G9="","",ROUND(E9*G9,0)) -> 76860 | I9: 本体は元請様支給 | J9: 2000 | K9: 1 | L9: =ROUND(K9*LABOR_DAY,0) -> 19000 | M9: =J9+L9 -> 21000 | N9: =COEF -> 1.22 | O9: =E9*M9 -> 63000 | P9: =ROUND(E9*L9*N9,0) -> 69540 | Q9: 図面カウント | R9: =IF(H9="","",H9-O9) -> 13860 | S9: =IF(OR(H9="",H9=0),"",R9/H9) -> 0.18032787 | T9: 27860 | U9: =IF(OR(T9="",T9=0),"",G9/T9) -> 0.91959799 | V9: 6330558 VRV 90クラス 27,860/台｜
A10: 追AC2 室外機 据付 | C10: 8HP 1F南側(AC-1/AC-5室外機隣) | E10: 1 | F10: 台 | G10: =IF(M10="","",ROUND(M10*N10,-1)) -> 30380 | H10: =IF(G10="","",ROUND(E10*G10,0)) -> 30380 | I10: 本体は元請様支給 | J10: 4000 | K10: 1.1 | L10: =ROUND(K10*LABOR_DAY,0) -> 20900 | M10: =J10+L10 -> 24900 | N10: =COEF -> 1.22 | O10: =E10*M10 -> 24900 | P10: =ROUND(E10*L10*N10,0) -> 25498 | Q10: 図面カウント | R10: =IF(H10="","",H10-O10) -> 5480 | S10: =IF(OR(H10="",H10=0),"",R10/H10) -> 0.18038183 | T10: 37860 | U10: =IF(OR(T10="",T10=0),"",G10/T10) -> 0.80243001 | V10: 8〜10HP 室外機（防振ゴム・架台固定共）｜
A11: 追AC3 室内機 据付 | C11: PA-P224L7HTNB 子機 2F北廊下 3箇所 | E11: 3 | F11: 台 | G11: =IF(M11="","",ROUND(M11*N11,-1)) -> 21660 | H11: =IF(G11="","",ROUND(E11*G11,0)) -> 64980 | I11: 本体は元請様支給 | J11: 1600 | K11: 0.85 | L11: =ROUND(K11*LABOR_DAY,0) -> 16150 | M11: =J11+L11 -> 17750 | N11: =COEF -> 1.22 | O11: =E11*M11 -> 53250 | P11: =ROUND(E11*L11*N11,0) -> 59109 | Q11: 図面カウント | R11: =IF(H11="","",H11-O11) -> 11730 | S11: =IF(OR(H11="",H11=0),"",R11/H11) -> 0.18051708 | T11: 21700 | U11: =IF(OR(T11="",T11=0),"",G11/T11) -> 0.99815668 | V11: 6330476-3 搬入据付 238,750/11台≒21,700/台、6330284-1 25,000/台｜
A12: 追AC3 室外機 据付 | C12: 8HP 1F東側地上(屋外階段A付近) | E12: 1 | F12: 台 | G12: =IF(M12="","",ROUND(M12*N12,-1)) -> 30380 | H12: =IF(G12="","",ROUND(E12*G12,0)) -> 30380 | I12: 本体は元請様支給 | J12: 4000 | K12: 1.1 | L12: =ROUND(K12*LABOR_DAY,0) -> 20900 | M12: =J12+L12 -> 24900 | N12: =COEF -> 1.22 | O12: =E12*M12 -> 24900 | P12: =ROUND(E12*L12*N12,0) -> 25498 | Q12: 図面カウント | R12: =IF(H12="","",H12-O12) -> 5480 | S12: =IF(OR(H12="",H12=0),"",R12/H12) -> 0.18038183 | T12: 37860 | U12: =IF(OR(T12="",T12=0),"",G12/T12) -> 0.80243001 | V12: 8〜10HP 室外機（防振ゴム・架台固定共）｜
A13: 追AC4 室内機 据付 | C13: PA-P224L7HTNB 子機 2F階段ホール2・南廊下1 | E13: 3 | F13: 台 | G13: =IF(M13="","",ROUND(M13*N13,-1)) -> 21660 | H13: =IF(G13="","",ROUND(E13*G13,0)) -> 64980 | I13: 本体は元請様支給 | J13: 1600 | K13: 0.85 | L13: =ROUND(K13*LABOR_DAY,0) -> 16150 | M13: =J13+L13 -> 17750 | N13: =COEF -> 1.22 | O13: =E13*M13 -> 53250 | P13: =ROUND(E13*L13*N13,0) -> 59109 | Q13: 図面カウント | R13: =IF(H13="","",H13-O13) -> 11730 | S13: =IF(OR(H13="",H13=0),"",R13/H13) -> 0.18051708 | T13: 21700 | U13: =IF(OR(T13="",T13=0),"",G13/T13) -> 0.99815668 | V13: 6330476-3 搬入据付 238,750/11台≒21,700/台、6330284-1 25,000/台｜
A14: 追AC4 室外機 据付 | C14: 8HP 1F東側地上(倉庫2東) | E14: 1 | F14: 台 | G14: =IF(M14="","",ROUND(M14*N14,-1)) -> 30380 | H14: =IF(G14="","",ROUND(E14*G14,0)) -> 30380 | I14: 本体は元請様支給 | J14: 4000 | K14: 1.1 | L14: =ROUND(K14*LABOR_DAY,0) -> 20900 | M14: =J14+L14 -> 24900 | N14: =COEF -> 1.22 | O14: =E14*M14 -> 24900 | P14: =ROUND(E14*L14*N14,0) -> 25498 | Q14: 図面カウント | R14: =IF(H14="","",H14-O14) -> 5480 | S14: =IF(OR(H14="",H14=0),"",R14/H14) -> 0.18038183 | T14: 37860 | U14: =IF(OR(T14="",T14=0),"",G14/T14) -> 0.80243001 | V14: 8〜10HP 室外機（防振ゴム・架台固定共）｜
A15: 追AC5 室内機 据付 | C15: PA-P224L7HTNB 子機 2F南廊下 3箇所 | E15: 3 | F15: 台 | G15: =IF(M15="","",ROUND(M15*N15,-1)) -> 21660 | H15: =IF(G15="","",ROUND(E15*G15,0)) -> 64980 | I15: 本体は元請様支給 | J15: 1600 | K15: 0.85 | L15: =ROUND(K15*LABOR_DAY,0) -> 16150 | M15: =J15+L15 -> 17750 | N15: =COEF -> 1.22 | O15: =E15*M15 -> 53250 | P15: =ROUND(E15*L15*N15,0) -> 59109 | Q15: 図面カウント | R15: =IF(H15="","",H15-O15) -> 11730 | S15: =IF(OR(H15="",H15=0),"",R15/H15) -> 0.18051708 | T15: 21700 | U15: =IF(OR(T15="",T15=0),"",G15/T15) -> 0.99815668 | V15: 6330476-3 搬入据付 238,750/11台≒21,700/台、6330284-1 25,000/台｜
A16: 追AC5 室外機 据付 | C16: 8HP 1F東側地上(倉庫2東) | E16: 1 | F16: 台 | G16: =IF(M16="","",ROUND(M16*N16,-1)) -> 30380 | H16: =IF(G16="","",ROUND(E16*G16,0)) -> 30380 | I16: 本体は元請様支給 | J16: 4000 | K16: 1.1 | L16: =ROUND(K16*LABOR_DAY,0) -> 20900 | M16: =J16+L16 -> 24900 | N16: =COEF -> 1.22 | O16: =E16*M16 -> 24900 | P16: =ROUND(E16*L16*N16,0) -> 25498 | Q16: 図面カウント | R16: =IF(H16="","",H16-O16) -> 5480 | S16: =IF(OR(H16="",H16=0),"",R16/H16) -> 0.18038183 | T16: 37860 | U16: =IF(OR(T16="",T16=0),"",G16/T16) -> 0.80243001 | V16: 8〜10HP 室外機（防振ゴム・架台固定共）｜
A17: 分岐管(トリプル用) 取付 | C17: 各系統2組 ※機器付属として元請支給想定・未支給なら別途 | E17: 10 | F17: 組 | G17: =IF(M17="","",ROUND(M17*N17,-1)) -> 6530 | H17: =IF(G17="","",ROUND(E17*G17,0)) -> 65300 | I17: 想定数量（別紙条件書） | J17: 600 | K17: 0.25 | L17: =ROUND(K17*LABOR_DAY,0) -> 4750 | M17: =J17+L17 -> 5350 | N17: =COEF -> 1.22 | O17: =E17*M17 -> 53500 | P17: =ROUND(E17*L17*N17,0) -> 57950 | Q17: 推測 | R17: =IF(H17="","",H17-O17) -> 11800 | S17: =IF(OR(H17="",H17=0),"",R17/H17) -> 0.18070444 | V17: 分岐管取付（支給）｜取付費のみ
A18: 冷媒配管 ① | C18: 被覆銅管 9.52/6.35 追AC1 枝管 | E18: 35 | F18: m | G18: =IF(M18="","",ROUND(M18*N18,-1)) -> 7320 | H18: =IF(G18="","",ROUND(E18*G18,0)) -> 256200 | I18: 想定数量（別紙条件書） | J18: 2200 | K18: 0.2 | L18: =ROUND(K18*LABOR_DAY,0) -> 3800 | M18: =J18+L18 -> 6000 | N18: =COEF -> 1.22 | O18: =E18*M18 -> 210000 | P18: =ROUND(E18*L18*N18,0) -> 162260 | Q18: 推測 | R18: =IF(H18="","",H18-O18) -> 46200 | S18: =IF(OR(H18="",H18=0),"",R18/H18) -> 0.18032787 | T18: 7328 | U18: =IF(OR(T18="",T18=0),"",G18/T18) -> 0.9989083 | V18: 6330539 ペアコイル6.35+9.52 988/m・2分3分級は1,450/m想定、5 m/人工｜配管経路図示なし 室内外機位置より推定
A19: 冷媒配管 ③ | C19: 被覆銅管 15.88/9.52 追AC1主管16m・追AC2～5 枝管168m | E19: 184 | F19: m | G19: =IF(M19="","",ROUND(M19*N19,-1)) -> 12540 | H19: =IF(G19="","",ROUND(E19*G19,0)) -> 2307360 | I19: 想定数量（別紙条件書） | J19: 6100 | K19: 0.22 | L19: =ROUND(K19*LABOR_DAY,0) -> 4180 | M19: =J19+L19 -> 10280 | N19: =COEF -> 1.22 | O19: =E19*M19 -> 1891520 | P19: =ROUND(E19*L19*N19,0) -> 938326 | Q19: 推測 | R19: =IF(H19="","",H19-O19) -> 415840 | S19: =IF(OR(H19="",H19=0),"",R19/H19) -> 0.18022329 | T19: 12556 | U19: =IF(OR(T19="",T19=0),"",G19/T19) -> 0.99872571 | V19: 6330476-3 / 6330344-1 9.52+15.88 4,025/m、4.6 m/人工｜同上
A20: 冷媒配管 ⑥ | C20: 被覆銅管 25.4/9.52 追AC2～5 主管 (立管2F→1F含む) | E20: 73 | F20: m | G20: =IF(M20="","",ROUND(M20*N20,-1)) -> 16620 | H20: =IF(G20="","",ROUND(E20*G20,0)) -> 1213260 | I20: 想定数量（別紙条件書） | J20: 8300 | K20: 0.28 | L20: =ROUND(K20*LABOR_DAY,0) -> 5320 | M20: =J20+L20 -> 13620 | N20: =COEF -> 1.22 | O20: =E20*M20 -> 994260 | P20: =ROUND(E20*L20*N20,0) -> 473799 | Q20: 推測 | R20: =IF(H20="","",H20-O20) -> 219000 | S20: =IF(OR(H20="",H20=0),"",R20/H20) -> 0.18050542 | T20: 16632 | U20: =IF(OR(T20="",T20=0),"",G20/T20) -> 0.9992785 | V20: 6330476-3 9.52+25.40 5,475/m、3.5 m/人工｜追AC2 12・AC3 14・AC4 31・AC5 16
A21: 冷媒配管 化粧ケース | C21: 屋外露出部 | E21: 13 | F21: m | G21: =IF(M21="","",ROUND(M21*N21,-1)) -> 4150 | H21: =IF(G21="","",ROUND(E21*G21,0)) -> 53950 | I21: 想定数量（別紙条件書） | J21: 1500 | K21: 0.1 | L21: =ROUND(K21*LABOR_DAY,0) -> 1900 | M21: =J21+L21 -> 3400 | N21: =COEF -> 1.22 | O21: =E21*M21 -> 44200 | P21: =ROUND(E21*L21*N21,0) -> 30134 | Q21: 推測 | R21: =IF(H21="","",H21-O21) -> 9750 | S21: =IF(OR(H21="",H21=0),"",R21/H21) -> 0.18072289 | T21: 3516 | U21: =IF(OR(T21="",T21=0),"",G21/T21) -> 1.1803185 | V21: 配管保温工事費 1,194/m（6330476-3）＋化粧ケース材｜5系統×2.5m
A22: 外壁貫通スリーブ材 | C22: VP100 | E22: 5 | F22: 箇所 | G22: =IF(M22="","",ROUND(M22*N22,-1)) -> 2490 | H22: =IF(G22="","",ROUND(E22*G22,0)) -> 12450 | I22: 想定数量（別紙条件書） | J22: 900 | K22: 0.06 | L22: =ROUND(K22*LABOR_DAY,0) -> 1140 | M22: =J22+L22 -> 2040 | N22: =COEF -> 1.22 | O22: =E22*M22 -> 10200 | P22: =ROUND(E22*L22*N22,0) -> 6954 | Q22: 推測 | R22: =IF(H22="","",H22-O22) -> 2250 | S22: =IF(OR(H22="",H22=0),"",R22/H22) -> 0.18072289 | V22: VP100 スリーブ材＋取付（参考実績なし）｜
A23: 区画貫通処理 | C23: 冷媒管・ドレン管 フィブロック 廊下区画壁 | E23: 5 | F23: 箇所 | G23: =IF(M23="","",ROUND(M23*N23,-1)) -> 14760 | H23: =IF(G23="","",ROUND(E23*G23,0)) -> 73800 | I23: 想定数量（別紙条件書） | J23: 4500 | K23: 0.4 | L23: =ROUND(K23*LABOR_DAY,0) -> 7600 | M23: =J23+L23 -> 12100 | N23: =COEF -> 1.22 | O23: =E23*M23 -> 60500 | P23: =ROUND(E23*L23*N23,0) -> 46360 | Q23: 推測 | R23: =IF(H23="","",H23-O23) -> 13300 | S23: =IF(OR(H23="",H23=0),"",R23/H23) -> 0.1802168 | V23: 6330248-2 防火区画貫通 88,000/式（箇所数不明）｜各系統1箇所と仮定
A24: ドレン管 VP25 | C24: 継手・支持共 15台×8m | E24: 120 | F24: m | G24: =IF(M24="","",ROUND(M24*N24,-1)) -> 3130 | H24: =IF(G24="","",ROUND(E24*G24,0)) -> 375600 | I24: 想定数量（別紙条件書） | J24: 475 | K24: 0.11 | L24: =ROUND(K24*LABOR_DAY,0) -> 2090 | M24: =J24+L24 -> 2565 | N24: =COEF -> 1.22 | O24: =E24*M24 -> 307800 | P24: =ROUND(E24*L24*N24,0) -> 305976 | Q24: 推測 | R24: =IF(H24="","",H24-O24) -> 67800 | S24: =IF(OR(H24="",H24=0),"",R24/H24) -> 0.18051118 | T24: 3134 | U24: =IF(OR(T24="",T24=0),"",G24/T24) -> 0.99872368 | V24: 6330344-1/476-3/248-2 VP25 313/m、工費 2,497/m｜
A25: ドレン管 VP40 | C25: 継手・支持共 集合管・立下り | E25: 30 | F25: m | G25: =IF(M25="","",ROUND(M25*N25,-1)) -> 3940 | H25: =IF(G25="","",ROUND(E25*G25,0)) -> 118200 | I25: 想定数量（別紙条件書） | J25: 760 | K25: 0.13 | L25: =ROUND(K25*LABOR_DAY,0) -> 2470 | M25: =J25+L25 -> 3230 | N25: =COEF -> 1.22 | O25: =E25*M25 -> 96900 | P25: =ROUND(E25*L25*N25,0) -> 90402 | Q25: 推測 | R25: =IF(H25="","",H25-O25) -> 21300 | S25: =IF(OR(H25="",H25=0),"",R25/H25) -> 0.18020305 | V25: VP25 比例｜
A26: ドレン管 保温 | C26: GW保温筒20 ALGC | E26: 150 | F26: m | G26: =IF(M26="","",ROUND(M26*N26,-1)) -> 2490 | H26: =IF(G26="","",ROUND(E26*G26,0)) -> 373500 | I26: 想定数量（別紙条件書） | J26: 900 | K26: 0.06 | L26: =ROUND(K26*LABOR_DAY,0) -> 1140 | M26: =J26+L26 -> 2040 | N26: =COEF -> 1.22 | O26: =E26*M26 -> 306000 | P26: =ROUND(E26*L26*N26,0) -> 208620 | Q26: 推測 | R26: =IF(H26="","",H26-O26) -> 67500 | S26: =IF(OR(H26="",H26=0),"",R26/H26) -> 0.18072289 | V26: GW保温筒20 ALGC（参考実績なし）｜
A27: 気密試験・真空引き・冷媒追加充填 作業 | E27: 5 | F27: 系統 | G27: =IF(M27="","",ROUND(M27*N27,-1)) -> 17570 | H27: =IF(G27="","",ROUND(E27*G27,0)) -> 87850 | J27: 3000 | K27: 0.6 | L27: =ROUND(K27*LABOR_DAY,0) -> 11400 | M27: =J27+L27 -> 14400 | N27: =COEF -> 1.22 | O27: =E27*M27 -> 72000 | P27: =ROUND(E27*L27*N27,0) -> 69540 | Q27: 図面カウント | R27: =IF(H27="","",H27-O27) -> 15850 | S27: =IF(OR(H27="",H27=0),"",R27/H27) -> 0.18042117 | T27: 20000 | U27: =IF(OR(T27="",T27=0),"",G27/T27) -> 0.8785 | V27: 気密テスト 15,000〜25,000/系統・真空引き 3,750〜5,640/系統（6330558/344-1/549）｜
A28: 冷媒追加充填 (冷媒代) | E28: 6 | F28: kg | G28: =IF(M28="","",ROUND(M28*N28,-1)) -> 4640 | H28: =IF(G28="","",ROUND(E28*G28,0)) -> 27840 | I28: 想定数量（別紙条件書） | J28: 3800 | K28: 0 | L28: =ROUND(K28*LABOR_DAY,0) -> 0 | M28: =J28+L28 -> 3800 | N28: =COEF -> 1.22 | O28: =E28*M28 -> 22800 | P28: =ROUND(E28*L28*N28,0) -> 0 | Q28: 推測 | R28: =IF(H28="","",H28-O28) -> 5040 | S28: =IF(OR(H28="",H28=0),"",R28/H28) -> 0.18103448 | V28: R32 冷媒代（参考に単価行なし）｜
A29: リモコン線・内外連絡線 配線 | C29: ワイヤードリモコン 系統毎 | E29: 5 | F29: 系統 | G29: =IF(M29="","",ROUND(M29*N29,-1)) -> 8470 | H29: =IF(G29="","",ROUND(E29*G29,0)) -> 42350 | J29: 2000 | K29: 0.26 | L29: =ROUND(K29*LABOR_DAY,0) -> 4940 | M29: =J29+L29 -> 6940 | N29: =COEF -> 1.22 | O29: =E29*M29 -> 34700 | P29: =ROUND(E29*L29*N29,0) -> 30134 | Q29: 図面カウント | R29: =IF(H29="","",H29-O29) -> 7650 | S29: =IF(OR(H29="",H29=0),"",R29/H29) -> 0.18063754 | T29: 8436 | U29: =IF(OR(T29="",T29=0),"",G29/T29) -> 1.0040303 | V29: VVF2.0-3C 203/m＋電線材料施工費 約500/m（12m/系統 8,436）→ 原価 6,900｜子機3台渡り
A30: 集中リモコン CR-1 制御配線 追加 | C30: S-LINK 5系統分 | E30: 1 | F30: 式 | G30: =IF(M30="","",ROUND(M30*N30,-1)) -> 26230 | H30: =IF(G30="","",ROUND(E30*G30,0)) -> 26230 | I30: 想定数量（別紙条件書） | J30: 12000 | K30: 0.5 | L30: =ROUND(K30*LABOR_DAY,0) -> 9500 | M30: =J30+L30 -> 21500 | N30: =COEF -> 1.22 | O30: =E30*M30 -> 21500 | P30: =ROUND(E30*L30*N30,0) -> 11590 | Q30: 推測 | R30: =IF(H30="","",H30-O30) -> 4730 | S30: =IF(OR(H30="",H30=0),"",R30/H30) -> 0.18032787 | V30: 集中リモコン制御線 200m 推定｜
A31: 試運転調整 | E31: 5 | F31: 系統 | G31: =IF(M31="","",ROUND(M31*N31,-1)) -> 10980 | H31: =IF(G31="","",ROUND(E31*G31,0)) -> 54900 | J31: 450 | K31: 0.45 | L31: =ROUND(K31*LABOR_DAY,0) -> 8550 | M31: =J31+L31 -> 9000 | N31: =COEF -> 1.22 | O31: =E31*M31 -> 45000 | P31: =ROUND(E31*L31*N31,0) -> 52155 | Q31: 図面カウント | R31: =IF(H31="","",H31-O31) -> 9900 | S31: =IF(OR(H31="",H31=0),"",R31/H31) -> 0.18032787 | T31: 11000 | U31: =IF(OR(T31="",T31=0),"",G31/T31) -> 0.99818182 | V31: 試運転調整費 10,000〜12,500/系統（6330344-1/549/476-3）｜
A32: 機器搬入・揚重・養生 追加 | E32: 1 | F32: 式 | G32: =IF(M32="","",ROUND(M32*N32,-1)) -> 91500 | H32: =IF(G32="","",ROUND(E32*G32,0)) -> 91500 | I32: 想定数量（別紙条件書） | J32: 75000 | K32: 0 | L32: =ROUND(K32*LABOR_DAY,0) -> 0 | M32: =J32+L32 -> 75000 | N32: =COEF -> 1.22 | O32: =E32*M32 -> 75000 | P32: =ROUND(E32*L32*N32,0) -> 0 | Q32: 推測 | R32: =IF(H32="","",H32-O32) -> 16500 | S32: =IF(OR(H32="",H32=0),"",R32/H32) -> 0.18032787 | T32: 93750 | U32: =IF(OR(T32="",T32=0),"",G32/T32) -> 0.976 | V32: 揚重工事費（レッカー）93,750/式（6330558）｜
A34: 【小 計】 | H34: =SUM(H6:H33) -> 5660790 | K34: =SUMPRODUCT(E6:E33,K6:K33) -> 125.57 | O34: =SUM(O6:O33) -> 4639680 | P34: =SUM(P6:P33) -> 2910712 | R34: =H34-O34 -> 1021110 | S34: =IF(H34=0,"",R34/H34) -> 0.18038295

Sheet 法定福利費内訳明細書
B1: 法 定 福 利 費 内 訳 明 細 書
B2: ="（御見積書 No."&'表紙(工事)'!K3&" の添付資料）" -> （御見積書 No. の添付資料）
B4: 見積年月日 | C4: ='表紙(工事)'!J4 -> 46301 | F4: 見積No. | G4: =IF('表紙(工事)'!K3="","",'表紙(工事)'!K3)
B5: 発注者名 | C5: 株式会社共栄店舗 御中
B6: 工事名 | C6: （仮称）サンフレッチェ広島 三矢寮新築工事 空調設備工事
B7: 施工場所 | C7: 広島県安芸高田市吉田町西浦字日南山835-27
B8: 会社名 | C8: 宮地機工株式会社 | F8: 所在地 | G8: 広島県尾道市東尾道9-9
B10: 【1】 労務費の内訳（法定福利費の算定基礎）
B11: ※ 本見積の労務費は、内訳書各項目の材工共単価のうち労務費相当額（自社施工分）の合計です。機器は元請様手配のため含みません。
B12: 項 目 | C12: 労務費（円） | E12: 摘 要
B13: 空調工事 労務費 | C13: ='内訳書(1.空調工事)'!P58 -> 6712464 | E13: 内訳書 No.1 各項目の労務費相当額の合計
B14: 空調追加 労務費 | C14: ='内訳書(2.空調追加)'!P34 -> 2910712 | E14: 内訳書 No.2 各項目の労務費相当額の合計
B15: 労 務 費 合 計 | C15: =SUM(C13:C14) -> 9623176 | E15: ← 法定福利費の算定基礎額
B17: 【2】 法定福利費の算定
B18: 計算式： 法定福利費 ＝ 労務費 × 事業主負担料率 （保険ごとに円未満切捨て）
B19: 保険の種類 | C19: 対象労務費（円） | E19: 事業主負担料率 | F19: 法定福利費（円） | G19: 算定根拠
B20: 健康保険料 | C20: =$C$15 -> 9623176 | E20: 0.0489 | F20: =ROUNDDOWN(C20*E20,0) -> 470573 | G20: 健康保険料率 9.780%（協会けんぽ 広島県 令和8年度）×1/2（労使折半）
B21: 介護保険料 | C21: =$C$15 -> 9623176 | E21: 0.0081 | F21: =ROUNDDOWN(C21*E21,0) -> 77947 | G21: 介護保険料率 1.620%（全国一律 令和8年度）×1/2（労使折半）
B22: 子ども・子育て支援金 | C22: =$C$15 -> 9623176 | E22: 0.00115 | F22: =ROUNDDOWN(C22*E22,0) -> 11066 | G22: 支援金率 0.230%（令和8年4月分〜）×1/2（労使折半）
B23: 厚生年金保険料 | C23: =$C$15 -> 9623176 | E23: 0.0915 | F23: =ROUNDDOWN(C23*E23,0) -> 880520 | G23: 厚生年金保険料率 18.300%（平成29年9月以降固定）×1/2（労使折半）
B24: 雇用保険料 | C24: =$C$15 -> 9623176 | E24: 0.0105 | F24: =ROUNDDOWN(C24*E24,0) -> 101043 | G24: 雇用保険料率（建設の事業）事業主負担分 1.050%
B25: 子ども・子育て拠出金 | C25: =$C$15 -> 9623176 | E25: 0.0036 | F25: =ROUNDDOWN(C25*E25,0) -> 34643 | G25: 拠出金率 0.360%（事業主全額負担）
B26: 合 計 | E26: =SUM(E20:E25) -> 0.16375 | F26: =SUM(F20:F25) -> 1575792
B28: ※ 料率は見積作成時点（令和8年度）の公表料率によります。料率が改定された場合は改定後の料率により精算させていただきます。
B29: ※ 法定福利費は御見積書の③に計上しています。

Sheet 御見積条件
A1: 御見積条件・注意事項
A2: （仮称）サンフレッチェ広島 三矢寮新築工事 空調設備工事 空調工事 御見積書 添付
A4: 【1】御見積条件・注意事項
A5: 1. | B5: 本見積は機械設備図 06（特記仕様書・空調機器表・換気機器表・空調平面図・換気平面図・厨房廻り詳細図）に基づき当社にて拾い出した数量により積算しております。配管・ダクトの平面延長は図面（A3 1:300、厨房詳細 1:70）から計測し、立上り・立下り・機器接続部および図面に経路の記載がない部分は想定数量として計上しています（別紙【2】参照）。
A6: 2. | B6: 空調機器・換気機器は元請様手配のため本見積には含みません（室内機・室外機・集中リモコン・換気扇・中間ファン・全熱交換器・パイプファン・有圧扇・屋外機架台（2段架台含む）・ドレンアップ・SUS製フード・ウェザーカバー等、機器表記載の本体および付属品）。本見積は上記機器の搬入・据付・取付費のみを計上しています。
A7: 3. | B7: 追加空調（追AC1〜5 同時トリプル）の分岐管は機器付属品として元請様支給を想定し、取付費のみ計上しています。支給外の場合は別途申し受けます。
A8: 4. | B8: 機器の電源供給（電源・動力配線、盤、接地、インバータ盤）は電気工事とし含みません。機器付属の制御盤およびリモコン制御の配管・配線（工事区分表「機械」）は本見積に計上しています。
A9: 5. | B9: 基礎（室外機基礎）、躯体・外壁の穴明け、スリーブ・型枠の穴埋め、天井点検口、天井・壁の開口補強および仕上げ補修は建築工事とし含みません（工事区分表による）。外壁貫通スリーブ材のみ計上しています。
A10: 6. | B10: 冷媒管は被覆銅管（製造者標準品）とし、露出部は化粧ケース仕上げとして計上しています。特記仕様書は脱酸銅管／被覆銅管とも未選択のため、管種凡例（被覆銅管）によっています。
A11: 7. | B11: ドレン管の保温は特記仕様書の保温表に記載がないため、公共建築工事標準仕様書に準じ天井内 GW保温筒20 ALGC として計上しています。不要の場合は減額いたします。
A12: 8. | B12: 冷媒配管の追加充填ガスは想定量で計上しています。系統・配管長の確定後に精算いたします。
A13: 9. | B13: 施工図・竣工図（完成図）の作成、風量測定・試験成績書の作成、官庁検査対応は含みません。必要な場合は別途お見積りいたします。
A14: 10. | B14: 仮設（足場・高所作業車・仮設電気・水道・資材置場等）および産業廃棄物の処分費は元請様にてご負担願います（当社発生材は指定集積場所への分別搬出まで）。
A15: 11. | B15: 工期は全体工程表（2026.8.18 共栄店舗）に基づく通常の日中作業を前提としております。夜間・休日作業、工程の大幅な変更や他工事との輻輳による手待ち、工期延長に伴う経費増は別途協議とさせていただきます。
A16: 12. | B16: 本見積書に記載なき事項については別途とさせていただきます。工事に係る電気・水道は無償支給願います。
A17: 13. | B17: 本見積金額には消費税は含まれておりません。労務費に係る法定福利費（事業主負担分）は別紙「法定福利費内訳明細書」のとおり計上しています。
A19: 【2】想定数量（推測）項目の前提
A20: 図面に数量・経路の記載がなく当社にて想定した項目です。「図面実測＋想定」は平面延長を図面計測し、立上り等を想定加算したものです。実数量確定後に精算させていただきます。
A21: No. | B21: 内訳書 | C21: 項 目 | D21: 前提・想定内容 | F21: 数量（区分）
A22: 1 | B22: No.1 | C22: 冷媒配管 ① 被覆銅管 9.52/6.35 (RAC-1,2 1F 及び RAC-3 2F) | D22: 平面実測34.3m＋推測(RAC-3 66台×4m、来客室RAC-2 5台×4m、RAC-1補正8m、立上り10台×3m) | F22: 360 m（実測＋想定）
A23: 2 | B23: No.1 | C23: 冷媒配管 ② 被覆銅管 12.7/6.35 (AC-5,7,8 AC-3枝 RAC-4) | D23: 平面実測56m＋推測(立上り4系統×4m、RAC-4 5m) | F23: 77 m（実測＋想定）
A24: 3 | B24: No.1 | C24: 冷媒配管 ③ 被覆銅管 15.88/9.52 (AC-1/2枝 AC-3主 AC-6,9,10) | D24: 平面実測72.2m＋推測(立上り3系統×4m、AC-10 2F分3.5m＋立管8m) | F24: 96 m（実測＋想定）
A25: 4 | B25: No.1 | C25: 冷媒配管 ⑥ 被覆銅管 25.4/9.52 (AC-2主管) | D25: 平面実測5m＋立上り4m | F25: 9 m（実測＋想定）
A26: 5 | B26: No.1 | C26: 冷媒配管 ⑦ 被覆銅管 25.4/12.7 (AC-1主管 4系統) | D26: 平面実測41m＋立上り4系統×4m | F26: 57 m（実測＋想定）
A27: 6 | B27: No.1 | C27: 冷媒配管 化粧ケース 屋外・屋内露出部 (管種凡例: 露出管は化粧ケース仕上) | D27: PAC13+RAC1F10箇所×2.5m、RAC-3/4 67台×1.0m | F27: 125 m（想定）
A28: 7 | B28: No.1 | C28: 外壁貫通スリーブ材 VP100 冷媒・ドレン用 (穴明けは建築工事) | D28: RAC77＋PAC13 | F28: 90 箇所（想定）
A29: 8 | B29: No.1 | C29: 冷媒追加充填 (冷媒代) R32/R410A | D29: 配管延長より約20g/m換算 | F29: 8 kg（想定）
A30: 9 | B30: No.1 | C30: ドレン管 VP20 硬質塩化ビニル管 継手・支持共 | D30: 平面実測7m＋推測(RAC-1/2 ドレンアップ吐出→屋外 10台×3m) | F30: 37 m（実測＋想定）
A31: 10 | B31: No.1 | C31: ドレン管 VP25 硬質塩化ビニル管 継手・支持共 | D31: 平面実測1F 87.3m・2F 6.1m(未判読分比例配分含む) | F31: 94 m（実測＋想定）
A32: 11 | B32: No.1 | C32: ドレン管 VP40 硬質塩化ビニル管 継手・支持共 | D32: 平面実測50.2m＋推測(立下り・屋外放流部12箇所×1.5m) | F32: 68 m（実測＋想定）
A33: 12 | B33: No.1 | C33: ドレン管 保温 GW保温筒20 ALGC 天井内 (特記仕様書 保温表は空欄・標準仕様に準じ計上 要確認) | D33: VP25・VP40 天井内相当分 | F33: 143 m（想定）
... A41: 20 | B41: No.2 | C41: 区画貫通処理 冷媒管・ドレン管 フィブロック 廊下区画壁 | D41: 各系統1箇所と仮定 | F41: 5 箇所（想定）
A43: 【3】図面読み取りに関する確認事項
A44: 1. | B44: 宛名は元請様を株式会社共栄店舗（詳細工程表作成者）と想定して記載しています。ご指定があれば修正します。
A45: 2. | B45: 2F 寮室のルームエアコン（RAC-3 66台）は図面に配管線の記載がなく、壁掛機→バルコニー屋外機 4m/台 の想定です。
A46: 3. | B46: 追AC1〜5 は図面08に配管経路の記載がなく、室内機・室外機の位置から経路長を推定しています（別紙【2】）。
A47: 4. | B47: 区画貫通処理は空調平面図1Fの区画貫通部記号（●）2箇所と、追加空調の廊下区画壁 各系統1箇所の想定です。

Sheet 数量拾い根拠(内部)
A1: 数量拾い根拠（内部用） ※計測方法: PDF図面(A3 1:300、厨房詳細 1:70)のベクトル線分を色・線幅で分離し延長を集計。「実測」=図面線分の平面延長、「推測」=図面に無い部分の推定
A3: 1. 冷媒配管（ベース06）系統別
A4: 系統 | B4: 口径記号 | C4: 平面実測(m) | D4: 推測加算(m) | E4: 合計(m) | F4: 推測内容
A5: RAC-2×3 和室・洋室・DK | B5: ① | C5: 28.1 | D5: 9 | E5: 37.1 | F5: 屋外機→屋内機 立上り 3台×3m
A6: AC-7 面談室 | B6: ② | C6: 13 | D6: 4 | E6: 17 | F6: 北西ゾーン実測60.3mを3系統に配分。立上り4m
A7: AC-5 管理人室 | B7: ② | C7: 18 | D7: 4 | E7: 22 | F7: 同上
A8: AC-1 ホール(ツイン) | B8: ⑦主/③枝 | C8: 29 | D8: 4 | E8: 33 | F8: 主管17m・枝管12m。立上り4m(⑦)
A9: AC-6/AC-8/AC-9/RAC-1×2 厨房ブロック | B9: ③/②/③/① | C9: 22.2 | D9: 20 | E9: 42.2 | F9: 重なり配管の未計測補正8m(RAC-1休憩室)・立上り4系統×3〜4m
A10: AC-1 食堂・ミーティング(ツイン×2) | B10: ⑦主/③枝 | C10: 30.7 | D10: 8 | E10: 38.7 | F10: 各系統 主管8m・枝管7.5m。立上り各4m
A11: AC-10 多目的スペース(2F) | B11: ③ | C11: 10.2 | D11: 11.5 | E11: 21.7 | F11: 2F平面3.5m・立管(1F地上→2F天井)8m
A12: AC-2 コーチルーム(ツイン) | B12: ⑥主/③枝 | C12: 11.1 | D12: 4 | E12: 15.1 | F12: 主管5m・枝管6m。立上り4m
A13: AC-1 トレーニング(ツイン)＋AC-5 ケア室 | B13: ⑦/③ ・ ② | C13: 32 | D13: 8 | E13: 40 | F13: AC-1 主8m枝12m・AC-5 12m。立上り各4m
A14: AC-3 脱衣室(ツイン) | B14: ③主/②枝 | C14: 13.9 | D14: 4 | E14: 17.9 | F14: 主管7m・枝管7m。立上り4m
A15: RAC-2×5 来客室 | B15: ① | C15: 2.7 | D15: 18 | E15: 20.7 | F15: 屋外機が各室直近。1台4m×5台
A16: RAC-3×66 2F寮室等 | B16: ① | C16: 0 | D16: 264 | E16: 264 | F16: 図面に配管線なし。壁掛機→バルコニー屋外機 4m/台
A17: RAC-4 寮務スタッフ室 | B17: ② | C17: 0 | D17: 5 | E17: 5 | F17: 同上 5m
A18: 合計 | C18: 211 | D18: 363.5 | E18: 574.5 | F18: 口径別: ①360 ②77 ③96 ⑥9 ⑦57 (m・端数調整後)
A20: 2. ドレン配管（ベース06）
A21: 区分 | B21: 口径 | C21: 平面実測(m) | D21: 推測加算(m) | E21: 合計(m) | F21: 備考
A22: 1F 空調平面図 青線(D) | B22: VP20 | C22: 6.6 | D22: 30 | E22: 36.6 | F22: RAC-1/2 ドレンアップ吐出→屋外 10台×3m
A23: 1F 空調平面図 青線(D) | B23: VP25 | C23: 87.3 | D23: 0 | E23: 87.3 | F23: 口径ラベル未割当31.3mを25/40へ比例配分済
A24: 1F 空調平面図 青線(D) | B24: VP40 | C24: 50.2 | D24: 18 | E24: 68.2 | F24: 立下り・屋外放流部 12箇所×1.5m
A25: 2F 空調平面図 青線(D) AC-10 | B25: VP25 | C25: 6.1 | D25: 0 | E25: 6.1
A26: 合計 | C26: 150.2 | D26: 48 | E26: 198.2
A28: 3. 冷媒配管（図面08 追加空調・すべて推測）
A29: 系統 | B29: 口径記号 | C29: 平面実測(m) | D29: 推測(m) | E29: 合計(m) | F29: 推定根拠
A30: 追AC1 PA-P140U7GTNB トリプル | B30: ③主/①枝 | C30: 0 | D30: 51 | E30: 51 | F30: 室外機:物干場側(AC-3隣) 室内機:ホール・洗濯室前廊下・階段ホール
A31: 追AC2 PA-P224L7HTNB トリプル | B31: ⑥主/③枝 | C31: 0 | D31: 57 | E31: 57 | F31: 室外機:南側(AC-1/5隣) 室内機:1F南廊下3箇所
A32: 追AC3 PA-P224L7HTNB トリプル | B32: ⑥主/③枝 | C32: 0 | D32: 64 | E32: 64 | F32: 室外機:東側地上 室内機:2F北廊下3箇所
A33: 追AC4 PA-P224L7HTNB トリプル | B33: ⑥主/③枝 | C33: 0 | D33: 51 | E33: 51 | F33: 室外機:東側地上(倉庫2東) 室内機:階段ホール2・南廊下1
A34: 追AC5 PA-P224L7HTNB トリプル | B34: ⑥主/③枝 | C34: 0 | D34: 69 | E34: 69 | F34: 室外機:東側地上 室内機:2F南廊下3箇所
A35: 合計 | C35: 0 | D35: 292 | E35: 292 | F35: 口径別: ①35 ③184 ⑥73
A37: 5. 機器台数（図面カウント）
A38: 記号 | B38: 台数 | C38: 備考
A39: AC-1 (ツイン) 室内8/室外4 | B39: 4系統 | C39: 空調機器表・平面図
A40: AC-2,3 (ツイン) 室内各2/室外各1 | B40: 2系統
A41: AC-5,6,7,8,9,10 室内各1/室外各1 | B41: 7台 | C41: AC-5は2台
A42: RAC-1/2/3/4 | B42: 2/8/66/1 | C42: 2F寮室×16+×3+×11+×8+×4+×24=66
A43: 追AC1 室内3/室外1、追AC2〜5 室内各3/室外各1 | B43: 5系統 | C43: 図面08 p19・p20 朱書き □ 位置より
A44: 区画貫通部 ● | B44: 1F 2箇所 | C44: 空調平面図1F 凡例
...

Sheet 単価マスタ(内部)
A1: 単価マスタ（内部） 原価＝材料原価＋人工×労務原価日額、提出（定価ベース）＝原価×提出係数。参考列は宮地機工 参考見積8件（2025.11〜2026.10）から整理
A2: 労務原価日額 19,000 円/人工 参考見積の人工単価 23,225 円/人工（6330476-3 配管工費 40人工 929,000） 提出係数 1.22 材料係数 ×1.85（継手30%＋消耗15%＋支持金物40%）
A4: キー | B4: 材料原価 | C4: 人工 | D4: 労務原価 | E4: 原価 | F4: 提出(定価ベース) | G4: 参考定価ベース | H4: 当社/参考 | I4: 出典・根拠
A5: REF_① | B5: 2200 | C5: 0.2 | D5: =ROUND(C5*LABOR_DAY,0) -> 3800 | E5: =IF(B5="","",B5+D5) -> 6000 | F5: =IF(E5="","",ROUND(E5*COEF,-1)) -> 7320 | G5: 7328 | H5: =IF(OR(G5="",F5=""),"",F5/G5) -> 0.9989083 | I5: 6330539 ペアコイル6.35+9.52 988/m・2分3分級は1,450/m想定、5 m/人工
A6: REF_② | B6: 2960 | C6: 0.21 | D6: =ROUND(C6*LABOR_DAY,0) -> 3990 | E6: =IF(B6="","",B6+D6) -> 6950 | F6: =IF(E6="","",ROUND(E6*COEF,-1)) -> 8480 | G6: 8485 | H6: =IF(OR(G6="",F6=""),"",F6/G6) -> 0.99941072 | I6: 補間（9.52+15.88 4,025 と 6.35+9.52 の間）
A7: REF_③ | B7: 6100 | C7: 0.22 | D7: =ROUND(C7*LABOR_DAY,0) -> 4180 | E7: =IF(B7="","",B7+D7) -> 10280 | F7: =IF(E7="","",ROUND(E7*COEF,-1)) -> 12540 | G7: 12556 | H7: =IF(OR(G7="",F7=""),"",F7/G7) -> 0.99872571 | I7: 6330476-3 / 6330344-1 9.52+15.88 4,025/m、4.6 m/人工
A8: REF_⑥ | B8: 8300 | C8: 0.28 | D8: =ROUND(C8*LABOR_DAY,0) -> 5320 | E8: =IF(B8="","",B8+D8) -> 13620 | F8: =IF(E8="","",ROUND(E8*COEF,-1)) -> 16620 | G8: 16632 | H8: =IF(OR(G8="",F8=""),"",F8/G8) -> 0.9992785 | I8: 6330476-3 9.52+25.40 5,475/m、3.5 m/人工
A9: REF_⑦ | B9: 8610 | C9: 0.3 | D9: =ROUND(C9*LABOR_DAY,0) -> 5700 | E9: =IF(B9="","",B9+D9) -> 14310 | F9: =IF(E9="","",ROUND(E9*COEF,-1)) -> 17460 | G9: 17466 | H9: =IF(OR(G9="",F9=""),"",F9/G9) -> 0.99965648 | I9: 6330476-3 12.70+25.40 5,675/m、3.3 m/人工
A10: REF_CASE | B10: 1500 | C10: 0.1 | D10: =ROUND(C10*LABOR_DAY,0) -> 1900 | E10: =IF(B10="","",B10+D10) -> 3400 | F10: =IF(E10="","",ROUND(E10*COEF,-1)) -> 4150 | G10: 3516 | H10: =IF(OR(G10="",F10=""),"",F10/G10) -> 1.1803185 | I10: 配管保温工事費 1,194/m（6330476-3）＋化粧ケース材
A11: SLEEVE | B11: 900 | C11: 0.06 | D11: =ROUND(C11*LABOR_DAY,0) -> 1140 | E11: =IF(B11="","",B11+D11) -> 2040 | F11: =IF(E11="","",ROUND(E11*COEF,-1)) -> 2490 | I11: VP100 スリーブ材＋取付（参考実績なし）
A12: FIRESTOP | B12: 4500 | C12: 0.4 | D12: =ROUND(C12*LABOR_DAY,0) -> 7600 | E12: =IF(B12="","",B12+D12) -> 12100 | F12: =IF(E12="","",ROUND(E12*COEF,-1)) -> 14760 | I12: 6330248-2 防火区画貫通 88,000/式（箇所数不明）
A13: LEAK_TEST | B13: 3000 | C13: 0.6 | D13: =ROUND(C13*LABOR_DAY,0) -> 11400 | E13: =IF(B13="","",B13+D13) -> 14400 | F13: =IF(E13="","",ROUND(E13*COEF,-1)) -> 17570 | G13: 20000 | H13: =IF(OR(G13="",F13=""),"",F13/G13) -> 0.8785 | I13: 気密テスト 15,000〜25,000/系統・真空引き 3,750〜5,640/系統（6330558/344-1/549）
A14: REFRIGERANT | B14: 3800 | C14: 0 | D14: =ROUND(C14*LABOR_DAY,0) -> 0 | E14: =IF(B14="","",B14+D14) -> 3800 | F14: =IF(E14="","",ROUND(E14*COEF,-1)) -> 4640 | I14: R32 冷媒代（参考に単価行なし）
A15: VP20 | B15: 380 | C15: 0.1 | D15: =ROUND(C15*LABOR_DAY,0) -> 1900 | E15: =IF(B15="","",B15+D15) -> 2280 | F15: =IF(E15="","",ROUND(E15*COEF,-1)) -> 2780 | G15: 2578 | H15: =IF(OR(G15="",F15=""),"",F15/G15) -> 1.0783553 | I15: 6330539 VP13 138/m、塩ビ工費 9.3〜12 m/人工
A16: VP25 | B16: 475 | C16: 0.11 | D16: =ROUND(C16*LABOR_DAY,0) -> 2090 | E16: =IF(B16="","",B16+D16) -> 2565 | F16: =IF(E16="","",ROUND(E16*COEF,-1)) -> 3130 | G16: 3134 | H16: =IF(OR(G16="",F16=""),"",F16/G16) -> 0.99872368 | I16: 6330344-1/476-3/248-2 VP25 313/m、工費 2,497/m
A17: VP40 | B17: 760 | C17: 0.13 | D17: =ROUND(C17*LABOR_DAY,0) -> 2470 | E17: =IF(B17="","",B17+D17) -> 3230 | F17: =IF(E17="","",ROUND(E17*COEF,-1)) -> 3940 | I17: VP25 比例
A18: DRAIN_INS | B18: 900 | C18: 0.06 | D18: =ROUND(C18*LABOR_DAY,0) -> 1140 | E18: =IF(B18="","",B18+D18) -> 2040 | F18: =IF(E18="","",ROUND(E18*COEF,-1)) -> 2490 | I18: GW保温筒20 ALGC（参考実績なし）
A19: DRAIN_HOSE | B19: 300 | C19: 0.05 | D19: =ROUND(C19*LABOR_DAY,0) -> 950 | E19: =IF(B19="","",B19+D19) -> 1250 | F19: =IF(E19="","",ROUND(E19*COEF,-1)) -> 1530 | I19: 推定
A20: PAC_IN | B20: 1600 | C20: 0.85 | D20: =ROUND(C20*LABOR_DAY,0) -> 16150 | E20: =IF(B20="","",B20+D20) -> 17750 | F20: =IF(E20="","",ROUND(E20*COEF,-1)) -> 21660 | G20: 21700 | H20: =IF(OR(G20="",F20=""),"",F20/G20) -> 0.99815668 | I20: 6330476-3 搬入据付 238,750/11台≒21,700/台、6330284-1 25,000/台
A21: PAC_IN_BIG | B21: 2000 | C21: 1 | D21: =ROUND(C21*LABOR_DAY,0) -> 19000 | E21: =IF(B21="","",B21+D21) -> 21000 | F21: =IF(E21="","",ROUND(E21*COEF,-1)) -> 25620 | G21: 27860 | H21: =IF(OR(G21="",F21=""),"",F21/G21) -> 0.91959799 | I21: 6330558 VRV 90クラス 27,860/台
A22: PAC_OUT | B22: 3000 | C22: 0.8 | D22: =ROUND(C22*LABOR_DAY,0) -> 15200 | E22: =IF(B22="","",B22+D22) -> 18200 | F22: =IF(E22="","",ROUND(E22*COEF,-1)) -> 22200 | G22: 29200 | H22: =IF(OR(G22="",F22=""),"",F22/G22) -> 0.76027397 | I22: 搬入据付＋基礎工事 5,800〜10,000/台（6330539/549/476-3）
A23: PAC_OUT_BIG | B23: 4000 | C23: 1.1 | D23: =ROUND(C23*LABOR_DAY,0) -> 20900 | E23: =IF(B23="","",B23+D23) -> 24900 | F23: =IF(E23="","",ROUND(E23*COEF,-1)) -> 30380 | G23: 37860 | H23: =IF(OR(G23="",F23=""),"",F23/G23) -> 0.80243001 | I23: 8〜10HP 室外機（防振ゴム・架台固定共）
A24: RAC_SET | B24: 750 | C24: 0.5 | D24: =ROUND(C24*LABOR_DAY,0) -> 9500 | E24: =IF(B24="","",B24+D24) -> 10250 | F24: =IF(E24="","",ROUND(E24*COEF,-1)) -> 12510 | G24: 18300 | H24: =IF(OR(G24="",F24=""),"",F24/G24) -> 0.68360656 | I24: 6330539 RA 搬入据付 12,500/組＋基礎 5,833/組
A25: REMOTE_CTRL | B25: 1000 | C25: 0.4 | D25: =ROUND(C25*LABOR_DAY,0) -> 7600 | E25: =IF(B25="","",B25+D25) -> 8600 | F25: =IF(E25="","",ROUND(E25*COEF,-1)) -> 10490 | G25: 9630 | H25: =IF(OR(G25="",F25=""),"",F25/G25) -> 1.0893043 | I25: リモコン配線工事 9,630/系統（6330549/558/476-3）
A26: CRANE | B26: 75000 | C26: 0 | D26: =ROUND(C26*LABOR_DAY,0) -> 0 | E26: =IF(B26="","",B26+D26) -> 75000 | F26: =IF(E26="","",ROUND(E26*COEF,-1)) -> 91500 | G26: 93750 | H26: =IF(OR(G26="",F26=""),"",F26/G26) -> 0.976 | I26: 揚重工事費（レッカー）93,750/式（6330558）
A27: CARRY_IN | B27: 0 | C27: 1 | D27: =ROUND(C27*LABOR_DAY,0) -> 19000 | E27: =IF(B27="","",B27+D27) -> 19000 | F27: =IF(E27="","",ROUND(E27*COEF,-1)) -> 23180 | I27: 搬入・小運搬 人工
A28: TEST_RUN | B28: 450 | C28: 0.45 | D28: =ROUND(C28*LABOR_DAY,0) -> 8550 | E28: =IF(B28="","",B28+D28) -> 9000 | F28: =IF(E28="","",ROUND(E28*COEF,-1)) -> 10980 | G28: 11000 | H28: =IF(OR(G28="",F28=""),"",F28/G28) -> 0.99818182 | I28: 試運転調整費 10,000〜12,500/系統（6330344-1/549/476-3）
A29: TEST_RUN_RAC | B29: 0 | C29: 0.1 | D29: =ROUND(C29*LABOR_DAY,0) -> 1900 | E29: =IF(B29="","",B29+D29) -> 1900 | F29: =IF(E29="","",ROUND(E29*COEF,-1)) -> 2320 | G29: 2500 | H29: =IF(OR(G29="",F29=""),"",F29/G29) -> 0.928 | I29: 6330539 試運転 7,500/3台
A30: DOCS | B30: 5000 | C30: 1 | D30: =ROUND(C30*LABOR_DAY,0) -> 19000 | E30: =IF(B30="","",B30+D30) -> 24000 | F30: =IF(E30="","",ROUND(E30*COEF,-1)) -> 29280 | I30: 書類作成 人工
A31: WIRE_PAC | B31: 2000 | C31: 0.26 | D31: =ROUND(C31*LABOR_DAY,0) -> 4940 | E31: =IF(B31="","",B31+D31) -> 6940 | F31: =IF(E31="","",ROUND(E31*COEF,-1)) -> 8470 | G31: 8436 | H31: =IF(OR(G31="",F31=""),"",F31/G31) -> 1.0040303 | I31: VVF2.0-3C 203/m＋電線材料施工費 約500/m（12m/系統 8,436）→ 原価 6,900
A32: WIRE_RAC | B32: 1130 | C32: 0.12 | D32: =ROUND(C32*LABOR_DAY,0) -> 2280 | E32: =IF(B32="","",B32+D32) -> 3410 | F32: =IF(E32="","",ROUND(E32*COEF,-1)) -> 4160 | G32: 3515 | H32: =IF(OR(G32="",F32=""),"",F32/G32) -> 1.1834993 | I32: VVF2.0-3C 5m/台
A33: SLINK | B33: 30000 | C33: 1.2 | D33: =ROUND(C33*LABOR_DAY,0) -> 22800 | E33: =IF(B33="","",B33+D33) -> 52800 | F33: =IF(E33="","",ROUND(E33*COEF,-1)) -> 64420 | I33: 集中リモコン制御線 200m 推定
A34: BRANCH | B34: 600 | C34: 0.25 | D34: =ROUND(C34*LABOR_DAY,0) -> 4750 | E34: =IF(B34="","",B34+D34) -> 5350 | F34: =IF(E34="","",ROUND(E34*COEF,-1)) -> 6530 | I34: 分岐管取付（支給）
A35: FAN_PIPE | B35: 300 | C35: 0.3 | D35: =ROUND(C35*LABOR_DAY,0) -> 5700 | E35: =IF(B35="","",B35+D35) -> 6000 | F35: =IF(E35="","",ROUND(E35*COEF,-1)) -> 7320 | I35: パイプファン取付（参考実績なし）
A36: FAN_CEIL | B36: 500 | C36: 0.45 | D36: =ROUND(C36*LABOR_DAY,0) -> 8550 | E36: =IF(B36="","",B36+D36) -> 9050 | F36: =IF(E36="","",ROUND(E36*COEF,-1)) -> 11040 | I36: 天井扇取付（参考実績なし）
A37: FAN_DUCT | B37: 2000 | C37: 1.2 | D37: =ROUND(C37*LABOR_DAY,0) -> 22800 | E37: =IF(B37="","",B37+D37) -> 24800 | F37: =IF(E37="","",ROUND(E37*COEF,-1)) -> 30260 | I37: 中間ファン（防振吊）取付
A38: FAN_PRESS | B38: 1500 | C38: 0.9 | D38: =ROUND(C38*LABOR_DAY,0) -> 17100 | E38: =IF(B38="","",B38+D38) -> 18600 | F38: =IF(E38="","",ROUND(E38*COEF,-1)) -> 22690 | I38: 有圧扇＋ウェザーカバー取付
A39: HEX_CEIL | B39: 2500 | C39: 1.4 | D39: =ROUND(C39*LABOR_DAY,0) -> 26600 | E39: =IF(B39="","",B39+D39) -> 29100 | F39: =IF(E39="","",ROUND(E39*COEF,-1)) -> 35500 | I39: 全熱交換器 天井埋込（ダクト接続別）
A40: HEX_WALL | B40: 500 | C40: 0.45 | D40: =ROUND(C40*LABOR_DAY,0) -> 8550 | E40: =IF(B40="","",B40+D40) -> 9050 | F40: =IF(E40="","",ROUND(E40*COEF,-1)) -> 11040 | I40: 壁掛ロスナイ取付
A41: CYCLE_FAN | B41: 300 | C41: 0.35 | D41: =ROUND(C41*LABOR_DAY,0) -> 6650 | E41: =IF(B41="","",B41+D41) -> 6950 | F41: =IF(E41="","",ROUND(E41*COEF,-1)) -> 8480 | I41: サイクル扇
...
