Workbook
Name COEF: '表紙(工事)'!$N$4
Name OVERHEAD_RATE: '表紙(工事)'!$N$5
Name ROUND_UNIT: '表紙(工事)'!$N$6
Name WELFARE_RATE: '法定福利費内訳明細書'!$E$26
Name LABOR_DAY: '表紙(工事)'!$N$8
Name TARGET: '表紙(工事)'!$N$9

Sheet 表紙(工事)
A1: 御 見 積 書
J3: No. | M3: 【設定・内部用】（印刷範囲外）
J4: 46301 | M4: 提出係数（原価→定価ベース単価） | N4: 1.22
A5: 株式会社共栄店舗 | G5: 御中 | M5: 諸経費率（現場経費・運搬・雑材・工事諸経費） | N5: 0.22
M6: 出精値引き 丸め単位（目標額空欄時） | N6: 100000
A7: 金額 | B7: ="¥"&TEXT(K28,"#,##0")&"-" -> ¥12,600,000- | F7: （税別） | H7: 宮地機工株式会社 | M7: 法定福利費率（労務費比） | N7: =WELFARE_RATE -> 0.16375
M8: 労務原価日額（円/人工） | N8: 19000
A9: 上記の通り御見積申し上げます。 | H9: 代表取締役 濱本 義樹 | M9: 目標提出額（税別・空欄なら丸め）
A10: 何卒ご用命賜わりますようお願い申し上げます。 | M10: 参考：宮地機工 人工単価（定価ベース） | N10: 23225
H11: 〒722-0051 | M11: ※ 原価＝材料原価＋人工×N8。提出単価＝原価×N4（1.22で参考見積の人工単価23,225に一致）。目標提出額 N9 を入れると出精値引きで合わせる
A12: 工事名 | D12: （仮称）サンフレッチェ広島 三矢寮新築工事 | H12: 広島県尾道市東尾道9-9
D13: 換気工事（機械設備図06ベース＋金額変更案08 ロスナイ中止） | H13: TEL.0848-20-2121 | K13: FAX.0848-20-2126
A14: 施工場所 | D14: 広島県安芸高田市吉田町西浦字日南山835-27 | H14: 担当者 | J14: 濱本 義武
A15: 工事期限 | D15: 全体工期 2026年5月1日～2027年2月15日（空調工事は工程表による・別途お打ち合わせ）
A16: 御支払条件 | D16: 別途お打ち合わせ
A17: 有効期限 | D17: 発行後3ヶ月
A19: 項 目 | B19: 内 容 | G19: 数 量 | H19: 単位 | I19: 単 価 | K19: 金 額 | L19: 備 考 | M19: 内部集計（原価・粗利） | N19: 基準原価 | O19: 労務費(提出) | P19: 粗利 | Q19: 粗利率
B20: 【（仮称）サンフレッチェ広島 三矢寮新築工事 空調設備工事 換気工事】
B21: ［換気機器（換気機器表・代替分 BFS-SUDC・V-08PPXD8）は元請様手配、電気工事・建築工事・自動制御は含まず］
A22: ① | B22: 換気工事（機械設備図 06） | G22: 1 | H22: 式 | I22: =K22 -> 9213300 | K22: ='内訳書(1.換気工事)'!H93 -> 9213300 | L22: 内訳書 No.1 | M22: ①換気工事 | N22: ='内訳書(1.換気工事)'!O93 -> 7552540 | O22: ='内訳書(1.換気工事)'!P93 -> 5423193 | P22: =K22-N22 -> 1660760 | Q22: =IF(K22=0,"",P22/K22) -> 0.1802568
A23: ② | B23: 金額変更案 No3・4 ロスナイ中止（検討図 08・減額・代替機器） | G23: 1 | H23: 式 | I23: =K23 -> 413860 | K23: ='内訳書(2.ロスナイ中止)'!H21 -> 413860 | L23: 内訳書 No.2 | M23: ②ロスナイ中止 | N23: ='内訳書(2.ロスナイ中止)'!O21 -> 339200 | O23: ='内訳書(2.ロスナイ中止)'!P21 -> 141398 | P23: =K23-N23 -> 74660 | Q23: =IF(K23=0,"",P23/K23) -> 0.18039917
A24: ③ | B24: 法定福利費（労務費に係る事業主負担分） | G24: 1 | H24: 式 | I24: =K24 -> 911200 | K24: ='法定福利費内訳明細書'!F26 -> 911200 | L24: 別紙明細書 | M24: ③法定福利費（原価＝提出値） | N24: =K24 -> 911200
A25: ④ | B25: 諸経費（現場経費・資材運搬・工事諸経費） | G25: 1 | H25: 式 | I25: =K25 -> 2118000 | K25: =ROUND(SUM(K22:K23)*OVERHEAD_RATE,-3) -> 2118000 | L25: ="①〜②計の"&TEXT(OVERHEAD_RATE,"0%") -> ①〜②計の22% | M25: ④諸経費（原価計上なし） | N25: 0
B27: 出精値引き | K27: =IF(TARGET="",FLOOR(SUM(K22:K25),ROUND_UNIT)-SUM(K22:K25),TARGET-SUM(K22:K25)) -> -56360 | L27: 端数調整 | M27: 出精値引き（原価なし・粗利から控除） | N27: 0 | P27: =K27 -> -56360
B28: 合 計 | K28: =SUM(K22:K27) -> 12600000 | L28: （税別） | M28: 合計（原価合計／粗利／粗利率） | N28: =SUM(N22:N27) -> 8802940 | O28: =SUM(O22:O27) -> 5564591 | P28: =K28-N28 -> 3797060 | Q28: =IF(K28=0,"",P28/K28) -> 0.30135397
A30: ※ | B30: 本見積は機械設備図（図面No.06 若本建築事務所 '26.1.31）に基づき当社にて数量を拾い出して積算しております。金額変更案検討図（図面No.08）の No3・4 ロスナイ中止は内訳書 No.2（朱書き）に減額・代替機器を計上しています。空調工事は別途御見積書によります。実施数量との差異は別途精算とさせていただきます。
A31: ※ | B31: 空調機器・換気機器（室内機・室外機・リモコン・換気扇・全熱交換器・屋外機架台・ドレンアップ等 機器表記載の本体および付属品）は元請様手配のため含みません（据付・取付費のみ計上）。
A32: ※ | B32: 機器の電源供給・接地等の電気工事、基礎・躯体貫通穴明け・スリーブ穴埋め・天井点検口等の建築工事、衛生・消火・ガス・浄化槽設備、自動制御設備は含みません。 | M32: 粗利率別 参考提出額（税別・万円未満切上げ） | N32: 参考提出額 | O32: 必要提出係数
A33: ※ | B33: 機器・資材の揚重機（クレーン・レッカー等）、仮設設備、産業廃棄物の処分は元請様にてご手配・ご負担願います。 | M33: 0.1 | N33: =ROUNDUP($N$28/(1-M33),-4) -> 9790000 | O33: =IF(SUM($N$22:$N$23)=0,"",ROUND(($N$28/(1-M33)-$N$24-$K$25)/SUM($N$22:$N$23),3)) -> 0.856
A34: ※ | B34: 一式計上および想定数量の項目は別紙「御見積条件」記載の前提にて計上しており、実数量確定後に精算させていただきます。 | M34: 0.15 | N34: =ROUNDUP($N$28/(1-M34),-4) -> 10360000 | O34: =IF(SUM($N$22:$N$23)=0,"",ROUND(($N$28/(1-M34)-$N$24-$K$25)/SUM($N$22:$N$23),3)) -> 0.928
A35: ※ | B35: 本見積書に記載なき事項については別途とさせて頂きます。工事に係る電気・水道は無償支給願います。 | M35: 0.2 | N35: =ROUNDUP($N$28/(1-M35),-4) -> 11010000 | O35: =IF(SUM($N$22:$N$23)=0,"",ROUND(($N$28/(1-M35)-$N$24-$K$25)/SUM($N$22:$N$23),3)) -> 1.01
A36: ※ | B36: 本見積金額には消費税は含まれておりません。有効期限内でも銅管・鋼材等の市況が著しく変動した場合は再見積をさせていただくことがあります。 | M36: 0.25 | N36: =ROUNDUP($N$28/(1-M36),-4) -> 11740000 | O36: =IF(SUM($N$22:$N$23)=0,"",ROUND(($N$28/(1-M36)-$N$24-$K$25)/SUM($N$22:$N$23),3)) -> 1.103
A37: ※ | B37: 詳細条件は別紙「御見積条件」をご参照ください。 | M37: 0.3 | N37: =ROUNDUP($N$28/(1-M37),-4) -> 12580000 | O37: =IF(SUM($N$22:$N$23)=0,"",ROUND(($N$28/(1-M37)-$N$24-$K$25)/SUM($N$22:$N$23),3)) -> 1.21
M38: ※ 必要提出係数は諸経費を現状額に固定した場合の目安

Sheet 内訳書(1.換気工事)
A1: 内 訳 書 | J1: 原 価 内 訳 書（内部用・印刷範囲外）
A2: 工事名：（仮称）サンフレッチェ広島 三矢寮新築工事 空調設備工事 換気工事 | I2: 内訳書 No.1
A3: 名 称 | C3: 規格・寸法 | E3: 数 量 | F3: 単位 | G3: 単 価 | H3: 金 額 | I3: 備 考 | J3: 材料原価 | K3: 人工/単位 | L3: 労務原価 | M3: 基準原価単価 | N3: 提出係数 | O3: 基準原価 | P3: 労務費(提出) | Q3: 数量根拠 | R3: 粗利 | S3: 粗利率 | T3: 参考定価ベース | U3: 当社/参考 | V3: 単価出典・メモ（内部）
A4: １．換気工事（機械設備図 06）
A6: （1）換気機器据付（機器は元請様支給）
A7: FE-A1 パイプファン 据付 | C7: V-12PS8 150φ ゴミ庫1・倉庫1 | E7: 2 | F7: 台 | G7: =IF(M7="","",ROUND(M7*N7,-1)) -> 7320 | H7: =IF(G7="","",ROUND(E7*G7,0)) -> 14640 | I7: 本体は元請様支給 | J7: 300 | K7: 0.3 | L7: =ROUND(K7*LABOR_DAY,0) -> 5700 | M7: =J7+L7 -> 6000 | N7: =COEF -> 1.22 | O7: =E7*M7 -> 12000 | P7: =ROUND(E7*L7*N7,0) -> 13908 | Q7: 図面カウント | R7: =IF(H7="","",H7-O7) -> 2640 | S7: =IF(OR(H7="",H7=0),"",R7/H7) -> 0.18032787 | V7: パイプファン取付（参考実績なし）｜
A8: FE-A2 天井扇 据付 | C8: VD-15ZC14 100φ 管理人和室洋室クローク・面談室 | E8: 2 | F8: 台 | G8: =IF(M8="","",ROUND(M8*N8,-1)) -> 11040 | H8: =IF(G8="","",ROUND(E8*G8,0)) -> 22080 | I8: 本体は元請様支給 | J8: 500 | K8: 0.45 | L8: =ROUND(K8*LABOR_DAY,0) -> 8550 | M8: =J8+L8 -> 9050 | N8: =COEF -> 1.22 | O8: =E8*M8 -> 18100 | P8: =ROUND(E8*L8*N8,0) -> 20862 | Q8: 図面カウント | R8: =IF(H8="","",H8-O8) -> 3980 | S8: =IF(OR(H8="",H8=0),"",R8/H8) -> 0.18025362 | V8: 天井扇取付（参考実績なし）｜
A9: FE-A3 天井扇 据付 | C9: VD-10ZC14 管理人WC | E9: 1 | F9: 台 | G9: =IF(M9="","",ROUND(M9*N9,-1)) -> 11040 | H9: =IF(G9="","",ROUND(E9*G9,0)) -> 11040 | I9: 本体は元請様支給 | J9: 500 | K9: 0.45 | L9: =ROUND(K9*LABOR_DAY,0) -> 8550 | M9: =J9+L9 -> 9050 | N9: =COEF -> 1.22 | O9: =E9*M9 -> 9050 | P9: =ROUND(E9*L9*N9,0) -> 10431 | Q9: 図面カウント | R9: =IF(H9="","",H9-O9) -> 1990 | S9: =IF(OR(H9="",H9=0),"",R9/H9) -> 0.18025362 | V9: 天井扇取付（参考実績なし）｜
A10: FE-A4 親子扇 据付 | C10: VD-10ZFC14 管理人洗面UB | E10: 1 | F10: 台 | G10: =IF(M10="","",ROUND(M10*N10,-1)) -> 11040 | H10: =IF(G10="","",ROUND(E10*G10,0)) -> 11040 | I10: 本体は元請様支給 | J10: 500 | K10: 0.45 | L10: =ROUND(K10*LABOR_DAY,0) -> 8550 | M10: =J10+L10 -> 9050 | N10: =COEF -> 1.22 | O10: =E10*M10 -> 9050 | P10: =ROUND(E10*L10*N10,0) -> 10431 | Q10: 図面カウント | R10: =IF(H10="","",H10-O10) -> 1990 | S10: =IF(OR(H10="",H10=0),"",R10/H10) -> 0.18025362 | V10: 天井扇取付（参考実績なし）｜
A11: FE-A5 天井扇 据付 | C11: VD-15ZC14 管理人室 | E11: 2 | F11: 台 | G11: =IF(M11="","",ROUND(M11*N11,-1)) -> 11040 | H11: =IF(G11="","",ROUND(E11*G11,0)) -> 22080 | I11: 本体は元請様支給 | J11: 500 | K11: 0.45 | L11: =ROUND(K11*LABOR_DAY,0) -> 8550 | M11: =J11+L11 -> 9050 | N11: =COEF -> 1.22 | O11: =E11*M11 -> 18100 | P11: =ROUND(E11*L11*N11,0) -> 20862 | Q11: 図面カウント | R11: =IF(H11="","",H11-O11) -> 3980 | S11: =IF(OR(H11="",H11=0),"",R11/H11) -> 0.18025362 | V11: 天井扇取付（参考実績なし）｜
A12: FE-A6 中間ファン 据付 | C12: BFS-50SYA2 200φ 1階男性WC | E12: 1 | F12: 台 | G12: =IF(M12="","",ROUND(M12*N12,-1)) -> 30260 | H12: =IF(G12="","",ROUND(E12*G12,0)) -> 30260 | I12: 本体は元請様支給 | J12: 2000 | K12: 1.2 | L12: =ROUND(K12*LABOR_DAY,0) -> 22800 | M12: =J12+L12 -> 24800 | N12: =COEF -> 1.22 | O12: =E12*M12 -> 24800 | P12: =ROUND(E12*L12*N12,0) -> 27816 | Q12: 図面カウント | R12: =IF(H12="","",H12-O12) -> 5460 | S12: =IF(OR(H12="",H12=0),"",R12/H12) -> 0.18043622 | V12: 中間ファン（防振吊）取付｜防振吊金具共
A13: FE-A7 天井扇 据付 | C13: VD-17ZSC14 1階多目的WC | E13: 1 | F13: 台 | G13: =IF(M13="","",ROUND(M13*N13,-1)) -> 11040 | H13: =IF(G13="","",ROUND(E13*G13,0)) -> 11040 | I13: 本体は元請様支給 | J13: 500 | K13: 0.45 | L13: =ROUND(K13*LABOR_DAY,0) -> 8550 | M13: =J13+L13 -> 9050 | N13: =COEF -> 1.22 | O13: =E13*M13 -> 9050 | P13: =ROUND(E13*L13*N13,0) -> 10431 | Q13: 図面カウント | R13: =IF(H13="","",H13-O13) -> 1990 | S13: =IF(OR(H13="",H13=0),"",R13/H13) -> 0.18025362 | V13: 天井扇取付（参考実績なし）｜
A14: FE-B1 天井扇 据付 | C14: VD-17ZSC14 シューズロッカー・洗い場 | E14: 2 | F14: 台 | G14: =IF(M14="","",ROUND(M14*N14,-1)) -> 11040 | H14: =IF(G14="","",ROUND(E14*G14,0)) -> 22080 | I14: 本体は元請様支給 | J14: 500 | K14: 0.45 | L14: =ROUND(K14*LABOR_DAY,0) -> 8550 | M14: =J14+L14 -> 9050 | N14: =COEF -> 1.22 | O14: =E14*M14 -> 18100 | P14: =ROUND(E14*L14*N14,0) -> 20862 | Q14: 図面カウント | R14: =IF(H14="","",H14-O14) -> 3980 | S14: =IF(OR(H14="",H14=0),"",R14/H14) -> 0.18025362 | V14: 天井扇取付（参考実績なし）｜
A15: FE-B2 天井扇 据付 | C15: VD-23ZB13 洗濯室 | E15: 2 | F15: 台 | G15: =IF(M15="","",ROUND(M15*N15,-1)) -> 11040 | H15: =IF(G15="","",ROUND(E15*G15,0)) -> 22080 | I15: 本体は元請様支給 | J15: 500 | K15: 0.45 | L15: =ROUND(K15*LABOR_DAY,0) -> 8550 | M15: =J15+L15 -> 9050 | N15: =COEF -> 1.22 | O15: =E15*M15 -> 18100 | P15: =ROUND(E15*L15*N15,0) -> 20862 | Q15: 図面カウント | R15: =IF(H15="","",H15-O15) -> 3980 | S15: =IF(OR(H15="",H15=0),"",R15/H15) -> 0.18025362 | V15: 天井扇取付（参考実績なし）｜
A16: FE-B3 有圧扇 据付 | C16: EF-25ASXC2 浴室 ウェザーカバー共 | E16: 2 | F16: 台 | G16: =IF(M16="","",ROUND(M16*N16,-1)) -> 22690 | H16: =IF(G16="","",ROUND(E16*G16,0)) -> 45380 | I16: 本体は元請様支給 | J16: 1500 | K16: 0.9 | L16: =ROUND(K16*LABOR_DAY,0) -> 17100 | M16: =J16+L16 -> 18600 | N16: =COEF -> 1.22 | O16: =E16*M16 -> 37200 | P16: =ROUND(E16*L16*N16,0) -> 41724 | Q16: 図面カウント | R16: =IF(H16="","",H16-O16) -> 8180 | S16: =IF(OR(H16="",H16=0),"",R16/H16) -> 0.18025562 | V16: 有圧扇＋ウェザーカバー取付｜
A17: FE-B4 中間ファン 据付 | C17: BFS-50SYA2 脱衣室・前室 | E17: 1 | F17: 台 | G17: =IF(M17="","",ROUND(M17*N17,-1)) -> 30260 | H17: =IF(G17="","",ROUND(E17*G17,0)) -> 30260 | I17: 本体は元請様支給 | J17: 2000 | K17: 1.2 | L17: =ROUND(K17*LABOR_DAY,0) -> 22800 | M17: =J17+L17 -> 24800 | N17: =COEF -> 1.22 | O17: =E17*M17 -> 24800 | P17: =ROUND(E17*L17*N17,0) -> 27816 | Q17: 図面カウント | R17: =IF(H17="","",H17-O17) -> 5460 | S17: =IF(OR(H17="",H17=0),"",R17/H17) -> 0.18043622 | V17: 中間ファン（防振吊）取付｜
A18: FE-C1 パイプファン 据付 | C18: V-08PPX8 厨房WC・休憩室・段ボール庫・ゴミ庫2 | E18: 4 | F18: 台 | G18: =IF(M18="","",ROUND(M18*N18,-1)) -> 7320 | H18: =IF(G18="","",ROUND(E18*G18,0)) -> 29280 | I18: 本体は元請様支給 | J18: 300 | K18: 0.3 | L18: =ROUND(K18*LABOR_DAY,0) -> 5700 | M18: =J18+L18 -> 6000 | N18: =COEF -> 1.22 | O18: =E18*M18 -> 24000 | P18: =ROUND(E18*L18*N18,0) -> 27816 | Q18: 図面カウント | R18: =IF(H18="","",H18-O18) -> 5280 | S18: =IF(OR(H18="",H18=0),"",R18/H18) -> 0.18032787 | V18: パイプファン取付（参考実績なし）｜
... A43: FS-2 中間ファン 据付 | C43: BFS-150SUG2 給気 厨房 F-2と連動 | E43: 1 | F43: 台 | G43: =IF(M43="","",ROUND(M43*N43,-1)) -> 30260 | H43: =IF(G43="","",ROUND(E43*G43,0)) -> 30260 | I43: 本体は元請様支給 | J43: 2000 | K43: 1.2 | L43: =ROUND(K43*LABOR_DAY,0) -> 22800 | M43: =J43+L43 -> 24800 | N43: =COEF -> 1.22 | O43: =E43*M43 -> 24800 | P43: =ROUND(E43*L43*N43,0) -> 27816 | Q43: 図面カウント | R43: =IF(H43="","",H43-O43) -> 5460 | S43: =IF(OR(H43="",H43=0),"",R43/H43) -> 0.18043622 | V43: 中間ファン（防振吊）取付｜
A44: 全熱交換器・中間ファン リモコン配線 | C44: HEX-1,2,3(4台)・F-3 リモコン線 工事区分表: 機械 | E44: 9 | F44: 台 | G44: =IF(M44="","",ROUND(M44*N44,-1)) -> 10490 | H44: =IF(G44="","",ROUND(E44*G44,0)) -> 94410 | I44: 図面08 中止に伴う減額 | J44: 1000 | K44: 0.4 | L44: =ROUND(K44*LABOR_DAY,0) -> 7600 | M44: =J44+L44 -> 8600 | N44: =COEF -> 1.22 | O44: =E44*M44 -> 77400 | P44: =ROUND(E44*L44*N44,0) -> 83448 | Q44: 図面カウント | R44: =IF(H44="","",H44-O44) -> 17010 | S44: =IF(OR(H44="",H44=0),"",R44/H44) -> 0.18017159 | T44: 9630 | U44: =IF(OR(T44="",T44=0),"",G44/T44) -> 1.0893043 | V44: リモコン配線工事 9,630/系統（6330549/558/476-3）｜HEX分は08で減額
A45: 機器搬入・養生 | C45: 換気機器 約140台 | E45: 1 | F45: 式 | G45: =IF(M45="","",ROUND(M45*N45,-1)) -> 81130 | H45: =IF(G45="","",ROUND(E45*G45,0)) -> 81130 | I45: 想定数量（別紙条件書） | J45: 0 | K45: 3.5 | L45: =ROUND(K45*LABOR_DAY,0) -> 66500 | M45: =J45+L45 -> 66500 | N45: =COEF -> 1.22 | O45: =E45*M45 -> 66500 | P45: =ROUND(E45*L45*N45,0) -> 81130 | Q45: 推測 | R45: =IF(H45="","",H45-O45) -> 14630 | S45: =IF(OR(H45="",H45=0),"",R45/H45) -> 0.18032787 | V45: 搬入・小運搬 人工｜
A46: （2）ダクト工事
A47: スパイラルダクト 100φ (EA) | C47: 亜鉛鉄板 低速 継手・支持共 | E47: 68 | F47: m | G47: =IF(M47="","",ROUND(M47*N47,-1)) -> 4000 | H47: =IF(G47="","",ROUND(E47*G47,0)) -> 272000 | I47: 図面実測数量 | J47: 1000 | K47: 0.12 | L47: =ROUND(K47*LABOR_DAY,0) -> 2280 | M47: =J47+L47 -> 3280 | N47: =COEF -> 1.22 | O47: =E47*M47 -> 223040 | P47: =ROUND(E47*L47*N47,0) -> 189149 | Q47: 実測 | R47: =IF(H47="","",H47-O47) -> 48960 | S47: =IF(OR(H47="",H47=0),"",R47/H47) -> 0.18 | V47: ダクト（参考実績なし・市況）｜1F 62.6m・2F 5.2m
A48: スパイラルダクト 150φ (EA) | C48: 亜鉛鉄板 低速 継手・支持共 | E48: 151 | F48: m | G48: =IF(M48="","",ROUND(M48*N48,-1)) -> 4950 | H48: =IF(G48="","",ROUND(E48*G48,0)) -> 747450 | I48: 図面実測数量 | J48: 1400 | K48: 0.14 | L48: =ROUND(K48*LABOR_DAY,0) -> 2660 | M48: =J48+L48 -> 4060 | N48: =COEF -> 1.22 | O48: =E48*M48 -> 613060 | P48: =ROUND(E48*L48*N48,0) -> 490025 | Q48: 実測 | R48: =IF(H48="","",H48-O48) -> 134390 | S48: =IF(OR(H48="",H48=0),"",R48/H48) -> 0.17979798 | V48: 1F 122.4m・2F 28.2m(口径未判読分含む)
A49: スパイラルダクト 200φ (EA) | C49: 亜鉛鉄板 低速 継手・支持共 | E49: 44 | F49: m | G49: =IF(M49="","",ROUND(M49*N49,-1)) -> 6030 | H49: =IF(G49="","",ROUND(E49*G49,0)) -> 265320 | I49: 図面実測＋想定（別紙） | J49: 1900 | K49: 0.16 | L49: =ROUND(K49*LABOR_DAY,0) -> 3040 | M49: =J49+L49 -> 4940 | N49: =COEF -> 1.22 | O49: =E49*M49 -> 217360 | P49: =ROUND(E49*L49*N49,0) -> 163187 | Q49: 実測+推測 | R49: =IF(H49="","",H49-O49) -> 47960 | S49: =IF(OR(H49="",H49=0),"",R49/H49) -> 0.18076285 | V49: 1F 25.2m・2F 9.8m 実測＋厨房詳細図 9m 推測
A50: スパイラルダクト 250φ (EA 厨房) | C50: 亜鉛鉄板 継手・支持共 | E50: 6 | F50: m | G50: =IF(M50="","",ROUND(M50*N50,-1)) -> 7810 | H50: =IF(G50="","",ROUND(E50*G50,0)) -> 46860 | I50: 想定数量（別紙条件書） | J50: 2600 | K50: 0.2 | L50: =ROUND(K50*LABOR_DAY,0) -> 3800 | M50: =J50+L50 -> 6400 | N50: =COEF -> 1.22 | O50: =E50*M50 -> 38400 | P50: =ROUND(E50*L50*N50,0) -> 27816 | Q50: 推測 | R50: =IF(H50="","",H50-O50) -> 8460 | S50: =IF(OR(H50="",H50=0),"",R50/H50) -> 0.18053777 | V50: 厨房廻り平面詳細図より
A51: スパイラルダクト 300φ (EA 厨房) | C51: 亜鉛鉄板 継手・支持共 | E51: 5 | F51: m | G51: =IF(M51="","",ROUND(M51*N51,-1)) -> 9590 | H51: =IF(G51="","",ROUND(E51*G51,0)) -> 47950 | I51: 想定数量（別紙条件書） | J51: 3300 | K51: 0.24 | L51: =ROUND(K51*LABOR_DAY,0) -> 4560 | M51: =J51+L51 -> 7860 | N51: =COEF -> 1.22 | O51: =E51*M51 -> 39300 | P51: =ROUND(E51*L51*N51,0) -> 27816 | Q51: 推測 | R51: =IF(H51="","",H51-O51) -> 8650 | S51: =IF(OR(H51="",H51=0),"",R51/H51) -> 0.18039625 | V51: フード③④→F-3 3台
A52: スパイラルダクト 100φ (OA) | C52: 亜鉛鉄板 継手・支持共 | E52: 4 | F52: m | G52: =IF(M52="","",ROUND(M52*N52,-1)) -> 4000 | H52: =IF(G52="","",ROUND(E52*G52,0)) -> 16000 | I52: 図面実測数量 | J52: 1000 | K52: 0.12 | L52: =ROUND(K52*LABOR_DAY,0) -> 2280 | M52: =J52+L52 -> 3280 | N52: =COEF -> 1.22 | O52: =E52*M52 -> 13120 | P52: =ROUND(E52*L52*N52,0) -> 11126 | Q52: 実測 | R52: =IF(H52="","",H52-O52) -> 2880 | S52: =IF(OR(H52="",H52=0),"",R52/H52) -> 0.18 | V52: ダクト（参考実績なし・市況）｜
A53: スパイラルダクト 150φ (OA) | C53: 亜鉛鉄板 継手・支持共 | E53: 51 | F53: m | G53: =IF(M53="","",ROUND(M53*N53,-1)) -> 4950 | H53: =IF(G53="","",ROUND(E53*G53,0)) -> 252450 | I53: 図面実測数量 | J53: 1400 | K53: 0.14 | L53: =ROUND(K53*LABOR_DAY,0) -> 2660 | M53: =J53+L53 -> 4060 | N53: =COEF -> 1.22 | O53: =E53*M53 -> 207060 | P53: =ROUND(E53*L53*N53,0) -> 165505 | Q53: 実測 | R53: =IF(H53="","",H53-O53) -> 45390 | S53: =IF(OR(H53="",H53=0),"",R53/H53) -> 0.17979798 | V53: 1F 50.4m
A54: スパイラルダクト 200φ (OA) | C54: 亜鉛鉄板 継手・支持共 | E54: 57 | F54: m | G54: =IF(M54="","",ROUND(M54*N54,-1)) -> 6030 | H54: =IF(G54="","",ROUND(E54*G54,0)) -> 343710 | I54: 図面実測＋想定（別紙） | J54: 1900 | K54: 0.16 | L54: =ROUND(K54*LABOR_DAY,0) -> 3040 | M54: =J54+L54 -> 4940 | N54: =COEF -> 1.22 | O54: =E54*M54 -> 281580 | P54: =ROUND(E54*L54*N54,0) -> 211402 | Q54: 実測+推測 | R54: =IF(H54="","",H54-O54) -> 62130 | S54: =IF(OR(H54="",H54=0),"",R54/H54) -> 0.18076285 | V54: 1F 45.7m・2F 3.5m 実測＋厨房FS-1 7.5m 推測
A55: スパイラルダクト 250φ (OA 厨房 FS-2) | C55: 亜鉛鉄板 継手・支持共 | E55: 6 | F55: m | G55: =IF(M55="","",ROUND(M55*N55,-1)) -> 7810 | H55: =IF(G55="","",ROUND(E55*G55,0)) -> 46860 | I55: 想定数量（別紙条件書） | J55: 2600 | K55: 0.2 | L55: =ROUND(K55*LABOR_DAY,0) -> 3800 | M55: =J55+L55 -> 6400 | N55: =COEF -> 1.22 | O55: =E55*M55 -> 38400 | P55: =ROUND(E55*L55*N55,0) -> 27816 | Q55: 推測 | R55: =IF(H55="","",H55-O55) -> 8460 | S55: =IF(OR(H55="",H55=0),"",R55/H55) -> 0.18053777
A56: スパイラルダクト 300φ (OA 厨房) | C56: 亜鉛鉄板 継手・支持共 F-3用自然給気 | E56: 3 | F56: m | G56: =IF(M56="","",ROUND(M56*N56,-1)) -> 9590 | H56: =IF(G56="","",ROUND(E56*G56,0)) -> 28770 | I56: 想定数量（別紙条件書） | J56: 3300 | K56: 0.24 | L56: =ROUND(K56*LABOR_DAY,0) -> 4560 | M56: =J56+L56 -> 7860 | N56: =COEF -> 1.22 | O56: =E56*M56 -> 23580 | P56: =ROUND(E56*L56*N56,0) -> 16690 | Q56: 推測 | R56: =IF(H56="","",H56-O56) -> 5190 | S56: =IF(OR(H56="",H56=0),"",R56/H56) -> 0.18039625
A57: 外壁貫通部ダクト (フード接続) | C57: 150φ相当 1.0m/箇所 | E57: 58 | F57: m | G57: =IF(M57="","",ROUND(M57*N57,-1)) -> 4950 | H57: =IF(G57="","",ROUND(E57*G57,0)) -> 287100 | I57: 想定数量（別紙条件書） | J57: 1400 | K57: 0.14 | L57: =ROUND(K57*LABOR_DAY,0) -> 2660 | M57: =J57+L57 -> 4060 | N57: =COEF -> 1.22 | O57: =E57*M57 -> 235480 | P57: =ROUND(E57*L57*N57,0) -> 188222 | Q57: 推測 | R57: =IF(H57="","",H57-O57) -> 51620 | S57: =IF(OR(H57="",H57=0),"",R57/H57) -> 0.17979798 | V57: 1F フード48箇所・2F廊下10箇所
A58: VD 風量調整ダンパー | C58: 150～200φ | E58: 13 | F58: 個 | G58: =IF(M58="","",ROUND(M58*N58,-1)) -> 11290 | H58: =IF(G58="","",ROUND(E58*G58,0)) -> 146770 | I58: 図面実測数量 | J58: 4500 | K58: 0.25 | L58: =ROUND(K58*LABOR_DAY,0) -> 4750 | M58: =J58+L58 -> 9250 | N58: =COEF -> 1.22 | O58: =E58*M58 -> 120250 | P58: =ROUND(E58*L58*N58,0) -> 75335 | Q58: 実測 | R58: =IF(H58="","",H58-O58) -> 26520 | S58: =IF(OR(H58="",H58=0),"",R58/H58) -> 0.18069088 | V58: 図示 VD 1F 9・2F 4
A59: フレキシブルダクト・接続材 | C59: 機器接続部 | E59: 1 | F59: 式 | G59: =IF(M59="","",ROUND(M59*N59,-1)) -> 67340 | H59: =IF(G59="","",ROUND(E59*G59,0)) -> 67340 | I59: 想定数量（別紙条件書） | J59: 40000 | K59: 0.8 | L59: =ROUND(K59*LABOR_DAY,0) -> 15200 | M59: =J59+L59 -> 55200 | N59: =COEF -> 1.22 | O59: =E59*M59 -> 55200 | P59: =ROUND(E59*L59*N59,0) -> 18544 | Q59: 推測 | R59: =IF(H59="","",H59-O59) -> 12140 | S59: =IF(OR(H59="",H59=0),"",R59/H59) -> 0.18027918
A60: （3）ダクト保温
A61: OAダクト 保温 | C61: GW保温筒25 ALGC 隠蔽(天井内) 特記仕様書 保温表 | E61: 123 | F61: m | G61: =IF(M61="","",ROUND(M61*N61,-1)) -> 3200 | H61: =IF(G61="","",ROUND(E61*G61,0)) -> 393600 | I61: 図面実測＋想定（別紙） | J61: 1100 | K61: 0.08 | L61: =ROUND(K61*LABOR_DAY,0) -> 1520 | M61: =J61+L61 -> 2620 | N61: =COEF -> 1.22 | O61: =E61*M61 -> 322260 | P61: =ROUND(E61*L61*N61,0) -> 228091 | Q61: 実測+推測 | R61: =IF(H61="","",H61-O61) -> 71340 | S61: =IF(OR(H61="",H61=0),"",R61/H61) -> 0.18125 | V61: GW保温筒25 ALGC｜OAダクト全長
A62: 厨房排気ダクト 保温 | C62: RW保温筒50 ＋アルミガラスクロス＋亀甲金網巻 | E62: 20 | F62: m | G62: =IF(M62="","",ROUND(M62*N62,-1)) -> 7380 | H62: =IF(G62="","",ROUND(E62*G62,0)) -> 147600 | I62: 想定数量（別紙条件書） | J62: 3200 | K62: 0.15 | L62: =ROUND(K62*LABOR_DAY,0) -> 2850 | M62: =J62+L62 -> 6050 | N62: =COEF -> 1.22 | O62: =E62*M62 -> 121000 | P62: =ROUND(E62*L62*N62,0) -> 69540 | Q62: 推測 | R62: =IF(H62="","",H62-O62) -> 26600 | S62: =IF(OR(H62="",H62=0),"",R62/H62) -> 0.1802168 | V62: RW50＋アルミガラスクロス＋金網｜厨房200/250/300φ EA
A63: （4）制気口・ボックス
A64: VHS 200×200 (開口率70%) | C64: SUS/鋼製 指定色 | E64: 8 | F64: 個 | G64: =IF(M64="","",ROUND(M64*N64,-1)) -> 11770 | H64: =IF(G64="","",ROUND(E64*G64,0)) -> 94160 | J64: 4900 | K64: 0.25 | L64: =ROUND(K64*LABOR_DAY,0) -> 4750 | M64: =J64+L64 -> 9650 | N64: =COEF -> 1.22 | O64: =E64*M64 -> 77200 | P64: =ROUND(E64*L64*N64,0) -> 46360 | Q64: 図面カウント | R64: =IF(H64="","",H64-O64) -> 16960 | S64: =IF(OR(H64="",H64=0),"",R64/H64) -> 0.18011895 | V64: 制気口 材＋取付0.25人工｜管理人室1・倉庫2 1・食堂3・ﾐｰﾃｨﾝｸﾞ3
A65: VHS 250×250 | E65: 3 | F65: 個 | G65: =IF(M65="","",ROUND(M65*N65,-1)) -> 13360 | H65: =IF(G65="","",ROUND(E65*G65,0)) -> 40080 | J65: 6200 | K65: 0.25 | L65: =ROUND(K65*LABOR_DAY,0) -> 4750 | M65: =J65+L65 -> 10950 | N65: =COEF -> 1.22 | O65: =E65*M65 -> 32850 | P65: =ROUND(E65*L65*N65,0) -> 17385 | Q65: 図面カウント | R65: =IF(H65="","",H65-O65) -> 7230 | S65: =IF(OR(H65="",H65=0),"",R65/H65) -> 0.18038922 | V65: 制気口 材＋取付0.25人工｜和室・シューズロッカー・廊下D1
...

Sheet 内訳書(2.ロスナイ中止)
A1: 内 訳 書 | J1: 原 価 内 訳 書（内部用・印刷範囲外）
A2: 工事名：（仮称）サンフレッチェ広島 三矢寮新築工事 空調設備工事 換気工事 | I2: 内訳書 No.2
A3: 名 称 | C3: 規格・寸法 | E3: 数 量 | F3: 単位 | G3: 単 価 | H3: 金 額 | I3: 備 考 | J3: 材料原価 | K3: 人工/単位 | L3: 労務原価 | M3: 基準原価単価 | N3: 提出係数 | O3: 基準原価 | P3: 労務費(提出) | Q3: 数量根拠 | R3: 粗利 | S3: 粗利率 | T3: 参考定価ベース | U3: 当社/参考 | V3: 単価出典・メモ（内部）
A4: ２．金額変更案 No3・4 ロスナイ中止（検討図 08 朱書き・減額は負数表示）
A6: （1）No3・4 ロスナイ中止（減額・代替機器）
A7: HEX-1 全熱交換器 据付 (中止) | C7: LGH-N80RXV2 食堂 | E7: -1 | F7: 台 | G7: =IF(M7="","",ROUND(M7*N7,-1)) -> 35500 | H7: =IF(G7="","",ROUND(E7*G7,0)) -> -35500 | I7: 本体は元請様支給 | J7: 2500 | K7: 1.4 | L7: =ROUND(K7*LABOR_DAY,0) -> 26600 | M7: =J7+L7 -> 29100 | N7: =COEF -> 1.22 | O7: =E7*M7 -> -29100 | P7: =ROUND(E7*L7*N7,0) -> -32452 | Q7: 図面カウント | R7: =IF(H7="","",H7-O7) -> -6400 | S7: =IF(OR(H7="",H7=0),"",R7/H7) -> 0.18028169 | V7: 全熱交換器 天井埋込（ダクト接続別）｜No3・4 ロスナイ中止
A8: HEX-2 全熱交換器 据付 (中止) | C8: LGH-N65RXW2 ミーティングルーム | E8: -1 | F8: 台 | G8: =IF(M8="","",ROUND(M8*N8,-1)) -> 35500 | H8: =IF(G8="","",ROUND(E8*G8,0)) -> -35500 | I8: 本体は元請様支給 | J8: 2500 | K8: 1.4 | L8: =ROUND(K8*LABOR_DAY,0) -> 26600 | M8: =J8+L8 -> 29100 | N8: =COEF -> 1.22 | O8: =E8*M8 -> -29100 | P8: =ROUND(E8*L8*N8,0) -> -32452 | Q8: 図面カウント | R8: =IF(H8="","",H8-O8) -> -6400 | S8: =IF(OR(H8="",H8=0),"",R8/H8) -> 0.18028169 | V8: 全熱交換器 天井埋込（ダクト接続別）｜
A9: HEX-3 全熱交換器 据付 (中止) | C9: SKU-50AC コーチルーム・トレーニングルーム | E9: -4 | F9: 台 | G9: =IF(M9="","",ROUND(M9*N9,-1)) -> 35500 | H9: =IF(G9="","",ROUND(E9*G9,0)) -> -142000 | I9: 本体は元請様支給 | J9: 2500 | K9: 1.4 | L9: =ROUND(K9*LABOR_DAY,0) -> 26600 | M9: =J9+L9 -> 29100 | N9: =COEF -> 1.22 | O9: =E9*M9 -> -116400 | P9: =ROUND(E9*L9*N9,0) -> -129808 | Q9: 図面カウント | R9: =IF(H9="","",H9-O9) -> -25600 | S9: =IF(OR(H9="",H9=0),"",R9/H9) -> 0.18028169 | V9: 全熱交換器 天井埋込（ダクト接続別）｜
A10: HEX-4 壁掛ロスナイ 据付 (中止) | C10: VL-10ES3 | E10: -46 | F10: 台 | G10: =IF(M10="","",ROUND(M10*N10,-1)) -> 11040 | H10: =IF(G10="","",ROUND(E10*G10,0)) -> -507840 | I10: 本体は元請様支給 | J10: 500 | K10: 0.45 | L10: =ROUND(K10*LABOR_DAY,0) -> 8550 | M10: =J10+L10 -> 9050 | N10: =COEF -> 1.22 | O10: =E10*M10 -> -416300 | P10: =ROUND(E10*L10*N10,0) -> -479826 | Q10: 図面カウント | R10: =IF(H10="","",H10-O10) -> -91540 | S10: =IF(OR(H10="",H10=0),"",R10/H10) -> 0.18025362 | V10: 壁掛ロスナイ取付｜
A11: HEX-5 壁掛ロスナイ 据付 (中止) | C11: VL-12ESH3 | E11: -27 | F11: 台 | G11: =IF(M11="","",ROUND(M11*N11,-1)) -> 11040 | H11: =IF(G11="","",ROUND(E11*G11,0)) -> -298080 | I11: 本体は元請様支給 | J11: 500 | K11: 0.45 | L11: =ROUND(K11*LABOR_DAY,0) -> 8550 | M11: =J11+L11 -> 9050 | N11: =COEF -> 1.22 | O11: =E11*M11 -> -244350 | P11: =ROUND(E11*L11*N11,0) -> -281637 | Q11: 図面カウント | R11: =IF(H11="","",H11-O11) -> -53730 | S11: =IF(OR(H11="",H11=0),"",R11/H11) -> 0.18025362 | V11: 壁掛ロスナイ取付｜
A12: 全熱交換器 リモコン配線 (中止) | C12: HEX-1,2,3 計6台分 | E12: -6 | F12: 台 | G12: =IF(M12="","",ROUND(M12*N12,-1)) -> 10490 | H12: =IF(G12="","",ROUND(E12*G12,0)) -> -62940 | I12: 図面08 中止に伴う減額 | J12: 1000 | K12: 0.4 | L12: =ROUND(K12*LABOR_DAY,0) -> 7600 | M12: =J12+L12 -> 8600 | N12: =COEF -> 1.22 | O12: =E12*M12 -> -51600 | P12: =ROUND(E12*L12*N12,0) -> -55632 | Q12: 図面カウント | R12: =IF(H12="","",H12-O12) -> -11340 | S12: =IF(OR(H12="",H12=0),"",R12/H12) -> 0.18017159 | T12: 9630 | U12: =IF(OR(T12="",T12=0),"",G12/T12) -> 1.0893043 | V12: リモコン配線工事 9,630/系統（6330549/558/476-3）｜
A13: HEX-1 → 中間ファン 据付 | C13: BFS-80SUDC 天井埋込形 250φ 食堂 防振吊金具・リモコン共 | E13: 1 | F13: 台 | G13: =IF(M13="","",ROUND(M13*N13,-1)) -> 30260 | H13: =IF(G13="","",ROUND(E13*G13,0)) -> 30260 | I13: 本体は元請様支給 | J13: 2000 | K13: 1.2 | L13: =ROUND(K13*LABOR_DAY,0) -> 22800 | M13: =J13+L13 -> 24800 | N13: =COEF -> 1.22 | O13: =E13*M13 -> 24800 | P13: =ROUND(E13*L13*N13,0) -> 27816 | Q13: 図面カウント | R13: =IF(H13="","",H13-O13) -> 5460 | S13: =IF(OR(H13="",H13=0),"",R13/H13) -> 0.18043622 | V13: 中間ファン（防振吊）取付｜EA側ダクト・HSは図示どおり、OA側は自然給気として残置と想定
A14: HEX-2 → 中間ファン 据付 | C14: BFS-65SUDC 200φ ミーティングルーム | E14: 1 | F14: 台 | G14: =IF(M14="","",ROUND(M14*N14,-1)) -> 30260 | H14: =IF(G14="","",ROUND(E14*G14,0)) -> 30260 | I14: 本体は元請様支給 | J14: 2000 | K14: 1.2 | L14: =ROUND(K14*LABOR_DAY,0) -> 22800 | M14: =J14+L14 -> 24800 | N14: =COEF -> 1.22 | O14: =E14*M14 -> 24800 | P14: =ROUND(E14*L14*N14,0) -> 27816 | Q14: 図面カウント | R14: =IF(H14="","",H14-O14) -> 5460 | S14: =IF(OR(H14="",H14=0),"",R14/H14) -> 0.18043622 | V14: 中間ファン（防振吊）取付｜
A15: HEX-3 → 中間ファン 据付 | C15: BFS-40SUDC 天井カセット形 200φ コーチルーム・トレーニングルーム | E15: 4 | F15: 台 | G15: =IF(M15="","",ROUND(M15*N15,-1)) -> 30260 | H15: =IF(G15="","",ROUND(E15*G15,0)) -> 121040 | I15: 本体は元請様支給 | J15: 2000 | K15: 1.2 | L15: =ROUND(K15*LABOR_DAY,0) -> 22800 | M15: =J15+L15 -> 24800 | N15: =COEF -> 1.22 | O15: =E15*M15 -> 99200 | P15: =ROUND(E15*L15*N15,0) -> 111264 | Q15: 図面カウント | R15: =IF(H15="","",H15-O15) -> 21840 | S15: =IF(OR(H15="",H15=0),"",R15/H15) -> 0.18043622 | V15: 中間ファン（防振吊）取付｜
A16: 中間ファン リモコン配線 | C16: BFS-SUDC用 6台 | E16: 6 | F16: 台 | G16: =IF(M16="","",ROUND(M16*N16,-1)) -> 10490 | H16: =IF(G16="","",ROUND(E16*G16,0)) -> 62940 | J16: 1000 | K16: 0.4 | L16: =ROUND(K16*LABOR_DAY,0) -> 7600 | M16: =J16+L16 -> 8600 | N16: =COEF -> 1.22 | O16: =E16*M16 -> 51600 | P16: =ROUND(E16*L16*N16,0) -> 55632 | Q16: 図面カウント | R16: =IF(H16="","",H16-O16) -> 11340 | S16: =IF(OR(H16="",H16=0),"",R16/H16) -> 0.18017159 | T16: 9630 | U16: =IF(OR(T16="",T16=0),"",G16/T16) -> 1.0893043 | V16: リモコン配線工事 9,630/系統（6330549/558/476-3）｜
A17: HEX-4/5 → パイプファン 据付 | C17: V-08PPXD8 壁掛1パイプ 100φ 来客室・寮室・寮務スタッフ室 | E17: 73 | F17: 台 | G17: =IF(M17="","",ROUND(M17*N17,-1)) -> 7320 | H17: =IF(G17="","",ROUND(E17*G17,0)) -> 534360 | I17: 本体は元請様支給 | J17: 300 | K17: 0.3 | L17: =ROUND(K17*LABOR_DAY,0) -> 5700 | M17: =J17+L17 -> 6000 | N17: =COEF -> 1.22 | O17: =E17*M17 -> 438000 | P17: =ROUND(E17*L17*N17,0) -> 507642 | Q17: 図面カウント | R17: =IF(H17="","",H17-O17) -> 96360 | S17: =IF(OR(H17="",H17=0),"",R17/H17) -> 0.18032787 | V17: パイプファン取付（参考実績なし）｜46＋27台
A18: 吸気口 内部 KS-8841PR3-SG 取付 | C18: 材工 (支給外と想定・要確認) | E18: 73 | F18: 個 | G18: =IF(M18="","",ROUND(M18*N18,-1)) -> 5980 | H18: =IF(G18="","",ROUND(E18*G18,0)) -> 436540 | J18: 3000 | K18: 0.1 | L18: =ROUND(K18*LABOR_DAY,0) -> 1900 | M18: =J18+L18 -> 4900 | N18: =COEF -> 1.22 | O18: =E18*M18 -> 357700 | P18: =ROUND(E18*L18*N18,0) -> 169214 | Q18: 図面カウント | R18: =IF(H18="","",H18-O18) -> 78840 | S18: =IF(OR(H18="",H18=0),"",R18/H18) -> 0.18060201 | V18: 吸気口 KS-8841PR3-SG 材＋取付｜朱書き: 吸気口 外部SUS製フード(指定色)・内部KS-8841PR3-SG
A19: 吸気口用 SUS製フード 取付 (支給品) | C19: 指定色塗装 | E19: 73 | F19: 箇所 | G19: =IF(M19="","",ROUND(M19*N19,-1)) -> 3840 | H19: =IF(G19="","",ROUND(E19*G19,0)) -> 280320 | I19: 支給品の取付費 | J19: 300 | K19: 0.15 | L19: =ROUND(K19*LABOR_DAY,0) -> 2850 | M19: =J19+L19 -> 3150 | N19: =COEF -> 1.22 | O19: =E19*M19 -> 229950 | P19: =ROUND(E19*L19*N19,0) -> 253821 | Q19: 図面カウント | R19: =IF(H19="","",H19-O19) -> 50370 | S19: =IF(OR(H19="",H19=0),"",R19/H19) -> 0.1796875 | V19: SUS製フード取付（支給）｜B-5の寮室146箇所と重複なし(排気73・給気73)
A21: 【小 計】 | H21: =SUM(H6:H20) -> 413860 | K21: =SUMPRODUCT(E6:E20,K6:K20) -> 6.1 | O21: =SUM(O6:O20) -> 339200 | P21: =SUM(P6:P20) -> 141398 | R21: =H21-O21 -> 74660 | S21: =IF(H21=0,"",R21/H21) -> 0.18039917

Sheet 法定福利費内訳明細書
B1: 法 定 福 利 費 内 訳 明 細 書
B2: ="（御見積書 No."&'表紙(工事)'!K3&" の添付資料）" -> （御見積書 No. の添付資料）
B4: 見積年月日 | C4: ='表紙(工事)'!J4 -> 46301 | F4: 見積No. | G4: =IF('表紙(工事)'!K3="","",'表紙(工事)'!K3)
B5: 発注者名 | C5: 株式会社共栄店舗 御中
B6: 工事名 | C6: （仮称）サンフレッチェ広島 三矢寮新築工事 空調設備工事
B7: 施工場所 | C7: 広島県安芸高田市吉田町西浦字日南山835-27
B8: 会社名 | C8: 宮地機工株式会社 | F8: 所在地 | G8: 広島県尾道市東尾道9-9
B10: 【1】 労務費の内訳（法定福利費の算定基礎）
B11: ※ 本見積の労務費は、内訳書各項目の材工共単価のうち労務費相当額（自社施工分）の合計です。機器は元請様手配のため含みません。
B12: 項 目 | C12: 労務費（円） | E12: 摘 要
B13: 換気工事 労務費 | C13: ='内訳書(1.換気工事)'!P93 -> 5423193 | E13: 内訳書 No.1 各項目の労務費相当額の合計
B14: ロスナイ中止・代替 労務費 | C14: ='内訳書(2.ロスナイ中止)'!P21 -> 141398 | E14: 内訳書 No.2 各項目の労務費相当額の合計
B15: 労 務 費 合 計 | C15: =SUM(C13:C14) -> 5564591 | E15: ← 法定福利費の算定基礎額
B17: 【2】 法定福利費の算定
B18: 計算式： 法定福利費 ＝ 労務費 × 事業主負担料率 （保険ごとに円未満切捨て）
B19: 保険の種類 | C19: 対象労務費（円） | E19: 事業主負担料率 | F19: 法定福利費（円） | G19: 算定根拠
B20: 健康保険料 | C20: =$C$15 -> 5564591 | E20: 0.0489 | F20: =ROUNDDOWN(C20*E20,0) -> 272108 | G20: 健康保険料率 9.780%（協会けんぽ 広島県 令和8年度）×1/2（労使折半）
B21: 介護保険料 | C21: =$C$15 -> 5564591 | E21: 0.0081 | F21: =ROUNDDOWN(C21*E21,0) -> 45073 | G21: 介護保険料率 1.620%（全国一律 令和8年度）×1/2（労使折半）
B22: 子ども・子育て支援金 | C22: =$C$15 -> 5564591 | E22: 0.00115 | F22: =ROUNDDOWN(C22*E22,0) -> 6399 | G22: 支援金率 0.230%（令和8年4月分〜）×1/2（労使折半）
B23: 厚生年金保険料 | C23: =$C$15 -> 5564591 | E23: 0.0915 | F23: =ROUNDDOWN(C23*E23,0) -> 509160 | G23: 厚生年金保険料率 18.300%（平成29年9月以降固定）×1/2（労使折半）
B24: 雇用保険料 | C24: =$C$15 -> 5564591 | E24: 0.0105 | F24: =ROUNDDOWN(C24*E24,0) -> 58428 | G24: 雇用保険料率（建設の事業）事業主負担分 1.050%
B25: 子ども・子育て拠出金 | C25: =$C$15 -> 5564591 | E25: 0.0036 | F25: =ROUNDDOWN(C25*E25,0) -> 20032 | G25: 拠出金率 0.360%（事業主全額負担）
B26: 合 計 | E26: =SUM(E20:E25) -> 0.16375 | F26: =SUM(F20:F25) -> 911200
B28: ※ 料率は見積作成時点（令和8年度）の公表料率によります。料率が改定された場合は改定後の料率により精算させていただきます。
B29: ※ 法定福利費は御見積書の③に計上しています。

Sheet 御見積条件
A1: 御見積条件・注意事項
A2: （仮称）サンフレッチェ広島 三矢寮新築工事 空調設備工事 換気工事 御見積書 添付
A4: 【1】御見積条件・注意事項
A5: 1. | B5: 本見積は機械設備図 06（特記仕様書・空調機器表・換気機器表・空調平面図・換気平面図・厨房廻り詳細図）に基づき当社にて拾い出した数量により積算しております。配管・ダクトの平面延長は図面（A3 1:300、厨房詳細 1:70）から計測し、立上り・立下り・機器接続部および図面に経路の記載がない部分は想定数量として計上しています（別紙【2】参照）。
A6: 2. | B6: 金額変更案検討図 08 のうち No3・4（ロスナイ中止）を内訳書 No.2 に朱書きで計上しています。ベース計上分の減額と代替機器（中間ファン・パイプファン・吸気口）の計上を併記しています。No5・6（空調追加）は空調工事の見積書に計上しています。No1（庇中止）・No2（既存フェンス再利用）は対象外です。
A7: 3. | B7: 空調機器・換気機器は元請様手配のため本見積には含みません（室内機・室外機・集中リモコン・換気扇・中間ファン・全熱交換器・パイプファン・有圧扇・屋外機架台（2段架台含む）・ドレンアップ・SUS製フード・ウェザーカバー等、機器表記載の本体および付属品）。本見積は上記機器の搬入・据付・取付費のみを計上しています。
A8: 4. | B8: 機器の電源供給（電源・動力配線、盤、接地、インバータ盤）は電気工事とし含みません。機器付属の制御盤およびリモコン制御の配管・配線（工事区分表「機械」）は本見積に計上しています。
A9: 5. | B9: 基礎（室外機基礎）、躯体・外壁の穴明け、スリーブ・型枠の穴埋め、天井点検口、天井・壁の開口補強および仕上げ補修は建築工事とし含みません（工事区分表による）。外壁貫通スリーブ材のみ計上しています。
A10: 6. | B10: 厨房フード①〜④（SUS製、グリスフィルター付）は機械設備図のフードリストにより本見積に計上しています。厨房機器工事の範囲となる場合は減額いたします。
A11: 7. | B11: ロスナイ中止後の OA 側ダクト・制気口は図示どおり自然給気として残置する前提で計上しています。撤去・変更がある場合は別途協議とさせていただきます。
A12: 8. | B12: 施工図・竣工図（完成図）の作成、風量測定・試験成績書の作成、官庁検査対応は含みません。必要な場合は別途お見積りいたします。
A13: 9. | B13: 仮設（足場・高所作業車・仮設電気・水道・資材置場等）および産業廃棄物の処分費は元請様にてご負担願います（当社発生材は指定集積場所への分別搬出まで）。
A14: 10. | B14: 工期は全体工程表（2026.8.18 共栄店舗）に基づく通常の日中作業を前提としております。夜間・休日作業、工程の大幅な変更や他工事との輻輳による手待ち、工期延長に伴う経費増は別途協議とさせていただきます。
A15: 11. | B15: 本見積書に記載なき事項については別途とさせていただきます。工事に係る電気・水道は無償支給願います。
A16: 12. | B16: 本見積金額には消費税は含まれておりません。労務費に係る法定福利費（事業主負担分）は別紙「法定福利費内訳明細書」のとおり計上しています。
A18: 【2】想定数量（推測）項目の前提
A19: 図面に数量・経路の記載がなく当社にて想定した項目です。「図面実測＋想定」は平面延長を図面計測し、立上り等を想定加算したものです。実数量確定後に精算させていただきます。
A20: No. | B20: 内訳書 | C20: 項 目 | D20: 前提・想定内容 | F20: 数量（区分）
A21: 1 | B21: No.1 | C21: スパイラルダクト 200φ (EA) 亜鉛鉄板 低速 継手・支持共 | D21: 1F 25.2m・2F 9.8m 実測＋厨房詳細図 9m 推測 | F21: 44 m（実測＋想定）
A22: 2 | B22: No.1 | C22: スパイラルダクト 250φ (EA 厨房) 亜鉛鉄板 継手・支持共 | D22: 厨房廻り平面詳細図より | F22: 6 m（想定）
A23: 3 | B23: No.1 | C23: スパイラルダクト 300φ (EA 厨房) 亜鉛鉄板 継手・支持共 | D23: フード③④→F-3 3台 | F23: 5 m（想定）
A24: 4 | B24: No.1 | C24: スパイラルダクト 200φ (OA) 亜鉛鉄板 継手・支持共 | D24: 1F 45.7m・2F 3.5m 実測＋厨房FS-1 7.5m 推測 | F24: 57 m（実測＋想定）
A25: 5 | B25: No.1 | C25: 外壁貫通部ダクト (フード接続) 150φ相当 1.0m/箇所 | D25: 1F フード48箇所・2F廊下10箇所 | F25: 58 m（想定）
A26: 6 | B26: No.1 | C26: OAダクト 保温 GW保温筒25 ALGC 隠蔽(天井内) 特記仕様書 保温表 | D26: OAダクト全長 | F26: 123 m（実測＋想定）
A27: 7 | B27: No.1 | C27: 厨房排気ダクト 保温 RW保温筒50 ＋アルミガラスクロス＋亀甲金網巻 | D27: 厨房200/250/300φ EA | F27: 20 m（想定）
A28: 8 | B28: No.1 | C28: SUS製フード 取付 (支給品) 指定色塗装 外壁貫通部 | D28: 1F 48・2F廊下10・寮室146(HEX-4/5分) | F28: 204 箇所（想定）
A30: 【3】図面読み取りに関する確認事項
A31: 1. | B31: 宛名は元請様を株式会社共栄店舗（詳細工程表作成者）と想定して記載しています。ご指定があれば修正します。
A32: 2. | B32: 換気平面図のダクト線（排気＝黒太線、給気＝青線）をベクトルデータから計測しています。機器記号と重なる短い線分は除外しているため、実測値は若干少なめになる傾向があります。
A33: 3. | B33: SUS製フード・ウェザーカバーは換気機器表の付属品として元請様支給と解釈し、取付費のみ計上しています。
A34: 4. | B34: 吸気口 KS-8841PR3-SG（図面08 朱書き）は支給範囲が不明のため材工で計上しています。支給の場合は材料分を減額します。

Sheet 数量拾い根拠(内部)
A1: 数量拾い根拠（内部用） ※計測方法: PDF図面(A3 1:300、厨房詳細 1:70)のベクトル線分を色・線幅で分離し延長を集計。「実測」=図面線分の平面延長、「推測」=図面に無い部分の推定
A3: 4. ダクト（ベース06）
A4: 図面 | B4: 系統 | C4: 100φ(m) | D4: 150φ(m) | E4: 200φ(m) | F4: 250φ(m) | G4: 300φ(m) | H4: 備考
A5: 1F換気平面図(p22) 黒太線 | B5: EA | C5: 62.6 | D5: 122.4 | E5: 25.2 | F5: 0 | G5: 0 | H5: 150φに口径未判読16.6m含む（実測）
A6: 1F換気平面図(p22) 青線 | B6: OA | C6: 3.5 | D6: 50.4 | E6: 45.7 | F6: 0 | G6: 0 | H6: 150φに未判読9.1m含む（実測）
A7: 2F換気平面図(p23) 黒太線 | B7: EA | C7: 5.2 | D7: 28.2 | E7: 9.8 | F7: 0 | G7: 0 | H7: 実測
A8: 2F換気平面図(p23) 青線 | B8: OA | C8: 0 | D8: 0 | E8: 3.5 | F8: 0 | G8: 0 | H8: 実測
A9: 厨房廻り詳細図(p24) 1:70 | B9: EA | C9: 0 | D9: 0 | E9: 9 | F9: 6 | G9: 5 | H9: 推測（二重線表記のため目視換算）
A10: 厨房廻り詳細図(p24) 1:70 | B10: OA(FS-1/2・F-3給気) | C10: 0 | D10: 0 | E10: 7.5 | F10: 6 | G10: 3 | H10: 推測
A11: 外壁貫通部・フード接続 | B11: EA/OA | C11: 0 | D11: 58 | E11: 0 | F11: 0 | G11: 0 | H11: 推測 1.0m/箇所×58
A12: 合計 | C12: 71.3 | D12: 259 | E12: 100.7 | F12: 12 | G12: 8 | H12: 内訳書は端数切上げ
A14: 5. 機器台数（図面カウント）
A15: 記号 | B15: 台数 | C15: 備考
A16: AC-1 (ツイン) 室内8/室外4 | B16: 4系統 | C16: 空調機器表・平面図
A17: AC-2,3 (ツイン) 室内各2/室外各1 | B17: 2系統
A18: AC-5,6,7,8,9,10 室内各1/室外各1 | B18: 7台 | C18: AC-5は2台
A19: RAC-1/2/3/4 | B19: 2/8/66/1 | C19: 2F寮室×16+×3+×11+×8+×4+×24=66
A20: 追AC1 室内3/室外1、追AC2〜5 室内各3/室外各1 | B20: 5系統 | C20: 図面08 p19・p20 朱書き □ 位置より
A21: 区画貫通部 ● | B21: 1F 2箇所 | C21: 空調平面図1F 凡例
A22: VD | B22: 1F 9・2F 4 | C22: 換気平面図ラベル数

Sheet 単価マスタ(内部)
A1: 単価マスタ（内部） 原価＝材料原価＋人工×労務原価日額、提出（定価ベース）＝原価×提出係数。参考列は宮地機工 参考見積8件（2025.11〜2026.10）から整理
A2: 労務原価日額 19,000 円/人工 参考見積の人工単価 23,225 円/人工（6330476-3 配管工費 40人工 929,000） 提出係数 1.22 材料係数 ×1.85（継手30%＋消耗15%＋支持金物40%）
A4: キー | B4: 材料原価 | C4: 人工 | D4: 労務原価 | E4: 原価 | F4: 提出(定価ベース) | G4: 参考定価ベース | H4: 当社/参考 | I4: 出典・根拠
A5: REF_① | B5: 2200 | C5: 0.2 | D5: =ROUND(C5*LABOR_DAY,0) -> 3800 | E5: =IF(B5="","",B5+D5) -> 6000 | F5: =IF(E5="","",ROUND(E5*COEF,-1)) -> 7320 | G5: 7328 | H5: =IF(OR(G5="",F5=""),"",F5/G5) -> 0.9989083 | I5: 6330539 ペアコイル6.35+9.52 988/m・2分3分級は1,450/m想定、5 m/人工
A6: REF_② | B6: 2960 | C6: 0.21 | D6: =ROUND(C6*LABOR_DAY,0) -> 3990 | E6: =IF(B6="","",B6+D6) -> 6950 | F6: =IF(E6="","",ROUND(E6*COEF,-1)) -> 8480 | G6: 8485 | H6: =IF(OR(G6="",F6=""),"",F6/G6) -> 0.99941072 | I6: 補間（9.52+15.88 4,025 と 6.35+9.52 の間）
A7: REF_③ | B7: 6100 | C7: 0.22 | D7: =ROUND(C7*LABOR_DAY,0) -> 4180 | E7: =IF(B7="","",B7+D7) -> 10280 | F7: =IF(E7="","",ROUND(E7*COEF,-1)) -> 12540 | G7: 12556 | H7: =IF(OR(G7="",F7=""),"",F7/G7) -> 0.99872571 | I7: 6330476-3 / 6330344-1 9.52+15.88 4,025/m、4.6 m/人工
A8: REF_⑥ | B8: 8300 | C8: 0.28 | D8: =ROUND(C8*LABOR_DAY,0) -> 5320 | E8: =IF(B8="","",B8+D8) -> 13620 | F8: =IF(E8="","",ROUND(E8*COEF,-1)) -> 16620 | G8: 16632 | H8: =IF(OR(G8="",F8=""),"",F8/G8) -> 0.9992785 | I8: 6330476-3 9.52+25.40 5,475/m、3.5 m/人工
A9: REF_⑦ | B9: 8610 | C9: 0.3 | D9: =ROUND(C9*LABOR_DAY,0) -> 5700 | E9: =IF(B9="","",B9+D9) -> 14310 | F9: =IF(E9="","",ROUND(E9*COEF,-1)) -> 17460 | G9: 17466 | H9: =IF(OR(G9="",F9=""),"",F9/G9) -> 0.99965648 | I9: 6330476-3 12.70+25.40 5,675/m、3.3 m/人工
A10: REF_CASE | B10: 1500 | C10: 0.1 | D10: =ROUND(C10*LABOR_DAY,0) -> 1900 | E10: =IF(B10="","",B10+D10) -> 3400 | F10: =IF(E10="","",ROUND(E10*COEF,-1)) -> 4150 | G10: 3516 | H10: =IF(OR(G10="",F10=""),"",F10/G10) -> 1.1803185 | I10: 配管保温工事費 1,194/m（6330476-3）＋化粧ケース材
A11: SLEEVE | B11: 900 | C11: 0.06 | D11: =ROUND(C11*LABOR_DAY,0) -> 1140 | E11: =IF(B11="","",B11+D11) -> 2040 | F11: =IF(E11="","",ROUND(E11*COEF,-1)) -> 2490 | I11: VP100 スリーブ材＋取付（参考実績なし）
A12: FIRESTOP | B12: 4500 | C12: 0.4 | D12: =ROUND(C12*LABOR_DAY,0) -> 7600 | E12: =IF(B12="","",B12+D12) -> 12100 | F12: =IF(E12="","",ROUND(E12*COEF,-1)) -> 14760 | I12: 6330248-2 防火区画貫通 88,000/式（箇所数不明）
A13: LEAK_TEST | B13: 3000 | C13: 0.6 | D13: =ROUND(C13*LABOR_DAY,0) -> 11400 | E13: =IF(B13="","",B13+D13) -> 14400 | F13: =IF(E13="","",ROUND(E13*COEF,-1)) -> 17570 | G13: 20000 | H13: =IF(OR(G13="",F13=""),"",F13/G13) -> 0.8785 | I13: 気密テスト 15,000〜25,000/系統・真空引き 3,750〜5,640/系統（6330558/344-1/549）
A14: REFRIGERANT | B14: 3800 | C14: 0 | D14: =ROUND(C14*LABOR_DAY,0) -> 0 | E14: =IF(B14="","",B14+D14) -> 3800 | F14: =IF(E14="","",ROUND(E14*COEF,-1)) -> 4640 | I14: R32 冷媒代（参考に単価行なし）
A15: VP20 | B15: 380 | C15: 0.1 | D15: =ROUND(C15*LABOR_DAY,0) -> 1900 | E15: =IF(B15="","",B15+D15) -> 2280 | F15: =IF(E15="","",ROUND(E15*COEF,-1)) -> 2780 | G15: 2578 | H15: =IF(OR(G15="",F15=""),"",F15/G15) -> 1.0783553 | I15: 6330539 VP13 138/m、塩ビ工費 9.3〜12 m/人工
A16: VP25 | B16: 475 | C16: 0.11 | D16: =ROUND(C16*LABOR_DAY,0) -> 2090 | E16: =IF(B16="","",B16+D16) -> 2565 | F16: =IF(E16="","",ROUND(E16*COEF,-1)) -> 3130 | G16: 3134 | H16: =IF(OR(G16="",F16=""),"",F16/G16) -> 0.99872368 | I16: 6330344-1/476-3/248-2 VP25 313/m、工費 2,497/m
A17: VP40 | B17: 760 | C17: 0.13 | D17: =ROUND(C17*LABOR_DAY,0) -> 2470 | E17: =IF(B17="","",B17+D17) -> 3230 | F17: =IF(E17="","",ROUND(E17*COEF,-1)) -> 3940 | I17: VP25 比例
A18: DRAIN_INS | B18: 900 | C18: 0.06 | D18: =ROUND(C18*LABOR_DAY,0) -> 1140 | E18: =IF(B18="","",B18+D18) -> 2040 | F18: =IF(E18="","",ROUND(E18*COEF,-1)) -> 2490 | I18: GW保温筒20 ALGC（参考実績なし）
A19: DRAIN_HOSE | B19: 300 | C19: 0.05 | D19: =ROUND(C19*LABOR_DAY,0) -> 950 | E19: =IF(B19="","",B19+D19) -> 1250 | F19: =IF(E19="","",ROUND(E19*COEF,-1)) -> 1530 | I19: 推定
A20: PAC_IN | B20: 1600 | C20: 0.85 | D20: =ROUND(C20*LABOR_DAY,0) -> 16150 | E20: =IF(B20="","",B20+D20) -> 17750 | F20: =IF(E20="","",ROUND(E20*COEF,-1)) -> 21660 | G20: 21700 | H20: =IF(OR(G20="",F20=""),"",F20/G20) -> 0.99815668 | I20: 6330476-3 搬入据付 238,750/11台≒21,700/台、6330284-1 25,000/台
A21: PAC_IN_BIG | B21: 2000 | C21: 1 | D21: =ROUND(C21*LABOR_DAY,0) -> 19000 | E21: =IF(B21="","",B21+D21) -> 21000 | F21: =IF(E21="","",ROUND(E21*COEF,-1)) -> 25620 | G21: 27860 | H21: =IF(OR(G21="",F21=""),"",F21/G21) -> 0.91959799 | I21: 6330558 VRV 90クラス 27,860/台
A22: PAC_OUT | B22: 3000 | C22: 0.8 | D22: =ROUND(C22*LABOR_DAY,0) -> 15200 | E22: =IF(B22="","",B22+D22) -> 18200 | F22: =IF(E22="","",ROUND(E22*COEF,-1)) -> 22200 | G22: 29200 | H22: =IF(OR(G22="",F22=""),"",F22/G22) -> 0.76027397 | I22: 搬入据付＋基礎工事 5,800〜10,000/台（6330539/549/476-3）
A23: PAC_OUT_BIG | B23: 4000 | C23: 1.1 | D23: =ROUND(C23*LABOR_DAY,0) -> 20900 | E23: =IF(B23="","",B23+D23) -> 24900 | F23: =IF(E23="","",ROUND(E23*COEF,-1)) -> 30380 | G23: 37860 | H23: =IF(OR(G23="",F23=""),"",F23/G23) -> 0.80243001 | I23: 8〜10HP 室外機（防振ゴム・架台固定共）
A24: RAC_SET | B24: 750 | C24: 0.5 | D24: =ROUND(C24*LABOR_DAY,0) -> 9500 | E24: =IF(B24="","",B24+D24) -> 10250 | F24: =IF(E24="","",ROUND(E24*COEF,-1)) -> 12510 | G24: 18300 | H24: =IF(OR(G24="",F24=""),"",F24/G24) -> 0.68360656 | I24: 6330539 RA 搬入据付 12,500/組＋基礎 5,833/組
A25: REMOTE_CTRL | B25: 1000 | C25: 0.4 | D25: =ROUND(C25*LABOR_DAY,0) -> 7600 | E25: =IF(B25="","",B25+D25) -> 8600 | F25: =IF(E25="","",ROUND(E25*COEF,-1)) -> 10490 | G25: 9630 | H25: =IF(OR(G25="",F25=""),"",F25/G25) -> 1.0893043 | I25: リモコン配線工事 9,630/系統（6330549/558/476-3）
A26: CRANE | B26: 75000 | C26: 0 | D26: =ROUND(C26*LABOR_DAY,0) -> 0 | E26: =IF(B26="","",B26+D26) -> 75000 | F26: =IF(E26="","",ROUND(E26*COEF,-1)) -> 91500 | G26: 93750 | H26: =IF(OR(G26="",F26=""),"",F26/G26) -> 0.976 | I26: 揚重工事費（レッカー）93,750/式（6330558）
A27: CARRY_IN | B27: 0 | C27: 1 | D27: =ROUND(C27*LABOR_DAY,0) -> 19000 | E27: =IF(B27="","",B27+D27) -> 19000 | F27: =IF(E27="","",ROUND(E27*COEF,-1)) -> 23180 | I27: 搬入・小運搬 人工
A28: TEST_RUN | B28: 450 | C28: 0.45 | D28: =ROUND(C28*LABOR_DAY,0) -> 8550 | E28: =IF(B28="","",B28+D28) -> 9000 | F28: =IF(E28="","",ROUND(E28*COEF,-1)) -> 10980 | G28: 11000 | H28: =IF(OR(G28="",F28=""),"",F28/G28) -> 0.99818182 | I28: 試運転調整費 10,000〜12,500/系統（6330344-1/549/476-3）
A29: TEST_RUN_RAC | B29: 0 | C29: 0.1 | D29: =ROUND(C29*LABOR_DAY,0) -> 1900 | E29: =IF(B29="","",B29+D29) -> 1900 | F29: =IF(E29="","",ROUND(E29*COEF,-1)) -> 2320 | G29: 2500 | H29: =IF(OR(G29="",F29=""),"",F29/G29) -> 0.928 | I29: 6330539 試運転 7,500/3台
A30: DOCS | B30: 5000 | C30: 1 | D30: =ROUND(C30*LABOR_DAY,0) -> 19000 | E30: =IF(B30="","",B30+D30) -> 24000 | F30: =IF(E30="","",ROUND(E30*COEF,-1)) -> 29280 | I30: 書類作成 人工
A31: WIRE_PAC | B31: 2000 | C31: 0.26 | D31: =ROUND(C31*LABOR_DAY,0) -> 4940 | E31: =IF(B31="","",B31+D31) -> 6940 | F31: =IF(E31="","",ROUND(E31*COEF,-1)) -> 8470 | G31: 8436 | H31: =IF(OR(G31="",F31=""),"",F31/G31) -> 1.0040303 | I31: VVF2.0-3C 203/m＋電線材料施工費 約500/m（12m/系統 8,436）→ 原価 6,900
A32: WIRE_RAC | B32: 1130 | C32: 0.12 | D32: =ROUND(C32*LABOR_DAY,0) -> 2280 | E32: =IF(B32="","",B32+D32) -> 3410 | F32: =IF(E32="","",ROUND(E32*COEF,-1)) -> 4160 | G32: 3515 | H32: =IF(OR(G32="",F32=""),"",F32/G32) -> 1.1834993 | I32: VVF2.0-3C 5m/台
A33: SLINK | B33: 30000 | C33: 1.2 | D33: =ROUND(C33*LABOR_DAY,0) -> 22800 | E33: =IF(B33="","",B33+D33) -> 52800 | F33: =IF(E33="","",ROUND(E33*COEF,-1)) -> 64420 | I33: 集中リモコン制御線 200m 推定
A34: BRANCH | B34: 600 | C34: 0.25 | D34: =ROUND(C34*LABOR_DAY,0) -> 4750 | E34: =IF(B34="","",B34+D34) -> 5350 | F34: =IF(E34="","",ROUND(E34*COEF,-1)) -> 6530 | I34: 分岐管取付（支給）
A35: FAN_PIPE | B35: 300 | C35: 0.3 | D35: =ROUND(C35*LABOR_DAY,0) -> 5700 | E35: =IF(B35="","",B35+D35) -> 6000 | F35: =IF(E35="","",ROUND(E35*COEF,-1)) -> 7320 | I35: パイプファン取付（参考実績なし）
A36: FAN_CEIL | B36: 500 | C36: 0.45 | D36: =ROUND(C36*LABOR_DAY,0) -> 8550 | E36: =IF(B36="","",B36+D36) -> 9050 | F36: =IF(E36="","",ROUND(E36*COEF,-1)) -> 11040 | I36: 天井扇取付（参考実績なし）
A37: FAN_DUCT | B37: 2000 | C37: 1.2 | D37: =ROUND(C37*LABOR_DAY,0) -> 22800 | E37: =IF(B37="","",B37+D37) -> 24800 | F37: =IF(E37="","",ROUND(E37*COEF,-1)) -> 30260 | I37: 中間ファン（防振吊）取付
A38: FAN_PRESS | B38: 1500 | C38: 0.9 | D38: =ROUND(C38*LABOR_DAY,0) -> 17100 | E38: =IF(B38="","",B38+D38) -> 18600 | F38: =IF(E38="","",ROUND(E38*COEF,-1)) -> 22690 | I38: 有圧扇＋ウェザーカバー取付
A39: HEX_CEIL | B39: 2500 | C39: 1.4 | D39: =ROUND(C39*LABOR_DAY,0) -> 26600 | E39: =IF(B39="","",B39+D39) -> 29100 | F39: =IF(E39="","",ROUND(E39*COEF,-1)) -> 35500 | I39: 全熱交換器 天井埋込（ダクト接続別）
A40: HEX_WALL | B40: 500 | C40: 0.45 | D40: =ROUND(C40*LABOR_DAY,0) -> 8550 | E40: =IF(B40="","",B40+D40) -> 9050 | F40: =IF(E40="","",ROUND(E40*COEF,-1)) -> 11040 | I40: 壁掛ロスナイ取付
A41: CYCLE_FAN | B41: 300 | C41: 0.35 | D41: =ROUND(C41*LABOR_DAY,0) -> 6650 | E41: =IF(B41="","",B41+D41) -> 6950 | F41: =IF(E41="","",ROUND(E41*COEF,-1)) -> 8480 | I41: サイクル扇
...
