Workbook
Name COEF: '表紙(工事)'!$N$4
Name OVERHEAD_RATE: '表紙(工事)'!$N$5
Name ROUND_UNIT: '表紙(工事)'!$N$6
Name WELFARE_RATE: '法定福利費内訳明細書'!$E$27

Sheet 表紙(工事)
A1: 御 見 積 書
J3: No. | M3: 【設定・内部用】（印刷範囲外）
J4: 46300 | M4: 提出係数（基準原価→提出単価） | N4: 1.1
A5: 株式会社共栄店舗 | G5: 御中 | M5: 諸経費率 | N5: 0.08
M6: 端数処理単位 | N6: 10000
A7: 金額 | B7: ="¥"&TEXT(K29,"#,##0")&"-" -> ¥30,810,000- | F7: （税別） | H7: 宮地機工株式会社 | M7: 法定福利費率（労務費比） | N7: =WELFARE_RATE -> 0.16375
M8: 参考：労務単価（円/人工） | N8: 27000
A9: 上記の通り御見積申し上げます。 | H9: 代表取締役 濱本 義樹 | M9: ※ 粗利率を変えたい場合は提出係数 N4 を変更（例 1.25 → 粗利率 20%）。行ごとに変える場合は内訳書の M列
A10: 何卒ご用命賜わりますようお願い申し上げます。
H11: 〒722-0051
A12: 工事名 | D12: （仮称）サンフレッチェ広島 三矢寮新築工事 | H12: 広島県尾道市東尾道9-9
D13: 空調設備工事（空調・換気／図面06ベース・金額変更案08） | H13: TEL.0848-20-2121 | K13: FAX.0848-20-2126
A14: 施工場所 | D14: 広島県安芸高田市吉田町西浦字日南山835-27 | H14: 担当者 | J14: 濱本 義武
A15: 工事期限 | D15: 全体工期 2026年5月1日～2027年2月15日（空調工事は工程表による・別途お打ち合わせ）
A16: 御支払条件 | D16: 別途お打ち合わせ
A17: 有効期限 | D17: 発行後3ヶ月
A19: 項 目 | B19: 内 容 | G19: 数 量 | H19: 単位 | I19: 単 価 | K19: 金 額 | L19: 備 考 | M19: 内部集計（原価・粗利） | N19: 基準原価 | O19: 労務費(提出) | P19: 粗利 | Q19: 粗利率
B20: 【（仮称）サンフレッチェ広島 三矢寮新築工事 空調設備工事】
B21: ［機器（空調機器表・換気機器表記載分）は元請様手配、電気工事・建築工事・自動制御は含まず］
A22: ① | B22: 空調工事（機械設備図 06） | G22: 1 | H22: 式 | I22: =K22 -> 10880980 | K22: ='内訳書(1.空調工事)'!H58 -> 10880980 | L22: 内訳書 No.1 | M22: ①空調工事 | N22: ='内訳書(1.空調工事)'!N58 -> 9891800 | O22: ='内訳書(1.空調工事)'!O58 -> 6749050 | P22: =K22-N22 -> 989180 | Q22: =IF(K22=0,"",P22/K22) -> 0.090909091
A23: ② | B23: 換気工事（機械設備図 06） | G23: 1 | H23: 式 | I23: =K23 -> 9971500 | K23: ='内訳書(2.換気工事)'!H93 -> 9971500 | L23: 内訳書 No.2 | M23: ②換気工事 | N23: ='内訳書(2.換気工事)'!N93 -> 9065000 | O23: ='内訳書(2.換気工事)'!O93 -> 6356460 | P23: =K23-N23 -> 906500 | Q23: =IF(K23=0,"",P23/K23) -> 0.090909091
A24: ③ | B24: 金額変更案（検討図 08 No3・4 ロスナイ中止／No5・6 空調追加） | G24: 1 | H24: 式 | I24: =K24 -> 5262950 | K24: ='内訳書(3.金額変更案)'!H48 -> 5262950 | L24: 内訳書 No.3 | M24: ③金額変更案 | N24: ='内訳書(3.金額変更案)'!N48 -> 4784500 | O24: ='内訳書(3.金額変更案)'!O48 -> 2863960 | P24: =K24-N24 -> 478450 | Q24: =IF(K24=0,"",P24/K24) -> 0.090909091
A25: ④ | B25: 法定福利費（労務費に係る事業主負担分） | G25: 1 | H25: 式 | I25: =K25 -> 2614998 | K25: ='法定福利費内訳明細書'!F27 -> 2614998 | L25: 別紙明細書 | M25: ④法定福利費（原価＝提出値） | N25: =K25 -> 2614998
A26: ⑤ | B26: 諸経費 | G26: 1 | H26: 式 | I26: =K26 -> 2089000 | K26: =ROUND((K22+K23+K24)*OVERHEAD_RATE,-3) -> 2089000 | L26: ="①〜③計の"&TEXT(OVERHEAD_RATE,"0%") -> ①〜③計の8% | M26: ⑤諸経費（原価計上なし） | N26: 0
B28: 出精値引き | K28: =FLOOR(SUM(K22:K26),ROUND_UNIT)-SUM(K22:K26) -> -9428 | L28: 端数調整 | M28: 出精値引き（粗利から控除） | N28: 0
B29: 合 計 | K29: =SUM(K22:K28) -> 30810000 | L29: （税別） | M29: 合計（原価合計／粗利／粗利率） | N29: =SUM(N22:N28) -> 26356298 | O29: =SUM(O22:O28) -> 15969470 | P29: =K29-N29 -> 4453702 | Q29: =IF(K29=0,"",P29/K29) -> 0.14455378
A31: ※ | B31: 本見積は機械設備図（図面No.06 若本建築事務所 '26.1.31）に基づき当社にて数量を拾い出して積算しております。金額変更案検討図（図面No.08）による追加・変更は内訳書 No.3（朱書き）に計上しています。実施数量との差異は別途精算とさせていただきます。
A32: ※ | B32: 空調機器・換気機器（室内機・室外機・リモコン・換気扇・全熱交換器・屋外機架台・ドレンアップ等 機器表記載の本体および付属品）は元請様手配のため含みません（据付・取付費のみ計上）。 | M32: 粗利率別 参考提出額（税別・万円未満切上げ） | N32: 参考提出額 | O32: 必要提出係数
A33: ※ | B33: 機器の電源供給・接地等の電気工事、基礎・躯体貫通穴明け・スリーブ穴埋め・天井点検口等の建築工事、衛生・消火・ガス・浄化槽設備、自動制御設備は含みません。 | M33: 0.1 | N33: =ROUNDUP($N$29/(1-M33),-4) -> 29290000 | O33: =IF(SUM($N$22:$N$24)=0,"",ROUND(($N$29/(1-M33)-$N$25-$K$26)/SUM($N$22:$N$24),3)) -> 1.035
A34: ※ | B34: 機器・資材の揚重機（クレーン・レッカー等）、仮設設備、産業廃棄物の処分は元請様にてご手配・ご負担願います。 | M34: 0.15 | N34: =ROUNDUP($N$29/(1-M34),-4) -> 31010000 | O34: =IF(SUM($N$22:$N$24)=0,"",ROUND(($N$29/(1-M34)-$N$25-$K$26)/SUM($N$22:$N$24),3)) -> 1.108
A35: ※ | B35: 一式計上および想定数量の項目は別紙「御見積条件」記載の前提にて計上しており、実数量確定後に精算させていただきます。 | M35: 0.2 | N35: =ROUNDUP($N$29/(1-M35),-4) -> 32950000 | O35: =IF(SUM($N$22:$N$24)=0,"",ROUND(($N$29/(1-M35)-$N$25-$K$26)/SUM($N$22:$N$24),3)) -> 1.19
A36: ※ | B36: 本見積書に記載なき事項については別途とさせて頂きます。工事に係る電気・水道は無償支給願います。 | M36: 0.25 | N36: =ROUNDUP($N$29/(1-M36),-4) -> 35150000 | O36: =IF(SUM($N$22:$N$24)=0,"",ROUND(($N$29/(1-M36)-$N$25-$K$26)/SUM($N$22:$N$24),3)) -> 1.282
A37: ※ | B37: 本見積金額には消費税は含まれておりません。有効期限内でも銅管・鋼材等の市況が著しく変動した場合は再見積をさせていただくことがあります。 | M37: 0.3 | N37: =ROUNDUP($N$29/(1-M37),-4) -> 37660000 | O37: =IF(SUM($N$22:$N$24)=0,"",ROUND(($N$29/(1-M37)-$N$25-$K$26)/SUM($N$22:$N$24),3)) -> 1.388
A38: ※ | B38: 詳細条件は別紙「御見積条件」をご参照ください。 | M38: ※ 必要提出係数は諸経費を現状額に固定した場合の目安

Sheet 内訳書(1.空調工事)
A1: 内 訳 書 | J1: 原 価 内 訳 書（内部用・印刷範囲外）
A2: 工事名：（仮称）サンフレッチェ広島 三矢寮新築工事 空調設備工事 | I2: 内訳書 No.1
A3: 名 称 | C3: 規格・寸法 | E3: 数 量 | F3: 単位 | G3: 単 価 | H3: 金 額 | I3: 備 考 | J3: 材料単価 | K3: 労務単価 | L3: 基準単価 | M3: 提出係数 | N3: 基準原価 | O3: 労務費(提出) | P3: 数量根拠 | Q3: 粗利 | R3: 粗利率 | S3: 前提・メモ（内部）
A4: １．空調工事（機械設備図 06）
A6: （1）空調機器据付（機器は元請様支給）
A7: AC-1 室内機 据付 | C7: 4方向天井カセット ツイン子機 PA-P280U7HDNB(10HP) 1F食堂・ﾐｰﾃｨﾝｸﾞ・ﾄﾚｰﾆﾝｸﾞ・ﾎｰﾙ | E7: 8 | F7: 台 | G7: =IF(L7="","",ROUND(L7*M7,-1)) -> 60500 | H7: =IF(G7="","",ROUND(E7*G7,0)) -> 484000 | I7: 本体は元請様支給 | J7: 8200 | K7: 46800 | L7: =J7+K7 -> 55000 | M7: =COEF -> 1.1 | N7: =E7*L7 -> 440000 | O7: =ROUND(E7*K7*M7,0) -> 411840 | P7: 図面カウント | Q7: =IF(H7="","",H7-N7) -> 44000 | R7: =IF(OR(H7="",H7=0),"",Q7/H7) -> 0.090909091 | S7: 4系統×2台 空調平面図1F
A8: AC-1 室外機 据付 | C8: 10HP 屋外機架台(支給)上 1F地上 | E8: 4 | F8: 台 | G8: =IF(L8="","",ROUND(L8*M8,-1)) -> 55000 | H8: =IF(G8="","",ROUND(E8*G8,0)) -> 220000 | I8: 本体は元請様支給 | J8: 7500 | K8: 42500 | L8: =J8+K8 -> 50000 | M8: =COEF -> 1.1 | N8: =E8*L8 -> 200000 | O8: =ROUND(E8*K8*M8,0) -> 187000 | P8: 図面カウント | Q8: =IF(H8="","",H8-N8) -> 20000 | R8: =IF(OR(H8="",H8=0),"",Q8/H8) -> 0.090909091 | S8: 基礎は建築工事
A9: AC-2 室内機 据付 | C9: 4方向天井カセット ツイン子機 PA-P224U7HDNB(8HP) コーチルーム | E9: 2 | F9: 台 | G9: =IF(L9="","",ROUND(L9*M9,-1)) -> 60500 | H9: =IF(G9="","",ROUND(E9*G9,0)) -> 121000 | I9: 本体は元請様支給 | J9: 8200 | K9: 46800 | L9: =J9+K9 -> 55000 | M9: =COEF -> 1.1 | N9: =E9*L9 -> 110000 | O9: =ROUND(E9*K9*M9,0) -> 102960 | P9: 図面カウント | Q9: =IF(H9="","",H9-N9) -> 11000 | R9: =IF(OR(H9="",H9=0),"",Q9/H9) -> 0.090909091
A10: AC-2 室外機 据付 | C10: 8HP | E10: 1 | F10: 台 | G10: =IF(L10="","",ROUND(L10*M10,-1)) -> 55000 | H10: =IF(G10="","",ROUND(E10*G10,0)) -> 55000 | I10: 本体は元請様支給 | J10: 7500 | K10: 42500 | L10: =J10+K10 -> 50000 | M10: =COEF -> 1.1 | N10: =E10*L10 -> 50000 | O10: =ROUND(E10*K10*M10,0) -> 46750 | P10: 図面カウント | Q10: =IF(H10="","",H10-N10) -> 5000 | R10: =IF(OR(H10="",H10=0),"",Q10/H10) -> 0.090909091
A11: AC-3 室内機 据付 | C11: 4方向天井カセット ツイン子機 (4HP) 脱衣室 | E11: 2 | F11: 台 | G11: =IF(L11="","",ROUND(L11*M11,-1)) -> 49500 | H11: =IF(G11="","",ROUND(E11*G11,0)) -> 99000 | I11: 本体は元請様支給 | J11: 6800 | K11: 38200 | L11: =J11+K11 -> 45000 | M11: =COEF -> 1.1 | N11: =E11*L11 -> 90000 | O11: =ROUND(E11*K11*M11,0) -> 84040 | P11: 図面カウント | Q11: =IF(H11="","",H11-N11) -> 9000 | R11: =IF(OR(H11="",H11=0),"",Q11/H11) -> 0.090909091
A12: AC-3 室外機 据付 | C12: 4HP 物干場側 | E12: 1 | F12: 台 | G12: =IF(L12="","",ROUND(L12*M12,-1)) -> 38500 | H12: =IF(G12="","",ROUND(E12*G12,0)) -> 38500 | I12: 本体は元請様支給 | J12: 5200 | K12: 29800 | L12: =J12+K12 -> 35000 | M12: =COEF -> 1.1 | N12: =E12*L12 -> 35000 | O12: =ROUND(E12*K12*M12,0) -> 32780 | P12: 図面カウント | Q12: =IF(H12="","",H12-N12) -> 3500 | R12: =IF(OR(H12="",H12=0),"",Q12/H12) -> 0.090909091
A13: AC-5 室内機 据付 | C13: 4方向天井カセット PA-P56U7HNB(2HP) ケア室・管理人室 | E13: 2 | F13: 台 | G13: =IF(L13="","",ROUND(L13*M13,-1)) -> 49500 | H13: =IF(G13="","",ROUND(E13*G13,0)) -> 99000 | I13: 本体は元請様支給 | J13: 6800 | K13: 38200 | L13: =J13+K13 -> 45000 | M13: =COEF -> 1.1 | N13: =E13*L13 -> 90000 | O13: =ROUND(E13*K13*M13,0) -> 84040 | P13: 図面カウント | Q13: =IF(H13="","",H13-N13) -> 9000 | R13: =IF(OR(H13="",H13=0),"",Q13/H13) -> 0.090909091
A14: AC-5 室外機 据付 | C14: 2HP | E14: 2 | F14: 台 | G14: =IF(L14="","",ROUND(L14*M14,-1)) -> 38500 | H14: =IF(G14="","",ROUND(E14*G14,0)) -> 77000 | I14: 本体は元請様支給 | J14: 5200 | K14: 29800 | L14: =J14+K14 -> 35000 | M14: =COEF -> 1.1 | N14: =E14*L14 -> 70000 | O14: =ROUND(E14*K14*M14,0) -> 65560 | P14: 図面カウント | Q14: =IF(H14="","",H14-N14) -> 7000 | R14: =IF(OR(H14="",H14=0),"",Q14/H14) -> 0.090909091
A15: AC-6 室内機 据付 | C15: 天吊形厨房用 PA-P140V7HNB(5HP) 厨房 | E15: 1 | F15: 台 | G15: =IF(L15="","",ROUND(L15*M15,-1)) -> 55000 | H15: =IF(G15="","",ROUND(E15*G15,0)) -> 55000 | I15: 本体は元請様支給 | J15: 7500 | K15: 42500 | L15: =J15+K15 -> 50000 | M15: =COEF -> 1.1 | N15: =E15*L15 -> 50000 | O15: =ROUND(E15*K15*M15,0) -> 46750 | P15: 図面カウント | Q15: =IF(H15="","",H15-N15) -> 5000 | R15: =IF(OR(H15="",H15=0),"",Q15/H15) -> 0.090909091
A16: AC-6 室外機 据付 | C16: 5HP | E16: 1 | F16: 台 | G16: =IF(L16="","",ROUND(L16*M16,-1)) -> 38500 | H16: =IF(G16="","",ROUND(E16*G16,0)) -> 38500 | I16: 本体は元請様支給 | J16: 5200 | K16: 29800 | L16: =J16+K16 -> 35000 | M16: =COEF -> 1.1 | N16: =E16*L16 -> 35000 | O16: =ROUND(E16*K16*M16,0) -> 32780 | P16: 図面カウント | Q16: =IF(H16="","",H16-N16) -> 3500 | R16: =IF(OR(H16="",H16=0),"",Q16/H16) -> 0.090909091
A17: AC-7 室内機 据付 | C17: 2方向天井カセット PA-P50L7HNB(1.8HP) 面談室 | E17: 1 | F17: 台 | G17: =IF(L17="","",ROUND(L17*M17,-1)) -> 49500 | H17: =IF(G17="","",ROUND(E17*G17,0)) -> 49500 | I17: 本体は元請様支給 | J17: 6800 | K17: 38200 | L17: =J17+K17 -> 45000 | M17: =COEF -> 1.1 | N17: =E17*L17 -> 45000 | O17: =ROUND(E17*K17*M17,0) -> 42020 | P17: 図面カウント | Q17: =IF(H17="","",H17-N17) -> 4500 | R17: =IF(OR(H17="",H17=0),"",Q17/H17) -> 0.090909091
A18: AC-7 室外機 据付 | C18: 1.8HP | E18: 1 | F18: 台 | G18: =IF(L18="","",ROUND(L18*M18,-1)) -> 38500 | H18: =IF(G18="","",ROUND(E18*G18,0)) -> 38500 | I18: 本体は元請様支給 | J18: 5200 | K18: 29800 | L18: =J18+K18 -> 35000 | M18: =COEF -> 1.1 | N18: =E18*L18 -> 35000 | O18: =ROUND(E18*K18*M18,0) -> 32780 | P18: 図面カウント | Q18: =IF(H18="","",H18-N18) -> 3500 | R18: =IF(OR(H18="",H18=0),"",Q18/H18) -> 0.090909091
A19: AC-8 室内機 据付 | C19: ビルトインダクト PA-P56FE7HNBC(2HP) 厨房 | E19: 1 | F19: 台 | G19: =IF(L19="","",ROUND(L19*M19,-1)) -> 55000 | H19: =IF(G19="","",ROUND(E19*G19,0)) -> 55000 | I19: 本体は元請様支給 | J19: 7500 | K19: 42500 | L19: =J19+K19 -> 50000 | M19: =COEF -> 1.1 | N19: =E19*L19 -> 50000 | O19: =ROUND(E19*K19*M19,0) -> 46750 | P19: 図面カウント | Q19: =IF(H19="","",H19-N19) -> 5000 | R19: =IF(OR(H19="",H19=0),"",Q19/H19) -> 0.090909091 | S19: ダクト・制気口は A-4 に計上
A20: AC-8 室外機 据付 | C20: 2HP | E20: 1 | F20: 台 | G20: =IF(L20="","",ROUND(L20*M20,-1)) -> 38500 | H20: =IF(G20="","",ROUND(E20*G20,0)) -> 38500 | I20: 本体は元請様支給 | J20: 5200 | K20: 29800 | L20: =J20+K20 -> 35000 | M20: =COEF -> 1.1 | N20: =E20*L20 -> 35000 | O20: =ROUND(E20*K20*M20,0) -> 32780 | P20: 図面カウント | Q20: =IF(H20="","",H20-N20) -> 3500 | R20: =IF(OR(H20="",H20=0),"",Q20/H20) -> 0.090909091
A21: AC-9 室内機 据付 | C21: 天吊形厨房用 PA-P80V7HNB(3HP) 弁当室 | E21: 1 | F21: 台 | G21: =IF(L21="","",ROUND(L21*M21,-1)) -> 55000 | H21: =IF(G21="","",ROUND(E21*G21,0)) -> 55000 | I21: 本体は元請様支給 | J21: 7500 | K21: 42500 | L21: =J21+K21 -> 50000 | M21: =COEF -> 1.1 | N21: =E21*L21 -> 50000 | O21: =ROUND(E21*K21*M21,0) -> 46750 | P21: 図面カウント | Q21: =IF(H21="","",H21-N21) -> 5000 | R21: =IF(OR(H21="",H21=0),"",Q21/H21) -> 0.090909091
A22: AC-9 室外機 据付 | C22: 3HP | E22: 1 | F22: 台 | G22: =IF(L22="","",ROUND(L22*M22,-1)) -> 38500 | H22: =IF(G22="","",ROUND(E22*G22,0)) -> 38500 | I22: 本体は元請様支給 | J22: 5200 | K22: 29800 | L22: =J22+K22 -> 35000 | M22: =COEF -> 1.1 | N22: =E22*L22 -> 35000 | O22: =ROUND(E22*K22*M22,0) -> 32780 | P22: 図面カウント | Q22: =IF(H22="","",H22-N22) -> 3500 | R22: =IF(OR(H22="",H22=0),"",Q22/H22) -> 0.090909091
A23: AC-10 室内機 据付 | C23: 4方向天井カセット PA-P140U7HNB(5HP) 2F多目的スペース | E23: 1 | F23: 台 | G23: =IF(L23="","",ROUND(L23*M23,-1)) -> 49500 | H23: =IF(G23="","",ROUND(E23*G23,0)) -> 49500 | I23: 本体は元請様支給 | J23: 6800 | K23: 38200 | L23: =J23+K23 -> 45000 | M23: =COEF -> 1.1 | N23: =E23*L23 -> 45000 | O23: =ROUND(E23*K23*M23,0) -> 42020 | P23: 図面カウント | Q23: =IF(H23="","",H23-N23) -> 4500 | R23: =IF(OR(H23="",H23=0),"",Q23/H23) -> 0.090909091
A24: AC-10 室外機 据付 | C24: 5HP 1F地上(中庭2西側) | E24: 1 | F24: 台 | G24: =IF(L24="","",ROUND(L24*M24,-1)) -> 38500 | H24: =IF(G24="","",ROUND(E24*G24,0)) -> 38500 | I24: 本体は元請様支給 | J24: 5200 | K24: 29800 | L24: =J24+K24 -> 35000 | M24: =COEF -> 1.1 | N24: =E24*L24 -> 35000 | O24: =ROUND(E24*K24*M24,0) -> 32780 | P24: 図面カウント | Q24: =IF(H24="","",H24-N24) -> 3500 | R24: =IF(OR(H24="",H24=0),"",Q24/H24) -> 0.090909091
A25: RAC-1 据付 | C25: 壁掛ルームエアコン XCS-255DGX-W 内外機・ドレンアップ共 洗浄室・休憩室 | E25: 2 | F25: 組 | G25: =IF(L25="","",ROUND(L25*M25,-1)) -> 30800 | H25: =IF(G25="","",ROUND(E25*G25,0)) -> 61600 | I25: 本体は元請様支給 | J25: 4200 | K25: 23800 | L25: =J25+K25 -> 28000 | M25: =COEF -> 1.1 | N25: =E25*L25 -> 56000 | O25: =ROUND(E25*K25*M25,0) -> 52360 | P25: 図面カウント | Q25: =IF(H25="","",H25-N25) -> 5600 | R25: =IF(OR(H25="",H25=0),"",Q25/H25) -> 0.090909091 | S25: 屋外機架台支給
A26: RAC-2 据付 | C26: 壁掛ルームエアコン XCS-405DGX-W 内外機・ドレンアップ共 来客室・和室・洋室・DK | E26: 8 | F26: 組 | G26: =IF(L26="","",ROUND(L26*M26,-1)) -> 30800 | H26: =IF(G26="","",ROUND(E26*G26,0)) -> 246400 | I26: 本体は元請様支給 | J26: 4200 | K26: 23800 | L26: =J26+K26 -> 28000 | M26: =COEF -> 1.1 | N26: =E26*L26 -> 224000 | O26: =ROUND(E26*K26*M26,0) -> 209440 | P26: 図面カウント | Q26: =IF(H26="","",H26-N26) -> 22400 | R26: =IF(OR(H26="",H26=0),"",Q26/H26) -> 0.090909091 | S26: 屋外機架台(2段)支給
A27: RAC-3 据付 | C27: 壁掛ルームエアコン XCS-405DGX2-W 内外機 2F寮室・予備室・コーチ宿泊室 | E27: 66 | F27: 組 | G27: =IF(L27="","",ROUND(L27*M27,-1)) -> 27500 | H27: =IF(G27="","",ROUND(E27*G27,0)) -> 1815000 | I27: 本体は元請様支給 | J27: 3800 | K27: 21200 | L27: =J27+K27 -> 25000 | M27: =COEF -> 1.1 | N27: =E27*L27 -> 1650000 | O27: =ROUND(E27*K27*M27,0) -> 1539120 | P27: 図面カウント | Q27: =IF(H27="","",H27-N27) -> 165000 | R27: =IF(OR(H27="",H27=0),"",Q27/H27) -> 0.090909091 | S27: 屋外機はバルコニー2段架台(支給)
A28: RAC-4 据付 | C28: 壁掛ルームエアコン XCS-635DGX2-W 内外機 2F寮務スタッフ室 | E28: 1 | F28: 組 | G28: =IF(L28="","",ROUND(L28*M28,-1)) -> 30800 | H28: =IF(G28="","",ROUND(E28*G28,0)) -> 30800 | I28: 本体は元請様支給 | J28: 4200 | K28: 23800 | L28: =J28+K28 -> 28000 | M28: =COEF -> 1.1 | N28: =E28*L28 -> 28000 | O28: =ROUND(E28*K28*M28,0) -> 26180 | P28: 図面カウント | Q28: =IF(H28="","",H28-N28) -> 2800 | R28: =IF(OR(H28="",H28=0),"",Q28/H28) -> 0.090909091
A29: CR-1 集中リモコン 取付 | C29: CZ-10ESM5・CZ-10ESW4 管理人室 | E29: 1 | F29: 台 | G29: =IF(L29="","",ROUND(L29*M29,-1)) -> 16500 | H29: =IF(G29="","",ROUND(E29*G29,0)) -> 16500 | J29: 6000 | K29: 9000 | L29: =J29+K29 -> 15000 | M29: =COEF -> 1.1 | N29: =E29*L29 -> 15000 | O29: =ROUND(E29*K29*M29,0) -> 9900 | P29: 図面カウント | Q29: =IF(H29="","",H29-N29) -> 1500 | R29: =IF(OR(H29="",H29=0),"",Q29/H29) -> 0.090909091 | S29: 配線は A-4
A30: 機器搬入・揚重・養生 | C30: PAC 32台・RAC 154台分 | E30: 1 | F30: 式 | G30: =IF(L30="","",ROUND(L30*M30,-1)) -> 275000 | H30: =IF(G30="","",ROUND(E30*G30,0)) -> 275000 | I30: 想定数量（別紙条件書） | J30: 25000 | K30: 225000 | L30: =J30+K30 -> 250000 | M30: =COEF -> 1.1 | N30: =E30*L30 -> 250000 | O30: =ROUND(E30*K30*M30,0) -> 247500 | P30: 推測 | Q30: =IF(H30="","",H30-N30) -> 25000 | R30: =IF(OR(H30="",H30=0),"",Q30/H30) -> 0.090909091
A31: （2）冷媒配管
A32: 冷媒配管 ① | C32: 被覆銅管 9.52/6.35 (RAC-1,2 1F 及び RAC-3 2F) | E32: 360 | F32: m | G32: =IF(L32="","",ROUND(L32*M32,-1)) -> 4950 | H32: =IF(G32="","",ROUND(E32*G32,0)) -> 1782000 | I32: 図面実測＋想定（別紙） | J32: 2500 | K32: 2000 | L32: =J32+K32 -> 4500 | M32: =COEF -> 1.1 | N32: =E32*L32 -> 1620000 | O32: =ROUND(E32*K32*M32,0) -> 792000 | P32: 実測+推測 | Q32: =IF(H32="","",H32-N32) -> 162000 | R32: =IF(OR(H32="",H32=0),"",Q32/H32) -> 0.090909091 | S32: 平面実測34.3m＋推測(RAC-3 66台×4m、来客室RAC-2 5台×4m、RAC-1補正8m、立上り10台×3m)
A33: 冷媒配管 ② | C33: 被覆銅管 12.7/6.35 (AC-5,7,8 AC-3枝 RAC-4) | E33: 77 | F33: m | G33: =IF(L33="","",ROUND(L33*M33,-1)) -> 5720 | H33: =IF(G33="","",ROUND(E33*G33,0)) -> 440440 | I33: 図面実測＋想定（別紙） | J33: 2900 | K33: 2300 | L33: =J33+K33 -> 5200 | M33: =COEF -> 1.1 | N33: =E33*L33 -> 400400 | O33: =ROUND(E33*K33*M33,0) -> 194810 | P33: 実測+推測 | Q33: =IF(H33="","",H33-N33) -> 40040 | R33: =IF(OR(H33="",H33=0),"",Q33/H33) -> 0.090909091 | S33: 平面実測56m＋推測(立上り4系統×4m、RAC-4 5m)
A34: 冷媒配管 ③ | C34: 被覆銅管 15.88/9.52 (AC-1/2枝 AC-3主 AC-6,9,10) | E34: 96 | F34: m | G34: =IF(L34="","",ROUND(L34*M34,-1)) -> 7150 | H34: =IF(G34="","",ROUND(E34*G34,0)) -> 686400 | I34: 図面実測＋想定（別紙） | J34: 3600 | K34: 2900 | L34: =J34+K34 -> 6500 | M34: =COEF -> 1.1 | N34: =E34*L34 -> 624000 | O34: =ROUND(E34*K34*M34,0) -> 306240 | P34: 実測+推測 | Q34: =IF(H34="","",H34-N34) -> 62400 | R34: =IF(OR(H34="",H34=0),"",Q34/H34) -> 0.090909091 | S34: 平面実測72.2m＋推測(立上り3系統×4m、AC-10 2F分3.5m＋立管8m)
A35: 冷媒配管 ⑥ | C35: 被覆銅管 25.4/9.52 (AC-2主管) | E35: 9 | F35: m | G35: =IF(L35="","",ROUND(L35*M35,-1)) -> 10450 | H35: =IF(G35="","",ROUND(E35*G35,0)) -> 94050 | I35: 図面実測＋想定（別紙） | J35: 5200 | K35: 4300 | L35: =J35+K35 -> 9500 | M35: =COEF -> 1.1 | N35: =E35*L35 -> 85500 | O35: =ROUND(E35*K35*M35,0) -> 42570 | P35: 実測+推測 | Q35: =IF(H35="","",H35-N35) -> 8550 | R35: =IF(OR(H35="",H35=0),"",Q35/H35) -> 0.090909091 | S35: 平面実測5m＋立上り4m
A36: 冷媒配管 ⑦ | C36: 被覆銅管 25.4/12.7 (AC-1主管 4系統) | E36: 57 | F36: m | G36: =IF(L36="","",ROUND(L36*M36,-1)) -> 11550 | H36: =IF(G36="","",ROUND(E36*G36,0)) -> 658350 | I36: 図面実測＋想定（別紙） | J36: 5800 | K36: 4700 | L36: =J36+K36 -> 10500 | M36: =COEF -> 1.1 | N36: =E36*L36 -> 598500 | O36: =ROUND(E36*K36*M36,0) -> 294690 | P36: 実測+推測 | Q36: =IF(H36="","",H36-N36) -> 59850 | R36: =IF(OR(H36="",H36=0),"",Q36/H36) -> 0.090909091 | S36: 平面実測41m＋立上り4系統×4m
A37: 冷媒配管 化粧ケース | C37: 屋外・屋内露出部 (管種凡例: 露出管は化粧ケース仕上) | E37: 125 | F37: m | G37: =IF(L37="","",ROUND(L37*M37,-1)) -> 3300 | H37: =IF(G37="","",ROUND(E37*G37,0)) -> 412500 | I37: 想定数量（別紙条件書） | J37: 1800 | K37: 1200 | L37: =J37+K37 -> 3000 | M37: =COEF -> 1.1 | N37: =E37*L37 -> 375000 | O37: =ROUND(E37*K37*M37,0) -> 165000 | P37: 推測 | Q37: =IF(H37="","",H37-N37) -> 37500 | R37: =IF(OR(H37="",H37=0),"",Q37/H37) -> 0.090909091 | S37: PAC13+RAC1F10箇所×2.5m、RAC-3/4 67台×1.0m
A38: 外壁貫通スリーブ材 | C38: VP100 冷媒・ドレン用 (穴明けは建築工事) | E38: 90 | F38: 箇所 | G38: =IF(L38="","",ROUND(L38*M38,-1)) -> 2750 | H38: =IF(G38="","",ROUND(E38*G38,0)) -> 247500 | I38: 想定数量（別紙条件書） | J38: 1300 | K38: 1200 | L38: =J38+K38 -> 2500 | M38: =COEF -> 1.1 | N38: =E38*L38 -> 225000 | O38: =ROUND(E38*K38*M38,0) -> 118800 | P38: 推測 | Q38: =IF(H38="","",H38-N38) -> 22500 | R38: =IF(OR(H38="",H38=0),"",Q38/H38) -> 0.090909091 | S38: RAC77＋PAC13
A39: 区画貫通処理 | C39: 冷媒管 フィブロック(認定工法) | E39: 2 | F39: 箇所 | G39: =IF(L39="","",ROUND(L39*M39,-1)) -> 13200 | H39: =IF(G39="","",ROUND(E39*G39,0)) -> 26400 | I39: 図面実測数量 | J39: 6000 | K39: 6000 | L39: =J39+K39 -> 12000 | M39: =COEF -> 1.1 | N39: =E39*L39 -> 24000 | O39: =ROUND(E39*K39*M39,0) -> 13200 | P39: 実測 | Q39: =IF(H39="","",H39-N39) -> 2400 | R39: =IF(OR(H39="",H39=0),"",Q39/H39) -> 0.090909091 | S39: 空調平面図1F ●区画貫通部 2箇所
A40: 気密試験・真空引き・冷媒追加充填 作業 | C40: PAC 系統毎 | E40: 13 | F40: 系統 | G40: =IF(L40="","",ROUND(L40*M40,-1)) -> 16500 | H40: =IF(G40="","",ROUND(E40*G40,0)) -> 214500 | J40: 13500 | K40: 1500 | L40: =J40+K40 -> 15000 | M40: =COEF -> 1.1 | N40: =E40*L40 -> 195000 | O40: =ROUND(E40*K40*M40,0) -> 21450 | P40: 図面カウント | Q40: =IF(H40="","",H40-N40) -> 19500 | R40: =IF(OR(H40="",H40=0),"",Q40/H40) -> 0.090909091
A41: 冷媒追加充填 (冷媒代) | C41: R32/R410A | E41: 8 | F41: kg | G41: =IF(L41="","",ROUND(L41*M41,-1)) -> 6600 | H41: =IF(G41="","",ROUND(E41*G41,0)) -> 52800 | I41: 想定数量（別紙条件書） | J41: 5400 | K41: 600 | L41: =J41+K41 -> 6000 | M41: =COEF -> 1.1 | N41: =E41*L41 -> 48000 | O41: =ROUND(E41*K41*M41,0) -> 5280 | P41: 推測 | Q41: =IF(H41="","",H41-N41) -> 4800 | R41: =IF(OR(H41="",H41=0),"",Q41/H41) -> 0.090909091 | S41: 配管延長より約20g/m換算
...

Sheet 内訳書(2.換気工事)
A1: 内 訳 書 | J1: 原 価 内 訳 書（内部用・印刷範囲外）
A2: 工事名：（仮称）サンフレッチェ広島 三矢寮新築工事 空調設備工事 | I2: 内訳書 No.2
A3: 名 称 | C3: 規格・寸法 | E3: 数 量 | F3: 単位 | G3: 単 価 | H3: 金 額 | I3: 備 考 | J3: 材料単価 | K3: 労務単価 | L3: 基準単価 | M3: 提出係数 | N3: 基準原価 | O3: 労務費(提出) | P3: 数量根拠 | Q3: 粗利 | R3: 粗利率 | S3: 前提・メモ（内部）
A4: ２．換気工事（機械設備図 06）
A6: （1）換気機器据付（機器は元請様支給）
A7: FE-A1 パイプファン 据付 | C7: V-12PS8 150φ ゴミ庫1・倉庫1 | E7: 2 | F7: 台 | G7: =IF(L7="","",ROUND(L7*M7,-1)) -> 8800 | H7: =IF(G7="","",ROUND(E7*G7,0)) -> 17600 | I7: 本体は元請様支給 | J7: 1200 | K7: 6800 | L7: =J7+K7 -> 8000 | M7: =COEF -> 1.1 | N7: =E7*L7 -> 16000 | O7: =ROUND(E7*K7*M7,0) -> 14960 | P7: 図面カウント | Q7: =IF(H7="","",H7-N7) -> 1600 | R7: =IF(OR(H7="",H7=0),"",Q7/H7) -> 0.090909091
A8: FE-A2 天井扇 据付 | C8: VD-15ZC14 100φ 管理人和室洋室クローク・面談室 | E8: 2 | F8: 台 | G8: =IF(L8="","",ROUND(L8*M8,-1)) -> 13200 | H8: =IF(G8="","",ROUND(E8*G8,0)) -> 26400 | I8: 本体は元請様支給 | J8: 1800 | K8: 10200 | L8: =J8+K8 -> 12000 | M8: =COEF -> 1.1 | N8: =E8*L8 -> 24000 | O8: =ROUND(E8*K8*M8,0) -> 22440 | P8: 図面カウント | Q8: =IF(H8="","",H8-N8) -> 2400 | R8: =IF(OR(H8="",H8=0),"",Q8/H8) -> 0.090909091
A9: FE-A3 天井扇 据付 | C9: VD-10ZC14 管理人WC | E9: 1 | F9: 台 | G9: =IF(L9="","",ROUND(L9*M9,-1)) -> 13200 | H9: =IF(G9="","",ROUND(E9*G9,0)) -> 13200 | I9: 本体は元請様支給 | J9: 1800 | K9: 10200 | L9: =J9+K9 -> 12000 | M9: =COEF -> 1.1 | N9: =E9*L9 -> 12000 | O9: =ROUND(E9*K9*M9,0) -> 11220 | P9: 図面カウント | Q9: =IF(H9="","",H9-N9) -> 1200 | R9: =IF(OR(H9="",H9=0),"",Q9/H9) -> 0.090909091
A10: FE-A4 親子扇 据付 | C10: VD-10ZFC14 管理人洗面UB | E10: 1 | F10: 台 | G10: =IF(L10="","",ROUND(L10*M10,-1)) -> 15400 | H10: =IF(G10="","",ROUND(E10*G10,0)) -> 15400 | I10: 本体は元請様支給 | J10: 2100 | K10: 11900 | L10: =J10+K10 -> 14000 | M10: =COEF -> 1.1 | N10: =E10*L10 -> 14000 | O10: =ROUND(E10*K10*M10,0) -> 13090 | P10: 図面カウント | Q10: =IF(H10="","",H10-N10) -> 1400 | R10: =IF(OR(H10="",H10=0),"",Q10/H10) -> 0.090909091
A11: FE-A5 天井扇 据付 | C11: VD-15ZC14 管理人室 | E11: 2 | F11: 台 | G11: =IF(L11="","",ROUND(L11*M11,-1)) -> 13200 | H11: =IF(G11="","",ROUND(E11*G11,0)) -> 26400 | I11: 本体は元請様支給 | J11: 1800 | K11: 10200 | L11: =J11+K11 -> 12000 | M11: =COEF -> 1.1 | N11: =E11*L11 -> 24000 | O11: =ROUND(E11*K11*M11,0) -> 22440 | P11: 図面カウント | Q11: =IF(H11="","",H11-N11) -> 2400 | R11: =IF(OR(H11="",H11=0),"",Q11/H11) -> 0.090909091
A12: FE-A6 中間ファン 据付 | C12: BFS-50SYA2 200φ 1階男性WC | E12: 1 | F12: 台 | G12: =IF(L12="","",ROUND(L12*M12,-1)) -> 38500 | H12: =IF(G12="","",ROUND(E12*G12,0)) -> 38500 | I12: 本体は元請様支給 | J12: 5200 | K12: 29800 | L12: =J12+K12 -> 35000 | M12: =COEF -> 1.1 | N12: =E12*L12 -> 35000 | O12: =ROUND(E12*K12*M12,0) -> 32780 | P12: 図面カウント | Q12: =IF(H12="","",H12-N12) -> 3500 | R12: =IF(OR(H12="",H12=0),"",Q12/H12) -> 0.090909091 | S12: 防振吊金具共
A13: FE-A7 天井扇 据付 | C13: VD-17ZSC14 1階多目的WC | E13: 1 | F13: 台 | G13: =IF(L13="","",ROUND(L13*M13,-1)) -> 13200 | H13: =IF(G13="","",ROUND(E13*G13,0)) -> 13200 | I13: 本体は元請様支給 | J13: 1800 | K13: 10200 | L13: =J13+K13 -> 12000 | M13: =COEF -> 1.1 | N13: =E13*L13 -> 12000 | O13: =ROUND(E13*K13*M13,0) -> 11220 | P13: 図面カウント | Q13: =IF(H13="","",H13-N13) -> 1200 | R13: =IF(OR(H13="",H13=0),"",Q13/H13) -> 0.090909091
A14: FE-B1 天井扇 据付 | C14: VD-17ZSC14 シューズロッカー・洗い場 | E14: 2 | F14: 台 | G14: =IF(L14="","",ROUND(L14*M14,-1)) -> 13200 | H14: =IF(G14="","",ROUND(E14*G14,0)) -> 26400 | I14: 本体は元請様支給 | J14: 1800 | K14: 10200 | L14: =J14+K14 -> 12000 | M14: =COEF -> 1.1 | N14: =E14*L14 -> 24000 | O14: =ROUND(E14*K14*M14,0) -> 22440 | P14: 図面カウント | Q14: =IF(H14="","",H14-N14) -> 2400 | R14: =IF(OR(H14="",H14=0),"",Q14/H14) -> 0.090909091
A15: FE-B2 天井扇 据付 | C15: VD-23ZB13 洗濯室 | E15: 2 | F15: 台 | G15: =IF(L15="","",ROUND(L15*M15,-1)) -> 15400 | H15: =IF(G15="","",ROUND(E15*G15,0)) -> 30800 | I15: 本体は元請様支給 | J15: 2100 | K15: 11900 | L15: =J15+K15 -> 14000 | M15: =COEF -> 1.1 | N15: =E15*L15 -> 28000 | O15: =ROUND(E15*K15*M15,0) -> 26180 | P15: 図面カウント | Q15: =IF(H15="","",H15-N15) -> 2800 | R15: =IF(OR(H15="",H15=0),"",Q15/H15) -> 0.090909091
A16: FE-B3 有圧扇 据付 | C16: EF-25ASXC2 浴室 ウェザーカバー共 | E16: 2 | F16: 台 | G16: =IF(L16="","",ROUND(L16*M16,-1)) -> 27500 | H16: =IF(G16="","",ROUND(E16*G16,0)) -> 55000 | I16: 本体は元請様支給 | J16: 2500 | K16: 22500 | L16: =J16+K16 -> 25000 | M16: =COEF -> 1.1 | N16: =E16*L16 -> 50000 | O16: =ROUND(E16*K16*M16,0) -> 49500 | P16: 図面カウント | Q16: =IF(H16="","",H16-N16) -> 5000 | R16: =IF(OR(H16="",H16=0),"",Q16/H16) -> 0.090909091
A17: FE-B4 中間ファン 据付 | C17: BFS-50SYA2 脱衣室・前室 | E17: 1 | F17: 台 | G17: =IF(L17="","",ROUND(L17*M17,-1)) -> 38500 | H17: =IF(G17="","",ROUND(E17*G17,0)) -> 38500 | I17: 本体は元請様支給 | J17: 5200 | K17: 29800 | L17: =J17+K17 -> 35000 | M17: =COEF -> 1.1 | N17: =E17*L17 -> 35000 | O17: =ROUND(E17*K17*M17,0) -> 32780 | P17: 図面カウント | Q17: =IF(H17="","",H17-N17) -> 3500 | R17: =IF(OR(H17="",H17=0),"",Q17/H17) -> 0.090909091
A18: FE-C1 パイプファン 据付 | C18: V-08PPX8 厨房WC・休憩室・段ボール庫・ゴミ庫2 | E18: 4 | F18: 台 | G18: =IF(L18="","",ROUND(L18*M18,-1)) -> 8800 | H18: =IF(G18="","",ROUND(E18*G18,0)) -> 35200 | I18: 本体は元請様支給 | J18: 1200 | K18: 6800 | L18: =J18+K18 -> 8000 | M18: =COEF -> 1.1 | N18: =E18*L18 -> 32000 | O18: =ROUND(E18*K18*M18,0) -> 29920 | P18: 図面カウント | Q18: =IF(H18="","",H18-N18) -> 3200 | R18: =IF(OR(H18="",H18=0),"",Q18/H18) -> 0.090909091
A19: FE-C2 パイプファン 据付 | C19: V-08PP8 厨房前室 | E19: 1 | F19: 台 | G19: =IF(L19="","",ROUND(L19*M19,-1)) -> 8800 | H19: =IF(G19="","",ROUND(E19*G19,0)) -> 8800 | I19: 本体は元請様支給 | J19: 1200 | K19: 6800 | L19: =J19+K19 -> 8000 | M19: =COEF -> 1.1 | N19: =E19*L19 -> 8000 | O19: =ROUND(E19*K19*M19,0) -> 7480 | P19: 図面カウント | Q19: =IF(H19="","",H19-N19) -> 800 | R19: =IF(OR(H19="",H19=0),"",Q19/H19) -> 0.090909091
A20: FE-C3 天井扇 据付 | C20: VD-15ZC14 冷蔵庫室 | E20: 1 | F20: 台 | G20: =IF(L20="","",ROUND(L20*M20,-1)) -> 13200 | H20: =IF(G20="","",ROUND(E20*G20,0)) -> 13200 | I20: 本体は元請様支給 | J20: 1800 | K20: 10200 | L20: =J20+K20 -> 12000 | M20: =COEF -> 1.1 | N20: =E20*L20 -> 12000 | O20: =ROUND(E20*K20*M20,0) -> 11220 | P20: 図面カウント | Q20: =IF(H20="","",H20-N20) -> 1200 | R20: =IF(OR(H20="",H20=0),"",Q20/H20) -> 0.090909091
A21: FE-C4 天井扇 据付 | C21: VD-17ZSC14 食品庫・弁当室 | E21: 2 | F21: 台 | G21: =IF(L21="","",ROUND(L21*M21,-1)) -> 13200 | H21: =IF(G21="","",ROUND(E21*G21,0)) -> 26400 | I21: 本体は元請様支給 | J21: 1800 | K21: 10200 | L21: =J21+K21 -> 12000 | M21: =COEF -> 1.1 | N21: =E21*L21 -> 24000 | O21: =ROUND(E21*K21*M21,0) -> 22440 | P21: 図面カウント | Q21: =IF(H21="","",H21-N21) -> 2400 | R21: =IF(OR(H21="",H21=0),"",Q21/H21) -> 0.090909091
A22: FE-C5 天井扇 据付 | C22: VD-13ZC14 厨房廊下 | E22: 1 | F22: 台 | G22: =IF(L22="","",ROUND(L22*M22,-1)) -> 13200 | H22: =IF(G22="","",ROUND(E22*G22,0)) -> 13200 | I22: 本体は元請様支給 | J22: 1800 | K22: 10200 | L22: =J22+K22 -> 12000 | M22: =COEF -> 1.1 | N22: =E22*L22 -> 12000 | O22: =ROUND(E22*K22*M22,0) -> 11220 | P22: 図面カウント | Q22: =IF(H22="","",H22-N22) -> 1200 | R22: =IF(OR(H22="",H22=0),"",Q22/H22) -> 0.090909091
A23: FE-D1 親子扇 据付 | C23: VD-10ZFC14 来客室UB | E23: 5 | F23: 台 | G23: =IF(L23="","",ROUND(L23*M23,-1)) -> 15400 | H23: =IF(G23="","",ROUND(E23*G23,0)) -> 77000 | I23: 本体は元請様支給 | J23: 2100 | K23: 11900 | L23: =J23+K23 -> 14000 | M23: =COEF -> 1.1 | N23: =E23*L23 -> 70000 | O23: =ROUND(E23*K23*M23,0) -> 65450 | P23: 図面カウント | Q23: =IF(H23="","",H23-N23) -> 7000 | R23: =IF(OR(H23="",H23=0),"",Q23/H23) -> 0.090909091
A24: FE-D2 有圧扇 据付 | C24: ENF-20YSA2 倉庫2 ウェザーカバー共 | E24: 1 | F24: 台 | G24: =IF(L24="","",ROUND(L24*M24,-1)) -> 27500 | H24: =IF(G24="","",ROUND(E24*G24,0)) -> 27500 | I24: 本体は元請様支給 | J24: 2500 | K24: 22500 | L24: =J24+K24 -> 25000 | M24: =COEF -> 1.1 | N24: =E24*L24 -> 25000 | O24: =ROUND(E24*K24*M24,0) -> 24750 | P24: 図面カウント | Q24: =IF(H24="","",H24-N24) -> 2500 | R24: =IF(OR(H24="",H24=0),"",Q24/H24) -> 0.090909091
... A32: FE-E6 親子扇 据付 | C32: VD-10ZFC14 寮務スタッフ室UB | E32: 1 | F32: 台 | G32: =IF(L32="","",ROUND(L32*M32,-1)) -> 15400 | H32: =IF(G32="","",ROUND(E32*G32,0)) -> 15400 | I32: 本体は元請様支給 | J32: 2100 | K32: 11900 | L32: =J32+K32 -> 14000 | M32: =COEF -> 1.1 | N32: =E32*L32 -> 14000 | O32: =ROUND(E32*K32*M32,0) -> 13090 | P32: 図面カウント | Q32: =IF(H32="","",H32-N32) -> 1400 | R32: =IF(OR(H32="",H32=0),"",Q32/H32) -> 0.090909091
A33: HEX-1 全熱交換器 据付 | C33: LGH-N80RXV2 天井埋込 食堂 リモコン共 | E33: 1 | F33: 台 | G33: =IF(L33="","",ROUND(L33*M33,-1)) -> 49500 | H33: =IF(G33="","",ROUND(E33*G33,0)) -> 49500 | I33: 本体は元請様支給 | J33: 18000 | K33: 27000 | L33: =J33+K33 -> 45000 | M33: =COEF -> 1.1 | N33: =E33*L33 -> 45000 | O33: =ROUND(E33*K33*M33,0) -> 29700 | P33: 図面カウント | Q33: =IF(H33="","",H33-N33) -> 4500 | R33: =IF(OR(H33="",H33=0),"",Q33/H33) -> 0.090909091 | S33: 08にて中止→C-1で減額
A34: HEX-2 全熱交換器 据付 | C34: LGH-N65RXW2 天井埋込 ミーティングルーム | E34: 1 | F34: 台 | G34: =IF(L34="","",ROUND(L34*M34,-1)) -> 49500 | H34: =IF(G34="","",ROUND(E34*G34,0)) -> 49500 | I34: 本体は元請様支給 | J34: 6800 | K34: 38200 | L34: =J34+K34 -> 45000 | M34: =COEF -> 1.1 | N34: =E34*L34 -> 45000 | O34: =ROUND(E34*K34*M34,0) -> 42020 | P34: 図面カウント | Q34: =IF(H34="","",H34-N34) -> 4500 | R34: =IF(OR(H34="",H34=0),"",Q34/H34) -> 0.090909091 | S34: 08にて中止→C-1で減額
A35: HEX-3 全熱交換器 据付 | C35: SKU-50AC 天井カセット コーチルーム・トレーニングルーム | E35: 4 | F35: 台 | G35: =IF(L35="","",ROUND(L35*M35,-1)) -> 44000 | H35: =IF(G35="","",ROUND(E35*G35,0)) -> 176000 | I35: 本体は元請様支給 | J35: 6000 | K35: 34000 | L35: =J35+K35 -> 40000 | M35: =COEF -> 1.1 | N35: =E35*L35 -> 160000 | O35: =ROUND(E35*K35*M35,0) -> 149600 | P35: 図面カウント | Q35: =IF(H35="","",H35-N35) -> 16000 | R35: =IF(OR(H35="",H35=0),"",Q35/H35) -> 0.090909091 | S35: 08にて中止→C-1で減額
A36: HEX-4 壁掛ロスナイ 据付 | C36: VL-10ES3 来客室・寮室(南)・寮務スタッフ室 | E36: 46 | F36: 台 | G36: =IF(L36="","",ROUND(L36*M36,-1)) -> 13200 | H36: =IF(G36="","",ROUND(E36*G36,0)) -> 607200 | I36: 本体は元請様支給 | J36: 1800 | K36: 10200 | L36: =J36+K36 -> 12000 | M36: =COEF -> 1.1 | N36: =E36*L36 -> 552000 | O36: =ROUND(E36*K36*M36,0) -> 516120 | P36: 図面カウント | Q36: =IF(H36="","",H36-N36) -> 55200 | R36: =IF(OR(H36="",H36=0),"",Q36/H36) -> 0.090909091 | S36: 08にて中止→C-1で減額
A37: HEX-5 壁掛ロスナイ 据付 | C37: VL-12ESH3 寮室(北) | E37: 27 | F37: 台 | G37: =IF(L37="","",ROUND(L37*M37,-1)) -> 13200 | H37: =IF(G37="","",ROUND(E37*G37,0)) -> 356400 | I37: 本体は元請様支給 | J37: 1800 | K37: 10200 | L37: =J37+K37 -> 12000 | M37: =COEF -> 1.1 | N37: =E37*L37 -> 324000 | O37: =ROUND(E37*K37*M37,0) -> 302940 | P37: 図面カウント | Q37: =IF(H37="","",H37-N37) -> 32400 | R37: =IF(OR(H37="",H37=0),"",Q37/H37) -> 0.090909091 | S37: 08にて中止→C-1で減額
A38: F-1 中間ファン 据付 | C38: BFS-80SXA2 厨房用 洗浄室 | E38: 1 | F38: 台 | G38: =IF(L38="","",ROUND(L38*M38,-1)) -> 38500 | H38: =IF(G38="","",ROUND(E38*G38,0)) -> 38500 | I38: 本体は元請様支給 | J38: 5200 | K38: 29800 | L38: =J38+K38 -> 35000 | M38: =COEF -> 1.1 | N38: =E38*L38 -> 35000 | O38: =ROUND(E38*K38*M38,0) -> 32780 | P38: 図面カウント | Q38: =IF(H38="","",H38-N38) -> 3500 | R38: =IF(OR(H38="",H38=0),"",Q38/H38) -> 0.090909091
A39: F-2 中間ファン 据付 | C39: BFS-150SXA2 厨房用 厨房 | E39: 1 | F39: 台 | G39: =IF(L39="","",ROUND(L39*M39,-1)) -> 44000 | H39: =IF(G39="","",ROUND(E39*G39,0)) -> 44000 | I39: 本体は元請様支給 | J39: 6000 | K39: 34000 | L39: =J39+K39 -> 40000 | M39: =COEF -> 1.1 | N39: =E39*L39 -> 40000 | O39: =ROUND(E39*K39*M39,0) -> 37400 | P39: 図面カウント | Q39: =IF(H39="","",H39-N39) -> 4000 | R39: =IF(OR(H39="",H39=0),"",Q39/H39) -> 0.090909091
A40: F-3 有圧扇 据付 | C40: EF-30BSXC2-HC 厨房 ウェザーカバー・リモコン共 | E40: 3 | F40: 台 | G40: =IF(L40="","",ROUND(L40*M40,-1)) -> 30800 | H40: =IF(G40="","",ROUND(E40*G40,0)) -> 92400 | I40: 本体は元請様支給 | J40: 2800 | K40: 25200 | L40: =J40+K40 -> 28000 | M40: =COEF -> 1.1 | N40: =E40*L40 -> 84000 | O40: =ROUND(E40*K40*M40,0) -> 83160 | P40: 図面カウント | Q40: =IF(H40="","",H40-N40) -> 8400 | R40: =IF(OR(H40="",H40=0),"",Q40/H40) -> 0.090909091
A41: F-4 サイクル扇 据付 | C41: CY-30WD 脱衣室 速度調節器共 | E41: 4 | F41: 台 | G41: =IF(L41="","",ROUND(L41*M41,-1)) -> 11000 | H41: =IF(G41="","",ROUND(E41*G41,0)) -> 44000 | I41: 本体は元請様支給 | J41: 1500 | K41: 8500 | L41: =J41+K41 -> 10000 | M41: =COEF -> 1.1 | N41: =E41*L41 -> 40000 | O41: =ROUND(E41*K41*M41,0) -> 37400 | P41: 図面カウント | Q41: =IF(H41="","",H41-N41) -> 4000 | R41: =IF(OR(H41="",H41=0),"",Q41/H41) -> 0.090909091
A42: FS-1 中間ファン 据付 | C42: BFS-80SUG2 給気 洗浄室 F-1と連動 | E42: 1 | F42: 台 | G42: =IF(L42="","",ROUND(L42*M42,-1)) -> 38500 | H42: =IF(G42="","",ROUND(E42*G42,0)) -> 38500 | I42: 本体は元請様支給 | J42: 5200 | K42: 29800 | L42: =J42+K42 -> 35000 | M42: =COEF -> 1.1 | N42: =E42*L42 -> 35000 | O42: =ROUND(E42*K42*M42,0) -> 32780 | P42: 図面カウント | Q42: =IF(H42="","",H42-N42) -> 3500 | R42: =IF(OR(H42="",H42=0),"",Q42/H42) -> 0.090909091
A43: FS-2 中間ファン 据付 | C43: BFS-150SUG2 給気 厨房 F-2と連動 | E43: 1 | F43: 台 | G43: =IF(L43="","",ROUND(L43*M43,-1)) -> 44000 | H43: =IF(G43="","",ROUND(E43*G43,0)) -> 44000 | I43: 本体は元請様支給 | J43: 6000 | K43: 34000 | L43: =J43+K43 -> 40000 | M43: =COEF -> 1.1 | N43: =E43*L43 -> 40000 | O43: =ROUND(E43*K43*M43,0) -> 37400 | P43: 図面カウント | Q43: =IF(H43="","",H43-N43) -> 4000 | R43: =IF(OR(H43="",H43=0),"",Q43/H43) -> 0.090909091
A44: 全熱交換器・中間ファン リモコン配線 | C44: HEX-1,2,3(4台)・F-3 リモコン線 工事区分表: 機械 | E44: 9 | F44: 台 | G44: =IF(L44="","",ROUND(L44*M44,-1)) -> 8800 | H44: =IF(G44="","",ROUND(E44*G44,0)) -> 79200 | I44: 図面08 中止に伴う減額 | J44: 3200 | K44: 4800 | L44: =J44+K44 -> 8000 | M44: =COEF -> 1.1 | N44: =E44*L44 -> 72000 | O44: =ROUND(E44*K44*M44,0) -> 47520 | P44: 図面カウント | Q44: =IF(H44="","",H44-N44) -> 7200 | R44: =IF(OR(H44="",H44=0),"",Q44/H44) -> 0.090909091 | S44: HEX分は08で減額
A45: 機器搬入・養生 | C45: 換気機器 約140台 | E45: 1 | F45: 式 | G45: =IF(L45="","",ROUND(L45*M45,-1)) -> 88000 | H45: =IF(G45="","",ROUND(E45*G45,0)) -> 88000 | I45: 想定数量（別紙条件書） | J45: 8000 | K45: 72000 | L45: =J45+K45 -> 80000 | M45: =COEF -> 1.1 | N45: =E45*L45 -> 80000 | O45: =ROUND(E45*K45*M45,0) -> 79200 | P45: 推測 | Q45: =IF(H45="","",H45-N45) -> 8000 | R45: =IF(OR(H45="",H45=0),"",Q45/H45) -> 0.090909091
A46: （2）ダクト工事
A47: スパイラルダクト 100φ (EA) | C47: 亜鉛鉄板 低速 継手・支持共 | E47: 68 | F47: m | G47: =IF(L47="","",ROUND(L47*M47,-1)) -> 4950 | H47: =IF(G47="","",ROUND(E47*G47,0)) -> 336600 | I47: 図面実測数量 | J47: 2300 | K47: 2200 | L47: =J47+K47 -> 4500 | M47: =COEF -> 1.1 | N47: =E47*L47 -> 306000 | O47: =ROUND(E47*K47*M47,0) -> 164560 | P47: 実測 | Q47: =IF(H47="","",H47-N47) -> 30600 | R47: =IF(OR(H47="",H47=0),"",Q47/H47) -> 0.090909091 | S47: 1F 62.6m・2F 5.2m
A48: スパイラルダクト 150φ (EA) | C48: 亜鉛鉄板 低速 継手・支持共 | E48: 151 | F48: m | G48: =IF(L48="","",ROUND(L48*M48,-1)) -> 6050 | H48: =IF(G48="","",ROUND(E48*G48,0)) -> 913550 | I48: 図面実測数量 | J48: 2700 | K48: 2800 | L48: =J48+K48 -> 5500 | M48: =COEF -> 1.1 | N48: =E48*L48 -> 830500 | O48: =ROUND(E48*K48*M48,0) -> 465080 | P48: 実測 | Q48: =IF(H48="","",H48-N48) -> 83050 | R48: =IF(OR(H48="",H48=0),"",Q48/H48) -> 0.090909091 | S48: 1F 122.4m・2F 28.2m(口径未判読分含む)
...

Sheet 内訳書(3.金額変更案)
A1: 内 訳 書 | J1: 原 価 内 訳 書（内部用・印刷範囲外）
A2: 工事名：（仮称）サンフレッチェ広島 三矢寮新築工事 空調設備工事 | I2: 内訳書 No.3
A3: 名 称 | C3: 規格・寸法 | E3: 数 量 | F3: 単位 | G3: 単 価 | H3: 金 額 | I3: 備 考 | J3: 材料単価 | K3: 労務単価 | L3: 基準単価 | M3: 提出係数 | N3: 基準原価 | O3: 労務費(提出) | P3: 数量根拠 | Q3: 粗利 | R3: 粗利率 | S3: 前提・メモ（内部）
A4: ３．金額変更案（検討図 08 朱書き・減額は負数表示）
A6: （1）No3・4 ロスナイ中止（減額・代替機器）
A7: HEX-1 全熱交換器 据付 (中止) | C7: LGH-N80RXV2 食堂 | E7: -1 | F7: 台 | G7: =IF(L7="","",ROUND(L7*M7,-1)) -> 49500 | H7: =IF(G7="","",ROUND(E7*G7,0)) -> -49500 | I7: 本体は元請様支給 | J7: 6800 | K7: 38200 | L7: =J7+K7 -> 45000 | M7: =COEF -> 1.1 | N7: =E7*L7 -> -45000 | O7: =ROUND(E7*K7*M7,0) -> -42020 | P7: 図面カウント | Q7: =IF(H7="","",H7-N7) -> -4500 | R7: =IF(OR(H7="",H7=0),"",Q7/H7) -> 0.090909091 | S7: No3・4 ロスナイ中止
A8: HEX-2 全熱交換器 据付 (中止) | C8: LGH-N65RXW2 ミーティングルーム | E8: -1 | F8: 台 | G8: =IF(L8="","",ROUND(L8*M8,-1)) -> 49500 | H8: =IF(G8="","",ROUND(E8*G8,0)) -> -49500 | I8: 本体は元請様支給 | J8: 6800 | K8: 38200 | L8: =J8+K8 -> 45000 | M8: =COEF -> 1.1 | N8: =E8*L8 -> -45000 | O8: =ROUND(E8*K8*M8,0) -> -42020 | P8: 図面カウント | Q8: =IF(H8="","",H8-N8) -> -4500 | R8: =IF(OR(H8="",H8=0),"",Q8/H8) -> 0.090909091
A9: HEX-3 全熱交換器 据付 (中止) | C9: SKU-50AC コーチルーム・トレーニングルーム | E9: -4 | F9: 台 | G9: =IF(L9="","",ROUND(L9*M9,-1)) -> 44000 | H9: =IF(G9="","",ROUND(E9*G9,0)) -> -176000 | I9: 本体は元請様支給 | J9: 6000 | K9: 34000 | L9: =J9+K9 -> 40000 | M9: =COEF -> 1.1 | N9: =E9*L9 -> -160000 | O9: =ROUND(E9*K9*M9,0) -> -149600 | P9: 図面カウント | Q9: =IF(H9="","",H9-N9) -> -16000 | R9: =IF(OR(H9="",H9=0),"",Q9/H9) -> 0.090909091
A10: HEX-4 壁掛ロスナイ 据付 (中止) | C10: VL-10ES3 | E10: -46 | F10: 台 | G10: =IF(L10="","",ROUND(L10*M10,-1)) -> 13200 | H10: =IF(G10="","",ROUND(E10*G10,0)) -> -607200 | I10: 本体は元請様支給 | J10: 1800 | K10: 10200 | L10: =J10+K10 -> 12000 | M10: =COEF -> 1.1 | N10: =E10*L10 -> -552000 | O10: =ROUND(E10*K10*M10,0) -> -516120 | P10: 図面カウント | Q10: =IF(H10="","",H10-N10) -> -55200 | R10: =IF(OR(H10="",H10=0),"",Q10/H10) -> 0.090909091
A11: HEX-5 壁掛ロスナイ 据付 (中止) | C11: VL-12ESH3 | E11: -27 | F11: 台 | G11: =IF(L11="","",ROUND(L11*M11,-1)) -> 13200 | H11: =IF(G11="","",ROUND(E11*G11,0)) -> -356400 | I11: 本体は元請様支給 | J11: 1800 | K11: 10200 | L11: =J11+K11 -> 12000 | M11: =COEF -> 1.1 | N11: =E11*L11 -> -324000 | O11: =ROUND(E11*K11*M11,0) -> -302940 | P11: 図面カウント | Q11: =IF(H11="","",H11-N11) -> -32400 | R11: =IF(OR(H11="",H11=0),"",Q11/H11) -> 0.090909091
A12: 全熱交換器 リモコン配線 (中止) | C12: HEX-1,2,3 計6台分 | E12: -6 | F12: 台 | G12: =IF(L12="","",ROUND(L12*M12,-1)) -> 8800 | H12: =IF(G12="","",ROUND(E12*G12,0)) -> -52800 | I12: 図面08 中止に伴う減額 | J12: 3200 | K12: 4800 | L12: =J12+K12 -> 8000 | M12: =COEF -> 1.1 | N12: =E12*L12 -> -48000 | O12: =ROUND(E12*K12*M12,0) -> -31680 | P12: 図面カウント | Q12: =IF(H12="","",H12-N12) -> -4800 | R12: =IF(OR(H12="",H12=0),"",Q12/H12) -> 0.090909091
A13: HEX-1 → 中間ファン 据付 | C13: BFS-80SUDC 天井埋込形 250φ 食堂 防振吊金具・リモコン共 | E13: 1 | F13: 台 | G13: =IF(L13="","",ROUND(L13*M13,-1)) -> 44000 | H13: =IF(G13="","",ROUND(E13*G13,0)) -> 44000 | I13: 本体は元請様支給 | J13: 16000 | K13: 24000 | L13: =J13+K13 -> 40000 | M13: =COEF -> 1.1 | N13: =E13*L13 -> 40000 | O13: =ROUND(E13*K13*M13,0) -> 26400 | P13: 図面カウント | Q13: =IF(H13="","",H13-N13) -> 4000 | R13: =IF(OR(H13="",H13=0),"",Q13/H13) -> 0.090909091 | S13: EA側ダクト・HSは図示どおり、OA側は自然給気として残置と想定
A14: HEX-2 → 中間ファン 据付 | C14: BFS-65SUDC 200φ ミーティングルーム | E14: 1 | F14: 台 | G14: =IF(L14="","",ROUND(L14*M14,-1)) -> 41800 | H14: =IF(G14="","",ROUND(E14*G14,0)) -> 41800 | I14: 本体は元請様支給 | J14: 5700 | K14: 32300 | L14: =J14+K14 -> 38000 | M14: =COEF -> 1.1 | N14: =E14*L14 -> 38000 | O14: =ROUND(E14*K14*M14,0) -> 35530 | P14: 図面カウント | Q14: =IF(H14="","",H14-N14) -> 3800 | R14: =IF(OR(H14="",H14=0),"",Q14/H14) -> 0.090909091
A15: HEX-3 → 中間ファン 据付 | C15: BFS-40SUDC 天井カセット形 200φ コーチルーム・トレーニングルーム | E15: 4 | F15: 台 | G15: =IF(L15="","",ROUND(L15*M15,-1)) -> 38500 | H15: =IF(G15="","",ROUND(E15*G15,0)) -> 154000 | I15: 本体は元請様支給 | J15: 5200 | K15: 29800 | L15: =J15+K15 -> 35000 | M15: =COEF -> 1.1 | N15: =E15*L15 -> 140000 | O15: =ROUND(E15*K15*M15,0) -> 131120 | P15: 図面カウント | Q15: =IF(H15="","",H15-N15) -> 14000 | R15: =IF(OR(H15="",H15=0),"",Q15/H15) -> 0.090909091
A16: 中間ファン リモコン配線 | C16: BFS-SUDC用 6台 | E16: 6 | F16: 台 | G16: =IF(L16="","",ROUND(L16*M16,-1)) -> 8800 | H16: =IF(G16="","",ROUND(E16*G16,0)) -> 52800 | J16: 3200 | K16: 4800 | L16: =J16+K16 -> 8000 | M16: =COEF -> 1.1 | N16: =E16*L16 -> 48000 | O16: =ROUND(E16*K16*M16,0) -> 31680 | P16: 図面カウント | Q16: =IF(H16="","",H16-N16) -> 4800 | R16: =IF(OR(H16="",H16=0),"",Q16/H16) -> 0.090909091
A17: HEX-4/5 → パイプファン 据付 | C17: V-08PPXD8 壁掛1パイプ 100φ 来客室・寮室・寮務スタッフ室 | E17: 73 | F17: 台 | G17: =IF(L17="","",ROUND(L17*M17,-1)) -> 8800 | H17: =IF(G17="","",ROUND(E17*G17,0)) -> 642400 | I17: 本体は元請様支給 | J17: 1200 | K17: 6800 | L17: =J17+K17 -> 8000 | M17: =COEF -> 1.1 | N17: =E17*L17 -> 584000 | O17: =ROUND(E17*K17*M17,0) -> 546040 | P17: 図面カウント | Q17: =IF(H17="","",H17-N17) -> 58400 | R17: =IF(OR(H17="",H17=0),"",Q17/H17) -> 0.090909091 | S17: 46＋27台
A18: 吸気口 内部 KS-8841PR3-SG 取付 | C18: 材工 (支給外と想定・要確認) | E18: 73 | F18: 個 | G18: =IF(L18="","",ROUND(L18*M18,-1)) -> 6600 | H18: =IF(G18="","",ROUND(E18*G18,0)) -> 481800 | J18: 3900 | K18: 2100 | L18: =J18+K18 -> 6000 | M18: =COEF -> 1.1 | N18: =E18*L18 -> 438000 | O18: =ROUND(E18*K18*M18,0) -> 168630 | P18: 図面カウント | Q18: =IF(H18="","",H18-N18) -> 43800 | R18: =IF(OR(H18="",H18=0),"",Q18/H18) -> 0.090909091 | S18: 朱書き: 吸気口 外部SUS製フード(指定色)・内部KS-8841PR3-SG
A19: 吸気口用 SUS製フード 取付 (支給品) | C19: 指定色塗装 | E19: 73 | F19: 箇所 | G19: =IF(L19="","",ROUND(L19*M19,-1)) -> 4400 | H19: =IF(G19="","",ROUND(E19*G19,0)) -> 321200 | I19: 支給品の取付費 | J19: 400 | K19: 3600 | L19: =J19+K19 -> 4000 | M19: =COEF -> 1.1 | N19: =E19*L19 -> 292000 | O19: =ROUND(E19*K19*M19,0) -> 289080 | P19: 図面カウント | Q19: =IF(H19="","",H19-N19) -> 29200 | R19: =IF(OR(H19="",H19=0),"",Q19/H19) -> 0.090909091 | S19: B-5の寮室146箇所と重複なし(排気73・給気73)
A20: （2）No5・6 空調追加
A21: 追AC1 室内機 据付 | C21: 空冷HP 4方向天井カセット PA-P140U7GTNB(5HP 同時トリプル) 子機 1Fホール・廊下(洗濯室前)・階段ホール | E21: 3 | F21: 台 | G21: =IF(L21="","",ROUND(L21*M21,-1)) -> 49500 | H21: =IF(G21="","",ROUND(E21*G21,0)) -> 148500 | I21: 本体は元請様支給 | J21: 6800 | K21: 38200 | L21: =J21+K21 -> 45000 | M21: =COEF -> 1.1 | N21: =E21*L21 -> 135000 | O21: =ROUND(E21*K21*M21,0) -> 126060 | P21: 図面カウント | Q21: =IF(H21="","",H21-N21) -> 13500 | R21: =IF(OR(H21="",H21=0),"",Q21/H21) -> 0.090909091 | S21: 空調平面図1F 朱書き □3箇所
A22: 追AC1 室外機 据付 | C22: 5HP 1F物干場側(AC-3室外機隣) | E22: 1 | F22: 台 | G22: =IF(L22="","",ROUND(L22*M22,-1)) -> 38500 | H22: =IF(G22="","",ROUND(E22*G22,0)) -> 38500 | I22: 本体は元請様支給 | J22: 5200 | K22: 29800 | L22: =J22+K22 -> 35000 | M22: =COEF -> 1.1 | N22: =E22*L22 -> 35000 | O22: =ROUND(E22*K22*M22,0) -> 32780 | P22: 図面カウント | Q22: =IF(H22="","",H22-N22) -> 3500 | R22: =IF(OR(H22="",H22=0),"",Q22/H22) -> 0.090909091
A23: 追AC2 室内機 据付 | C23: 空冷HP 2方向天井カセット PA-P224L7HTNB(8HP 同時トリプル) 子機 1F南廊下 3箇所 | E23: 3 | F23: 台 | G23: =IF(L23="","",ROUND(L23*M23,-1)) -> 55000 | H23: =IF(G23="","",ROUND(E23*G23,0)) -> 165000 | I23: 本体は元請様支給 | J23: 7500 | K23: 42500 | L23: =J23+K23 -> 50000 | M23: =COEF -> 1.1 | N23: =E23*L23 -> 150000 | O23: =ROUND(E23*K23*M23,0) -> 140250 | P23: 図面カウント | Q23: =IF(H23="","",H23-N23) -> 15000 | R23: =IF(OR(H23="",H23=0),"",Q23/H23) -> 0.090909091
A24: 追AC2 室外機 据付 | C24: 8HP 1F南側(AC-1/AC-5室外機隣) | E24: 1 | F24: 台 | G24: =IF(L24="","",ROUND(L24*M24,-1)) -> 55000 | H24: =IF(G24="","",ROUND(E24*G24,0)) -> 55000 | I24: 本体は元請様支給 | J24: 7500 | K24: 42500 | L24: =J24+K24 -> 50000 | M24: =COEF -> 1.1 | N24: =E24*L24 -> 50000 | O24: =ROUND(E24*K24*M24,0) -> 46750 | P24: 図面カウント | Q24: =IF(H24="","",H24-N24) -> 5000 | R24: =IF(OR(H24="",H24=0),"",Q24/H24) -> 0.090909091
A25: 追AC3 室内機 据付 | C25: PA-P224L7HTNB 子機 2F北廊下 3箇所 | E25: 3 | F25: 台 | G25: =IF(L25="","",ROUND(L25*M25,-1)) -> 55000 | H25: =IF(G25="","",ROUND(E25*G25,0)) -> 165000 | I25: 本体は元請様支給 | J25: 7500 | K25: 42500 | L25: =J25+K25 -> 50000 | M25: =COEF -> 1.1 | N25: =E25*L25 -> 150000 | O25: =ROUND(E25*K25*M25,0) -> 140250 | P25: 図面カウント | Q25: =IF(H25="","",H25-N25) -> 15000 | R25: =IF(OR(H25="",H25=0),"",Q25/H25) -> 0.090909091
A26: 追AC3 室外機 据付 | C26: 8HP 1F東側地上(屋外階段A付近) | E26: 1 | F26: 台 | G26: =IF(L26="","",ROUND(L26*M26,-1)) -> 55000 | H26: =IF(G26="","",ROUND(E26*G26,0)) -> 55000 | I26: 本体は元請様支給 | J26: 7500 | K26: 42500 | L26: =J26+K26 -> 50000 | M26: =COEF -> 1.1 | N26: =E26*L26 -> 50000 | O26: =ROUND(E26*K26*M26,0) -> 46750 | P26: 図面カウント | Q26: =IF(H26="","",H26-N26) -> 5000 | R26: =IF(OR(H26="",H26=0),"",Q26/H26) -> 0.090909091
A27: 追AC4 室内機 据付 | C27: PA-P224L7HTNB 子機 2F階段ホール2・南廊下1 | E27: 3 | F27: 台 | G27: =IF(L27="","",ROUND(L27*M27,-1)) -> 55000 | H27: =IF(G27="","",ROUND(E27*G27,0)) -> 165000 | I27: 本体は元請様支給 | J27: 7500 | K27: 42500 | L27: =J27+K27 -> 50000 | M27: =COEF -> 1.1 | N27: =E27*L27 -> 150000 | O27: =ROUND(E27*K27*M27,0) -> 140250 | P27: 図面カウント | Q27: =IF(H27="","",H27-N27) -> 15000 | R27: =IF(OR(H27="",H27=0),"",Q27/H27) -> 0.090909091
A28: 追AC4 室外機 据付 | C28: 8HP 1F東側地上(倉庫2東) | E28: 1 | F28: 台 | G28: =IF(L28="","",ROUND(L28*M28,-1)) -> 55000 | H28: =IF(G28="","",ROUND(E28*G28,0)) -> 55000 | I28: 本体は元請様支給 | J28: 7500 | K28: 42500 | L28: =J28+K28 -> 50000 | M28: =COEF -> 1.1 | N28: =E28*L28 -> 50000 | O28: =ROUND(E28*K28*M28,0) -> 46750 | P28: 図面カウント | Q28: =IF(H28="","",H28-N28) -> 5000 | R28: =IF(OR(H28="",H28=0),"",Q28/H28) -> 0.090909091
A29: 追AC5 室内機 据付 | C29: PA-P224L7HTNB 子機 2F南廊下 3箇所 | E29: 3 | F29: 台 | G29: =IF(L29="","",ROUND(L29*M29,-1)) -> 55000 | H29: =IF(G29="","",ROUND(E29*G29,0)) -> 165000 | I29: 本体は元請様支給 | J29: 7500 | K29: 42500 | L29: =J29+K29 -> 50000 | M29: =COEF -> 1.1 | N29: =E29*L29 -> 150000 | O29: =ROUND(E29*K29*M29,0) -> 140250 | P29: 図面カウント | Q29: =IF(H29="","",H29-N29) -> 15000 | R29: =IF(OR(H29="",H29=0),"",Q29/H29) -> 0.090909091
A30: 追AC5 室外機 据付 | C30: 8HP 1F東側地上(倉庫2東) | E30: 1 | F30: 台 | G30: =IF(L30="","",ROUND(L30*M30,-1)) -> 55000 | H30: =IF(G30="","",ROUND(E30*G30,0)) -> 55000 | I30: 本体は元請様支給 | J30: 7500 | K30: 42500 | L30: =J30+K30 -> 50000 | M30: =COEF -> 1.1 | N30: =E30*L30 -> 50000 | O30: =ROUND(E30*K30*M30,0) -> 46750 | P30: 図面カウント | Q30: =IF(H30="","",H30-N30) -> 5000 | R30: =IF(OR(H30="",H30=0),"",Q30/H30) -> 0.090909091
A31: 分岐管(トリプル用) 取付 | C31: 各系統2組 ※機器付属として元請支給想定・未支給なら別途 | E31: 10 | F31: 組 | G31: =IF(L31="","",ROUND(L31*M31,-1)) -> 6600 | H31: =IF(G31="","",ROUND(E31*G31,0)) -> 66000 | I31: 想定数量（別紙条件書） | J31: 600 | K31: 5400 | L31: =J31+K31 -> 6000 | M31: =COEF -> 1.1 | N31: =E31*L31 -> 60000 | O31: =ROUND(E31*K31*M31,0) -> 59400 | P31: 推測 | Q31: =IF(H31="","",H31-N31) -> 6000 | R31: =IF(OR(H31="",H31=0),"",Q31/H31) -> 0.090909091 | S31: 取付費のみ
A32: 冷媒配管 ① | C32: 被覆銅管 9.52/6.35 追AC1 枝管 | E32: 35 | F32: m | G32: =IF(L32="","",ROUND(L32*M32,-1)) -> 4950 | H32: =IF(G32="","",ROUND(E32*G32,0)) -> 173250 | I32: 想定数量（別紙条件書） | J32: 2500 | K32: 2000 | L32: =J32+K32 -> 4500 | M32: =COEF -> 1.1 | N32: =E32*L32 -> 157500 | O32: =ROUND(E32*K32*M32,0) -> 77000 | P32: 推測 | Q32: =IF(H32="","",H32-N32) -> 15750 | R32: =IF(OR(H32="",H32=0),"",Q32/H32) -> 0.090909091 | S32: 配管経路図示なし 室内外機位置より推定
A33: 冷媒配管 ③ | C33: 被覆銅管 15.88/9.52 追AC1主管16m・追AC2～5 枝管168m | E33: 184 | F33: m | G33: =IF(L33="","",ROUND(L33*M33,-1)) -> 7150 | H33: =IF(G33="","",ROUND(E33*G33,0)) -> 1315600 | I33: 想定数量（別紙条件書） | J33: 3600 | K33: 2900 | L33: =J33+K33 -> 6500 | M33: =COEF -> 1.1 | N33: =E33*L33 -> 1196000 | O33: =ROUND(E33*K33*M33,0) -> 586960 | P33: 推測 | Q33: =IF(H33="","",H33-N33) -> 119600 | R33: =IF(OR(H33="",H33=0),"",Q33/H33) -> 0.090909091 | S33: 同上
A34: 冷媒配管 ⑥ | C34: 被覆銅管 25.4/9.52 追AC2～5 主管 (立管2F→1F含む) | E34: 73 | F34: m | G34: =IF(L34="","",ROUND(L34*M34,-1)) -> 10450 | H34: =IF(G34="","",ROUND(E34*G34,0)) -> 762850 | I34: 想定数量（別紙条件書） | J34: 5200 | K34: 4300 | L34: =J34+K34 -> 9500 | M34: =COEF -> 1.1 | N34: =E34*L34 -> 693500 | O34: =ROUND(E34*K34*M34,0) -> 345290 | P34: 推測 | Q34: =IF(H34="","",H34-N34) -> 69350 | R34: =IF(OR(H34="",H34=0),"",Q34/H34) -> 0.090909091 | S34: 追AC2 12・AC3 14・AC4 31・AC5 16
A35: 冷媒配管 化粧ケース | C35: 屋外露出部 | E35: 13 | F35: m | G35: =IF(L35="","",ROUND(L35*M35,-1)) -> 3300 | H35: =IF(G35="","",ROUND(E35*G35,0)) -> 42900 | I35: 想定数量（別紙条件書） | J35: 1800 | K35: 1200 | L35: =J35+K35 -> 3000 | M35: =COEF -> 1.1 | N35: =E35*L35 -> 39000 | O35: =ROUND(E35*K35*M35,0) -> 17160 | P35: 推測 | Q35: =IF(H35="","",H35-N35) -> 3900 | R35: =IF(OR(H35="",H35=0),"",Q35/H35) -> 0.090909091 | S35: 5系統×2.5m
A36: 外壁貫通スリーブ材 | C36: VP100 | E36: 5 | F36: 箇所 | G36: =IF(L36="","",ROUND(L36*M36,-1)) -> 2750 | H36: =IF(G36="","",ROUND(E36*G36,0)) -> 13750 | I36: 想定数量（別紙条件書） | J36: 1300 | K36: 1200 | L36: =J36+K36 -> 2500 | M36: =COEF -> 1.1 | N36: =E36*L36 -> 12500 | O36: =ROUND(E36*K36*M36,0) -> 6600 | P36: 推測 | Q36: =IF(H36="","",H36-N36) -> 1250 | R36: =IF(OR(H36="",H36=0),"",Q36/H36) -> 0.090909091
A37: 区画貫通処理 | C37: 冷媒管・ドレン管 フィブロック 廊下区画壁 | E37: 5 | F37: 箇所 | G37: =IF(L37="","",ROUND(L37*M37,-1)) -> 13200 | H37: =IF(G37="","",ROUND(E37*G37,0)) -> 66000 | I37: 想定数量（別紙条件書） | J37: 6000 | K37: 6000 | L37: =J37+K37 -> 12000 | M37: =COEF -> 1.1 | N37: =E37*L37 -> 60000 | O37: =ROUND(E37*K37*M37,0) -> 33000 | P37: 推測 | Q37: =IF(H37="","",H37-N37) -> 6000 | R37: =IF(OR(H37="",H37=0),"",Q37/H37) -> 0.090909091 | S37: 各系統1箇所と仮定
A38: ドレン管 VP25 | C38: 継手・支持共 15台×8m | E38: 120 | F38: m | G38: =IF(L38="","",ROUND(L38*M38,-1)) -> 3520 | H38: =IF(G38="","",ROUND(E38*G38,0)) -> 422400 | I38: 想定数量（別紙条件書） | J38: 1600 | K38: 1600 | L38: =J38+K38 -> 3200 | M38: =COEF -> 1.1 | N38: =E38*L38 -> 384000 | O38: =ROUND(E38*K38*M38,0) -> 211200 | P38: 推測 | Q38: =IF(H38="","",H38-N38) -> 38400 | R38: =IF(OR(H38="",H38=0),"",Q38/H38) -> 0.090909091
A39: ドレン管 VP40 | C39: 継手・支持共 集合管・立下り | E39: 30 | F39: m | G39: =IF(L39="","",ROUND(L39*M39,-1)) -> 4400 | H39: =IF(G39="","",ROUND(E39*G39,0)) -> 132000 | I39: 想定数量（別紙条件書） | J39: 2000 | K39: 2000 | L39: =J39+K39 -> 4000 | M39: =COEF -> 1.1 | N39: =E39*L39 -> 120000 | O39: =ROUND(E39*K39*M39,0) -> 66000 | P39: 推測 | Q39: =IF(H39="","",H39-N39) -> 12000 | R39: =IF(OR(H39="",H39=0),"",Q39/H39) -> 0.090909091
A40: ドレン管 保温 | C40: GW保温筒20 ALGC | E40: 150 | F40: m | G40: =IF(L40="","",ROUND(L40*M40,-1)) -> 2750 | H40: =IF(G40="","",ROUND(E40*G40,0)) -> 412500 | I40: 想定数量（別紙条件書） | J40: 1100 | K40: 1400 | L40: =J40+K40 -> 2500 | M40: =COEF -> 1.1 | N40: =E40*L40 -> 375000 | O40: =ROUND(E40*K40*M40,0) -> 231000 | P40: 推測 | Q40: =IF(H40="","",H40-N40) -> 37500 | R40: =IF(OR(H40="",H40=0),"",Q40/H40) -> 0.090909091
A41: 気密試験・真空引き・冷媒追加充填 作業 | E41: 5 | F41: 系統 | G41: =IF(L41="","",ROUND(L41*M41,-1)) -> 16500 | H41: =IF(G41="","",ROUND(E41*G41,0)) -> 82500 | J41: 13500 | K41: 1500 | L41: =J41+K41 -> 15000 | M41: =COEF -> 1.1 | N41: =E41*L41 -> 75000 | O41: =ROUND(E41*K41*M41,0) -> 8250 | P41: 図面カウント | Q41: =IF(H41="","",H41-N41) -> 7500 | R41: =IF(OR(H41="",H41=0),"",Q41/H41) -> 0.090909091
...

Sheet 法定福利費内訳明細書
B1: 法 定 福 利 費 内 訳 明 細 書
B2: ="（御見積書 No."&'表紙(工事)'!K3&" の添付資料）" -> （御見積書 No. の添付資料）
B4: 見積年月日 | C4: ='表紙(工事)'!J4 -> 46300 | F4: 見積No. | G4: =IF('表紙(工事)'!K3="","",'表紙(工事)'!K3)
B5: 発注者名 | C5: 株式会社共栄店舗 御中
B6: 工事名 | C6: （仮称）サンフレッチェ広島 三矢寮新築工事 空調設備工事
B7: 施工場所 | C7: 広島県安芸高田市吉田町西浦字日南山835-27
B8: 会社名 | C8: 宮地機工株式会社 | F8: 所在地 | G8: 広島県尾道市東尾道9-9
B10: 【1】 労務費の内訳（法定福利費の算定基礎）
B11: ※ 本見積の労務費は、内訳書各項目の材工共単価のうち労務費相当額（自社施工分）の合計です。機器は元請様手配のため含みません。
B12: 項 目 | C12: 労務費（円） | E12: 摘 要
B13: 空調工事 労務費 | C13: ='内訳書(1.空調工事)'!O58 -> 6749050 | E13: 内訳書 No.1 各項目の労務費相当額の合計
B14: 換気工事 労務費 | C14: ='内訳書(2.換気工事)'!O93 -> 6356460 | E14: 内訳書 No.2 各項目の労務費相当額の合計
B15: 金額変更案 労務費 | C15: ='内訳書(3.金額変更案)'!O48 -> 2863960 | E15: 内訳書 No.3 各項目の労務費相当額の合計
B16: 労 務 費 合 計 | C16: =SUM(C13:C15) -> 15969470 | E16: ← 法定福利費の算定基礎額
B18: 【2】 法定福利費の算定
B19: 計算式： 法定福利費 ＝ 労務費 × 事業主負担料率 （保険ごとに円未満切捨て）
B20: 保険の種類 | C20: 対象労務費（円） | E20: 事業主負担料率 | F20: 法定福利費（円） | G20: 算定根拠
B21: 健康保険料 | C21: =$C$16 -> 15969470 | E21: 0.0489 | F21: =ROUNDDOWN(C21*E21,0) -> 780907 | G21: 健康保険料率 9.780%（協会けんぽ 広島県 令和8年度）×1/2（労使折半）
B22: 介護保険料 | C22: =$C$16 -> 15969470 | E22: 0.0081 | F22: =ROUNDDOWN(C22*E22,0) -> 129352 | G22: 介護保険料率 1.620%（全国一律 令和8年度）×1/2（労使折半）
B23: 子ども・子育て支援金 | C23: =$C$16 -> 15969470 | E23: 0.00115 | F23: =ROUNDDOWN(C23*E23,0) -> 18364 | G23: 支援金率 0.230%（令和8年4月分〜）×1/2（労使折半）
B24: 厚生年金保険料 | C24: =$C$16 -> 15969470 | E24: 0.0915 | F24: =ROUNDDOWN(C24*E24,0) -> 1461206 | G24: 厚生年金保険料率 18.300%（平成29年9月以降固定）×1/2（労使折半）
B25: 雇用保険料 | C25: =$C$16 -> 15969470 | E25: 0.0105 | F25: =ROUNDDOWN(C25*E25,0) -> 167679 | G25: 雇用保険料率（建設の事業）事業主負担分 1.050%
B26: 子ども・子育て拠出金 | C26: =$C$16 -> 15969470 | E26: 0.0036 | F26: =ROUNDDOWN(C26*E26,0) -> 57490 | G26: 拠出金率 0.360%（事業主全額負担）
B27: 合 計 | E27: =SUM(E21:E26) -> 0.16375 | F27: =SUM(F21:F26) -> 2614998
B29: ※ 料率は見積作成時点（令和8年度）の公表料率によります。料率が改定された場合は改定後の料率により精算させていただきます。
B30: ※ 法定福利費は御見積書の④に計上しています。

Sheet 御見積条件
A1: 御見積条件・注意事項
A2: （仮称）サンフレッチェ広島 三矢寮新築工事 空調設備工事 御見積書 添付
A4: 【1】御見積条件・注意事項
A5: 1. | B5: 本見積は機械設備図 06（特記仕様書・空調機器表・換気機器表・空調平面図・換気平面図・厨房廻り詳細図）に基づき当社にて拾い出した数量により積算しております。配管・ダクトの平面延長は図面（A3 1:300、厨房詳細 1:70）から計測し、立上り・立下り・機器接続部および図面に経路の記載がない部分は想定数量として計上しています（別紙【2】参照）。
A6: 2. | B6: 金額変更案検討図 08 のうち No3・4（ロスナイ中止）および No5・6（空調追加）を内訳書 No.3 に朱書きで計上しています。ロスナイ中止はベース計上分の減額と代替機器（中間ファン・パイプファン・吸気口）の計上を併記しています。No1（庇中止）・No2（既存フェンス再利用）は対象外です。
A7: 3. | B7: 空調機器・換気機器は元請様手配のため本見積には含みません（室内機・室外機・集中リモコン・換気扇・中間ファン・全熱交換器・パイプファン・有圧扇・屋外機架台（2段架台含む）・ドレンアップ・SUS製フード・ウェザーカバー等、機器表記載の本体および付属品）。本見積は上記機器の搬入・据付・取付費のみを計上しています。
A8: 4. | B8: 追加空調（追AC1〜5 同時トリプル）の分岐管は機器付属品として元請様支給を想定し、取付費のみ計上しています。支給外の場合は別途申し受けます。
A9: 5. | B9: 機器の電源供給（電源・動力配線、盤、接地、インバータ盤）は電気工事とし含みません。機器付属の制御盤およびリモコン制御の配管・配線（工事区分表「機械」）は本見積に計上しています。
A10: 6. | B10: 基礎（室外機基礎）、躯体・外壁の穴明け、スリーブ・型枠の穴埋め、天井点検口、天井・壁の開口補強および仕上げ補修は建築工事とし含みません（工事区分表による）。外壁貫通スリーブ材のみ計上しています。
A11: 7. | B11: 冷媒管は被覆銅管（製造者標準品）とし、露出部は化粧ケース仕上げとして計上しています。特記仕様書は脱酸銅管／被覆銅管とも未選択のため、管種凡例（被覆銅管）によっています。
A12: 8. | B12: ドレン管の保温は特記仕様書の保温表に記載がないため、公共建築工事標準仕様書に準じ天井内 GW保温筒20 ALGC として計上しています。不要の場合は減額いたします。
A13: 9. | B13: 厨房フード①〜④（SUS製、グリスフィルター付）は機械設備図のフードリストにより本見積に計上しています。厨房機器工事の範囲となる場合は減額いたします。
A14: 10. | B14: ロスナイ中止後の OA 側ダクト・制気口は図示どおり自然給気として残置する前提で計上しています。撤去・変更がある場合は別途協議とさせていただきます。
A15: 11. | B15: 冷媒配管の追加充填ガスは想定量で計上しています。系統・配管長の確定後に精算いたします。
A16: 12. | B16: 施工図・竣工図（完成図）の作成、風量測定・試験成績書の作成、官庁検査対応は含みません。必要な場合は別途お見積りいたします。
... A20: 16. | B20: 本見積金額には消費税は含まれておりません。労務費に係る法定福利費（事業主負担分）は別紙「法定福利費内訳明細書」のとおり計上しています。
A22: 【2】想定数量（推測）項目の前提
A23: 図面に数量・経路の記載がなく当社にて想定した項目です。「図面実測＋想定」は平面延長を図面計測し、立上り等を想定加算したものです。実数量確定後に精算させていただきます。
A24: No. | B24: 内訳書 | C24: 項 目 | D24: 前提・想定内容 | F24: 数量（区分）
A25: 1 | B25: No.1 | C25: 冷媒配管 ① 被覆銅管 9.52/6.35 (RAC-1,2 1F 及び RAC-3 2F) | D25: 平面実測34.3m＋推測(RAC-3 66台×4m、来客室RAC-2 5台×4m、RAC-1補正8m、立上り10台×3m) | F25: 360 m（実測＋想定）
A26: 2 | B26: No.1 | C26: 冷媒配管 ② 被覆銅管 12.7/6.35 (AC-5,7,8 AC-3枝 RAC-4) | D26: 平面実測56m＋推測(立上り4系統×4m、RAC-4 5m) | F26: 77 m（実測＋想定）
A27: 3 | B27: No.1 | C27: 冷媒配管 ③ 被覆銅管 15.88/9.52 (AC-1/2枝 AC-3主 AC-6,9,10) | D27: 平面実測72.2m＋推測(立上り3系統×4m、AC-10 2F分3.5m＋立管8m) | F27: 96 m（実測＋想定）
A28: 4 | B28: No.1 | C28: 冷媒配管 ⑥ 被覆銅管 25.4/9.52 (AC-2主管) | D28: 平面実測5m＋立上り4m | F28: 9 m（実測＋想定）
A29: 5 | B29: No.1 | C29: 冷媒配管 ⑦ 被覆銅管 25.4/12.7 (AC-1主管 4系統) | D29: 平面実測41m＋立上り4系統×4m | F29: 57 m（実測＋想定）
A30: 6 | B30: No.1 | C30: 冷媒配管 化粧ケース 屋外・屋内露出部 (管種凡例: 露出管は化粧ケース仕上) | D30: PAC13+RAC1F10箇所×2.5m、RAC-3/4 67台×1.0m | F30: 125 m（想定）
A31: 7 | B31: No.1 | C31: 外壁貫通スリーブ材 VP100 冷媒・ドレン用 (穴明けは建築工事) | D31: RAC77＋PAC13 | F31: 90 箇所（想定）
A32: 8 | B32: No.1 | C32: 冷媒追加充填 (冷媒代) R32/R410A | D32: 配管延長より約20g/m換算 | F32: 8 kg（想定）
A33: 9 | B33: No.1 | C33: ドレン管 VP20 硬質塩化ビニル管 継手・支持共 | D33: 平面実測7m＋推測(RAC-1/2 ドレンアップ吐出→屋外 10台×3m) | F33: 37 m（実測＋想定）
A34: 10 | B34: No.1 | C34: ドレン管 VP25 硬質塩化ビニル管 継手・支持共 | D34: 平面実測1F 87.3m・2F 6.1m(未判読分比例配分含む) | F34: 94 m（実測＋想定）
A35: 11 | B35: No.1 | C35: ドレン管 VP40 硬質塩化ビニル管 継手・支持共 | D35: 平面実測50.2m＋推測(立下り・屋外放流部12箇所×1.5m) | F35: 68 m（実測＋想定）
A36: 12 | B36: No.1 | C36: ドレン管 保温 GW保温筒20 ALGC 天井内 (特記仕様書 保温表は空欄・標準仕様に準じ計上 要確認) | D36: VP25・VP40 天井内相当分 | F36: 143 m（想定）
... A52: 28 | B52: No.3 | C52: 区画貫通処理 冷媒管・ドレン管 フィブロック 廊下区画壁 | D52: 各系統1箇所と仮定 | F52: 5 箇所（想定）
A54: 【3】図面読み取りに関する確認事項
A55: 1. | B55: 宛名は元請様を株式会社共栄店舗（詳細工程表作成者）と想定して記載しています。ご指定があれば修正します。
A56: 2. | B56: 空調平面図の配管線（冷媒管＝黒線、ドレン管＝青線）および換気平面図のダクト線（排気＝黒太線、給気＝青線）をベクトルデータから計測しています。機器記号と重なる短い線分は除外しているため、実測値は若干少なめになる傾向があります。
A57: 3. | B57: 2F 寮室のルームエアコン（RAC-3 66台）は図面に配管線の記載がなく、壁掛機→バルコニー屋外機 4m/台 の想定です。
A58: 4. | B58: 追AC1〜5 は図面08に配管経路の記載がなく、室内機・室外機の位置から経路長を推定しています（別紙【2】）。
A59: 5. | B59: 区画貫通処理は空調平面図1Fの区画貫通部記号（●）2箇所と、追加空調の廊下区画壁 各系統1箇所の想定です。
A60: 6. | B60: SUS製フード・ウェザーカバーは換気機器表の付属品として元請様支給と解釈し、取付費のみ計上しています。
A61: 7. | B61: 吸気口 KS-8841PR3-SG（図面08 朱書き）は支給範囲が不明のため材工で計上しています。支給の場合は材料分を減額します。

Sheet 数量拾い根拠(内部)
A1: 数量拾い根拠（内部用） ※計測方法: PDF図面(A3 1:300、厨房詳細 1:70)のベクトル線分を色・線幅で分離し延長を集計。「実測」=図面線分の平面延長、「推測」=図面に無い部分の推定
A3: 1. 冷媒配管（ベース06）系統別
A4: 系統 | B4: 口径記号 | C4: 平面実測(m) | D4: 推測加算(m) | E4: 合計(m) | F4: 推測内容
A5: RAC-2×3 和室・洋室・DK | B5: ① | C5: 28.1 | D5: 9 | E5: 37.1 | F5: 屋外機→屋内機 立上り 3台×3m
A6: AC-7 面談室 | B6: ② | C6: 13 | D6: 4 | E6: 17 | F6: 北西ゾーン実測60.3mを3系統に配分。立上り4m
A7: AC-5 管理人室 | B7: ② | C7: 18 | D7: 4 | E7: 22 | F7: 同上
A8: AC-1 ホール(ツイン) | B8: ⑦主/③枝 | C8: 29 | D8: 4 | E8: 33 | F8: 主管17m・枝管12m。立上り4m(⑦)
A9: AC-6/AC-8/AC-9/RAC-1×2 厨房ブロック | B9: ③/②/③/① | C9: 22.2 | D9: 20 | E9: 42.2 | F9: 重なり配管の未計測補正8m(RAC-1休憩室)・立上り4系統×3〜4m
A10: AC-1 食堂・ミーティング(ツイン×2) | B10: ⑦主/③枝 | C10: 30.7 | D10: 8 | E10: 38.7 | F10: 各系統 主管8m・枝管7.5m。立上り各4m
A11: AC-10 多目的スペース(2F) | B11: ③ | C11: 10.2 | D11: 11.5 | E11: 21.7 | F11: 2F平面3.5m・立管(1F地上→2F天井)8m
A12: AC-2 コーチルーム(ツイン) | B12: ⑥主/③枝 | C12: 11.1 | D12: 4 | E12: 15.1 | F12: 主管5m・枝管6m。立上り4m
A13: AC-1 トレーニング(ツイン)＋AC-5 ケア室 | B13: ⑦/③ ・ ② | C13: 32 | D13: 8 | E13: 40 | F13: AC-1 主8m枝12m・AC-5 12m。立上り各4m
A14: AC-3 脱衣室(ツイン) | B14: ③主/②枝 | C14: 13.9 | D14: 4 | E14: 17.9 | F14: 主管7m・枝管7m。立上り4m
A15: RAC-2×5 来客室 | B15: ① | C15: 2.7 | D15: 18 | E15: 20.7 | F15: 屋外機が各室直近。1台4m×5台
A16: RAC-3×66 2F寮室等 | B16: ① | C16: 0 | D16: 264 | E16: 264 | F16: 図面に配管線なし。壁掛機→バルコニー屋外機 4m/台
A17: RAC-4 寮務スタッフ室 | B17: ② | C17: 0 | D17: 5 | E17: 5 | F17: 同上 5m
A18: 合計 | C18: 211 | D18: 363.5 | E18: 574.5 | F18: 口径別: ①360 ②77 ③96 ⑥9 ⑦57 (m・端数調整後)
A20: 2. ドレン配管（ベース06）
A21: 区分 | B21: 口径 | C21: 平面実測(m) | D21: 推測加算(m) | E21: 合計(m) | F21: 備考
A22: 1F 空調平面図 青線(D) | B22: VP20 | C22: 6.6 | D22: 30 | E22: 36.6 | F22: RAC-1/2 ドレンアップ吐出→屋外 10台×3m
A23: 1F 空調平面図 青線(D) | B23: VP25 | C23: 87.3 | D23: 0 | E23: 87.3 | F23: 口径ラベル未割当31.3mを25/40へ比例配分済
A24: 1F 空調平面図 青線(D) | B24: VP40 | C24: 50.2 | D24: 18 | E24: 68.2 | F24: 立下り・屋外放流部 12箇所×1.5m
A25: 2F 空調平面図 青線(D) AC-10 | B25: VP25 | C25: 6.1 | D25: 0 | E25: 6.1
A26: 合計 | C26: 150.2 | D26: 48 | E26: 198.2
A28: 3. 冷媒配管（図面08 追加空調・すべて推測）
A29: 系統 | B29: 口径記号 | C29: 平面実測(m) | D29: 推測(m) | E29: 合計(m) | F29: 推定根拠
A30: 追AC1 PA-P140U7GTNB トリプル | B30: ③主/①枝 | C30: 0 | D30: 51 | E30: 51 | F30: 室外機:物干場側(AC-3隣) 室内機:ホール・洗濯室前廊下・階段ホール
A31: 追AC2 PA-P224L7HTNB トリプル | B31: ⑥主/③枝 | C31: 0 | D31: 57 | E31: 57 | F31: 室外機:南側(AC-1/5隣) 室内機:1F南廊下3箇所
A32: 追AC3 PA-P224L7HTNB トリプル | B32: ⑥主/③枝 | C32: 0 | D32: 64 | E32: 64 | F32: 室外機:東側地上 室内機:2F北廊下3箇所
A33: 追AC4 PA-P224L7HTNB トリプル | B33: ⑥主/③枝 | C33: 0 | D33: 51 | E33: 51 | F33: 室外機:東側地上(倉庫2東) 室内機:階段ホール2・南廊下1
A34: 追AC5 PA-P224L7HTNB トリプル | B34: ⑥主/③枝 | C34: 0 | D34: 69 | E34: 69 | F34: 室外機:東側地上 室内機:2F南廊下3箇所
A35: 合計 | C35: 0 | D35: 292 | E35: 292 | F35: 口径別: ①35 ③184 ⑥73
A37: 4. ダクト（ベース06）
A38: 図面 | B38: 系統 | C38: 100φ(m) | D38: 150φ(m) | E38: 200φ(m) | F38: 250φ(m) | G38: 300φ(m) | H38: 備考
A39: 1F換気平面図(p22) 黒太線 | B39: EA | C39: 62.6 | D39: 122.4 | E39: 25.2 | F39: 0 | G39: 0 | H39: 150φに口径未判読16.6m含む（実測）
A40: 1F換気平面図(p22) 青線 | B40: OA | C40: 3.5 | D40: 50.4 | E40: 45.7 | F40: 0 | G40: 0 | H40: 150φに未判読9.1m含む（実測）
A41: 2F換気平面図(p23) 黒太線 | B41: EA | C41: 5.2 | D41: 28.2 | E41: 9.8 | F41: 0 | G41: 0 | H41: 実測
A42: 2F換気平面図(p23) 青線 | B42: OA | C42: 0 | D42: 0 | E42: 3.5 | F42: 0 | G42: 0 | H42: 実測
A43: 厨房廻り詳細図(p24) 1:70 | B43: EA | C43: 0 | D43: 0 | E43: 9 | F43: 6 | G43: 5 | H43: 推測（二重線表記のため目視換算）
A44: 厨房廻り詳細図(p24) 1:70 | B44: OA(FS-1/2・F-3給気) | C44: 0 | D44: 0 | E44: 7.5 | F44: 6 | G44: 3 | H44: 推測
...
