Workbook
Name TARGET_MARGIN: '表紙(工事)'!$N$4
Name ROUND_UNIT: '表紙(工事)'!$N$5
Name LABOR_COST: '表紙(工事)'!$N$6
Name MAT_RATIO: '表紙(工事)'!$N$7
Name EST_LABOR_PIPE: '表紙(工事)'!$N$8
Name EST_LABOR_ELEC: '表紙(工事)'!$N$9
Name WELFARE_RATE: '法定福利費内訳明細書'!$E$28
Name INCLUDE_TBD: '表紙(工事)'!$N$11
Name TARGET: '表紙(工事)'!$N$12
Name SUBMIT: '表紙(工事)'!$N$13
Name COST_TOTAL: '表紙(工事)'!$O$29

Sheet 表紙(工事)
A1: 御 見 積 書
J3: No. | M3: 【設定・内部用】（印刷範囲外）黄セル＝入力
J4: 46304 | M4: 目標粗利率 | N4: 0.2
A5: 宗教法人 安楽寺 | G5: 御中 | M5: 提出額の丸め単位（切上げ） | N5: 10000
M6: 労務原価日額（円/人工、当社） | N6: 19000
A7: 金額 | B7: ="¥"&TEXT(K30,"#,##0")&"-" -> ¥2,810,000- | F7: （税別） | H7: 宮地機工株式会社 | M7: 材料原価率（エスト材料単価＝建設物価相当に対する比率） | N7: 1
M8: エスト労務単価 配管工費（円/人） | N8: 33750
A9: つぎのとおりお見積いたしました。 | H9: 代表取締役 濱本 義樹 | M9: エスト労務単価 電線材料施工費（円/人） | N9: 33600
A10: なにとぞご用命くださいますようお願い申しあげます。 | M10: 法定福利費率（事業主負担） | N10: =WELFARE_RATE -> 0.16375
H11: 〒722-0051 | M11: 要見積（概算）を提出額に含める（1=含める／0=別途見積） | N11: 0
A12: 件名 | D12: 安楽寺 本堂 新築工事 | H12: 広島県尾道市東尾道9-9 | M12: 目標提出額（税別・空欄なら粗利率から自動）
D13: 空調・換気設備工事 | H13: TEL.0848-20-2121 | K13: FAX.0848-20-2126 | M13: 提出額（自動計算） | N13: =IF(TARGET="",ROUNDUP(COST_TOTAL/(1-TARGET_MARGIN)/ROUND_UNIT,0)*ROUND_UNIT,TARGET) -> 2810000
A14: 施工場所 | D14: 安楽寺 本堂 新築工事現場（所在地は確認申請書による） | H14: 担当者 | J14: 濱本 義武 | M14: ※ 提出額＝原価合計÷（1－目標粗利率）を丸め単位で切上げ。小計（エスト単価の定価ベース）との差を出精値引に計上
A15: 工事期限 | D15: 御協議による（建築工程に合わせて施工） | M15: ※ 原価＝材料（エスト材料単価×材料原価率＝建設物価相当）＋人工×労務原価日額＋法定福利費（事業主負担）
A16: 支払条件 | D16: 御協議による
A17: 本書有効期間 | D17: 10日
A19: 項 | B19: 品 名 | G19: 数 量 | H19: 単位 | I19: 単 価 | K19: 金 額 | L19: 備 考 | M19: 内部集計 | N19: 定価ベース | O19: 原価 | P19: 粗利 | Q19: 粗利率
B20: 【安楽寺 本堂 新築工事 空調・換気設備工事】 空気調和・換気設備工事
B21: =IF(INCLUDE_TBD=1,"［空調機・換気機器を含む（材工）。電源・スイッチ等の電気工事、外壁開口補強・仕上げ補修等の建築工事は別途］","［空調機・換気機器を含む（材工）。電源・スイッチ等の電気工事、外壁開口補強・仕上げ補修等の建築工事は別途］") -> ［空調機・換気機器を含む（材工）。電源・スイッチ等の電気工事、外壁開口補強・仕上げ補修等の建築工事は別途］
A22: ① | B22: 空調設備機器 | G22: 1 | H22: 式 | I22: =K22 -> 1086750 | K22: ='内訳書(空調設備工事)'!H11 -> 1086750 | L22: 内訳書 １ | M22: ①空調設備機器 | N22: =K22 -> 1086750 | O22: ='内訳書(空調設備工事)'!P11 -> 869400 | P22: =N22-O22 -> 217350 | Q22: =IF(N22=0,"",P22/N22) -> 0.2
A23: ② | B23: 空調設備工事 | G23: 1 | H23: 式 | I23: =K23 -> 157000 | K23: ='内訳書(空調設備工事)'!H28 -> 157000 | L23: 内訳書 ２ | M23: ②空調設備工事 | N23: =K23 -> 157000 | O23: ='内訳書(空調設備工事)'!P28 -> 172450 | P23: =N23-O23 -> -15450 | Q23: =IF(N23=0,"",P23/N23) -> -0.098407643
A24: ③ | B24: 配管設備工事 | G24: 1 | H24: 式 | I24: =K24 -> 480000 | K24: ='内訳書(空調設備工事)'!H60 -> 480000 | L24: 内訳書 ３ | M24: ③配管設備工事 | N24: =K24 -> 480000 | O24: ='内訳書(空調設備工事)'!P60 -> 320399 | P24: =N24-O24 -> 159601 | Q24: =IF(N24=0,"",P24/N24) -> 0.33250208
A25: ④ | B25: 換気設備機器 | G25: 1 | H25: 式 | I25: =K25 -> 257040 | K25: ='内訳書(空調設備工事)'!H77 -> 257040 | L25: 内訳書 ４ | M25: ④換気設備機器 | N25: =K25 -> 257040 | O25: ='内訳書(空調設備工事)'!P77 -> 205632 | P25: =N25-O25 -> 51408 | Q25: =IF(N25=0,"",P25/N25) -> 0.2
A26: ⑤ | B26: 換気設備工事 | G26: 1 | H26: 式 | I26: =K26 -> 832000 | K26: ='内訳書(空調設備工事)'!H100 -> 832000 | L26: 内訳書 ５ | M26: ⑤換気設備工事 | N26: =K26 -> 832000 | O26: ='内訳書(空調設備工事)'!P100 -> 555270 | P26: =N26-O26 -> 276730 | Q26: =IF(N26=0,"",P26/N26) -> 0.33260817
A27: ⑥ | B27: 工事諸経費 | G27: 1 | H27: 式 | I27: =K27 -> 73500 | K27: ='内訳書(空調設備工事)'!H102 -> 73500 | L27: 内訳書 ６ | M27: ⑥工事諸経費（原価なし） | N27: =K27 -> 73500 | O27: 0 | P27: =N27-O27 -> 73500 | Q27: =IF(N27=0,"",P27/N27) -> 1
B28: 小 計 | K28: =SUM(K22:K27) -> 2886290 | M28: 法定福利費（事業主負担・原価） | O28: =ROUND('内訳書(空調設備工事)'!Q104*WELFARE_RATE,0) -> 119488
A29: ⑦ | B29: 出精値引 | K29: =IF(SUBMIT<K28,SUBMIT-K28,0) -> -76290 | M29: 原価合計 | N29: =K28 -> 2886290 | O29: =SUM(O22:O28) -> 2242639
B30: 合 計 | K30: =K28+K29 -> 2810000 | L30: （税別） | M30: 提出額（合計）／粗利／粗利率 | N30: =K30 -> 2810000 | O30: =O29 -> 2242639 | P30: =N30-O30 -> 567361 | Q30: =IF(N30=0,"",P30/N30) -> 0.20190783
A32: 上記の工事費には、以下の法定福利費相当額を含んでいます。
A33: ="【法定福利費相当額（Ａ）】"&TEXT('法定福利費内訳明細書'!$F$28,"#,##0")&"円 Ａ＝Ｙ×Ｚ Ｙ：労務費相当額 "&TEXT('法定福利費内訳明細書'!$C$17,"#,##0")&"円 Ｚ：法定福利費事業者負担率（合計値："&TEXT('法定福利費内訳明細書'!$E$28*100,"0.000")&"／100）" -> 【法定福利費相当額（Ａ）】164,469円 Ａ＝Ｙ×Ｚ Ｙ：労務費相当額 1,004,413円 Ｚ：法定福利費事業者負担率（合計値：16.375／100） | M33: ⚠ アラート（提出前に確認）
M34: 要見積 0件：（概算原価の合計） | N34: =0 -> 0 | O34: =IF(INCLUDE_TBD=1,"概算を提出額に含めています","別途見積（提出額に含めていません）") -> 別途見積（提出額に含めていません）
A35: ※ | B35: 本見積は当社作図の空調設備平面図（M-1）・換気設備平面図（M-2）および24時間換気計算書に基づき作成しております。数量は図面より当社にて拾い出しており、実施数量との差異は別途精算とさせていただきます。 | M35: 要見積を概算で含めた場合の提出額（目安） | N35: =IF(INCLUDE_TBD=1,SUBMIT,ROUNDUP((COST_TOTAL+N34)/(1-TARGET_MARGIN)/ROUND_UNIT,0)*ROUND_UNIT) -> 2810000 | O35: N11 を 1 にすると反映
A36: ※ | B36: 空調機（ダイキン SZRV80BZV×2組、S284ATEV-W×2組、S404ATEV-W×1組）および換気機器（三菱電機 パイプ用ファン・天井埋込形換気扇・給排気グリル・深形フード）を含みます（材工）。 | M36: 単価要確認 15件：室外機置台・スリーブインサート費・パイプ用ファン取付・天井埋込形換気扇取付・天井埋込形換気扇取付・給排気グリル取付・屋外フード取付・スパイラルダクト・スパイラルダクト・スパイラルダクト・ダクト保温・外壁貫通処理・外壁貫通処理・外壁貫通処理・試運転調整費 | O36: エストに単価なし。当社単価・推定単価で仮計上（単価出典シート）
A37: ※ | B37: 電源・専用回路・スイッチ（24時間換気の常時運転表示を含む）等の電気工事、外壁開口の補強・外装仕上げ補修・天井開口補強等の建築工事、揚重機、足場・仮設、産業廃棄物処分は含みません。 | M37: 定価ベース（エスト単価）で目標粗利に届くか | O37: =IF(SUBMIT>K28,"⚠ 値引きなしでも粗利率 "&TEXT((K28-COST_TOTAL)/K28,"0.0%")&"（目標未達）","OK（出精値引で調整）") -> OK（出精値引で調整）
A38: ※ | B38: 天井高・機器の取付位置は意匠図確定前の想定です。変更が生じた場合は御協議のうえ精算させていただきます。 | M38: 機器の仕入率はダイキン業務用0.20・家庭用0.30・三菱電機換気0.32（job.py の EQ_RATES）。目標粗利率を変えた場合は機器の提出単価も job.py で再生成
A39: ※ | B39: 本見積書に記載なき事項については別途とさせて頂きます。工事に係る電気・水道は無償支給願います。本見積金額には消費税は含まれておりません。 | M39: 空調機の定価は VE案（8/10付）の値。三菱電機機器は WIN2K／販売店掲載の価格（税別）
A40: ※ | B40: 詳細条件は別紙「御見積条件」をご参照ください。 | M40: 天井高・冷媒管長・ダクト立上りは想定値（items.py 先頭で変更可）
M41: 施工場所（地番）未確定
M43: 参考（感度） | N43: 金額 | O43: 原価 | Q43: 粗利率
M44: 労務を公共工事設計労務単価（広島 配管工）で計算した場合 | N44: =K30 -> 2810000 | O44: =COST_TOTAL+'内訳書(空調設備工事)'!M104*(N47-LABOR_COST)*(1+WELFARE_RATE) -> 2497393.8 | Q44: =(N44-O44)/N44 -> 0.11124777
...

Sheet 内訳書(空調設備工事)
A1: 内 訳 書 | J1: 原 価・単価出典（内部用・印刷範囲外） 黄セル＝入力、赤＝要見積、橙＝単価要確認
A2: 工事名：安楽寺 本堂 新築工事 空調・換気設備工事 | I2: 内訳書 No.1
A3: 品 名 | C3: 規格・寸法 | E3: 数 量 | F3: 単位 | G3: 単 価 | H3: 金 額 | I3: 備 考 | J3: 単価区分 | K3: アラート | L3: 材料原価/単位 | M3: 人工/単位 | N3: 労務原価/単位 | O3: 原価単価 | P3: 原価金額 | Q3: 労務原価金額 | R3: 労務費相当額(提出) | S3: 粗利(定価) | T3: 粗利率 | U3: 率・歩掛 | V3: 要見積 概算原価/単位 | W3: 単価の参照元 | X3: エストマスタ参考 | Y3: 数量根拠 | Z3: 出典・メモ（内部）
A4: 空気調和・換気設備工事
A5: １ 空調設備機器
A6: 業務用パッケージエアコン（ダイキン）
A7: AC-1 床置形ペア EcoZEAS | C7: SZRV80BZV（P80）単相200V | E7: 2 | F7: 組 | G7: 316500 | H7: =ROUND(E7*G7,0) -> 633000 | I7: 大間・外陣 | J7: 原価基準（仕入率） | L7: 253200 | M7: 0 | N7: =ROUND(M7*LABOR_COST,0) -> 0 | O7: =L7+N7 -> 253200 | P7: =E7*O7 -> 506400 | Q7: =E7*N7 -> 0 | R7: =IF(H7=0,0,IF(E7*M7*EST_LABOR_PIPE>H7,H7,E7*M7*EST_LABOR_PIPE)) -> 0 | S7: =IF(H7="","",H7-P7) -> 126600 | T7: =IF(OR(H7="",H7=0),"",S7/H7) -> 0.2 | W7: 原価基準: 定価 1,266,000円（VE案 8月10日付 定価）× 仕入率 0.20（ダイキン業務用（EcoZEAS・FIVESTAR））＝原価 253,200円 ÷（1－目標粗利率 0.20） | Y7: 図面カウント | Z7: 定価 1,266,000円 × 仕入率 0.20（ダイキン業務用（EcoZEAS・FIVESTAR））＝原価 253,200円
A8: ルームエアコン（ダイキン）
A9: AC-2 壁掛形 | C9: S284ATEV-W（2.8kW）単相200V | E9: 2 | F9: 組 | G9: 142500 | H9: =ROUND(E9*G9,0) -> 285000 | I9: 和室(1)・和室(2) | J9: 原価基準（仕入率） | L9: 114000 | M9: 0 | N9: =ROUND(M9*LABOR_COST,0) -> 0 | O9: =L9+N9 -> 114000 | P9: =E9*O9 -> 228000 | Q9: =E9*N9 -> 0 | R9: =IF(H9=0,0,IF(E9*M9*EST_LABOR_PIPE>H9,H9,E9*M9*EST_LABOR_PIPE)) -> 0 | S9: =IF(H9="","",H9-P9) -> 57000 | T9: =IF(OR(H9="",H9=0),"",S9/H9) -> 0.2 | W9: 原価基準: 定価 380,000円（VE案 8月10日付 定価）× 仕入率 0.30（ダイキン家庭用（定価あり））＝原価 114,000円 ÷（1－目標粗利率 0.20） | Y9: 図面カウント | Z9: 定価 380,000円 × 仕入率 0.30（ダイキン家庭用（定価あり））＝原価 114,000円
A10: AC-3 壁掛形 | C10: S404ATEV-W（4.0kW）単相200V | E10: 1 | F10: 組 | G10: 168750 | H10: =ROUND(E10*G10,0) -> 168750 | I10: 談話室 | J10: 原価基準（仕入率） | L10: 135000 | M10: 0 | N10: =ROUND(M10*LABOR_COST,0) -> 0 | O10: =L10+N10 -> 135000 | P10: =E10*O10 -> 135000 | Q10: =E10*N10 -> 0 | R10: =IF(H10=0,0,IF(E10*M10*EST_LABOR_PIPE>H10,H10,E10*M10*EST_LABOR_PIPE)) -> 0 | S10: =IF(H10="","",H10-P10) -> 33750 | T10: =IF(OR(H10="",H10=0),"",S10/H10) -> 0.2 | W10: 原価基準: 定価 450,000円（VE案 8月10日付 定価）× 仕入率 0.30（ダイキン家庭用（定価あり））＝原価 135,000円 ÷（1－目標粗利率 0.20） | Y10: 図面カウント | Z10: 定価 450,000円 × 仕入率 0.30（ダイキン家庭用（定価あり））＝原価 135,000円
A11: － 計 － | H11: =SUM(H6:H10) -> 1086750 | M11: =SUMPRODUCT(E6:E10,M6:M10) -> 0 | P11: =SUM(P6:P10) -> 869400 | Q11: =SUM(Q6:Q10) -> 0 | R11: =SUM(R6:R10) -> 0 | S11: =H11-P11 -> 217350 | T11: =IF(H11=0,"",S11/H11) -> 0.2
A13: ２ 空調設備工事
A14: 搬入据付工事
A15: SA 室外機 | C15: P80（SZRV80BZV）地上設置 | E15: 2 | F15: 台 | G15: 8750 | H15: =ROUND(E15*G15,0) -> 17500 | I15: 大間・外陣 | J15: エスト見積 | L15: 1500 | M15: 0.8 | N15: =ROUND(M15*LABOR_COST,0) -> 15200 | O15: =L15+N15 -> 16700 | P15: =E15*O15 -> 33400 | Q15: =E15*N15 -> 30400 | R15: =IF(H15=0,0,IF(E15*M15*EST_LABOR_PIPE>H15,H15,E15*M15*EST_LABOR_PIPE)) -> 17500 | S15: =IF(H15="","",H15-P15) -> -15900 | T15: =IF(OR(H15="",H15=0),"",S15/H15) -> -0.90857143 | W15: エスト見積 6330560-1 SA 室外機 11.2-16.0 | X15: SA室外機 地上設置 P112 13,000（P80 はエスト見積 11.2-16.0 を準用） | Y15: 図面カウント | Z15: エスト見積の 11.2-16.0 を P80 に準用
A16: SA 室内機 | C16: 床置形 P80（転倒防止金具共） | E16: 2 | F16: 台 | G16: 13000 | H16: =ROUND(E16*G16,0) -> 26000 | I16: 大間・外陣 | J16: エストマスタ | L16: 1500 | M16: 0.8 | N16: =ROUND(M16*LABOR_COST,0) -> 15200 | O16: =L16+N16 -> 16700 | P16: =E16*O16 -> 33400 | Q16: =E16*N16 -> 30400 | R16: =IF(H16=0,0,IF(E16*M16*EST_LABOR_PIPE>H16,H16,E16*M16*EST_LABOR_PIPE)) -> 26000 | S16: =IF(H16="","",H16-P16) -> -7400 | T16: =IF(OR(H16="",H16=0),"",S16/H16) -> -0.28461538 | W16: エストマスタ 搬入据付 スカイエア室内機 床置形 P140 | X16: SA室内機 床置形 P140 13,000（P80 に準用） | Y16: 図面カウント | Z16: エストマスタ 床置形 P140 を P80 に準用
A17: RA 室外機 | C17: セパレート 2.2-5.0（S284/S404） | E17: 3 | F17: 台 | G17: 6250 | H17: =ROUND(E17*G17,0) -> 18750 | I17: 和室・談話室 | J17: エスト見積 | L17: 500 | M17: 0.4 | N17: =ROUND(M17*LABOR_COST,0) -> 7600 | O17: =L17+N17 -> 8100 | P17: =E17*O17 -> 24300 | Q17: =E17*N17 -> 22800 | R17: =IF(H17=0,0,IF(E17*M17*EST_LABOR_PIPE>H17,H17,E17*M17*EST_LABOR_PIPE)) -> 18750 | S17: =IF(H17="","",H17-P17) -> -5550 | T17: =IF(OR(H17="",H17=0),"",S17/H17) -> -0.296 | W17: エスト見積 6330560-1 RA 室外機 セパレート2.2-5.0 | X17: ルームエアコン 室外機 地上設置 2,000 | Y17: 図面カウント
A18: RA 室内機 | C18: 壁掛（据付板・ドレンホース共） | E18: 3 | F18: 台 | G18: 6250 | H18: =ROUND(E18*G18,0) -> 18750 | I18: 和室・談話室 | J18: エスト見積 | L18: 800 | M18: 0.5 | N18: =ROUND(M18*LABOR_COST,0) -> 9500 | O18: =L18+N18 -> 10300 | P18: =E18*O18 -> 30900 | Q18: =E18*N18 -> 28500 | R18: =IF(H18=0,0,IF(E18*M18*EST_LABOR_PIPE>H18,H18,E18*M18*EST_LABOR_PIPE)) -> 18750 | S18: =IF(H18="","",H18-P18) -> -12150 | T18: =IF(OR(H18="",H18=0),"",S18/H18) -> -0.648 | W18: エスト見積 6330560-1 RA 室内機 壁掛 | X18: ルームエアコン 室内機 壁掛形 P22 5,000 | Y18: 図面カウント
A19: 基礎工事
A20: 基礎工事 | C20: 縁石基礎（SA 室外機 P80） | E20: 2 | F20: 台 | G20: 5000 | H20: =ROUND(E20*G20,0) -> 10000 | I20: 大間・外陣 | J20: エスト見積 | L20: 2500 | M20: 0.15 | N20: =ROUND(M20*LABOR_COST,0) -> 2850 | O20: =L20+N20 -> 5350 | P20: =E20*O20 -> 10700 | Q20: =E20*N20 -> 5700 | R20: =IF(H20=0,0,IF(E20*M20*EST_LABOR_PIPE>H20,H20,E20*M20*EST_LABOR_PIPE)) -> 10000 | S20: =IF(H20="","",H20-P20) -> -700 | T20: =IF(OR(H20="",H20=0),"",S20/H20) -> -0.07 | W20: エスト見積 6330560-1 縁石 11.2-16.0 | X20: 基礎工事 スカイエア 縁石基礎 P28〜P140 5,000 | Y20: 図面カウント | Z20: エスト見積 縁石 11.2-16.0 を準用
A21: 室外機置台 | C21: RA 室外機用 プラ製（防振ゴム付） | E21: 3 | F21: 台 | G21: 5500 | H21: =ROUND(E21*G21,0) -> 16500 | I21: 和室・談話室 | J21: 当社単価（要確認） | K21: 単価要確認 | L21: 2500 | M21: 0.1 | N21: =ROUND(M21*LABOR_COST,0) -> 1900 | O21: =L21+N21 -> 4400 | P21: =E21*O21 -> 13200 | Q21: =E21*N21 -> 5700 | R21: =IF(H21=0,0,IF(E21*M21*EST_LABOR_PIPE>H21,H21,E21*M21*EST_LABOR_PIPE)) -> 10125 | S21: =IF(H21="","",H21-P21) -> 3300 | T21: =IF(OR(H21="",H21=0),"",S21/H21) -> 0.2 | W21: 当社単価: 置台 2,500＋0.1人工（エストに単価なし） | X21: （エストマスタに単価なし） | Y21: 図面カウント
A22: 試運転調整費
A23: 試運転調整費 | C23: SA 室外機（-160） | E23: 2 | F23: 台 | G23: 10000 | H23: =ROUND(E23*G23,0) -> 20000 | J23: エスト見積 | L23: 450 | M23: 0.45 | N23: =ROUND(M23*LABOR_COST,0) -> 8550 | O23: =L23+N23 -> 9000 | P23: =E23*O23 -> 18000 | Q23: =E23*N23 -> 17100 | R23: =IF(H23=0,0,IF(E23*M23*EST_LABOR_PIPE>H23,H23,E23*M23*EST_LABOR_PIPE)) -> 20000 | S23: =IF(H23="","",H23-P23) -> 2000 | T23: =IF(OR(H23="",H23=0),"",S23/H23) -> 0.1 | W23: エスト見積 6330560-1 試運転調整費 SA 室外機(-160) | Y23: 図面カウント
A24: 試運転調整費 | C24: RA 室外機（0-56） | E24: 3 | F24: 台 | G24: 2500 | H24: =ROUND(E24*G24,0) -> 7500 | J24: エスト見積 | L24: 0 | M24: 0.15 | N24: =ROUND(M24*LABOR_COST,0) -> 2850 | O24: =L24+N24 -> 2850 | P24: =E24*O24 -> 8550 | Q24: =E24*N24 -> 8550 | R24: =IF(H24=0,0,IF(E24*M24*EST_LABOR_PIPE>H24,H24,E24*M24*EST_LABOR_PIPE)) -> 7500 | S24: =IF(H24="","",H24-P24) -> -1050 | T24: =IF(OR(H24="",H24=0),"",S24/H24) -> -0.14 | W24: エスト見積 6330560-1 試運転調整費 RA 室外機(0-56) | Y24: 図面カウント
A25: 消耗品及び雑材料 | E25: 1 | F25: 式 | H25: =ROUNDUP(SUM(H14:H24)*U25,-2) -> 4100 | J25: 経費 | P25: 0 | Q25: 0 | R25: 0 | U25: 0.03 | W25: 基礎額×率（100円未満切上げ）
A26: 資材運搬交通費 | E26: 1 | F26: 式 | H26: =ROUNDUP((SUM(H14:H24)+H25)*U26,-2) -> 5600 | J26: 経費 | P26: 0 | Q26: 0 | R26: 0 | U26: 0.04 | W26: （基礎額＋消耗品）×率（100円未満切上げ）
A27: 現場経費 | E27: 1 | F27: 式 | H27: =ROUNDUP((SUM(H14:H24)+H25+H26)+ROUNDUP((SUM(H14:H24)+H25+H26)*U27,-2),-3)-(SUM(H14:H24)+H25+H26) -> 12300 | J27: 経費 | P27: 0 | Q27: 0 | R27: 0 | U27: 0.08 | W27: （基礎額＋消耗品＋運搬費）×率を加え、計を1,000円未満切上げ
A28: － 計 － | H28: =SUM(H14:H27) -> 157000 | M28: =SUMPRODUCT(E14:E27,M14:M27) -> 7.85 | P28: =SUM(P14:P27) -> 172450 | Q28: =SUM(Q14:Q27) -> 149150 | R28: =SUM(R14:R27) -> 128625 | S28: =H28-P28 -> -15450 | T28: =IF(H28=0,"",S28/H28) -> -0.098407643
A30: ３ 配管設備工事
A31: 冷媒（冷媒銅管）
A32: 冷媒用被覆銅管（10+20t） | C32: 9.52+15.88mm（10t+20t）AC-1 | E32: 6 | F32: m | G32: 5138 | H32: =ROUND(E32*G32,0) -> 30828 | I32: 想定数量 | J32: エスト見積 | L32: =ROUND(G32*MAT_RATIO*1.05,0) -> 5395 | M32: 0 | N32: =ROUND(M32*LABOR_COST,0) -> 0 | O32: =L32+N32 -> 5395 | P32: =E32*O32 -> 32370 | Q32: =E32*N32 -> 0 | R32: =IF(H32=0,0,IF(E32*M32*EST_LABOR_PIPE>H32,H32,E32*M32*EST_LABOR_PIPE)) -> 0 | S32: =IF(H32="","",H32-P32) -> -1542 | T32: =IF(OR(H32="",H32=0),"",S32/H32) -> -0.050019463 | U32: 0.15 | W32: エスト見積 6330560-1 冷媒用被覆銅管(10+20t) 9.52+15.88 | X32: 冷媒配管（テープ巻き）新築 φ9.5/15.9 5m以下29,500＋1m追加5,900（仕様違い） | Y32: 推測 | Z32: 材料原価＝単価×材料原価率×管長割増1.05（建設物価相当）｜AC-1 床置形 2系統 × 3.0m（室外機は外壁直近。最小配管長 3m を確保、壁貫通・立上り・余長込み）
A33: 冷媒用被覆銅管（10+20t） | C33: 6.35+9.52mm（10t+20t）AC-2・AC-3 | E33: 12 | F33: m | G33: 3388 | H33: =ROUND(E33*G33,0) -> 40656 | I33: 想定数量 | J33: エスト見積 | L33: =ROUND(G33*MAT_RATIO*1.05,0) -> 3557 | M33: 0 | N33: =ROUND(M33*LABOR_COST,0) -> 0 | O33: =L33+N33 -> 3557 | P33: =E33*O33 -> 42684 | Q33: =E33*N33 -> 0 | R33: =IF(H33=0,0,IF(E33*M33*EST_LABOR_PIPE>H33,H33,E33*M33*EST_LABOR_PIPE)) -> 0 | S33: =IF(H33="","",H33-P33) -> -2028 | T33: =IF(OR(H33="",H33=0),"",S33/H33) -> -0.049881936 | U33: 0.104 | W33: エスト見積 6330560-1 冷媒用被覆銅管(10+20t) 6.35+9.52 | X33: 冷媒配管（テープ巻き）新築 φ6.4/9.5 5m以下26,000＋1m追加5,300（仕様違い） | Y33: 推測 | Z33: 材料原価＝単価×材料原価率×管長割増1.05（建設物価相当）｜AC-2・AC-3 壁掛形 3台 × 4.0m（壁掛 約2.2m → 屋外置台への立下り・余長込み）
A34: 継手類 | E34: 1 | F34: 式 | H34: =ROUND((H32+H33)*U34,0) -> 21445 | J34: エスト算式 | P34: =ROUND((P32+P33)*U34,0) -> 22516 | Q34: 0 | R34: 0 | S34: =IF(H34="","",H34-P34) -> -1071 | T34: =IF(OR(H34="",H34=0),"",S34/H34) -> -0.049941711 | U34: 0.3 | W34: 管金額×率（エスト・公共積算と同率）。原価も同率
A35: 消耗品 | E35: 1 | F35: 式 | H35: =ROUND((H32+H33)*U35,0) -> 10723 | J35: エスト算式 | P35: =ROUND((P32+P33)*U35,0) -> 11258 | Q35: 0 | R35: 0 | S35: =IF(H35="","",H35-P35) -> -535 | T35: =IF(OR(H35="",H35=0),"",S35/H35) -> -0.049892754 | U35: 0.15 | W35: 管金額×率（エスト・公共積算と同率）。原価も同率
A36: 支持金物 | E36: 1 | F36: 式 | H36: =ROUND((H32+H33)*U36,0) -> 28594 | J36: エスト算式 | P36: =ROUND((P32+P33)*U36,0) -> 30022 | Q36: 0 | R36: 0 | S36: =IF(H36="","",H36-P36) -> -1428 | T36: =IF(OR(H36="",H36=0),"",S36/H36) -> -0.049940547 | U36: 0.4 | W36: 管金額×率（エスト・公共積算と同率）。原価も同率
A37: 排水（硬質塩化ビニル管）
A38: 硬質塩化ビニル管 | C38: VP 25A（AC-1 ドレン） | E38: 3 | F38: m | G38: 313 | H38: =ROUND(E38*G38,0) -> 939 | I38: 想定数量 | J38: エスト見積 | L38: =ROUND(G38*MAT_RATIO*1.1,0) -> 344 | M38: 0 | N38: =ROUND(M38*LABOR_COST,0) -> 0 | O38: =L38+N38 -> 344 | P38: =E38*O38 -> 1032 | Q38: =E38*N38 -> 0 | R38: =IF(H38=0,0,IF(E38*M38*EST_LABOR_PIPE>H38,H38,E38*M38*EST_LABOR_PIPE)) -> 0 | S38: =IF(H38="","",H38-P38) -> -93 | T38: =IF(OR(H38="",H38=0),"",S38/H38) -> -0.099041534 | U38: 0.074 | W38: エスト見積 6330560-1 硬質塩化ビニル管 VP 25A | X38: ドレン配管 新築 5m以下14,200＋1m追加2,800（参考） | Y38: 推測 | Z38: 材料原価＝単価×材料原価率×管長割増1.1（建設物価相当）｜AC-1 2系統 × 1.5m（室内 1.0m＋屋外放流 0.5m）。ルームエアコンは付属ドレンホース
A39: 継手類 | E39: 1 | F39: 式 | H39: =ROUND((H38)*U39,0) -> 188 | J39: エスト算式 | P39: =ROUND((P38)*U39,0) -> 206 | Q39: 0 | R39: 0 | S39: =IF(H39="","",H39-P39) -> -18 | T39: =IF(OR(H39="",H39=0),"",S39/H39) -> -0.095744681 | U39: 0.2 | W39: 管金額×率（エスト・公共積算と同率）。原価も同率
A40: 消耗品 | E40: 1 | F40: 式 | H40: =ROUND((H38)*U40,0) -> 94 | J40: エスト算式 | P40: =ROUND((P38)*U40,0) -> 103 | Q40: 0 | R40: 0 | S40: =IF(H40="","",H40-P40) -> -9 | T40: =IF(OR(H40="",H40=0),"",S40/H40) -> -0.095744681 | U40: 0.1 | W40: 管金額×率（エスト・公共積算と同率）。原価も同率
A41: 支持金物 | E41: 1 | F41: 式 | H41: =ROUND((H38)*U41,0) -> 235 | J41: エスト算式 | P41: =ROUND((P38)*U41,0) -> 258 | Q41: 0 | R41: 0 | S41: =IF(H41="","",H41-P41) -> -23 | T41: =IF(OR(H41="",H41=0),"",S41/H41) -> -0.09787234 | U41: 0.25 | W41: 管金額×率（エスト・公共積算と同率）。原価も同率
A42: 電線・ケーブル類
...

Sheet 法定福利費内訳明細書
B1: 法 定 福 利 費 内 訳 明 細 書
B2: ="（御見積書 No."&'表紙(工事)'!K3&" の添付資料）" -> （御見積書 No. の添付資料）
B4: 見積年月日 | C4: ='表紙(工事)'!J4 -> 46304 | F4: 見積No. | G4: =IF('表紙(工事)'!K3="","",'表紙(工事)'!K3)
B5: 発注者名 | C5: 宗教法人 安楽寺 御中
B6: 工事名 | C6: 安楽寺 本堂 新築工事 空調・換気設備工事
B7: 施工場所 | C7: 安楽寺 本堂 新築工事現場（所在地は確認申請書による）
B8: 会社名 | C8: 宮地機工株式会社 | F8: 所在地 | G8: 広島県尾道市東尾道9-9
B10: 【1】 労務費相当額（Ｙ）の内訳
B11: ※ 労務費相当額は、内訳書各項目の金額のうち労務費に相当する額（配管工費・電線材料施工費、および据付・保温・試験等の人工相当額）に、出精値引き後の比率を乗じたものです。空調機器・換気機器は含みません。
B12: 項 目 | C12: 労務費相当額（円） | E12: 摘 要
B13: 空調設備工事 | C13: ='内訳書(空調設備工事)'!R28 -> 128625 | E13: 内訳書 ２ 空調設備工事（定価ベース）
B14: 配管設備工事 | C14: ='内訳書(空調設備工事)'!R60 -> 233157.5 | E14: 内訳書 ３ 配管設備工事（定価ベース）
B15: 換気設備工事 | C15: ='内訳書(空調設備工事)'!R100 -> 669900 | E15: 内訳書 ５ 換気設備工事（定価ベース）
B16: 小 計 | C16: =C13+C14+C15 -> 1031682.5 | E16: 定価ベース
B17: 労務費相当額（Ｙ） | C17: =ROUNDDOWN(C16*'表紙(工事)'!K30/'表紙(工事)'!K28,0) -> 1004413 | E17: 小計 × 出精値引き後比率（合計÷小計）
B19: 【2】 法定福利費相当額（Ａ）の算定
B20: 計算式： Ａ ＝ Ｙ × Ｚ（Ｚ：法定福利費事業者負担率、保険ごとに円未満切捨て）
B21: 保険の種類 | C21: 労務費相当額（円） | E21: 事業主負担料率 | F21: 法定福利費（円） | G21: 算定根拠
B22: 健康保険料 | C22: =$C$17 -> 1004413 | E22: 0.0489 | F22: =ROUNDDOWN(C22*E22,0) -> 49115 | G22: 健康保険料率 9.780%（協会けんぽ 広島県 令和8年度）×1/2（労使折半）
B23: 介護保険料 | C23: =$C$17 -> 1004413 | E23: 0.0081 | F23: =ROUNDDOWN(C23*E23,0) -> 8135 | G23: 介護保険料率 1.620%（全国一律 令和8年度）×1/2（労使折半）
B24: 子ども・子育て支援金 | C24: =$C$17 -> 1004413 | E24: 0.00115 | F24: =ROUNDDOWN(C24*E24,0) -> 1155 | G24: 支援金率 0.230%（令和8年4月分〜）×1/2（労使折半）
B25: 厚生年金保険料 | C25: =$C$17 -> 1004413 | E25: 0.0915 | F25: =ROUNDDOWN(C25*E25,0) -> 91903 | G25: 厚生年金保険料率 18.300%（平成29年9月以降固定）×1/2（労使折半）
B26: 雇用保険料 | C26: =$C$17 -> 1004413 | E26: 0.0105 | F26: =ROUNDDOWN(C26*E26,0) -> 10546 | G26: 雇用保険料率（建設の事業）事業主負担分 1.050%
B27: 子ども・子育て拠出金 | C27: =$C$17 -> 1004413 | E27: 0.0036 | F27: =ROUNDDOWN(C27*E27,0) -> 3615 | G27: 拠出金率 0.360%（事業主全額負担）
B28: 合計（Ｚ ／ Ａ） | E28: =SUM(E22:E27) -> 0.16375 | F28: =SUM(F22:F27) -> 164469
B30: ※ 法定福利費相当額（Ａ）は見積金額（工事費）に含まれています。別途加算するものではありません。
B31: ※ 料率は見積作成時点（令和8年度）の公表料率によります。料率が改定された場合は改定後の料率により精算させていただきます。

Sheet 御見積条件
A1: 御見積条件・注意事項
A2: 安楽寺 本堂 新築工事 空調・換気設備工事 御見積書 添付
A4: 【1】御見積条件・注意事項
A5: 1. | B5: 本見積は当社作図の空調設備平面図（M-1）・換気設備平面図（M-2）（意匠 平面図 令和8年7月20日版ベース）および24時間換気計算書に基づいて作成しています。空調機の機種は8月10日付 検討最終VE案（提案① ダイキン）、換気機器は三菱電機製としています。
A6: 2. | B6: 空調工事の範囲: 空調機の搬入・据付（AC-1 床置形 SZRV80BZV×2組〔大間・外陣〕、AC-2 壁掛形 S284ATEV-W×2組〔和室(1)・和室(2)〕、AC-3 壁掛形 S404ATEV-W×1組〔談話室〕）、室外機基礎（縁石基礎・置台）、冷媒配管（被覆銅管 液管10t・ガス管20t）・屋外化粧カバー、ドレン配管（VP 25A）・保温、内外連絡線（VVF 2.0-3C）、外壁貫通部の処理、気密試験・真空引き、試運転調整。
A7: 3. | B7: 換気工事の範囲: 24時間換気（第3種機械換気）用パイプ用ファン V-08PP8-BL×3台、局所換気用天井埋込形換気扇（VD-18ZC14×5台〔焼香・護摩の排煙〕、VD-15ZC14・VD-10ZC14 各1台）、給気用給排気グリル×8個、スパイラルダクト（φ100〜φ200）・外気導入ダクトの保温、深形フード（ステンレス製・防虫網付）×18個、外壁貫通処理、試運転調整（風量確認）。
A8: 4. | B8: 機器の単価は、メーカー定価（空調機はVE案の定価、換気機器は三菱電機の価格〔税別〕）を基準に当社にて算定しています。機器のメーカー価格改定（三菱電機は2027年1月1日改定予定）が生じた場合は御協議させていただきます。
A9: 5. | B9: 24時間換気の有効換気量は、パイプ用ファン V-08PP8-BL のP-Q線図（電源周波数60Hz）により算定しています（80 m³/h/台×3台＝240 m³/h ≧ 必要有効換気量185.1 m³/h）。天井高の確定により必要換気量が増える場合は機器の見直しをお願いすることがあります。
A10: 6. | B10: 電源・専用回路（空調機 単相200V×5回路、換気扇 単相100V）・スイッチ・接地等の電気工事、リモコン配線（本体リモコン・ワイヤレスリモコンのため不要の想定）は含みません。
A11: 7. | B11: 外壁の開口補強・外装仕上げの補修、天井開口の補強・点検口、揚重機（クレーン等）、足場・高所作業車等の仮設、産業廃棄物（機器の梱包材を含む）の処分は含みません。外壁貫通部の穴あけ・防水処理は本見積に含みます。
A12: 8. | B12: 冷媒の追加充填は、配管長が各機器のチャージレス配管長以内のため計上していません（真空引き・ガス充填は基本料金）。
A13: 9. | B13: ドレンは、AC-1は硬質塩化ビニル管（VP 25A、屋内部分は保温）で、AC-2・AC-3は付属ドレンホースで屋外へ開放排水する想定です（側溝・桝への接続は含みません）。
A14: 10. | B14: 工期は建築工程に合わせた通常の日中作業を前提としております。夜間・休日作業、工程変更や他工事との輻輳による手待ち、工期延長に伴う経費増は別途協議とさせていただきます。
A15: 11. | B15: 労務費に係る法定福利費（事業主負担分）は工事費に含んでおり、その額は御見積書表紙および別紙「法定福利費内訳明細書」のとおりです。
A16: 12. | B16: 本見積書に記載なき事項については別途とさせていただきます。工事に係る電気・水道は無償支給願います。本見積金額には消費税は含まれておりません。本書有効期間は10日です。
A18: 【2】想定数量（推測）項目の前提
A19: 図面に数量・経路の記載がなく当社にて想定した項目です。「図面実測＋想定」は平面延長を図面計測し、立上り等を想定加算したものです。実数量確定後に精算させていただきます。
A20: No. | B20: 内訳書 | C20: 項 目 | D20: 前提・想定内容 | F20: 数量（区分）
A21: 1 | B21: ３ | C21: 冷媒用被覆銅管（10+20t） 9.52+15.88mm（10t+20t）AC-1 | D21: AC-1 床置形 2系統 × 3.0m（室外機は外壁直近。最小配管長 3m を確保、壁貫通・立上り・余長込み） | F21: 6 m（想定）
A22: 2 | B22: ３ | C22: 冷媒用被覆銅管（10+20t） 6.35+9.52mm（10t+20t）AC-2・AC-3 | D22: AC-2・AC-3 壁掛形 3台 × 4.0m（壁掛 約2.2m → 屋外置台への立下り・余長込み） | F22: 12 m（想定）
A23: 3 | B23: ３ | C23: 硬質塩化ビニル管 VP 25A（AC-1 ドレン） | D23: AC-1 2系統 × 1.5m（室内 1.0m＋屋外放流 0.5m）。ルームエアコンは付属ドレンホース | F23: 3 m（想定）
A24: 4 | B24: ３ | C24: VVFケーブル（内外連絡線） 600V VV-F 2.0mm-3C | D24: 内外連絡線 AC-1 5.0m×2・AC-2/3 5.0m×3（余長込み） | F24: 25 m（想定）
A25: 5 | B25: ３ | C25: 樹脂製化粧カバー 9.52+15.88 屋外（AC-1） | D25: AC-1 屋外 壁貫通〜室外機 1.0m × 2 | F25: 2 m（想定）
A26: 6 | B26: ３ | C26: 樹脂製化粧カバー 6.35+9.52 屋外（AC-2・3） | D26: AC-2・AC-3 屋外立下り 2.0m × 3 | F26: 6 m（想定）
A27: 7 | B27: ３ | C27: 排水VP保温 GW20mm+ALGC 屋内隠蔽 25A | D27: AC-1 ドレンの屋内部分 1.0m × 2系統 | F27: 2 m（想定）
A28: 8 | B28: ５ | C28: スパイラルダクト φ100 継手・支持金物共 | D28: 給気 SA-3 ×3・局所 EF-3/EF-4 の器具〜外壁（平面）＋立上り・接続 0.5m/本 ＝ 6.77m | F28: 7 m（実測＋想定）
A29: 9 | B29: ５ | C29: スパイラルダクト φ150 継手・支持金物共 | D29: 給気 SA-2・局所 EF-2 ×5 の器具〜外壁（平面）＋0.5m/本 ＝ 21.30m | F29: 22 m（実測＋想定）
A30: 10 | B30: ５ | C30: スパイラルダクト φ200 継手・支持金物共 | D30: 給気 SA-1 ×4 の器具〜外壁（平面）＋0.5m/本 ＝ 11.22m | F30: 12 m（実測＋想定）
A31: 11 | B31: ５ | C31: ダクト保温 GW25＋ALGC 外気導入ダクト | D31: 外気導入（給気）ダクトの全長 ＝ 17.14m（結露防止） | F31: 18 m（実測＋想定）
A33: 【3】図面読み取りに関する確認事項
A34: 1. | B34: 施工場所（地番）をご教示ください。24時間換気は電源周波数60Hz（中国電力管内）で算定しています（50Hzの場合も 204 m³/h で適合）。
A35: 2. | B35: 天井高（外陣・内陣・護摩堂の格天井・折上天井を含む）が未確定のため、24時間換気計算は仮定値（外陣3.3m・内陣3.6m・護摩堂3.3m・その他2.4m）で行っています。
A36: 3. | B36: 室外機は各室の外壁直近（大間・外陣は西側、和室(1)は北側、和室(2)・談話室は東側）に置く計画です。設置場所の地盤・景観上の制約があればご指示ください。
A37: 4. | B37: AC-1（床置形）の位置は大間・外陣の西側 広縁としています。仏具・建具の配置と干渉する場合はご指示ください。
A38: 5. | B38: 換気扇・給気口の位置、ダクトルートは当社計画です。天井内の梁・野縁との取合いにより変更となる場合があります。
A39: 6. | B39: 機器の型番・価格（特に空調機のVE案定価、三菱電機機器の価格）は提出前に最新の価格表で確認します。

Sheet 単価出典(内部)
A1: 単価出典（内部用） エスト見積 → エストマスタ → 推定 → 当社単価 → 要見積 の順で単価を決定
A3: 区分 | B3: 品名 | C3: 規格 | D3: 数量 | E3: 単位 | F3: 単価 | G3: 金額 | H3: 単価区分 | I3: アラート | J3: 単価の参照元
A4: 空調設備機器 | B4: AC-1 床置形ペア EcoZEAS | C4: SZRV80BZV（P80）単相200V | D4: ='内訳書(空調設備工事)'!E7 -> 2 | E4: 組 | F4: ='内訳書(空調設備工事)'!G7 -> 316500 | G4: ='内訳書(空調設備工事)'!H7 -> 633000 | H4: 原価基準（仕入率） | J4: 原価基準: 定価 1,266,000円（VE案 8月10日付 定価）× 仕入率 0.20（ダイキン業務用（EcoZEAS・FIVESTAR））＝原価 253,200円 ÷（1－目標粗利率 0.20）
A5: 空調設備機器 | B5: AC-2 壁掛形 | C5: S284ATEV-W（2.8kW）単相200V | D5: ='内訳書(空調設備工事)'!E9 -> 2 | E5: 組 | F5: ='内訳書(空調設備工事)'!G9 -> 142500 | G5: ='内訳書(空調設備工事)'!H9 -> 285000 | H5: 原価基準（仕入率） | J5: 原価基準: 定価 380,000円（VE案 8月10日付 定価）× 仕入率 0.30（ダイキン家庭用（定価あり））＝原価 114,000円 ÷（1－目標粗利率 0.20）
A6: 空調設備機器 | B6: AC-3 壁掛形 | C6: S404ATEV-W（4.0kW）単相200V | D6: ='内訳書(空調設備工事)'!E10 -> 1 | E6: 組 | F6: ='内訳書(空調設備工事)'!G10 -> 168750 | G6: ='内訳書(空調設備工事)'!H10 -> 168750 | H6: 原価基準（仕入率） | J6: 原価基準: 定価 450,000円（VE案 8月10日付 定価）× 仕入率 0.30（ダイキン家庭用（定価あり））＝原価 135,000円 ÷（1－目標粗利率 0.20）
A7: 空調設備工事 | B7: SA 室外機 | C7: P80（SZRV80BZV）地上設置 | D7: ='内訳書(空調設備工事)'!E15 -> 2 | E7: 台 | F7: ='内訳書(空調設備工事)'!G15 -> 8750 | G7: ='内訳書(空調設備工事)'!H15 -> 17500 | H7: エスト見積 | J7: エスト見積 6330560-1 SA 室外機 11.2-16.0
A8: 空調設備工事 | B8: SA 室内機 | C8: 床置形 P80（転倒防止金具共） | D8: ='内訳書(空調設備工事)'!E16 -> 2 | E8: 台 | F8: ='内訳書(空調設備工事)'!G16 -> 13000 | G8: ='内訳書(空調設備工事)'!H16 -> 26000 | H8: エストマスタ | J8: エストマスタ 搬入据付 スカイエア室内機 床置形 P140
A9: 空調設備工事 | B9: RA 室外機 | C9: セパレート 2.2-5.0（S284/S404） | D9: ='内訳書(空調設備工事)'!E17 -> 3 | E9: 台 | F9: ='内訳書(空調設備工事)'!G17 -> 6250 | G9: ='内訳書(空調設備工事)'!H17 -> 18750 | H9: エスト見積 | J9: エスト見積 6330560-1 RA 室外機 セパレート2.2-5.0
A10: 空調設備工事 | B10: RA 室内機 | C10: 壁掛（据付板・ドレンホース共） | D10: ='内訳書(空調設備工事)'!E18 -> 3 | E10: 台 | F10: ='内訳書(空調設備工事)'!G18 -> 6250 | G10: ='内訳書(空調設備工事)'!H18 -> 18750 | H10: エスト見積 | J10: エスト見積 6330560-1 RA 室内機 壁掛
A11: 空調設備工事 | B11: 基礎工事 | C11: 縁石基礎（SA 室外機 P80） | D11: ='内訳書(空調設備工事)'!E20 -> 2 | E11: 台 | F11: ='内訳書(空調設備工事)'!G20 -> 5000 | G11: ='内訳書(空調設備工事)'!H20 -> 10000 | H11: エスト見積 | J11: エスト見積 6330560-1 縁石 11.2-16.0
A12: 空調設備工事 | B12: 室外機置台 | C12: RA 室外機用 プラ製（防振ゴム付） | D12: ='内訳書(空調設備工事)'!E21 -> 3 | E12: 台 | F12: ='内訳書(空調設備工事)'!G21 -> 5500 | G12: ='内訳書(空調設備工事)'!H21 -> 16500 | H12: 当社単価（要確認） | I12: 単価要確認 | J12: 当社単価: 置台 2,500＋0.1人工（エストに単価なし）
A13: 空調設備工事 | B13: 試運転調整費 | C13: SA 室外機（-160） | D13: ='内訳書(空調設備工事)'!E23 -> 2 | E13: 台 | F13: ='内訳書(空調設備工事)'!G23 -> 10000 | G13: ='内訳書(空調設備工事)'!H23 -> 20000 | H13: エスト見積 | J13: エスト見積 6330560-1 試運転調整費 SA 室外機(-160)
A14: 空調設備工事 | B14: 試運転調整費 | C14: RA 室外機（0-56） | D14: ='内訳書(空調設備工事)'!E24 -> 3 | E14: 台 | F14: ='内訳書(空調設備工事)'!G24 -> 2500 | G14: ='内訳書(空調設備工事)'!H24 -> 7500 | H14: エスト見積 | J14: エスト見積 6330560-1 試運転調整費 RA 室外機(0-56)
A15: 配管設備工事 | B15: 冷媒用被覆銅管（10+20t） | C15: 9.52+15.88mm（10t+20t）AC-1 | D15: ='内訳書(空調設備工事)'!E32 -> 6 | E15: m | F15: ='内訳書(空調設備工事)'!G32 -> 5138 | G15: ='内訳書(空調設備工事)'!H32 -> 30828 | H15: エスト見積 | J15: エスト見積 6330560-1 冷媒用被覆銅管(10+20t) 9.52+15.88
A16: 配管設備工事 | B16: 冷媒用被覆銅管（10+20t） | C16: 6.35+9.52mm（10t+20t）AC-2・AC-3 | D16: ='内訳書(空調設備工事)'!E33 -> 12 | E16: m | F16: ='内訳書(空調設備工事)'!G33 -> 3388 | G16: ='内訳書(空調設備工事)'!H33 -> 40656 | H16: エスト見積 | J16: エスト見積 6330560-1 冷媒用被覆銅管(10+20t) 6.35+9.52
A17: 配管設備工事 | B17: 硬質塩化ビニル管 | C17: VP 25A（AC-1 ドレン） | D17: ='内訳書(空調設備工事)'!E38 -> 3 | E17: m | F17: ='内訳書(空調設備工事)'!G38 -> 313 | G17: ='内訳書(空調設備工事)'!H38 -> 939 | H17: エスト見積 | J17: エスト見積 6330560-1 硬質塩化ビニル管 VP 25A
A18: 配管設備工事 | B18: VVFケーブル（内外連絡線） | C18: 600V VV-F 2.0mm-3C | D18: ='内訳書(空調設備工事)'!E43 -> 25 | E18: m | F18: ='内訳書(空調設備工事)'!G43 -> 203 | G18: ='内訳書(空調設備工事)'!H43 -> 5075 | H18: エスト見積 | J18: エスト見積 6330560-1 VVF 2.0mm-3C
A19: 配管設備工事 | B19: 樹脂製化粧カバー | C19: 9.52+15.88 屋外（AC-1） | D19: ='内訳書(空調設備工事)'!E48 -> 2 | E19: m | F19: ='内訳書(空調設備工事)'!G48 -> 5525 | G19: ='内訳書(空調設備工事)'!H48 -> 11050 | H19: エスト見積 | J19: エスト見積 6330560-1 樹脂製化粧カバー（9.52+15.88 用と推定）
A20: 配管設備工事 | B20: 樹脂製化粧カバー | C20: 6.35+9.52 屋外（AC-2・3） | D20: ='内訳書(空調設備工事)'!E49 -> 6 | E20: m | F20: ='内訳書(空調設備工事)'!G49 -> 4225 | G20: ='内訳書(空調設備工事)'!H49 -> 25350 | H20: エスト見積 | J20: エスト見積 6330560-1 樹脂製化粧カバー（6.35+9.52 用と推定）
A21: 配管設備工事 | B21: 排水VP保温 GW20mm+ALGC | C21: 屋内隠蔽 25A | D21: ='内訳書(空調設備工事)'!E50 -> 2 | E21: m | F21: ='内訳書(空調設備工事)'!G50 -> 2563 | G21: ='内訳書(空調設備工事)'!H50 -> 5126 | H21: エスト見積 | J21: エスト見積 6330560-1 排水VP 屋内隠蔽 GW20mm+アルミガラスクロス（25A と推定）
A22: 配管設備工事 | B22: スリーブインサート費 | C22: 外壁貫通 穴あけ・シーリング | D22: ='内訳書(空調設備工事)'!E52 -> 5 | E22: 箇所 | F22: ='内訳書(空調設備工事)'!G52 -> 12500 | G22: ='内訳書(空調設備工事)'!H52 -> 62500 | H22: 推定（要確認） | I22: 単価要確認（推定） | J22: 按分: エスト見積 6330560-1 スリーブインサート費 50,000円／外壁貫通4箇所
A23: 配管設備工事 | B23: 気密テスト費 | C23: SA | D23: ='内訳書(空調設備工事)'!E53 -> 2 | E23: 系統 | F23: ='内訳書(空調設備工事)'!G53 -> 12500 | G23: ='内訳書(空調設備工事)'!H53 -> 25000 | H23: エスト見積 | J23: エスト見積 6330560-1 気密テスト費 SA
A24: 配管設備工事 | B24: 気密テスト費 | C24: RA | D24: ='内訳書(空調設備工事)'!E54 -> 3 | E24: 系統 | F24: ='内訳書(空調設備工事)'!G54 -> 10000 | G24: ='内訳書(空調設備工事)'!H54 -> 30000 | H24: エスト見積 | J24: エスト見積 6330560-1 気密テスト費 RA
A25: 配管設備工事 | B25: 真空引き・ガス充填 | C25: SA（基本料金） | D25: ='内訳書(空調設備工事)'!E55 -> 2 | E25: 系統 | F25: ='内訳書(空調設備工事)'!G55 -> 2500 | G25: ='内訳書(空調設備工事)'!H55 -> 5000 | H25: エスト見積 | J25: エスト見積 6330560-1 真空引き・ガス充填 SA（基本料金）
A26: 配管設備工事 | B26: 真空引き・ガス充填 | C26: RA（基本料金） | D26: ='内訳書(空調設備工事)'!E56 -> 3 | E26: 系統 | F26: ='内訳書(空調設備工事)'!G56 -> 1880 | G26: ='内訳書(空調設備工事)'!H56 -> 5640 | H26: エスト見積 | J26: エスト見積 6330560-1 真空引き・ガス充填 RA（基本料金）
A27: 換気設備機器 | B27: EF-1 パイプ用ファン | C27: V-08PP8-BL（三菱）φ100 BL品 | D27: ='内訳書(空調設備工事)'!E64 -> 3 | E27: 台 | F27: ='内訳書(空調設備工事)'!G64 -> 4920 | G27: ='内訳書(空調設備工事)'!H64 -> 14760 | H27: 原価基準（仕入率） | J27: 原価基準: 定価 12,300円（三菱電機 WIN2K 価格（税別））× 仕入率 0.32（三菱電機 換気機器）＝原価 3,936円 ÷（1－目標粗利率 0.20）
A28: 換気設備機器 | B28: EF-2 天井埋込形換気扇 | C28: VD-18ZC14（三菱）φ150 排煙用 | D28: ='内訳書(空調設備工事)'!E66 -> 5 | E28: 台 | F28: ='内訳書(空調設備工事)'!G66 -> 15920 | G28: ='内訳書(空調設備工事)'!H66 -> 79600 | H28: 原価基準（仕入率） | J28: 原価基準: 定価 39,800円（販売店掲載の参考基準価格（税別））× 仕入率 0.32（三菱電機 換気機器）＝原価 12,736円 ÷（1－目標粗利率 0.20）
A29: 換気設備機器 | B29: EF-3 天井埋込形換気扇 | C29: VD-15ZC14（三菱）φ100 台所 | D29: ='内訳書(空調設備工事)'!E67 -> 1 | E29: 台 | F29: ='内訳書(空調設備工事)'!G67 -> 10080 | G29: ='内訳書(空調設備工事)'!H67 -> 10080 | H29: 原価基準（仕入率） | J29: 原価基準: 定価 25,200円（販売店掲載の参考基準価格（税別））× 仕入率 0.32（三菱電機 換気機器）＝原価 8,064円 ÷（1－目標粗利率 0.20）
A30: 換気設備機器 | B30: EF-4 天井埋込形換気扇 | C30: VD-10ZC14（三菱）φ100 | D30: ='内訳書(空調設備工事)'!E68 -> 1 | E30: 台 | F30: ='内訳書(空調設備工事)'!G68 -> 8280 | G30: ='内訳書(空調設備工事)'!H68 -> 8280 | H30: 原価基準（仕入率） | J30: 原価基準: 定価 20,700円（販売店掲載の参考基準価格（税別））× 仕入率 0.32（三菱電機 換気機器）＝原価 6,624円 ÷（1－目標粗利率 0.20）
A31: 換気設備機器 | B31: SA-1 給排気グリル | C31: P-23GHF5（三菱）φ200 フィルター付 | D31: ='内訳書(空調設備工事)'!E70 -> 4 | E31: 個 | F31: ='内訳書(空調設備工事)'!G70 -> 4360 | G31: ='内訳書(空調設備工事)'!H70 -> 17440 | H31: 原価基準（仕入率） | J31: 原価基準: 定価 10,900円（三菱電機 WIN2K 価格（税別））× 仕入率 0.32（三菱電機 換気機器）＝原価 3,488円 ÷（1－目標粗利率 0.20）
A32: 換気設備機器 | B32: SA-2 給排気グリル | C32: P-18GHF5（三菱）φ150 フィルター付 | D32: ='内訳書(空調設備工事)'!E71 -> 1 | E32: 個 | F32: ='内訳書(空調設備工事)'!G71 -> 2400 | G32: ='内訳書(空調設備工事)'!H71 -> 2400 | H32: 原価基準（仕入率） | J32: 原価基準: 定価 6,000円（販売店掲載の参考基準価格（税別））× 仕入率 0.32（三菱電機 換気機器）＝原価 1,920円 ÷（1－目標粗利率 0.20）
A33: 換気設備機器 | B33: SA-3 給排気グリル | C33: P-13GHF5（三菱）φ100 フィルター付 | D33: ='内訳書(空調設備工事)'!E72 -> 3 | E33: 個 | F33: ='内訳書(空調設備工事)'!G72 -> 1840 | G33: ='内訳書(空調設備工事)'!H72 -> 5520 | H33: 原価基準（仕入率） | J33: 原価基準: 定価 4,600円（販売店掲載の参考基準価格（税別）（税込5,060円））× 仕入率 0.32（三菱電機 換気機器）＝原価 1,472円 ÷（1－目標粗利率 0.20）
A34: 換気設備機器 | B34: 深形フード | C34: P-13VSQ4（三菱）φ100 SUS 防虫網付 | D34: ='内訳書(空調設備工事)'!E74 -> 8 | E34: 個 | F34: ='内訳書(空調設備工事)'!G74 -> 4200 | G34: ='内訳書(空調設備工事)'!H74 -> 33600 | H34: 原価基準（仕入率） | J34: 原価基準: 定価 10,500円（販売店掲載の参考基準価格（税別））× 仕入率 0.32（三菱電機 換気機器）＝原価 3,360円 ÷（1－目標粗利率 0.20）
A35: 換気設備機器 | B35: 深形フード | C35: P-18VSQ4（三菱）φ150 SUS 防虫網付 | D35: ='内訳書(空調設備工事)'!E75 -> 6 | E35: 個 | F35: ='内訳書(空調設備工事)'!G75 -> 5320 | G35: ='内訳書(空調設備工事)'!H75 -> 31920 | H35: 原価基準（仕入率） | J35: 原価基準: 定価 13,300円（三菱電機 WIN2K 価格（税別））× 仕入率 0.32（三菱電機 換気機器）＝原価 4,256円 ÷（1－目標粗利率 0.20）
A36: 換気設備機器 | B36: 深形フード | C36: P-23VSQ4（三菱）φ200 SUS 防虫網付 | D36: ='内訳書(空調設備工事)'!E76 -> 4 | E36: 個 | F36: ='内訳書(空調設備工事)'!G76 -> 13360 | G36: ='内訳書(空調設備工事)'!H76 -> 53440 | H36: 原価基準（仕入率） | J36: 原価基準: 定価 33,400円（販売店掲載の参考基準価格（税別））× 仕入率 0.32（三菱電機 換気機器）＝原価 10,688円 ÷（1－目標粗利率 0.20）
A37: 換気設備工事 | B37: パイプ用ファン取付 | C37: V-08PP8-BL 外壁付け（VU100共） | D37: ='内訳書(空調設備工事)'!E81 -> 3 | E37: 台 | F37: ='内訳書(空調設備工事)'!G81 -> 9400 | G37: ='内訳書(空調設備工事)'!H81 -> 28200 | H37: 当社単価（要確認） | I37: 単価要確認 | J37: 当社単価: 材料800（VU100・ビス）＋0.35人工（エストに単価なし）
A38: 換気設備工事 | B38: 天井埋込形換気扇取付 | C38: VD-18ZC14（吊ボルト共） | D38: ='内訳書(空調設備工事)'!E82 -> 5 | E38: 台 | F38: ='内訳書(空調設備工事)'!G82 -> 15300 | G38: ='内訳書(空調設備工事)'!H82 -> 76500 | H38: 当社単価（要確認） | I38: 単価要確認 | J38: 当社単価: 材料800（吊ボルト・振れ止め）＋0.6人工（エストに単価なし）
A39: 換気設備工事 | B39: 天井埋込形換気扇取付 | C39: VD-15ZC14・VD-10ZC14 | D39: ='内訳書(空調設備工事)'!E83 -> 2 | E39: 台 | F39: ='内訳書(空調設備工事)'!G83 -> 11400 | G39: ='内訳書(空調設備工事)'!H83 -> 22800 | H39: 当社単価（要確認） | I39: 単価要確認 | J39: 当社単価: 材料500＋0.45人工（エストに単価なし）
A40: 換気設備工事 | B40: 給排気グリル取付 | C40: φ100〜φ200 ダクト接続共 | D40: ='内訳書(空調設備工事)'!E84 -> 8 | E40: 個 | F40: ='内訳書(空調設備工事)'!G84 -> 6400 | G40: ='内訳書(空調設備工事)'!H84 -> 51200 | H40: 当社単価（要確認） | I40: 単価要確認 | J40: 当社単価: 材料300＋0.25人工（エストに単価なし）
A41: 換気設備工事 | B41: 屋外フード取付 | C41: 深形フード φ100〜φ200 | D41: ='内訳書(空調設備工事)'!E85 -> 18 | E41: 個 | F41: ='内訳書(空調設備工事)'!G85 -> 4000 | G41: ='内訳書(空調設備工事)'!H85 -> 72000 | H41: 当社単価（要確認） | I41: 単価要確認 | J41: 当社単価: 材料300＋0.15人工（エストに単価なし）
...

Sheet エストマスタ(参考)
A1: エスト単価マスタ（参考・抜粋） エスト見積 6330560-1 に単価がない種別はこのマスタの値を採用
A3: 区分 | B3: 種別 | C3: 単価（円）
A4: 基礎工事 スカイエア | B4: 縁石基礎 | C4: P28〜P140 5,000 ／ P160〜P280 8,000
A5: 基礎工事 スカイエア | B5: ベタ基礎 | C5: P28〜P56 22,000 ／ P63〜P140 33,000 ／ P160〜P280 39,000
A6: 搬入据付 スカイエア室内機 | B6: 天井埋込カセット形 | C6: P28〜P56 28,000 ／ P63〜P80 28,500 ／ P90〜P160 29,000
A7: 搬入据付 スカイエア室内機 | B7: 天井吊形 | C7: P36〜P56 16,000 ／ P63〜P80 16,500 ／ P90〜P112 17,000 ／ P125〜P160 23,000
A8: 搬入据付 スカイエア室内機 | B8: 壁掛形 | C8: P36〜P56 8,000 ／ P63〜P112 12,000
A9: 搬入据付 スカイエア室内機 | B9: ダクト形 | C9: P50・P63 16,500 ／ P80 17,000 ／ P112〜P160 23,000
A10: 搬入据付 スカイエア室外機 | B10: 地上設置 ／ 2F設置 ／ 3F設置 | C10: P112 13,000・33,000・48,000 ／ P140 15,000・35,000・50,000
A11: 搬入据付 ルームエアコン | B11: 室内機 壁掛形 ／ 室外機 地上設置 | C11: P22 5,000 ／ 2,000
A12: フレキダクト工事 スカイエア | B12: 5m以下 ／ 追加1m ／ 吹出口1ケ | C12: 21,000 ／ 4,200 ／ 6,000
A13: 冷媒配管（テープ巻き）新築 | B13: φ6.4/9.5 ／ φ6.4/12.7 ／ φ9.5/15.9 | C13: 5m以下 26,000・27,700・29,500 ＋1m追加 5,300・5,600・5,900
A14: 外装仕上げ スカイダクト | B14: φ6.4/9.5・φ6.4/12.7 ／ φ9.5/15.9 | C14: 5m以下 10,500 ／ 15,800 ＋1m追加 2,100 ／ 2,600
... A16: ドレン配管 新築 | B16: φ6.4/9.5 ／ それ以外 | C16: 5m以下 10,500 ／ 14,200 ＋1m追加 2,100 ／ 2,800

Sheet 数量拾い根拠(内部)
A1: 数量拾い根拠（内部用） 当社作図 M-1 空調設備平面図・M-2 換気設備平面図（JWW、1単位＝実寸50mm）の配置座標から算出
A2: 空調は室外機を各室の外壁直近に置く計画のため配管は短く、最小配管長・立下り・余長を想定値で計上。換気ダクトは器具〜外壁の平面距離＋立上り・接続 0.5m/本。座標・機器定義は drawings/tools/project_data.py
A4: 1. 冷媒・ドレン配管（M-1 空調設備平面図：室外機は各室外壁の直近）
A5: 系統 | B5: 管径 | C5: 数量 | D5: 1系統(m) | E5: 合計(m) | F5: 想定内容
A6: AC-1 SZRV80BZV 床置形（大間・外陣） | B6: φ9.52/15.88 | C6: 2 | D6: 3 | E6: 6 | F6: AC-1 床置形 2系統 × 3.0m（室外機は外壁直近。最小配管長 3m を確保、壁貫通・立上り・余長込み）
A7: AC-2 S284ATEV-W・AC-3 S404ATEV-W 壁掛形 | B7: φ6.35/9.52 | C7: 3 | D7: 4 | E7: 12 | F7: AC-2・AC-3 壁掛形 3台 × 4.0m（壁掛 約2.2m → 屋外置台への立下り・余長込み）
A8: ドレン VP25（AC-1） | B8: 25A | C8: 2 | D8: 1.5 | E8: 3 | F8: AC-1 2系統 × 1.5m（室内 1.0m＋屋外放流 0.5m）。ルームエアコンは付属ドレンホース
A9: 内外連絡線 VVF 2.0-3C | C9: 5 | D9: 5 | E9: 25 | F9: 内外連絡線 AC-1 5.0m×2・AC-2/3 5.0m×3（余長込み）
A11: 2. 換気ダクト（M-2 換気設備平面図：器具〜外壁の平面距離＋立上り・接続）
A12: 記号 | B12: 室名 | C12: 口径 | D12: 平面(m) | E12: 計(m) | F12: 備考
A13: SA-1 | B13: 外陣（大間） | C13: φ200 | D13: 1.37 | E13: 1.87 | F13: 給気（外気導入）
A14: SA-1 | B14: 外陣（大間） | C14: φ200 | D14: 1.37 | E14: 1.87 | F14: 給気（外気導入）
A15: SA-1 | B15: 外陣（大間） | C15: φ200 | D15: 1.37 | E15: 1.87 | F15: 給気（外気導入）
A16: SA-1 | B16: 内陣（本陣・御本尊） | C16: φ200 | D16: 5.11 | E16: 5.61 | F16: 給気（外気導入）
A17: SA-2 | B17: 護摩堂 | C17: φ150 | D17: 0.86 | E17: 1.36 | F17: 給気（外気導入）
A18: SA-3 | B18: 和室(1) | C18: φ100 | D18: 0.41 | E18: 0.91 | F18: 給気（外気導入）
A19: SA-3 | B19: 和室(2) | C19: φ100 | D19: 1.7 | E19: 2.2 | F19: 給気（外気導入）
A20: SA-3 | B20: 談話室 | C20: φ100 | D20: 0.95 | E20: 1.45 | F20: 給気（外気導入）
A21: EF-2 | B21: 外陣（大間） | C21: φ150 | D21: 3.37 | E21: 3.87 | F21: 局所排気
A22: EF-2 | B22: 外陣（大間） | C22: φ150 | D22: 3.37 | E22: 3.87 | F22: 局所排気
A23: EF-2 | B23: 外陣（大間） | C23: φ150 | D23: 3.37 | E23: 3.87 | F23: 局所排気
A24: EF-2 | B24: 内陣（本陣・御本尊） | C24: φ150 | D24: 5.37 | E24: 5.87 | F24: 局所排気
... A27: EF-4 | B27: パントリー | C27: φ100 | D27: 0.51 | E27: 1.01 | F27: 局所排気
A28: 合計 → 内訳書 | E28: 39.29 | F28: φ100 7m・φ150 22m・φ200 12m、保温（給気）18m
A30: 3. 機器・外壁貫通（図面カウント）
A31: 項目 | B31: 数量 | C31: 備考
A32: 24時間換気 パイプファン V-08PP8-BL | B32: 3台 | C32: 便所(女)・小便所・便所(男) 外壁付け
A33: 天井埋込形換気扇 VD-18ZC14 / VD-15ZC14 / VD-10ZC14 | B33: 5・1・1台 | C33: 局所換気（排煙・台所・パントリー）
A34: 給排気グリル P-23GHF5 / P-18GHF5 / P-13GHF5 | B34: 4・1・3個 | C34: 外気導入（給気）
A35: 外壁貫通・深形フード φ100 / φ150 / φ200 | B35: 8・6・4箇所 | C35: パイプファン・給気・局所排気
A36: 空調 外壁貫通（冷媒・ドレン） | B36: 5箇所 | C36: AC-1 ×2、AC-2・AC-3 ×3

Sheet 原価根拠(内部)
A1: 原価根拠（内部用） 材料＝建設物価相当、労務＝人工×労務原価日額、法定福利費＝労務原価×事業主負担率
A3: 出典
A4: エスト見積 | B4: 見積番号 6330560-1（2026年10月8日、2026/11月からの価格）。単価・経費率・配管工費の算式の基準
A5: エスト単価マスタ | B5: 搬入据付・基礎・フレキダクト・冷媒配管/外装仕上げ/ドレン配管（5m以下＋1m追加）
A6: 公共工事設計労務単価 | B6: 令和8年3月適用（農林水産省・国土交通省）広島県: 配管工 24,700、保温工 25,100、電工 26,300 円/日
A7: 公共建築工事標準単価積算基準 | B7: 令和8年改定（国土交通省 官庁営繕部）表M1-1-50 冷媒用断熱材被覆銅管、表M1-1-46 硬質ポリ塩化ビニル管
A8: メーカー公表価格 | B8: 桃陽電線 冷媒用被覆銅管 標準単価表 2026年2月1日改定版（国交省仕様 10×20mm保温 2分3分 110,600・2分4分 130,300・3分5分 175,400 円/20m）
A9: 建設物価 | B9: 会員制のため数値未取得。自治体の公表単価表でも冷媒管・保温は主要資材として非公表。材料原価はエスト材料単価を建設物価相当として採用
A11: 公共工事設計労務単価（令和8年3月適用・広島県、円/日）
A12: 配管工 | B12: 24700
A13: 保温工 | B13: 25100
A14: 電工 | B14: 26300
A15: ダクト工 | B15: 24300
A16: 普通作業員 | B16: 22200
A17: 特殊作業員 | B17: 25800
A18: 設備機械工 | B18: 29500
A19: 鉄骨工 | B19: 27000
A20: 溶接工 | B20: 27300
A22: 国交省 公共建築工事標準単価積算基準（令和8年改定）配管工 歩掛（人/m）
A23: 被覆銅管6.35+9.52 | B23: 0.104
A24: 被覆銅管6.35+12.70 | B24: 0.118
A25: 被覆銅管9.52+15.88 | B25: 0.15
A26: VP25 | B26: 0.074
A27: VP30 | B27: 0.079
A28: VP40 | B28: 0.101
A29: VVF2.0-3C | B29: 0.017
A31: 原価の前提（内訳書 L・M 列の黄セル）
A32: ・機器: 原価＝定価×仕入率（ダイキン業務用 EcoZEAS・FIVESTAR 0.20、ダイキン家庭用 0.30、三菱電機 換気機器 0.32）。内訳書 L 列＝原価（定額）、提出単価＝原価÷（1－0.20）の10円未満切上げ
A33: ・据付の人工: SA 室外 0.8・床置室内 0.8、RA 室外 0.4・室内 0.5 人工/台。縁石基礎 材料2,500＋0.15、RA 置台 2,500＋0.1
A34: ・試運転: SA 材料450＋0.45、RA 0.15人工。気密: SA 2,000＋0.45、RA 1,000＋0.3。真空引き: SA 500＋0.15、RA 300＋0.12
A35: ・化粧カバー: 大径2,400・小径1,800円/m＋0.10人工/m。GW保温 25A: 900＋0.06人工/m。スリーブ: 材料1,500＋0.25人工/箇所
A36: ・換気: パイプファン取付 800＋0.35、天井扇 VD-18 800＋0.6・VD-15/10 500＋0.45、グリル 300＋0.25、フード 300＋0.15、スパイラルダクト φ100 1,000＋0.12・φ150 1,400＋0.14・φ200 1,900＋0.16（/m、三矢寮の当社想定）、ダクト保温 1,100＋0.08/m、外壁貫通 φ100 800＋0.25・φ150 1,000＋0.30・φ200 1,200＋0.35、試運転 3,000＋1.0人工
A37: ・当社単価の項目（要確認）は 原価×1.25 を100円切上げ（粗利20%相当）。エストに同種の単価が見つかれば差し替える
