Workbook
Name TARGET_MARGIN: '表紙(工事)'!$N$4
Name ROUND_UNIT: '表紙(工事)'!$N$5
Name LABOR_COST: '表紙(工事)'!$N$6
Name MAT_RATIO: '表紙(工事)'!$N$7
Name EST_LABOR_PIPE: '表紙(工事)'!$N$8
Name EST_LABOR_ELEC: '表紙(工事)'!$N$9
Name WELFARE_RATE: '法定福利費内訳明細書'!$E$27
Name INCLUDE_TBD: '表紙(工事)'!$N$11
Name TARGET: '表紙(工事)'!$N$12
Name SUBMIT: '表紙(工事)'!$N$13
Name COST_TOTAL: '表紙(工事)'!$O$27

Sheet 表紙(工事)
A1: 御 見 積 書
J3: No. | M3: 【設定・内部用】（印刷範囲外）黄セル＝入力
J4: 46303 | M4: 目標粗利率 | N4: 0.2
A5: 今治空調設備 | G5: 御中 | M5: 提出額の丸め単位（切上げ） | N5: 10000
M6: 労務原価日額（円/人工、当社） | N6: 19000
A7: 金額 | B7: ="¥"&TEXT(K28,"#,##0")&"-" -> ¥1,290,000- | F7: （税別） | H7: 宮地機工株式会社 | M7: 材料原価率（エスト材料単価＝建設物価相当に対する比率） | N7: 1
M8: エスト労務単価 配管工費（円/人） | N8: 33750
A9: つぎのとおりお見積いたしました。 | H9: 代表取締役 濱本 義樹 | M9: エスト労務単価 電線材料施工費（円/人） | N9: 33600
A10: なにとぞご用命くださいますようお願い申しあげます。 | M10: 法定福利費率（事業主負担） | N10: =WELFARE_RATE -> 0.16375
H11: 〒722-0051 | M11: 要見積（概算）を提出額に含める（1=含める／0=別途見積） | N11: 0
A12: 件名 | D12: 吉野家 呉海岸店 | H12: 広島県尾道市東尾道9-9 | M12: 目標提出額（税別・空欄なら粗利率から自動）
D13: 空調設備工事 | H13: TEL.0848-20-2121 | K13: FAX.0848-20-2126 | M13: 提出額（自動計算） | N13: =IF(TARGET="",ROUNDUP(COST_TOTAL/(1-TARGET_MARGIN)/ROUND_UNIT,0)*ROUND_UNIT,TARGET) -> 1290000
A14: 施工場所 | D14: 広島県呉市海岸（国道31号沿い） | H14: 担当者 | J14: 濱本 義武 | M14: ※ 提出額＝原価合計÷（1－目標粗利率）を丸め単位で切上げ。小計（エスト単価の定価ベース）との差を出精値引に計上
A15: 工事期限 | D15: 工程表による（全体工期 2026年9月1日～2026年11月16日） | M15: ※ 原価＝材料（エスト材料単価×材料原価率＝建設物価相当）＋人工×労務原価日額＋法定福利費（事業主負担）
A16: 支払条件 | D16: 御協議による
A17: 本書有効期間 | D17: 10日
A19: 項 | B19: 品 名 | G19: 数 量 | H19: 単位 | I19: 単 価 | K19: 金 額 | L19: 備 考 | M19: 内部集計 | N19: 定価ベース | O19: 原価 | P19: 粗利 | Q19: 粗利率
B20: 【吉野家 呉海岸店 空調設備工事】 空気調和工事
B21: =IF(INCLUDE_TBD=1,"［空調機・リモコン・吹出しパンカーは支給品。鉄骨架台は概算計上（詳細見積後に精算）］","［空調機・リモコン・吹出しパンカーは支給品。鉄骨架台は別途御見積］") -> ［空調機・リモコン・吹出しパンカーは支給品。鉄骨架台は別途御見積］
A22: ① | B22: 空調設備機器 | G22: 1 | H22: 式 | I22: =K22 -> 0 | K22: 0 | L22: 支給品
A23: ② | B23: 空調設備工事 | G23: 1 | H23: 式 | I23: =K23 -> 190000 | K23: ='内訳書(空調設備工事)'!H22 -> 190000 | L23: 内訳書 ２ | M23: ②空調設備工事 | N23: =K23 -> 190000 | O23: ='内訳書(空調設備工事)'!P22 -> 181819 | P23: =N23-O23 -> 8181 | Q23: =IF(N23=0,"",P23/N23) -> 0.043057895
A24: ③ | B24: 配管設備工事 | G24: 1 | H24: 式 | I24: =K24 -> 1114000 | K24: ='内訳書(空調設備工事)'!H60 -> 1114000 | L24: 内訳書 ３ | M24: ③配管設備工事 | N24: =K24 -> 1114000 | O24: ='内訳書(空調設備工事)'!P60 -> 771033 | P24: =N24-O24 -> 342967 | Q24: =IF(N24=0,"",P24/N24) -> 0.30786984
A25: ④ | B25: 工事諸経費 | G25: 1 | H25: 式 | I25: =K25 -> 65200 | K25: ='内訳書(空調設備工事)'!H62 -> 65200 | L25: 内訳書 ８ | M25: ④工事諸経費（原価なし） | N25: =K25 -> 65200 | O25: 0 | P25: =N25-O25 -> 65200 | Q25: =IF(N25=0,"",P25/N25) -> 1
B26: 小 計 | K26: =SUM(K22:K25) -> 1369200 | M26: 法定福利費（事業主負担・原価） | O26: =ROUND('内訳書(空調設備工事)'!Q64*WELFARE_RATE,0) -> 71251
A27: ⑤ | B27: 出精値引 | K27: =IF(SUBMIT<K26,SUBMIT-K26,0) -> -79200 | M27: 原価合計 | N27: =K26 -> 1369200 | O27: =SUM(O23:O26) -> 1024103
B28: 合 計 | K28: =K26+K27 -> 1290000 | L28: （税別） | M28: 提出額（合計）／粗利／粗利率 | N28: =K28 -> 1290000 | O28: =O27 -> 1024103 | P28: =N28-O28 -> 265897 | Q28: =IF(N28=0,"",P28/N28) -> 0.20612171
A30: 上記の工事費には、以下の法定福利費相当額を含んでいます。
A31: ="【法定福利費相当額（Ａ）】"&TEXT('法定福利費内訳明細書'!$F$27,"#,##0")&"円 Ａ＝Ｙ×Ｚ Ｙ：労務費相当額 "&TEXT('法定福利費内訳明細書'!$C$16,"#,##0")&"円 Ｚ：法定福利費事業者負担率（合計値："&TEXT('法定福利費内訳明細書'!$E$27*100,"0.000")&"／100）" -> 【法定福利費相当額（Ａ）】96,545円 Ａ＝Ｙ×Ｚ Ｙ：労務費相当額 589,610円 Ｚ：法定福利費事業者負担率（合計値：16.375／100） | M31: ⚠ アラート（提出前に確認）
M32: 要見積 2件：架台制作及び取付費（概算原価の合計） | N32: ='内訳書(空調設備工事)'!E14*'内訳書(空調設備工事)'!V14+'内訳書(空調設備工事)'!E15*'内訳書(空調設備工事)'!V15 -> 550000 | O32: =IF(INCLUDE_TBD=1,"概算を提出額に含めています","別途見積（提出額に含めていません）") -> 別途見積（提出額に含めていません）
A33: ※ | B33: 本見積は2026年11月からの価格で作成しております。数量は換気空調機器表（F-01）・空調設備図（F-02-1）・平面図（A-08）より当社にて拾い出しており、実施数量との差異は別途精算とさせていただきます。 | M33: 要見積を概算で含めた場合の提出額（目安） | N33: =IF(INCLUDE_TBD=1,SUBMIT,ROUNDUP((COST_TOTAL+N32)/(1-TARGET_MARGIN)/ROUND_UNIT,0)*ROUND_UNIT) -> 1970000 | O33: N11 を 1 にすると反映
A34: ※ | B34: 空調機（AC-1・AC-2・RAC の室内機・室外機・リモコン）および吹出しパンカーは支給品のため含みません（搬入・吊込み・据付費を計上）。 | M34: 単価要確認 1件：ドレンホース用逆止弁 | O34: エスト単価なし。当社単価で仮計上
A35: ※ | B35: 鉄骨架台（2段積み・溶融亜鉛メッキ）は製作品のため別途御見積とさせていただきます。 | M35: エストと数量が異なる行 6件（内訳書 K列・エスト比較シート） | O35: SA室外機3台（エスト2台）ほか
A36: ※ | B36: リモコン配線、AC-2 吹出しダクト・吹出しパンカー取付、換気設備、電源・接地等の電気工事、建築工事、揚重機、足場・仮設、撤去・産業廃棄物処分は含みません。 | M36: 定価ベース（エスト単価）で目標粗利に届くか | O36: =IF(SUBMIT>K26,"⚠ 値引きなしでも粗利率 "&TEXT((K26-COST_TOTAL)/K26,"0.0%")&"（目標未達）","OK（出精値引で調整）") -> OK（出精値引で調整）
A37: ※ | B37: 本見積書に記載なき事項については別途とさせて頂きます。工事に係る電気・水道は無償支給願います。本見積金額には消費税は含まれておりません。
A38: ※ | B38: 詳細条件は別紙「御見積条件」をご参照ください。 | M38: 参考（感度・エストとの比較） | N38: 金額 | O38: 原価 | Q38: 粗利率
M39: エスト見積 6330560-1 の提出額（当社数量・当社原価で見た粗利率） | N39: 1100000 | O39: =COST_TOTAL -> 1024103 | Q39: =(N39-O39)/N39 -> 0.068997273
M40: 労務を公共工事設計労務単価（広島 配管工 24,700）で計算した場合 | N40: =K28 -> 1290000 | O40: =COST_TOTAL+'内訳書(空調設備工事)'!M64*(N44-LABOR_COST)*(1+WELFARE_RATE) -> 1176013.9 | Q40: =(N40-O40)/N40 -> 0.088361302
M41: 出精値引率（変更増減の算定に使用：増減額×(1－この率)） | N41: =IF(K26=0,"",-K27/K26) -> 0.057843996
M42: 人工合計（内訳書） | N42: ='内訳書(空調設備工事)'!M64 -> 22.901
M44: 公共工事設計労務単価 広島 配管工（R8.3） | N44: 24700
...

Sheet 内訳書(空調設備工事)
A1: 内 訳 書 | J1: 原 価・エスト比較（内部用・印刷範囲外） 黄セル＝入力、赤＝要見積、橙＝単価要確認・エストと数量差
A2: 工事名：吉野家 呉海岸店 空調設備工事 | I2: 内訳書 No.1
A3: 品 名 | C3: 規格・寸法 | E3: 数 量 | F3: 単位 | G3: 単 価 | H3: 金 額 | I3: 備 考 | J3: 単価区分 | K3: アラート | L3: 材料原価/単位 | M3: 人工/単位 | N3: 労務原価/単位 | O3: 原価単価 | P3: 原価金額 | Q3: 労務原価金額 | R3: 労務費相当額(提出) | S3: 粗利(定価) | T3: 粗利率 | U3: 率・歩掛 | V3: 要見積 概算原価/単位 | W3: エスト数量 | X3: エスト単価 | Y3: エスト金額 | Z3: 差額(当社-エスト) | AA3: エストマスタ参考 | AB3: 数量根拠 | AC3: 出典・メモ（内部）
A4: 空気調和工事
A5: ２ 空調設備工事
A6: 搬入据付工事
A7: RA 室外機 | C7: セパレート2.2-5.0（店長室 RAC）架台上段 | E7: 1 | F7: 台 | G7: 6250 | H7: =ROUND(E7*G7,0) -> 6250 | I7: 支給品の据付 | J7: エスト見積 | L7: 500 | M7: 0.5 | N7: =ROUND(M7*LABOR_COST,0) -> 9500 | O7: =L7+N7 -> 10000 | P7: =E7*O7 -> 10000 | Q7: =E7*N7 -> 9500 | R7: =IF(H7=0,0,IF(E7*M7*EST_LABOR_PIPE>H7,H7,E7*M7*EST_LABOR_PIPE)) -> 6250 | S7: =IF(H7="","",H7-P7) -> -3750 | T7: =IF(OR(H7="",H7=0),"",S7/H7) -> -0.6 | W7: 1 | X7: 6250 | Y7: 6250 | Z7: =H7-Y7 -> 0 | AA7: RA室外機 地上設置 P22 2,000 | AB7: 図面カウント | AC7: 架台上段への揚重を人工に含む
A8: RA 室内機 | C8: 壁掛 2.2kW（店長室） | E8: 1 | F8: 台 | G8: 6250 | H8: =ROUND(E8*G8,0) -> 6250 | I8: 支給品の据付 | J8: エスト見積 | L8: 500 | M8: 0.4 | N8: =ROUND(M8*LABOR_COST,0) -> 7600 | O8: =L8+N8 -> 8100 | P8: =E8*O8 -> 8100 | Q8: =E8*N8 -> 7600 | R8: =IF(H8=0,0,IF(E8*M8*EST_LABOR_PIPE>H8,H8,E8*M8*EST_LABOR_PIPE)) -> 6250 | S8: =IF(H8="","",H8-P8) -> -1850 | T8: =IF(OR(H8="",H8=0),"",S8/H8) -> -0.296 | W8: 1 | X8: 6250 | Y8: 6250 | Z8: =H8-Y8 -> 0 | AA8: RA室内機 壁掛形 P22 5,000 | AB8: 図面カウント
A9: SA 室外機 | C9: 11.2-16.0（AC-1×2・AC-2、5HP） | E9: 3 | F9: 台 | G9: 8750 | H9: =ROUND(E9*G9,0) -> 26250 | I9: 支給品の据付 | J9: エスト見積 | K9: エストと数量差 | L9: 1500 | M9: 0.967 | N9: =ROUND(M9*LABOR_COST,0) -> 18373 | O9: =L9+N9 -> 19873 | P9: =E9*O9 -> 59619 | Q9: =E9*N9 -> 55119 | R9: =IF(H9=0,0,IF(E9*M9*EST_LABOR_PIPE>H9,H9,E9*M9*EST_LABOR_PIPE)) -> 26250 | S9: =IF(H9="","",H9-P9) -> -33369 | T9: =IF(OR(H9="",H9=0),"",S9/H9) -> -1.2712 | W9: 2 | X9: 8750 | Y9: 17500 | Z9: =H9-Y9 -> 8750 | AA9: SA室外機 地上設置 P140 15,000 | AB9: 図面カウント | AC9: 架台下段2台 0.8人・上段1台 1.3人（揚重）の平均。エストは2台（AC-1を1系統と入力した可能性）
A10: SA 室内機 | C10: ダクト形11.2-16（AC-2 天井ビルトイン 5HP） | E10: 1 | F10: 台 | G10: 27500 | H10: =ROUND(E10*G10,0) -> 27500 | I10: 支給品の吊込み | J10: エスト見積 | L10: 2500 | M10: 1.2 | N10: =ROUND(M10*LABOR_COST,0) -> 22800 | O10: =L10+N10 -> 25300 | P10: =E10*O10 -> 25300 | Q10: =E10*N10 -> 22800 | R10: =IF(H10=0,0,IF(E10*M10*EST_LABOR_PIPE>H10,H10,E10*M10*EST_LABOR_PIPE)) -> 27500 | S10: =IF(H10="","",H10-P10) -> 2200 | T10: =IF(OR(H10="",H10=0),"",S10/H10) -> 0.08 | W10: 1 | X10: 27500 | Y10: 27500 | Z10: =H10-Y10 -> 0 | AA10: SA室内機 ダクト形 P140 23,000 | AB10: 図面カウント | AC10: 吊ボルト・受け金物共
A11: SA 室内機 | C11: カセット形2.8-16（AC-1 天井カセット 5HP） | E11: 2 | F11: 台 | G11: 25000 | H11: =ROUND(E11*G11,0) -> 50000 | I11: 支給品の吊込み | J11: エスト見積 | L11: 2000 | M11: 0.9 | N11: =ROUND(M11*LABOR_COST,0) -> 17100 | O11: =L11+N11 -> 19100 | P11: =E11*O11 -> 38200 | Q11: =E11*N11 -> 34200 | R11: =IF(H11=0,0,IF(E11*M11*EST_LABOR_PIPE>H11,H11,E11*M11*EST_LABOR_PIPE)) -> 50000 | S11: =IF(H11="","",H11-P11) -> 11800 | T11: =IF(OR(H11="",H11=0),"",S11/H11) -> 0.236 | W11: 2 | X11: 25000 | Y11: 50000 | Z11: =H11-Y11 -> 0 | AA11: SA室内機 天井埋込カセット形 P140 29,000 | AB11: 図面カウント | AC11: 吊ボルト・受け金物・化粧パネル取付共
A12: 基礎工事
A13: 縁石 | C13: 22.4-28.0（2段架台用） | E13: 2 | F13: 台 | G13: 7500 | H13: =ROUND(E13*G13,0) -> 15000 | J13: エスト見積 | L13: 3000 | M13: 0.15 | N13: =ROUND(M13*LABOR_COST,0) -> 2850 | O13: =L13+N13 -> 5850 | P13: =E13*O13 -> 11700 | Q13: =E13*N13 -> 5700 | R13: =IF(H13=0,0,IF(E13*M13*EST_LABOR_PIPE>H13,H13,E13*M13*EST_LABOR_PIPE)) -> 10125 | S13: =IF(H13="","",H13-P13) -> 3300 | T13: =IF(OR(H13="",H13=0),"",S13/H13) -> 0.22 | W13: 2 | X13: 7500 | Y13: 15000 | Z13: =H13-Y13 -> 0 | AA13: 縁石基礎 P224〜P280 8,000（P140 5,000） | AB13: 図面カウント | AC13: 架台2基分。エストは 22.4-28.0×2 ＋ 11.2-16.0×1（5,000）の3台
A14: 架台制作及び取付費 | C14: 鉄骨2段積み 溶融亜鉛メッキ（AC-1 上下段用・防振ゴム共） | E14: 1 | F14: 基 | G14: =IF(INCLUDE_TBD=1,ROUNDUP(V14/(1-TARGET_MARGIN),-3),"") | H14: =IF(INCLUDE_TBD=1,ROUND(E14*G14,0),0) -> 0 | I14: =IF(INCLUDE_TBD=1,"概算（要見積）","別途見積") -> 別途見積 | J14: 要見積 | K14: 要見積 | L14: =V14 -> 300000 | M14: 0 | N14: 0 | O14: =L14+N14 -> 300000 | P14: =IF(INCLUDE_TBD=1,E14*O14,0) -> 0 | Q14: 0 | R14: 0 | S14: =IF(H14="","",H14-P14) -> 0 | T14: =IF(OR(H14="",H14=0),"",S14/H14) | V14: 300000 | W14: 1 | Y14: 0 | Z14: =H14-Y14 -> 0 | AA14: （エストマスタに単価なし） | AB14: 図面カウント | AC14: 単価情報が少なく要見積。製作品は高額になりやすい。概算原価は鋼材約130kg×製作2,000円/kg＋めっき・運搬・据付を想定
A15: 架台制作及び取付費 | C15: 鉄骨2段積み 溶融亜鉛メッキ（AC-2 下段・RAC 上段用・防振ゴム共） | E15: 1 | F15: 基 | G15: =IF(INCLUDE_TBD=1,ROUNDUP(V15/(1-TARGET_MARGIN),-3),"") | H15: =IF(INCLUDE_TBD=1,ROUND(E15*G15,0),0) -> 0 | I15: =IF(INCLUDE_TBD=1,"概算（要見積）","別途見積") -> 別途見積 | J15: 要見積 | K15: 要見積 | L15: =V15 -> 250000 | M15: 0 | N15: 0 | O15: =L15+N15 -> 250000 | P15: =IF(INCLUDE_TBD=1,E15*O15,0) -> 0 | Q15: 0 | R15: 0 | S15: =IF(H15="","",H15-P15) -> 0 | T15: =IF(OR(H15="",H15=0),"",S15/H15) | V15: 250000 | AA15: （エストマスタに単価なし） | AB15: 図面カウント | AC15: 同上（上段がRAのため軽量）。鉄工所またはメーカーの見積で差し替え
A16: 試運転調整費
A17: 試運転調整費 | C17: SA 室外機（-160） | E17: 3 | F17: 台 | G17: 10000 | H17: =ROUND(E17*G17,0) -> 30000 | J17: エスト見積 | K17: エストと数量差 | L17: 450 | M17: 0.45 | N17: =ROUND(M17*LABOR_COST,0) -> 8550 | O17: =L17+N17 -> 9000 | P17: =E17*O17 -> 27000 | Q17: =E17*N17 -> 25650 | R17: =IF(H17=0,0,IF(E17*M17*EST_LABOR_PIPE>H17,H17,E17*M17*EST_LABOR_PIPE)) -> 30000 | S17: =IF(H17="","",H17-P17) -> 3000 | T17: =IF(OR(H17="",H17=0),"",S17/H17) -> 0.1 | W17: 2 | X17: 10000 | Y17: 20000 | Z17: =H17-Y17 -> 10000 | AB17: 図面カウント | AC17: エストは2台
A18: 試運転調整費 | C18: RA 室外機（0-56） | E18: 1 | F18: 台 | G18: 2500 | H18: =ROUND(E18*G18,0) -> 2500 | J18: エスト見積 | L18: 0 | M18: 0.1 | N18: =ROUND(M18*LABOR_COST,0) -> 1900 | O18: =L18+N18 -> 1900 | P18: =E18*O18 -> 1900 | Q18: =E18*N18 -> 1900 | R18: =IF(H18=0,0,IF(E18*M18*EST_LABOR_PIPE>H18,H18,E18*M18*EST_LABOR_PIPE)) -> 2500 | S18: =IF(H18="","",H18-P18) -> 600 | T18: =IF(OR(H18="",H18=0),"",S18/H18) -> 0.24 | W18: 1 | X18: 2500 | Y18: 2500 | Z18: =H18-Y18 -> 0 | AB18: 図面カウント
A19: 消耗品及び雑材料 | E19: 1 | F19: 式 | H19: =ROUNDUP(SUM(H6:H18)*U19,-2) -> 5000 | J19: 経費 | P19: 0 | Q19: 0 | R19: 0 | U19: 0.03 | W19: 1 | Y19: 4500 | Z19: =H19-Y19 -> 500 | AC19: 基礎額×率（100円未満切上げ）
A20: 資材運搬交通費 | E20: 1 | F20: 式 | H20: =ROUNDUP((SUM(H6:H18)+H19)*U20,-2) -> 6800 | J20: 経費 | P20: 0 | Q20: 0 | R20: 0 | U20: 0.04 | W20: 1 | Y20: 6200 | Z20: =H20-Y20 -> 600 | AC20: （基礎額＋消耗品）×率（100円未満切上げ）
A21: 現場経費 | E21: 1 | F21: 式 | H21: =ROUNDUP((SUM(H6:H18)+H19+H20)+ROUNDUP((SUM(H6:H18)+H19+H20)*U21,-2),-3)-(SUM(H6:H18)+H19+H20) -> 14450 | J21: 経費 | P21: 0 | Q21: 0 | R21: 0 | U21: 0.08 | W21: 1 | Y21: 13300 | Z21: =H21-Y21 -> 1150 | AC21: （基礎額＋消耗品＋運搬費）×率を加え、計を1,000円未満切上げ（端数はここに吸収）
A22: － 計 － | H22: =SUM(H6:H21) -> 190000 | M22: =SUMPRODUCT(E6:E21,M6:M21) -> 8.551 | P22: =SUM(P6:P21) -> 181819 | Q22: =SUM(Q6:Q21) -> 162469 | R22: =SUM(R6:R21) -> 158875 | S22: =H22-P22 -> 8181 | T22: =IF(H22=0,"",S22/H22) -> 0.043057895 | Y22: 174000 | Z22: =H22-Y22 -> 16000
A24: ３ 配管設備工事
A25: 冷媒（冷媒銅管）
A26: 冷媒用被覆銅管（10+20t） | C26: 6.35+9.52mm（10t+20t）RAC | E26: 10 | F26: m | G26: 3388 | H26: =ROUND(E26*G26,0) -> 33880 | I26: 図面実測＋想定 | J26: エスト見積 | L26: =ROUND(G26*MAT_RATIO*1.05,0) -> 3557 | M26: 0 | N26: =ROUND(M26*LABOR_COST,0) -> 0 | O26: =L26+N26 -> 3557 | P26: =E26*O26 -> 35570 | Q26: =E26*N26 -> 0 | R26: =IF(H26=0,0,IF(E26*M26*EST_LABOR_PIPE>H26,H26,E26*M26*EST_LABOR_PIPE)) -> 0 | S26: =IF(H26="","",H26-P26) -> -1690 | T26: =IF(OR(H26="",H26=0),"",S26/H26) -> -0.049881936 | U26: 0.104 | W26: 10 | X26: 3388 | Y26: 33880 | Z26: =H26-Y26 -> 0 | AA26: 冷媒配管（テープ巻き）新築 φ6.4/9.5 5m以下26,000＋1m追加5,300（仕様違い） | AB26: 実測+推測 | AC26: 材料原価＝エスト単価×材料原価率×管長割増1.05（建設物価相当）｜平面実測 7.65m＋立上り（架台上段）0.9m＋店長室 立下り 0.6m＋余長 0.3m ＝ 9.45m
A27: 冷媒用被覆銅管（10+20t） | C27: 9.52+15.88mm（10t+20t）AC-1×2・AC-2 | E27: 35 | F27: m | G27: 5138 | H27: =ROUND(E27*G27,0) -> 179830 | I27: 図面実測＋想定 | J27: エスト見積 | L27: =ROUND(G27*MAT_RATIO*1.05,0) -> 5395 | M27: 0 | N27: =ROUND(M27*LABOR_COST,0) -> 0 | O27: =L27+N27 -> 5395 | P27: =E27*O27 -> 188825 | Q27: =E27*N27 -> 0 | R27: =IF(H27=0,0,IF(E27*M27*EST_LABOR_PIPE>H27,H27,E27*M27*EST_LABOR_PIPE)) -> 0 | S27: =IF(H27="","",H27-P27) -> -8995 | T27: =IF(OR(H27="",H27=0),"",S27/H27) -> -0.050019463 | U27: 0.15 | W27: 35 | X27: 5138 | Y27: 179830 | Z27: =H27-Y27 -> 0 | AA27: 冷媒配管（テープ巻き）新築 φ9.5/15.9 5m以下29,500＋1m追加5,900（仕様違い） | AB27: 実測+推測 | AC27: 材料原価＝エスト単価×材料原価率×管長割増1.05（建設物価相当）｜平面実測 26.77m（AC-1西 11.15・AC-1東 7.54・AC-2 8.08）＋立上り（架台下段 2.2m×2・上段 0.9m×1）＋機器接続 0.3m×3＋余長 0.5m×3 ＝ 34.47m
A28: 継手類 | E28: 1 | F28: 式 | H28: =ROUND((H26+H27)*U28,0) -> 64113 | J28: エスト算式 | P28: =ROUND((P26+P27)*U28,0) -> 67319 | Q28: 0 | R28: 0 | S28: =IF(H28="","",H28-P28) -> -3206 | T28: =IF(OR(H28="",H28=0),"",S28/H28) -> -0.050005459 | U28: 0.3 | W28: 1 | Y28: 64107 | Z28: =H28-Y28 -> 6 | AC28: 管金額×率（エスト・公共積算と同率）。原価も同率
A29: 消耗品 | E29: 1 | F29: 式 | H29: =ROUND((H26+H27)*U29,0) -> 32057 | J29: エスト算式 | P29: =ROUND((P26+P27)*U29,0) -> 33659 | Q29: 0 | R29: 0 | S29: =IF(H29="","",H29-P29) -> -1602 | T29: =IF(OR(H29="",H29=0),"",S29/H29) -> -0.049973485 | U29: 0.15 | W29: 1 | Y29: 32054 | Z29: =H29-Y29 -> 3 | AC29: 管金額×率（エスト・公共積算と同率）。原価も同率
A30: 支持金物 | E30: 1 | F30: 式 | H30: =ROUND((H26+H27)*U30,0) -> 85484 | J30: エスト算式 | P30: =ROUND((P26+P27)*U30,0) -> 89758 | Q30: 0 | R30: 0 | S30: =IF(H30="","",H30-P30) -> -4274 | T30: =IF(OR(H30="",H30=0),"",S30/H30) -> -0.04999766 | U30: 0.4 | W30: 1 | Y30: 85475 | Z30: =H30-Y30 -> 9 | AC30: 管金額×率（エスト・公共積算と同率）。原価も同率
A31: 排水（硬質塩化ビニル管）
A32: 硬質塩化ビニル管 | C32: VP 25A | E32: 9 | F32: m | G32: 313 | H32: =ROUND(E32*G32,0) -> 2817 | I32: 図面実測＋想定 | J32: エスト見積 | L32: =ROUND(G32*MAT_RATIO*1.1,0) -> 344 | M32: 0 | N32: =ROUND(M32*LABOR_COST,0) -> 0 | O32: =L32+N32 -> 344 | P32: =E32*O32 -> 3096 | Q32: =E32*N32 -> 0 | R32: =IF(H32=0,0,IF(E32*M32*EST_LABOR_PIPE>H32,H32,E32*M32*EST_LABOR_PIPE)) -> 0 | S32: =IF(H32="","",H32-P32) -> -279 | T32: =IF(OR(H32="",H32=0),"",S32/H32) -> -0.099041534 | U32: 0.074 | W32: 9 | X32: 313 | Y32: 2817 | Z32: =H32-Y32 -> 0 | AB32: 実測+推測 | AC32: 材料原価＝エスト単価×材料原価率×管長割増1.1（建設物価相当）｜平面実測 5.20m（東主管 2.72・AC-2枝 1.28・西枝 0.76・RAC 0.44）＋ドレンアップ立上り 0.3m×3＋東カセット接続 0.3m＋RAC 立下り 1.9m ＝ 8.30m
A33: 硬質塩化ビニル管 | C33: VP 30A | E33: 4 | F33: m | G33: 363 | H33: =ROUND(E33*G33,0) -> 1452 | J33: エスト見積 | L33: =ROUND(G33*MAT_RATIO*1.1,0) -> 399 | M33: 0 | N33: =ROUND(M33*LABOR_COST,0) -> 0 | O33: =L33+N33 -> 399 | P33: =E33*O33 -> 1596 | Q33: =E33*N33 -> 0 | R33: =IF(H33=0,0,IF(E33*M33*EST_LABOR_PIPE>H33,H33,E33*M33*EST_LABOR_PIPE)) -> 0 | S33: =IF(H33="","",H33-P33) -> -144 | T33: =IF(OR(H33="",H33=0),"",S33/H33) -> -0.099173554 | U33: 0.079 | W33: 4 | X33: 363 | Y33: 1452 | Z33: =H33-Y33 -> 0 | AB33: 実測 | AC33: 材料原価＝エスト単価×材料原価率×管長割増1.1（建設物価相当）
A34: 硬質塩化ビニル管 | C34: VP 40A | E34: 6 | F34: m | G34: 363 | H34: =ROUND(E34*G34,0) -> 2178 | I34: 図面実測＋想定 | J34: エスト見積 | L34: =ROUND(G34*MAT_RATIO*1.1,0) -> 399 | M34: 0 | N34: =ROUND(M34*LABOR_COST,0) -> 0 | O34: =L34+N34 -> 399 | P34: =E34*O34 -> 2394 | Q34: =E34*N34 -> 0 | R34: =IF(H34=0,0,IF(E34*M34*EST_LABOR_PIPE>H34,H34,E34*M34*EST_LABOR_PIPE)) -> 0 | S34: =IF(H34="","",H34-P34) -> -216 | T34: =IF(OR(H34="",H34=0),"",S34/H34) -> -0.099173554 | U34: 0.101 | W34: 6 | X34: 363 | Y34: 2178 | Z34: =H34-Y34 -> 0 | AB34: 実測+推測 | AC34: 材料原価＝エスト単価×材料原価率×管長割増1.1（建設物価相当）｜平面実測 3.29m＋天井内→接続立上り（H=150）への立下り 2.45m ＝ 5.74m
A35: 継手類 | E35: 1 | F35: 式 | H35: =ROUND((H32+H33+H34)*U35,0) -> 1289 | J35: エスト算式 | P35: =ROUND((P32+P33+P34)*U35,0) -> 1417 | Q35: 0 | R35: 0 | S35: =IF(H35="","",H35-P35) -> -128 | T35: =IF(OR(H35="",H35=0),"",S35/H35) -> -0.099301784 | U35: 0.2 | W35: 1 | Y35: 1288 | Z35: =H35-Y35 -> 1 | AC35: 管金額×率（エスト・公共積算と同率）。原価も同率
A36: 消耗品 | E36: 1 | F36: 式 | H36: =ROUND((H32+H33+H34)*U36,0) -> 645 | J36: エスト算式 | P36: =ROUND((P32+P33+P34)*U36,0) -> 709 | Q36: 0 | R36: 0 | S36: =IF(H36="","",H36-P36) -> -64 | T36: =IF(OR(H36="",H36=0),"",S36/H36) -> -0.099224806 | U36: 0.1 | W36: 1 | Y36: 644 | Z36: =H36-Y36 -> 1 | AC36: 管金額×率（エスト・公共積算と同率）。原価も同率
A37: 支持金物 | E37: 1 | F37: 式 | H37: =ROUND((H32+H33+H34)*U37,0) -> 1612 | J37: エスト算式 | P37: =ROUND((P32+P33+P34)*U37,0) -> 1772 | Q37: 0 | R37: 0 | S37: =IF(H37="","",H37-P37) -> -160 | T37: =IF(OR(H37="",H37=0),"",S37/H37) -> -0.099255583 | U37: 0.25 | W37: 1 | Y37: 1610 | Z37: =H37-Y37 -> 2 | AC37: 管金額×率（エスト・公共積算と同率）。原価も同率
A38: ドレンホース用逆止弁 | C38: NDB-20-25（図示品） | E38: 1 | F38: 個 | G38: 5730 | H38: =ROUND(E38*G38,0) -> 5730 | J38: 当社単価（要確認） | K38: 単価要確認 | L38: 2800 | M38: 0.1 | N38: =ROUND(M38*LABOR_COST,0) -> 1900 | O38: =L38+N38 -> 4700 | P38: =E38*O38 -> 4700 | Q38: =E38*N38 -> 1900 | R38: =IF(H38=0,0,IF(E38*M38*EST_LABOR_PIPE>H38,H38,E38*M38*EST_LABOR_PIPE)) -> 3375 | S38: =IF(H38="","",H38-P38) -> 1030 | T38: =IF(OR(H38="",H38=0),"",S38/H38) -> 0.17975567 | AA38: （エストに単価なし） | AB38: 図面カウント | AC38: エストに単価がないため当社単価（前回見積）で仮計上。仕入価格を確認
A39: 電線・ケーブル類
A40: VVFケーブル（内外連絡線） | C40: 600V VV-F 2.0mm-3C | E40: 56 | F40: m | G40: 203 | H40: =ROUND(E40*G40,0) -> 11368 | I40: 想定数量 | J40: エスト見積 | L40: =ROUND(G40*MAT_RATIO*1.0,0) -> 203 | M40: 0 | N40: =ROUND(M40*LABOR_COST,0) -> 0 | O40: =L40+N40 -> 203 | P40: =E40*O40 -> 11368 | Q40: =E40*N40 -> 0 | R40: =IF(H40=0,0,IF(E40*M40*EST_LABOR_PIPE>H40,H40,E40*M40*EST_LABOR_PIPE)) -> 0 | S40: =IF(H40="","",H40-P40) -> 0 | T40: =IF(OR(H40="",H40=0),"",S40/H40) -> 0 | U40: 0.017 | W40: 56 | X40: 203 | Y40: 11368 | Z40: =H40-Y40 -> 0 | AB40: 推測 | AC40: 材料原価＝エスト単価×材料原価率×管長割増1.0（建設物価相当）｜内外連絡線＝冷媒配管の系統長（14.15＋9.24＋11.08＋9.45m）＋余長 3.0m×4系統 ＝ 55.92m（エスト見積も 56m）
A41: 配管工費（冷媒配管） | E41: 1 | F41: 式 | H41: =ROUNDUP(M41*EST_LABOR_PIPE,-1) -> 212290 | J41: エスト算式 | L41: 0 | M41: =E26*U26+E27*U27 -> 6.29 | N41: =ROUND(M41*LABOR_COST,0) -> 119510 | O41: =L41+N41 -> 119510 | P41: =E41*O41 -> 119510 | Q41: =E41*N41 -> 119510 | R41: =H41 -> 212290 | S41: =IF(H41="","",H41-P41) -> 92780 | T41: =IF(OR(H41="",H41=0),"",S41/H41) -> 0.43704367 | W41: 1 | Y41: 212290 | Z41: =H41-Y41 -> 0 | AC41: 歩掛 公共建築工事標準単価積算基準 R8 表M1-1-50（液管＋ガス管）× エスト労務単価
...

Sheet 法定福利費内訳明細書
B1: 法 定 福 利 費 内 訳 明 細 書
B2: ="（御見積書 No."&'表紙(工事)'!K3&" の添付資料）" -> （御見積書 No. の添付資料）
B4: 見積年月日 | C4: ='表紙(工事)'!J4 -> 46303 | F4: 見積No. | G4: =IF('表紙(工事)'!K3="","",'表紙(工事)'!K3)
B5: 発注者名 | C5: 今治空調設備 御中
B6: 工事名 | C6: 吉野家 呉海岸店 空調設備工事
B7: 施工場所 | C7: 広島県呉市海岸（国道31号沿い）
B8: 会社名 | C8: 宮地機工株式会社 | F8: 所在地 | G8: 広島県尾道市東尾道9-9
B10: 【1】 労務費相当額（Ｙ）の内訳
B11: ※ 労務費相当額は、内訳書各項目の金額のうち労務費に相当する額（配管工費・電線材料施工費、および据付・保温・試験等の人工相当額）に、出精値引き後の比率を乗じたものです。空調機は支給品のため含みません。
B12: 項 目 | C12: 労務費相当額（円） | E12: 摘 要
B13: 空調設備工事 | C13: ='内訳書(空調設備工事)'!R22 -> 158875 | E13: 内訳書 ２ 空調設備工事（定価ベース）
B14: 配管設備工事 | C14: ='内訳書(空調設備工事)'!R60 -> 466935 | E14: 内訳書 ３ 配管設備工事（定価ベース）
B15: 小 計 | C15: =C13+C14 -> 625810 | E15: 定価ベース
B16: 労務費相当額（Ｙ） | C16: =ROUNDDOWN(C15*'表紙(工事)'!K28/'表紙(工事)'!K26,0) -> 589610 | E16: 小計 × 出精値引き後比率（合計÷小計）
B18: 【2】 法定福利費相当額（Ａ）の算定
B19: 計算式： Ａ ＝ Ｙ × Ｚ（Ｚ：法定福利費事業者負担率、保険ごとに円未満切捨て）
B20: 保険の種類 | C20: 労務費相当額（円） | E20: 事業主負担料率 | F20: 法定福利費（円） | G20: 算定根拠
B21: 健康保険料 | C21: =$C$16 -> 589610 | E21: 0.0489 | F21: =ROUNDDOWN(C21*E21,0) -> 28831 | G21: 健康保険料率 9.780%（協会けんぽ 広島県 令和8年度）×1/2（労使折半）
B22: 介護保険料 | C22: =$C$16 -> 589610 | E22: 0.0081 | F22: =ROUNDDOWN(C22*E22,0) -> 4775 | G22: 介護保険料率 1.620%（全国一律 令和8年度）×1/2（労使折半）
B23: 子ども・子育て支援金 | C23: =$C$16 -> 589610 | E23: 0.00115 | F23: =ROUNDDOWN(C23*E23,0) -> 678 | G23: 支援金率 0.230%（令和8年4月分〜）×1/2（労使折半）
B24: 厚生年金保険料 | C24: =$C$16 -> 589610 | E24: 0.0915 | F24: =ROUNDDOWN(C24*E24,0) -> 53949 | G24: 厚生年金保険料率 18.300%（平成29年9月以降固定）×1/2（労使折半）
B25: 雇用保険料 | C25: =$C$16 -> 589610 | E25: 0.0105 | F25: =ROUNDDOWN(C25*E25,0) -> 6190 | G25: 雇用保険料率（建設の事業）事業主負担分 1.050%
B26: 子ども・子育て拠出金 | C26: =$C$16 -> 589610 | E26: 0.0036 | F26: =ROUNDDOWN(C26*E26,0) -> 2122 | G26: 拠出金率 0.360%（事業主全額負担）
B27: 合計（Ｚ ／ Ａ） | E27: =SUM(E21:E26) -> 0.16375 | F27: =SUM(F21:F26) -> 96545
B29: ※ 法定福利費相当額（Ａ）は見積金額（工事費）に含まれています。別途加算するものではありません。
B30: ※ 料率は見積作成時点（令和8年度）の公表料率によります。料率が改定された場合は改定後の料率により精算させていただきます。

Sheet 御見積条件
A1: 御見積条件・注意事項
A2: 吉野家 呉海岸店 空調設備工事 御見積書 添付
A4: 【1】御見積条件・注意事項
A5: 1. | B5: 本見積は2026年11月からの価格で作成しております。数量は換気空調機器表 F-01（2025.05.25）・空調設備図 F-02-1（2026.05.25）・平面図 A-08（2026.07.29）に基づき当社にて拾い出しています。冷媒管・ドレン管の平面延長は空調設備図（1/50）から計測し、立上り・立下り・機器接続部および内外連絡線は想定数量として計上しています（別紙【2】参照）。
A6: 2. | B6: 工事範囲: 空調機の搬入・吊込み・据付（AC-1 天井カセット形×2台、AC-2 天井ビルトイン形×1台、RAC 壁掛形×1台、室外機×4台）、室外機基礎（縁石）、冷媒配管（被覆銅管 液管10t・ガス管20t）・屋外化粧カバー、ドレン配管（VP）・保温（GW20mm＋アルミガラスクロス）、内外連絡線（VVF 2.0-3C）、外壁スリーブ、気密試験・真空引き、試運転調整。
A7: 3. | B7: 空調機（AC-1 SSRC140C×2台、AC-2 SSRB140C×1台、RAC×1台、各リモコン）および吹出しパンカー PK-SB#10TK×4台は支給品のため含みません。
A8: 4. | B8: 鉄骨架台（2段積み・溶融亜鉛メッキ防錆処理、防振ゴム共）は空調設備図の特記により空調設備工事ですが、製作品のため別途御見積とさせていただきます。架台はダイキン製室外機（H1,430mm）に対応する段間寸法とし、背面と建物壁面の隙間200mm以上を確保します。
A9: 5. | B9: リモコン配線、AC-2（天井ビルトイン形）から吹出しパンカーまでのダクト・パンカー取付、換気設備（換気扇・送風機・フード・ダクト類）、電源・接地等の電気工事は含みません。
A10: 6. | B10: 冷媒の追加充填は、各系統の配管長（最長約14m）が支給機のチャージレス配管長以内と想定し計上していません（真空引き・ガス充填は基本料金）。必要となった場合は実費にて精算させていただきます。
A11: 7. | B11: ドレン管は硬質塩化ビニル管（VP 25A・30A・40A）とし、範囲は各機器から「空調機ドレン接続立上り（H=150）」まで、以降は給排水工事です。図示のドレンホース用逆止弁 NDB-20-25 を計上しています。
A12: 8. | B12: 揚重機（クレーン等）、足場・高所作業車等の仮設、天井・壁の開口補強および仕上げ補修、天井点検口、既設機器の撤去、産業廃棄物（支給品の梱包材を含む）の処分は含みません。
A13: 9. | B13: 工期は工程表（吉野家呉海岸通店新設工事 工程表）に基づく通常の日中作業を前提としております。夜間・休日作業、工程変更や他工事との輻輳による手待ち、工期延長に伴う経費増は別途協議とさせていただきます。
A14: 10. | B14: 労務費に係る法定福利費（事業主負担分）は工事費に含んでおり、その額は御見積書表紙および別紙「法定福利費内訳明細書」のとおりです。
A15: 11. | B15: 本見積書に記載なき事項については別途とさせていただきます。工事に係る電気・水道は無償支給願います。本見積金額には消費税は含まれておりません。本書有効期間は10日です。
A17: 【2】想定数量（推測）項目の前提
A18: 図面に数量・経路の記載がなく当社にて想定した項目です。「図面実測＋想定」は平面延長を図面計測し、立上り等を想定加算したものです。実数量確定後に精算させていただきます。
A19: No. | B19: 内訳書 | C19: 項 目 | D19: 前提・想定内容 | F19: 数量（区分）
A20: 1 | B20: ３ | C20: 冷媒用被覆銅管（10+20t） 6.35+9.52mm（10t+20t）RAC | D20: 平面実測 7.65m＋立上り（架台上段）0.9m＋店長室 立下り 0.6m＋余長 0.3m ＝ 9.45m | F20: 10 m（実測＋想定）
A21: 2 | B21: ３ | C21: 冷媒用被覆銅管（10+20t） 9.52+15.88mm（10t+20t）AC-1×2・AC-2 | D21: 平面実測 26.77m（AC-1西 11.15・AC-1東 7.54・AC-2 8.08）＋立上り（架台下段 2.2m×2・上段 0.9m×1）＋機器接続 0.3m×3＋余長 0.5m×3 ＝ 34.47m | F21: 35 m（実測＋想定）
A22: 3 | B22: ３ | C22: 硬質塩化ビニル管 VP 25A | D22: 平面実測 5.20m（東主管 2.72・AC-2枝 1.28・西枝 0.76・RAC 0.44）＋ドレンアップ立上り 0.3m×3＋東カセット接続 0.3m＋RAC 立下り 1.9m ＝ 8.30m | F22: 9 m（実測＋想定）
A23: 4 | B23: ３ | C23: 硬質塩化ビニル管 VP 40A | D23: 平面実測 3.29m＋天井内→接続立上り（H=150）への立下り 2.45m ＝ 5.74m | F23: 6 m（実測＋想定）
A24: 5 | B24: ３ | C24: VVFケーブル（内外連絡線） 600V VV-F 2.0mm-3C | D24: 内外連絡線＝冷媒配管の系統長（14.15＋9.24＋11.08＋9.45m）＋余長 3.0m×4系統 ＝ 55.92m | F24: 56 m（想定）
A25: 6 | B25: ３ | C25: 樹脂製化粧カバー 冷媒用被覆銅管（10+20t）6.35+9.52 屋外 | D25: RAC: 屋外平面 1.21m（実測）＋立上り（上段）0.9m ＝ 2.11m | F25: 3 m（実測＋想定）
A26: 7 | B26: ３ | C26: 樹脂製化粧カバー 冷媒用被覆銅管（10+20t）9.52+15.88 屋外 | D26: AC-1×2・AC-2: 屋外平面 2.60m（実測）＋立上り（下段 2.2m×2・上段 0.9m×1）＝ 7.90m | F26: 8 m（実測＋想定）
A27: 8 | B27: ３ | C27: 排水VP保温 GW20mm+ALGC 屋内隠蔽 25A | D27: ドレン管 VP25 と同長 | F27: 9 m（実測＋想定）
A28: 9 | B28: ３ | C28: 排水VP保温 GW20mm+ALGC 屋内隠蔽 40A | D28: ドレン管 VP40 と同長 | F28: 6 m（実測＋想定）
A30: 【3】図面読み取りに関する確認事項
A31: 1. | B31: 空調機器表の AC-1（天井カセット形 5馬力相当）は2台（室内機2台・室外機2台の2系統）、AC-2 は1系統として計上しています（空調設備図 F-02-1・室外機設置概要図による）。
A32: 2. | B32: 室外機は室外機設置概要図により、架台①＝AC-1（下段）＋AC-1（上段）、架台②＝AC-2（下段）＋RAC（上段）の2段積み2基としています。
A33: 3. | B33: 冷媒管・ドレン管は空調設備図 F-02-1 の配管線（R・D 記号）から計測し、立上り・立下りは室外機設置概要図と天井高（客席 CH2,600、厨房・店長室 CH2,500）から想定しています。
A34: 4. | B34: 特記の「天井内冷媒配管は厚20耐熱ポリスチレンフォーム断熱材巻き」は、冷媒管用の耐熱ポリエチレンフォーム保温材（ガス管20mm）と解釈しています。
A35: 5. | B35: ドレン接続立上り（H=150）の立上り管および以降の排水管は給排水工事と解釈しています。
A36: 6. | B36: 施工場所は位置図（呉海岸）によります。地番をご教示ください。

Sheet エスト比較(内部)
A1: エスト見積 6330560-1 との比較（内部用） 単価はエストに合わせ、数量は図面拾い。差額の主因を右列に記載
A3: 区分 | B3: 品名 | C3: 規格 | D3: エスト数量 | E3: エスト単価 | F3: エスト金額 | G3: 当社数量 | H3: 当社単価 | I3: 当社金額 | J3: 差額 | K3: 差異の理由
A4: 空調設備工事 | B4: RA 室外機 | C4: セパレート2.2-5.0（店長室 RAC）架台上段 | D4: 1 | E4: 6250 | F4: 6250 | G4: ='内訳書(空調設備工事)'!E7 -> 1 | H4: ='内訳書(空調設備工事)'!G7 -> 6250 | I4: ='内訳書(空調設備工事)'!H7 -> 6250 | J4: =I4-F4 -> 0
A5: 空調設備工事 | B5: RA 室内機 | C5: 壁掛 2.2kW（店長室） | D5: 1 | E5: 6250 | F5: 6250 | G5: ='内訳書(空調設備工事)'!E8 -> 1 | H5: ='内訳書(空調設備工事)'!G8 -> 6250 | I5: ='内訳書(空調設備工事)'!H8 -> 6250 | J5: =I5-F5 -> 0
A6: 空調設備工事 | B6: SA 室外機 | C6: 11.2-16.0（AC-1×2・AC-2、5HP） | D6: 2 | E6: 8750 | F6: 17500 | G6: ='内訳書(空調設備工事)'!E9 -> 3 | H6: ='内訳書(空調設備工事)'!G9 -> 8750 | I6: ='内訳書(空調設備工事)'!H9 -> 26250 | J6: =I6-F6 -> 8750 | K6: 図面は AC-1×2・AC-2 の3台（エストは2台）
A7: 空調設備工事 | B7: SA 室内機 | C7: ダクト形11.2-16（AC-2 天井ビルトイン 5HP） | D7: 1 | E7: 27500 | F7: 27500 | G7: ='内訳書(空調設備工事)'!E10 -> 1 | H7: ='内訳書(空調設備工事)'!G10 -> 27500 | I7: ='内訳書(空調設備工事)'!H10 -> 27500 | J7: =I7-F7 -> 0
A8: 空調設備工事 | B8: SA 室内機 | C8: カセット形2.8-16（AC-1 天井カセット 5HP） | D8: 2 | E8: 25000 | F8: 50000 | G8: ='内訳書(空調設備工事)'!E11 -> 2 | H8: ='内訳書(空調設備工事)'!G11 -> 25000 | I8: ='内訳書(空調設備工事)'!H11 -> 50000 | J8: =I8-F8 -> 0
A9: 空調設備工事 | B9: 縁石 | C9: 22.4-28.0（2段架台用） | D9: 2 | E9: 7500 | F9: 15000 | G9: ='内訳書(空調設備工事)'!E13 -> 2 | H9: ='内訳書(空調設備工事)'!G13 -> 7500 | I9: ='内訳書(空調設備工事)'!H13 -> 15000 | J9: =I9-F9 -> 0
A10: 空調設備工事 | B10: 架台制作及び取付費 | C10: 鉄骨2段積み 溶融亜鉛メッキ（AC-1 上下段用・防振ゴム共） | D10: 1 | F10: 0 | G10: ='内訳書(空調設備工事)'!E14 -> 1 | H10: ='内訳書(空調設備工事)'!G14 | I10: ='内訳書(空調設備工事)'!H14 -> 0 | J10: =I10-F10 -> 0 | K10: エストは 0（単価なし）→ 要見積
A11: 空調設備工事 | B11: 架台制作及び取付費 | C11: 鉄骨2段積み 溶融亜鉛メッキ（AC-2 下段・RAC 上段用・防振ゴム共） | G11: ='内訳書(空調設備工事)'!E15 -> 1 | H11: ='内訳書(空調設備工事)'!G15 | I11: ='内訳書(空調設備工事)'!H15 -> 0 | J11: =I11-F11 -> 0 | K11: 同上
A12: 空調設備工事 | B12: 試運転調整費 | C12: SA 室外機（-160） | D12: 2 | E12: 10000 | F12: 20000 | G12: ='内訳書(空調設備工事)'!E17 -> 3 | H12: ='内訳書(空調設備工事)'!G17 -> 10000 | I12: ='内訳書(空調設備工事)'!H17 -> 30000 | J12: =I12-F12 -> 10000 | K12: 同上（3台）
A13: 空調設備工事 | B13: 試運転調整費 | C13: RA 室外機（0-56） | D13: 1 | E13: 2500 | F13: 2500 | G13: ='内訳書(空調設備工事)'!E18 -> 1 | H13: ='内訳書(空調設備工事)'!G18 -> 2500 | I13: ='内訳書(空調設備工事)'!H18 -> 2500 | J13: =I13-F13 -> 0
A14: 空調設備工事 | B14: 消耗品及び雑材料 | D14: 1 | F14: 4500 | G14: ='内訳書(空調設備工事)'!E19 -> 1 | I14: ='内訳書(空調設備工事)'!H19 -> 5000 | J14: =I14-F14 -> 500 | K14: 基礎額の差による（率はエストと同じ）
A15: 空調設備工事 | B15: 資材運搬交通費 | D15: 1 | F15: 6200 | G15: ='内訳書(空調設備工事)'!E20 -> 1 | I15: ='内訳書(空調設備工事)'!H20 -> 6800 | J15: =I15-F15 -> 600 | K15: 基礎額の差による（率はエストと同じ）
A16: 空調設備工事 | B16: 現場経費 | D16: 1 | F16: 13300 | G16: ='内訳書(空調設備工事)'!E21 -> 1 | I16: ='内訳書(空調設備工事)'!H21 -> 14450 | J16: =I16-F16 -> 1150 | K16: 基礎額の差による（率はエストと同じ）
A17: 配管設備工事 | B17: 冷媒用被覆銅管（10+20t） | C17: 6.35+9.52mm（10t+20t）RAC | D17: 10 | E17: 3388 | F17: 33880 | G17: ='内訳書(空調設備工事)'!E26 -> 10 | H17: ='内訳書(空調設備工事)'!G26 -> 3388 | I17: ='内訳書(空調設備工事)'!H26 -> 33880 | J17: =I17-F17 -> 0
A18: 配管設備工事 | B18: 冷媒用被覆銅管（10+20t） | C18: 9.52+15.88mm（10t+20t）AC-1×2・AC-2 | D18: 35 | E18: 5138 | F18: 179830 | G18: ='内訳書(空調設備工事)'!E27 -> 35 | H18: ='内訳書(空調設備工事)'!G27 -> 5138 | I18: ='内訳書(空調設備工事)'!H27 -> 179830 | J18: =I18-F18 -> 0
A19: 配管設備工事 | B19: 継手類 | D19: 1 | F19: 64107 | G19: ='内訳書(空調設備工事)'!E28 -> 1 | I19: ='内訳書(空調設備工事)'!H28 -> 64113 | J19: =I19-F19 -> 6 | K19: 数量同一のため同額（率・算式はエストと同じ）
A20: 配管設備工事 | B20: 消耗品 | D20: 1 | F20: 32054 | G20: ='内訳書(空調設備工事)'!E29 -> 1 | I20: ='内訳書(空調設備工事)'!H29 -> 32057 | J20: =I20-F20 -> 3 | K20: 数量同一のため同額（率・算式はエストと同じ）
A21: 配管設備工事 | B21: 支持金物 | D21: 1 | F21: 85475 | G21: ='内訳書(空調設備工事)'!E30 -> 1 | I21: ='内訳書(空調設備工事)'!H30 -> 85484 | J21: =I21-F21 -> 9 | K21: 数量同一のため同額（率・算式はエストと同じ）
A22: 配管設備工事 | B22: 硬質塩化ビニル管 | C22: VP 25A | D22: 9 | E22: 313 | F22: 2817 | G22: ='内訳書(空調設備工事)'!E32 -> 9 | H22: ='内訳書(空調設備工事)'!G32 -> 313 | I22: ='内訳書(空調設備工事)'!H32 -> 2817 | J22: =I22-F22 -> 0
A23: 配管設備工事 | B23: 硬質塩化ビニル管 | C23: VP 30A | D23: 4 | E23: 363 | F23: 1452 | G23: ='内訳書(空調設備工事)'!E33 -> 4 | H23: ='内訳書(空調設備工事)'!G33 -> 363 | I23: ='内訳書(空調設備工事)'!H33 -> 1452 | J23: =I23-F23 -> 0
A24: 配管設備工事 | B24: 硬質塩化ビニル管 | C24: VP 40A | D24: 6 | E24: 363 | F24: 2178 | G24: ='内訳書(空調設備工事)'!E34 -> 6 | H24: ='内訳書(空調設備工事)'!G34 -> 363 | I24: ='内訳書(空調設備工事)'!H34 -> 2178 | J24: =I24-F24 -> 0
A25: 配管設備工事 | B25: 継手類 | D25: 1 | F25: 1288 | G25: ='内訳書(空調設備工事)'!E35 -> 1 | I25: ='内訳書(空調設備工事)'!H35 -> 1289 | J25: =I25-F25 -> 1 | K25: 数量同一のため同額（率・算式はエストと同じ）
A26: 配管設備工事 | B26: 消耗品 | D26: 1 | F26: 644 | G26: ='内訳書(空調設備工事)'!E36 -> 1 | I26: ='内訳書(空調設備工事)'!H36 -> 645 | J26: =I26-F26 -> 1 | K26: 数量同一のため同額（率・算式はエストと同じ）
A27: 配管設備工事 | B27: 支持金物 | D27: 1 | F27: 1610 | G27: ='内訳書(空調設備工事)'!E37 -> 1 | I27: ='内訳書(空調設備工事)'!H37 -> 1612 | J27: =I27-F27 -> 2 | K27: 数量同一のため同額（率・算式はエストと同じ）
A28: 配管設備工事 | B28: ドレンホース用逆止弁 | C28: NDB-20-25（図示品） | G28: ='内訳書(空調設備工事)'!E38 -> 1 | H28: ='内訳書(空調設備工事)'!G38 -> 5730 | I28: ='内訳書(空調設備工事)'!H38 -> 5730 | J28: =I28-F28 -> 5730 | K28: エストに単価・行なし（当社単価で追加）
A29: 配管設備工事 | B29: VVFケーブル（内外連絡線） | C29: 600V VV-F 2.0mm-3C | D29: 56 | E29: 203 | F29: 11368 | G29: ='内訳書(空調設備工事)'!E40 -> 56 | H29: ='内訳書(空調設備工事)'!G40 -> 203 | I29: ='内訳書(空調設備工事)'!H40 -> 11368 | J29: =I29-F29 -> 0
A30: 配管設備工事 | B30: 配管工費（冷媒配管） | D30: 1 | F30: 212290 | G30: ='内訳書(空調設備工事)'!E41 -> 1 | I30: ='内訳書(空調設備工事)'!H41 -> 212290 | J30: =I30-F30 -> 0 | K30: 数量同一のため同額（率・算式はエストと同じ）
A31: 配管設備工事 | B31: 配管工費（塩ビ管類） | D31: 1 | F31: 53600 | G31: ='内訳書(空調設備工事)'!E42 -> 1 | I31: ='内訳書(空調設備工事)'!H42 -> 53600 | J31: =I31-F31 -> 0 | K31: 数量同一のため同額（率・算式はエストと同じ）
A32: 配管設備工事 | B32: 電線材料施工費 | D32: 1 | F32: 31990 | G32: ='内訳書(空調設備工事)'!E43 -> 1 | I32: ='内訳書(空調設備工事)'!H43 -> 31990 | J32: =I32-F32 -> 0 | K32: 数量同一のため同額（率・算式はエストと同じ）
A33: 配管設備工事 | B33: 樹脂製化粧カバー | C33: 冷媒用被覆銅管（10+20t）6.35+9.52 屋外 | D33: 5 | E33: 4225 | F33: 21125 | G33: ='内訳書(空調設備工事)'!E45 -> 3 | H33: ='内訳書(空調設備工事)'!G45 -> 4225 | I33: ='内訳書(空調設備工事)'!H45 -> 12675 | J33: =I33-F33 -> -8450 | K33: 図面実測 2.11m→3m（エスト 5m）
A34: 配管設備工事 | B34: 樹脂製化粧カバー | C34: 冷媒用被覆銅管（10+20t）9.52+15.88 屋外 | D34: 10 | E34: 5525 | F34: 55250 | G34: ='内訳書(空調設備工事)'!E46 -> 8 | H34: ='内訳書(空調設備工事)'!G46 -> 5525 | I34: ='内訳書(空調設備工事)'!H46 -> 44200 | J34: =I34-F34 -> -11050 | K34: 図面実測 7.90m→8m（エスト 10m）
A35: 配管設備工事 | B35: 排水VP保温 GW20mm+ALGC | C35: 屋内隠蔽 25A | D35: 9 | E35: 2563 | F35: 23067 | G35: ='内訳書(空調設備工事)'!E47 -> 9 | H35: ='内訳書(空調設備工事)'!G47 -> 2563 | I35: ='内訳書(空調設備工事)'!H47 -> 23067 | J35: =I35-F35 -> 0
A36: 配管設備工事 | B36: 排水VP保温 GW20mm+ALGC | C36: 屋内隠蔽 30A | D36: 4 | E36: 2713 | F36: 10852 | G36: ='内訳書(空調設備工事)'!E48 -> 4 | H36: ='内訳書(空調設備工事)'!G48 -> 2713 | I36: ='内訳書(空調設備工事)'!H48 -> 10852 | J36: =I36-F36 -> 0
A37: 配管設備工事 | B37: 排水VP保温 GW20mm+ALGC | C37: 屋内隠蔽 40A | D37: 6 | E37: 2950 | F37: 17700 | G37: ='内訳書(空調設備工事)'!E49 -> 6 | H37: ='内訳書(空調設備工事)'!G49 -> 2950 | I37: ='内訳書(空調設備工事)'!H49 -> 17700 | J37: =I37-F37 -> 0
A38: 配管設備工事 | B38: スリーブインサート費 | C38: 外壁貫通 4箇所（穴明け・シーリング） | D38: 1 | F38: 50000 | G38: ='内訳書(空調設備工事)'!E50 -> 1 | H38: ='内訳書(空調設備工事)'!G50 -> 50000 | I38: ='内訳書(空調設備工事)'!H50 -> 50000 | J38: =I38-F38 -> 0
A39: 配管設備工事 | B39: 気密テスト費 | C39: SA | D39: 2 | E39: 12500 | F39: 25000 | G39: ='内訳書(空調設備工事)'!E52 -> 3 | H39: ='内訳書(空調設備工事)'!G52 -> 12500 | I39: ='内訳書(空調設備工事)'!H52 -> 37500 | J39: =I39-F39 -> 12500 | K39: 同上（3系統）
A40: 配管設備工事 | B40: 気密テスト費 | C40: RA | D40: 1 | E40: 10000 | F40: 10000 | G40: ='内訳書(空調設備工事)'!E53 -> 1 | H40: ='内訳書(空調設備工事)'!G53 -> 10000 | I40: ='内訳書(空調設備工事)'!H53 -> 10000 | J40: =I40-F40 -> 0
A41: 配管設備工事 | B41: 真空引き・ガス充填 | C41: SA（基本料金） | D41: 2 | E41: 2500 | F41: 5000 | G41: ='内訳書(空調設備工事)'!E55 -> 3 | H41: ='内訳書(空調設備工事)'!G55 -> 2500 | I41: ='内訳書(空調設備工事)'!H55 -> 7500 | J41: =I41-F41 -> 2500 | K41: 同上（3系統）
...

Sheet エストマスタ(参考)
A1: エスト単価マスタ（参考） 内訳書はエスト見積 6330560-1 の単価を優先し、このマスタの値は内訳書 AA 列に併記
A2: 見積とマスタで単価が異なる行（据付・基礎）はエスト見積の値を採用。マスタを採用する場合は内訳書 G 列を差し替え
A4: 区分 | B4: 種別 | C4: 単価（円）
A5: 基礎工事 スカイエア | B5: 縁石基礎 | C5: P140 5,000 ／ P160・P180 8,000 ／ P200〜P280 8,000
A6: 基礎工事 スカイエア | B6: ベタ基礎 | C6: P140 33,000 ／ P160・P180 39,000 ／ P200〜P280 39,000
A7: 基礎工事 ルームエアコン | B7: 縁石基礎 ／ ベタ基礎 | C7: P22 5,000 ／ 22,000
A8: 搬入据付 スカイエア室内機 | B8: 天井埋込カセット形 | C8: P140 29,000
A9: 搬入据付 スカイエア室内機 | B9: ダクト形 | C9: P140 23,000
A10: 搬入据付 スカイエア室外機 | B10: 地上設置 ／ 2F設置 ／ 3F設置 | C10: P140 15,000 ／ 35,000 ／ 50,000
A11: 搬入据付 ルームエアコン室内機 | B11: 壁掛形 | C11: P22 5,000
A12: 搬入据付 ルームエアコン室外機 | B12: 地上設置 ／ 屋根設置 ／ 壁面設置 | C12: P22 2,000 ／ 5,500 ／ 7,000
A13: フレキダクト工事 スカイエア | B13: 5m以下 ／ 追加1m ／ 吹出口1ケ | C13: P140 21,000 ／ 4,200 ／ 6,000
A14: 冷媒配管（テープ巻き）新築 | B14: φ6.4/9.5 ／ φ9.5/15.9 | C14: 5m以下 26,000＋1m追加 5,300 ／ 5m以下 29,500＋1m追加 5,900
A15: 外装仕上げ スカイダクト | B15: φ6.4/9.5 ／ φ9.5/15.9 | C15: 5m以下 10,500＋1m追加 2,100 ／ 5m以下 15,800＋1m追加 2,600
... A18: ドレン配管 新築 | B18: φ6.4/9.5 ／ φ9.5/15.9 | C18: 5m以下 10,500＋1m追加 2,100 ／ 5m以下 14,200＋1m追加 2,800

Sheet 数量拾い根拠(内部)
A1: 数量拾い根拠（内部用） ※空調設備図 F-02-1（A3 1/50）のベクトル線分（黒・線幅0.72pt）を連結し系統別に延長を集計（data/takeoff_f02.py）。「実測」=図面線分の平面延長、「想定」=立上り・立下り等の図面に無い部分
A2: 縮尺確認: 通り芯 Y6-Y5 910mm＝51.6pt、Y5-Y4 1,820mm＝103.3pt → 1pt＝17.64mm。拾い根拠画像: takeoff_F02_冷媒ドレン.png
A4: 1. 冷媒配管 系統別（空調設備図 F-02-1 1/50 実測＋想定）
A5: 系統 | B5: 管径 | C5: 平面実測(m) | D5: 想定加算(m) | E5: 合計(m) | F5: 想定内容
A6: AC-1（客席西 天井カセット） | B6: φ9.52/15.88 | C6: 11.15 | D6: 3 | E6: 14.15 | F6: 架台下段 立上り 2.2m・機器接続 0.3m・余長 0.5m
A7: AC-1（客席東 天井カセット） | B7: φ9.52/15.88 | C7: 7.54 | D7: 1.7 | E7: 9.24 | F7: 架台上段 立上り 0.9m・機器接続 0.3m・余長 0.5m
A8: AC-2（厨房 天井ビルトイン） | B8: φ9.52/15.88 | C8: 8.08 | D8: 3 | E8: 11.08 | F8: 架台下段 立上り 2.2m・機器接続 0.3m・余長 0.5m
A9: RAC（店長室 壁掛） | B9: φ6.35/9.52 | C9: 7.65 | D9: 1.8 | E9: 9.45 | F9: 架台上段 立上り 0.9m・壁掛機への立下り 0.6m・余長 0.3m
A10: 合計 → 内訳書 | C10: 34.42 | D10: 9.5 | E10: 43.92 | F10: φ9.52/15.88 35m・φ6.35/9.52 10m（切上げ）
A12: 2. 外部冷媒配管 化粧カバー
A13: 系統 | B13: 屋外平面(m) | C13: 立上り(m) | D13: 合計(m) | F13: 備考
A14: AC-1（下段） | B14: 0.65 | C14: 2.2 | D14: 2.85 | F14: 外壁 Y6 より北の線分を実測
A15: AC-1（上段） | B15: 1.27 | C15: 0.9 | D15: 2.17
A16: AC-2（下段） | B16: 0.68 | C16: 2.2 | D16: 2.88
A17: RAC（上段） | B17: 1.21 | C17: 0.9 | D17: 2.11
A18: 合計 → 内訳書 | B18: 3.81 | C18: 6.2 | D18: 10.01 | F18: 9.52+15.88用 8m（7.90）・6.35+9.52用 3m（2.11）
A20: 3. ドレン配管（空調設備図の口径ラベルで区分）
A21: 区間 | B21: 口径 | C21: 平面実測(m) | D21: 想定加算(m) | E21: 合計(m) | F21: 備考
A22: 主管 接続立上り〜西カセット合流 | B22: 40A | C22: 3.29 | D22: 2.45 | E22: 5.74 | F22: 天井内→H=150 立下り 2.45m
A23: 主管 西カセット合流〜AC-2合流 | B23: 30A | C23: 3.41 | D23: 0 | E23: 3.41
A24: 主管 AC-2合流〜東カセット | B24: 25A | C24: 2.72 | D24: 0.6 | E24: 3.32 | F24: 機器接続・ドレンアップ立上り
A25: AC-2 枝 | B25: 25A | C25: 1.28 | D25: 0.3 | E25: 1.58 | F25: ドレンアップ立上り
A26: 西カセット 枝 | B26: 25A | C26: 0.76 | D26: 0.3 | E26: 1.06 | F26: ドレンアップ立上り
A27: RAC | B27: 25A | C27: 0.44 | D27: 1.9 | E27: 2.34 | F27: 壁内 立下り（NDB-20-25 経由で接続）
A28: 合計 → 内訳書 | C28: 11.9 | D28: 5.55 | E28: 17.45 | F28: VP25 9m・VP30 4m・VP40 6m（保温も同長）
A30: 4. 機器台数（換気空調機器表・室外機設置概要図）
A31: 記号 | B31: 台数 | C31: 備考
A32: AC-1 天井カセット形 5馬力 SSRC140C | B32: 室内2・室外2 | C32: 客席。室外機は架台①の下段・上段
A33: AC-2 天井ビルトイン形 5馬力 SSRB140C | B33: 室内1・室外1 | C33: 厨房。室外機は架台②の下段。吹出しパンカー×4（支給）・ダクトは範囲外
A34: RAC ルームエアコン 2.2kW | B34: 室内1・室外1 | C34: 店長室。室外機は架台②の上段
A35: 鉄骨架台 2段積み | B35: 2基 | C35: 特記「空調本工事」。溶融亜鉛メッキ
A36: 外壁貫通 | B36: 4箇所 | C36: 冷媒管 4系統の外壁貫通位置（F-02-1）→ エストの「スリーブインサート費 1式」に対応
A37: 内外連絡線 VVF 2.0-3C | B37: 56m | C37: 図示なし。冷媒配管の系統長＋余長3m/系統（エスト見積 56m と一致）

Sheet 原価根拠(内部)
A1: 原価根拠（内部用） 材料＝建設物価相当、労務＝人工×労務原価日額、法定福利費＝労務原価×事業主負担率
A3: 出典
A4: エスト見積 | B4: 見積番号 6330560-1（2026年10月8日、2026/11月からの価格）。単価・経費率・配管工費の算式の基準
A5: エスト単価マスタ | B5: 搬入据付・基礎・フレキダクト・冷媒配管/外装仕上げ/ドレン配管（5m以下＋1m追加）。参考列に表示
A6: 公共工事設計労務単価 | B6: 令和8年3月適用（農林水産省・国土交通省）広島県: 配管工 24,700、保温工 25,100、電工 26,300、ダクト工 24,300、普通作業員 22,200 円/日
A7: 公共建築工事標準単価積算基準 | B7: 令和8年改定（国土交通省 官庁営繕部）第4編 機械設備工事 表M1-1-50 冷媒用断熱材被覆銅管、表M1-1-46 硬質ポリ塩化ビニル管（排水・通気）
A8: メーカー公表価格 | B8: 桃陽電線 冷媒用被覆銅管 標準単価表 2026年2月1日改定版（国交省仕様 10×20mm保温 3分5分 175,400円/20m 等）
A9: 建設物価 | B9: 会員制のため数値未取得。自治体の公表単価表（新潟市・佐賀県・鹿児島県 令和8年度）でも冷媒用被覆銅管・保温は主要資材として非公表。材料原価はエスト材料単価を建設物価相当として仮採用（材料原価率で調整）
A11: 公共工事設計労務単価（令和8年3月適用・広島県、円/日）
A12: 配管工 | B12: 24700
A13: 保温工 | B13: 25100
A14: 電工 | B14: 26300
A15: ダクト工 | B15: 24300
A16: 普通作業員 | B16: 22200
A17: 特殊作業員 | B17: 25800
A18: 設備機械工 | B18: 29500
A19: 鉄骨工 | B19: 27000
A20: 溶接工 | B20: 27300
A21: ※ 設計労務単価は事業主負担の法定福利費等を含まない。当社の労務原価日額（表紙 N6）との比較・感度確認に使用
A23: 国交省 公共建築工事標準単価積算基準（令和8年改定）配管工 歩掛（人/m）
A24: 冷媒用断熱材被覆銅管（液10・ガス20）6.35 | B24: 0.044
A25: 同 9.52 | B25: 0.06
A26: 同 15.88 | B26: 0.09
A27: 硬質塩ビ管VP 排水・屋内一般 25 | B27: 0.074
A28: 同 30 | B28: 0.079
A29: 同 40 | B29: 0.101
A30: ※ 被覆銅管は液管・ガス管それぞれの外径の歩掛を合算。継手・接合材 管単価×0.30、支持金物 ×0.40、雑材料 ×0.15、管長 1.05（塩ビ 1.10）
A32: メーカー公表価格（参考）
A33: 桃陽電線 TDS-3520A 3分5分 10×20mm保温 20m巻（2026.2.1） | B33: 175400 | C33: 1mあたり 8,770 円。エスト材料単価はこの約6割（3分5分 5,138円/m＝58.6%、2分3分 3,388円/m＝61.3%）＝実勢価格水準
A34: 桃陽電線 TDS-2320A 2分3分 10×20mm保温 20m巻（2026.2.1） | B34: 110600 | C34: 1mあたり 5,530 円。エスト材料単価はこの約6割（3分5分 5,138円/m＝58.6%、2分3分 3,388円/m＝61.3%）＝実勢価格水準
A36: 原価の前提（内訳書 L・M 列の黄セル）
A37: ・据付の人工: 天井カセット 0.9、天井ビルトイン 1.2、RA室内 0.4、SA室外 下段0.8・上段1.3（揚重）、RA室外 上段0.5 人工/台
A38: ・縁石: 材料3,000＋0.15人工/台。試運転: SA 材料450＋0.45人工、RA 0.1人工。気密: SA 2,000＋0.45、RA 1,000＋0.2。真空引き: SA 500＋0.15、RA 300＋0.1
A39: ・化粧カバー: 材料 小径1,800・大径2,400円/m＋0.10人工/m。GW保温: 25A 900＋0.06、30A 1,000＋0.065、40A 1,100＋0.07（市場単価は非公表のため当社想定）
A40: ・スリーブ: 4箇所×（材料1,500＋0.25人工）。架台: 要見積（概算原価 300,000／250,000、鉄工所またはメーカー見積で差し替え）
A41: ・材料原価率を下げると（実際の仕入が建設物価より安い場合）提出額は下がる。材料原価率0.8で提出額は約1,180,000円（粗利20%）
